2020-02-07 17:38:45,023 DEBUG download_runner.impl.historical_end_reader:37 poll stock ? => True
2020-02-07 17:38:45,216 ERROR root:30 unhandled exception getting latest timestamp for A
Traceback (most recent call last):
  File "/Users/dali/workspace/ib_python/runner/services/historical_data_service.py", line 24, in get_latest_timestamp
    response = self.stub.GetLatestTimeStamp(request)
  File "/Users/dali/workspace/ib_python/runner/venv/lib/python3.7/site-packages/grpc/_channel.py", line 604, in __call__
    return _end_unary_response_blocking(state, call, False, None)
  File "/Users/dali/workspace/ib_python/runner/venv/lib/python3.7/site-packages/grpc/_channel.py", line 506, in _end_unary_response_blocking
    raise _Rendezvous(state, None, None, deadline)
grpc._channel._Rendezvous: <_Rendezvous of RPC that terminated with:
	status = StatusCode.UNAVAILABLE
	details = "failed to connect to all addresses"
	debug_error_string = "{"created":"@1581097125.215924000","description":"Failed to pick subchannel","file":"src/core/ext/filters/client_channel/client_channel.cc","file_line":3876,"referenced_errors":[{"created":"@1581097125.215923000","description":"failed to connect to all addresses","file":"src/core/ext/filters/client_channel/lb_policy/pick_first/pick_first.cc","file_line":395,"grpc_status":14}]}"
>
2020-02-07 17:38:45,218 INFO download_runner.impl.historical_runner:32 sending - historical data request : A 2019-01-01 2020-01-01
2020-02-07 17:38:45,533 INFO download_runner.impl.historical_runner:35 sent - historical data request : A 2019-01-01 2020-01-01
2020-02-07 17:38:45,533 DEBUG download_runner.impl.historical_runner:36 request accounted for...
2020-02-07 17:38:45,533 INFO download_runner.impl.historical_runner:37 status : True
2020-02-07 17:38:45,533 INFO download_runner.impl.historical_runner:42 Historical data request sent : A 2019-01-01 2020-01-01
2020-02-07 17:38:45,533 DEBUG download_runner.impl.historical_end_reader:37 poll stock ? => True
2020-02-07 17:38:45,534 ERROR root:30 unhandled exception getting latest timestamp for ACIA
Traceback (most recent call last):
  File "/Users/dali/workspace/ib_python/runner/services/historical_data_service.py", line 24, in get_latest_timestamp
    response = self.stub.GetLatestTimeStamp(request)
  File "/Users/dali/workspace/ib_python/runner/venv/lib/python3.7/site-packages/grpc/_channel.py", line 604, in __call__
    return _end_unary_response_blocking(state, call, False, None)
  File "/Users/dali/workspace/ib_python/runner/venv/lib/python3.7/site-packages/grpc/_channel.py", line 506, in _end_unary_response_blocking
    raise _Rendezvous(state, None, None, deadline)
grpc._channel._Rendezvous: <_Rendezvous of RPC that terminated with:
	status = StatusCode.UNAVAILABLE
	details = "failed to connect to all addresses"
	debug_error_string = "{"created":"@1581097125.534191000","description":"Failed to pick subchannel","file":"src/core/ext/filters/client_channel/client_channel.cc","file_line":3876,"referenced_errors":[{"created":"@1581097125.215923000","description":"failed to connect to all addresses","file":"src/core/ext/filters/client_channel/lb_policy/pick_first/pick_first.cc","file_line":395,"grpc_status":14}]}"
>
2020-02-07 17:38:45,534 INFO download_runner.impl.historical_runner:32 sending - historical data request : ACIA 2019-01-01 2020-01-01
2020-02-07 17:38:45,894 INFO download_runner.impl.historical_runner:35 sent - historical data request : ACIA 2019-01-01 2020-01-01
2020-02-07 17:38:45,894 DEBUG download_runner.impl.historical_runner:36 request accounted for...
2020-02-07 17:38:45,894 INFO download_runner.impl.historical_runner:37 status : True
2020-02-07 17:38:45,894 INFO download_runner.impl.historical_runner:42 Historical data request sent : ACIA 2019-01-01 2020-01-01
2020-02-07 17:38:45,894 DEBUG download_runner.impl.historical_end_reader:37 poll stock ? => True
2020-02-07 17:38:45,894 ERROR root:30 unhandled exception getting latest timestamp for ACIO
Traceback (most recent call last):
  File "/Users/dali/workspace/ib_python/runner/services/historical_data_service.py", line 24, in get_latest_timestamp
    response = self.stub.GetLatestTimeStamp(request)
  File "/Users/dali/workspace/ib_python/runner/venv/lib/python3.7/site-packages/grpc/_channel.py", line 604, in __call__
    return _end_unary_response_blocking(state, call, False, None)
  File "/Users/dali/workspace/ib_python/runner/venv/lib/python3.7/site-packages/grpc/_channel.py", line 506, in _end_unary_response_blocking
    raise _Rendezvous(state, None, None, deadline)
grpc._channel._Rendezvous: <_Rendezvous of RPC that terminated with:
	status = StatusCode.UNAVAILABLE
	details = "failed to connect to all addresses"
	debug_error_string = "{"created":"@1581097125.894920000","description":"Failed to pick subchannel","file":"src/core/ext/filters/client_channel/client_channel.cc","file_line":3876,"referenced_errors":[{"created":"@1581097125.215923000","description":"failed to connect to all addresses","file":"src/core/ext/filters/client_channel/lb_policy/pick_first/pick_first.cc","file_line":395,"grpc_status":14}]}"
>
2020-02-07 17:38:45,895 INFO download_runner.impl.historical_runner:32 sending - historical data request : ACIO 2019-01-01 2020-01-01
2020-02-07 17:38:46,342 INFO download_runner.impl.historical_runner:35 sent - historical data request : ACIO 2019-01-01 2020-01-01
2020-02-07 17:38:46,342 DEBUG download_runner.impl.historical_runner:36 request accounted for...
2020-02-07 17:38:46,342 INFO download_runner.impl.historical_runner:37 status : True
2020-02-07 17:38:46,342 INFO download_runner.impl.historical_runner:42 Historical data request sent : ACIO 2019-01-01 2020-01-01
2020-02-07 17:38:46,343 DEBUG download_runner.impl.historical_end_reader:37 poll stock ? => True
2020-02-07 17:38:46,343 ERROR root:30 unhandled exception getting latest timestamp for ACIU
Traceback (most recent call last):
  File "/Users/dali/workspace/ib_python/runner/services/historical_data_service.py", line 24, in get_latest_timestamp
    response = self.stub.GetLatestTimeStamp(request)
  File "/Users/dali/workspace/ib_python/runner/venv/lib/python3.7/site-packages/grpc/_channel.py", line 604, in __call__
    return _end_unary_response_blocking(state, call, False, None)
  File "/Users/dali/workspace/ib_python/runner/venv/lib/python3.7/site-packages/grpc/_channel.py", line 506, in _end_unary_response_blocking
    raise _Rendezvous(state, None, None, deadline)
grpc._channel._Rendezvous: <_Rendezvous of RPC that terminated with:
	status = StatusCode.UNAVAILABLE
	details = "failed to connect to all addresses"
	debug_error_string = "{"created":"@1581097126.343326000","description":"Failed to pick subchannel","file":"src/core/ext/filters/client_channel/client_channel.cc","file_line":3876,"referenced_errors":[{"created":"@1581097126.343324000","description":"failed to connect to all addresses","file":"src/core/ext/filters/client_channel/lb_policy/pick_first/pick_first.cc","file_line":395,"grpc_status":14}]}"
>
2020-02-07 17:38:46,343 INFO download_runner.impl.historical_runner:32 sending - historical data request : ACIU 2019-01-01 2020-01-01
2020-02-07 17:38:46,869 INFO download_runner.impl.historical_runner:35 sent - historical data request : ACIU 2019-01-01 2020-01-01
2020-02-07 17:38:46,869 DEBUG download_runner.impl.historical_runner:36 request accounted for...
2020-02-07 17:38:46,869 INFO download_runner.impl.historical_runner:37 status : True
2020-02-07 17:38:46,869 INFO download_runner.impl.historical_runner:42 Historical data request sent : ACIU 2019-01-01 2020-01-01
2020-02-07 17:38:46,869 DEBUG download_runner.impl.historical_end_reader:37 poll stock ? => True
2020-02-07 17:38:46,870 ERROR root:30 unhandled exception getting latest timestamp for ACIW
Traceback (most recent call last):
  File "/Users/dali/workspace/ib_python/runner/services/historical_data_service.py", line 24, in get_latest_timestamp
    response = self.stub.GetLatestTimeStamp(request)
  File "/Users/dali/workspace/ib_python/runner/venv/lib/python3.7/site-packages/grpc/_channel.py", line 604, in __call__
    return _end_unary_response_blocking(state, call, False, None)
  File "/Users/dali/workspace/ib_python/runner/venv/lib/python3.7/site-packages/grpc/_channel.py", line 506, in _end_unary_response_blocking
    raise _Rendezvous(state, None, None, deadline)
grpc._channel._Rendezvous: <_Rendezvous of RPC that terminated with:
	status = StatusCode.UNAVAILABLE
	details = "failed to connect to all addresses"
	debug_error_string = "{"created":"@1581097126.870031000","description":"Failed to pick subchannel","file":"src/core/ext/filters/client_channel/client_channel.cc","file_line":3876,"referenced_errors":[{"created":"@1581097126.343324000","description":"failed to connect to all addresses","file":"src/core/ext/filters/client_channel/lb_policy/pick_first/pick_first.cc","file_line":395,"grpc_status":14}]}"
>
2020-02-07 17:38:46,870 INFO download_runner.impl.historical_runner:32 sending - historical data request : ACIW 2019-01-01 2020-01-01
2020-02-07 17:38:47,578 INFO download_runner.impl.historical_runner:35 sent - historical data request : ACIW 2019-01-01 2020-01-01
2020-02-07 17:38:47,578 DEBUG download_runner.impl.historical_runner:36 request accounted for...
2020-02-07 17:38:47,578 INFO download_runner.impl.historical_runner:37 status : True
2020-02-07 17:38:47,578 INFO download_runner.impl.historical_runner:42 Historical data request sent : ACIW 2019-01-01 2020-01-01
2020-02-07 17:38:47,578 DEBUG download_runner.impl.historical_end_reader:37 poll stock ? => True
2020-02-07 17:38:47,578 ERROR root:30 unhandled exception getting latest timestamp for ACLS
Traceback (most recent call last):
  File "/Users/dali/workspace/ib_python/runner/services/historical_data_service.py", line 24, in get_latest_timestamp
    response = self.stub.GetLatestTimeStamp(request)
  File "/Users/dali/workspace/ib_python/runner/venv/lib/python3.7/site-packages/grpc/_channel.py", line 604, in __call__
    return _end_unary_response_blocking(state, call, False, None)
  File "/Users/dali/workspace/ib_python/runner/venv/lib/python3.7/site-packages/grpc/_channel.py", line 506, in _end_unary_response_blocking
    raise _Rendezvous(state, None, None, deadline)
grpc._channel._Rendezvous: <_Rendezvous of RPC that terminated with:
	status = StatusCode.UNAVAILABLE
	details = "failed to connect to all addresses"
	debug_error_string = "{"created":"@1581097127.578871000","description":"Failed to pick subchannel","file":"src/core/ext/filters/client_channel/client_channel.cc","file_line":3876,"referenced_errors":[{"created":"@1581097127.578868000","description":"failed to connect to all addresses","file":"src/core/ext/filters/client_channel/lb_policy/pick_first/pick_first.cc","file_line":395,"grpc_status":14}]}"
>
2020-02-07 17:38:47,579 INFO download_runner.impl.historical_runner:32 sending - historical data request : ACLS 2019-01-01 2020-01-01
2020-02-07 17:38:51,930 INFO download_runner.impl.historical_runner:35 sent - historical data request : ACLS 2019-01-01 2020-01-01
2020-02-07 17:38:51,931 DEBUG download_runner.impl.historical_runner:36 request accounted for...
2020-02-07 17:38:51,931 INFO download_runner.impl.historical_runner:37 status : True
2020-02-07 17:38:51,931 INFO download_runner.impl.historical_runner:42 Historical data request sent : ACLS 2019-01-01 2020-01-01
2020-02-07 17:38:51,931 DEBUG download_runner.impl.historical_end_reader:37 poll stock ? => True
2020-02-07 17:38:51,931 ERROR root:30 unhandled exception getting latest timestamp for ACM
Traceback (most recent call last):
  File "/Users/dali/workspace/ib_python/runner/services/historical_data_service.py", line 24, in get_latest_timestamp
    response = self.stub.GetLatestTimeStamp(request)
  File "/Users/dali/workspace/ib_python/runner/venv/lib/python3.7/site-packages/grpc/_channel.py", line 604, in __call__
    return _end_unary_response_blocking(state, call, False, None)
  File "/Users/dali/workspace/ib_python/runner/venv/lib/python3.7/site-packages/grpc/_channel.py", line 506, in _end_unary_response_blocking
    raise _Rendezvous(state, None, None, deadline)
grpc._channel._Rendezvous: <_Rendezvous of RPC that terminated with:
	status = StatusCode.UNAVAILABLE
	details = "failed to connect to all addresses"
	debug_error_string = "{"created":"@1581097131.931605000","description":"Failed to pick subchannel","file":"src/core/ext/filters/client_channel/client_channel.cc","file_line":3876,"referenced_errors":[{"created":"@1581097131.931602000","description":"failed to connect to all addresses","file":"src/core/ext/filters/client_channel/lb_policy/pick_first/pick_first.cc","file_line":395,"grpc_status":14}]}"
>
2020-02-07 17:38:51,931 INFO download_runner.impl.historical_runner:32 sending - historical data request : ACM 2019-01-01 2020-01-01
2020-02-07 17:38:52,516 INFO download_runner.impl.historical_runner:35 sent - historical data request : ACM 2019-01-01 2020-01-01
2020-02-07 17:38:52,516 DEBUG download_runner.impl.historical_runner:36 request accounted for...
2020-02-07 17:38:52,516 INFO download_runner.impl.historical_runner:37 status : True
2020-02-07 17:38:52,516 INFO download_runner.impl.historical_runner:42 Historical data request sent : ACM 2019-01-01 2020-01-01
2020-02-07 17:38:52,516 DEBUG download_runner.impl.historical_end_reader:37 poll stock ? => True
2020-02-07 17:38:52,517 ERROR root:30 unhandled exception getting latest timestamp for ACMR
Traceback (most recent call last):
  File "/Users/dali/workspace/ib_python/runner/services/historical_data_service.py", line 24, in get_latest_timestamp
    response = self.stub.GetLatestTimeStamp(request)
  File "/Users/dali/workspace/ib_python/runner/venv/lib/python3.7/site-packages/grpc/_channel.py", line 604, in __call__
    return _end_unary_response_blocking(state, call, False, None)
  File "/Users/dali/workspace/ib_python/runner/venv/lib/python3.7/site-packages/grpc/_channel.py", line 506, in _end_unary_response_blocking
    raise _Rendezvous(state, None, None, deadline)
grpc._channel._Rendezvous: <_Rendezvous of RPC that terminated with:
	status = StatusCode.UNAVAILABLE
	details = "failed to connect to all addresses"
	debug_error_string = "{"created":"@1581097132.517206000","description":"Failed to pick subchannel","file":"src/core/ext/filters/client_channel/client_channel.cc","file_line":3876,"referenced_errors":[{"created":"@1581097131.931602000","description":"failed to connect to all addresses","file":"src/core/ext/filters/client_channel/lb_policy/pick_first/pick_first.cc","file_line":395,"grpc_status":14}]}"
>
2020-02-07 17:38:52,517 INFO download_runner.impl.historical_runner:32 sending - historical data request : ACMR 2019-01-01 2020-01-01
2020-02-07 17:38:57,817 INFO download_runner.impl.historical_runner:35 sent - historical data request : ACMR 2019-01-01 2020-01-01
2020-02-07 17:38:57,817 DEBUG download_runner.impl.historical_runner:36 request accounted for...
2020-02-07 17:38:57,817 INFO download_runner.impl.historical_runner:37 status : True
2020-02-07 17:38:57,817 INFO download_runner.impl.historical_runner:42 Historical data request sent : ACMR 2019-01-01 2020-01-01
2020-02-07 17:38:57,817 DEBUG download_runner.impl.historical_end_reader:37 poll stock ? => True
2020-02-07 17:38:57,817 ERROR root:30 unhandled exception getting latest timestamp for ACN
Traceback (most recent call last):
  File "/Users/dali/workspace/ib_python/runner/services/historical_data_service.py", line 24, in get_latest_timestamp
    response = self.stub.GetLatestTimeStamp(request)
  File "/Users/dali/workspace/ib_python/runner/venv/lib/python3.7/site-packages/grpc/_channel.py", line 604, in __call__
    return _end_unary_response_blocking(state, call, False, None)
  File "/Users/dali/workspace/ib_python/runner/venv/lib/python3.7/site-packages/grpc/_channel.py", line 506, in _end_unary_response_blocking
    raise _Rendezvous(state, None, None, deadline)
grpc._channel._Rendezvous: <_Rendezvous of RPC that terminated with:
	status = StatusCode.UNAVAILABLE
	details = "failed to connect to all addresses"
	debug_error_string = "{"created":"@1581097137.817839000","description":"Failed to pick subchannel","file":"src/core/ext/filters/client_channel/client_channel.cc","file_line":3876,"referenced_errors":[{"created":"@1581097135.027040000","description":"failed to connect to all addresses","file":"src/core/ext/filters/client_channel/lb_policy/pick_first/pick_first.cc","file_line":395,"grpc_status":14}]}"
>
2020-02-07 17:38:57,818 INFO download_runner.impl.historical_runner:32 sending - historical data request : ACN 2019-01-01 2020-01-01
2020-02-07 17:38:58,617 INFO download_runner.impl.historical_runner:35 sent - historical data request : ACN 2019-01-01 2020-01-01
2020-02-07 17:38:58,617 DEBUG download_runner.impl.historical_runner:36 request accounted for...
2020-02-07 17:38:58,617 INFO download_runner.impl.historical_runner:37 status : True
2020-02-07 17:38:58,617 INFO download_runner.impl.historical_runner:42 Historical data request sent : ACN 2019-01-01 2020-01-01
2020-02-07 17:38:58,617 DEBUG download_runner.impl.historical_end_reader:37 poll stock ? => True
2020-02-07 17:38:58,617 ERROR root:30 unhandled exception getting latest timestamp for ACNB
Traceback (most recent call last):
  File "/Users/dali/workspace/ib_python/runner/services/historical_data_service.py", line 24, in get_latest_timestamp
    response = self.stub.GetLatestTimeStamp(request)
  File "/Users/dali/workspace/ib_python/runner/venv/lib/python3.7/site-packages/grpc/_channel.py", line 604, in __call__
    return _end_unary_response_blocking(state, call, False, None)
  File "/Users/dali/workspace/ib_python/runner/venv/lib/python3.7/site-packages/grpc/_channel.py", line 506, in _end_unary_response_blocking
    raise _Rendezvous(state, None, None, deadline)
grpc._channel._Rendezvous: <_Rendezvous of RPC that terminated with:
	status = StatusCode.UNAVAILABLE
	details = "failed to connect to all addresses"
	debug_error_string = "{"created":"@1581097138.617623000","description":"Failed to pick subchannel","file":"src/core/ext/filters/client_channel/client_channel.cc","file_line":3876,"referenced_errors":[{"created":"@1581097135.027040000","description":"failed to connect to all addresses","file":"src/core/ext/filters/client_channel/lb_policy/pick_first/pick_first.cc","file_line":395,"grpc_status":14}]}"
>
2020-02-07 17:38:58,617 INFO download_runner.impl.historical_runner:32 sending - historical data request : ACNB 2019-01-01 2020-01-01
2020-02-07 17:39:03,830 INFO download_runner.impl.historical_runner:35 sent - historical data request : ACNB 2019-01-01 2020-01-01
2020-02-07 17:39:03,830 DEBUG download_runner.impl.historical_runner:36 request accounted for...
2020-02-07 17:39:03,830 INFO download_runner.impl.historical_runner:37 status : True
2020-02-07 17:39:03,830 INFO download_runner.impl.historical_runner:42 Historical data request sent : ACNB 2019-01-01 2020-01-01
2020-02-07 17:39:03,830 DEBUG download_runner.impl.historical_end_reader:37 poll stock ? => True
2020-02-07 17:39:03,831 ERROR root:30 unhandled exception getting latest timestamp for ACOR
Traceback (most recent call last):
  File "/Users/dali/workspace/ib_python/runner/services/historical_data_service.py", line 24, in get_latest_timestamp
    response = self.stub.GetLatestTimeStamp(request)
  File "/Users/dali/workspace/ib_python/runner/venv/lib/python3.7/site-packages/grpc/_channel.py", line 604, in __call__
    return _end_unary_response_blocking(state, call, False, None)
  File "/Users/dali/workspace/ib_python/runner/venv/lib/python3.7/site-packages/grpc/_channel.py", line 506, in _end_unary_response_blocking
    raise _Rendezvous(state, None, None, deadline)
grpc._channel._Rendezvous: <_Rendezvous of RPC that terminated with:
	status = StatusCode.UNAVAILABLE
	details = "failed to connect to all addresses"
	debug_error_string = "{"created":"@1581097143.831135000","description":"Failed to pick subchannel","file":"src/core/ext/filters/client_channel/client_channel.cc","file_line":3876,"referenced_errors":[{"created":"@1581097143.831133000","description":"failed to connect to all addresses","file":"src/core/ext/filters/client_channel/lb_policy/pick_first/pick_first.cc","file_line":395,"grpc_status":14}]}"
>
2020-02-07 17:39:03,831 INFO download_runner.impl.historical_runner:32 sending - historical data request : ACOR 2019-01-01 2020-01-01
2020-02-07 17:39:04,630 INFO download_runner.impl.historical_runner:35 sent - historical data request : ACOR 2019-01-01 2020-01-01
2020-02-07 17:39:04,630 DEBUG download_runner.impl.historical_runner:36 request accounted for...
2020-02-07 17:39:04,631 INFO download_runner.impl.historical_runner:37 status : True
2020-02-07 17:39:04,631 INFO download_runner.impl.historical_runner:42 Historical data request sent : ACOR 2019-01-01 2020-01-01
2020-02-07 17:39:04,631 DEBUG download_runner.impl.historical_end_reader:37 poll stock ? => True
2020-02-07 17:39:04,631 ERROR root:30 unhandled exception getting latest timestamp for ACP
Traceback (most recent call last):
  File "/Users/dali/workspace/ib_python/runner/services/historical_data_service.py", line 24, in get_latest_timestamp
    response = self.stub.GetLatestTimeStamp(request)
  File "/Users/dali/workspace/ib_python/runner/venv/lib/python3.7/site-packages/grpc/_channel.py", line 604, in __call__
    return _end_unary_response_blocking(state, call, False, None)
  File "/Users/dali/workspace/ib_python/runner/venv/lib/python3.7/site-packages/grpc/_channel.py", line 506, in _end_unary_response_blocking
    raise _Rendezvous(state, None, None, deadline)
grpc._channel._Rendezvous: <_Rendezvous of RPC that terminated with:
	status = StatusCode.UNAVAILABLE
	details = "failed to connect to all addresses"
	debug_error_string = "{"created":"@1581097144.631431000","description":"Failed to pick subchannel","file":"src/core/ext/filters/client_channel/client_channel.cc","file_line":3876,"referenced_errors":[{"created":"@1581097143.831133000","description":"failed to connect to all addresses","file":"src/core/ext/filters/client_channel/lb_policy/pick_first/pick_first.cc","file_line":395,"grpc_status":14}]}"
>
2020-02-07 17:39:04,631 INFO download_runner.impl.historical_runner:32 sending - historical data request : ACP 2019-01-01 2020-01-01
2020-02-07 17:39:10,115 INFO download_runner.impl.historical_runner:35 sent - historical data request : ACP 2019-01-01 2020-01-01
2020-02-07 17:39:10,116 DEBUG download_runner.impl.historical_runner:36 request accounted for...
2020-02-07 17:39:10,116 INFO download_runner.impl.historical_runner:37 status : True
2020-02-07 17:39:10,116 INFO download_runner.impl.historical_runner:42 Historical data request sent : ACP 2019-01-01 2020-01-01
2020-02-07 17:39:10,116 DEBUG download_runner.impl.historical_end_reader:37 poll stock ? => True
2020-02-07 17:39:10,116 ERROR root:30 unhandled exception getting latest timestamp for ACRE
Traceback (most recent call last):
  File "/Users/dali/workspace/ib_python/runner/services/historical_data_service.py", line 24, in get_latest_timestamp
    response = self.stub.GetLatestTimeStamp(request)
  File "/Users/dali/workspace/ib_python/runner/venv/lib/python3.7/site-packages/grpc/_channel.py", line 604, in __call__
    return _end_unary_response_blocking(state, call, False, None)
  File "/Users/dali/workspace/ib_python/runner/venv/lib/python3.7/site-packages/grpc/_channel.py", line 506, in _end_unary_response_blocking
    raise _Rendezvous(state, None, None, deadline)
grpc._channel._Rendezvous: <_Rendezvous of RPC that terminated with:
	status = StatusCode.UNAVAILABLE
	details = "failed to connect to all addresses"
	debug_error_string = "{"created":"@1581097150.116527000","description":"Failed to pick subchannel","file":"src/core/ext/filters/client_channel/client_channel.cc","file_line":3876,"referenced_errors":[{"created":"@1581097143.831133000","description":"failed to connect to all addresses","file":"src/core/ext/filters/client_channel/lb_policy/pick_first/pick_first.cc","file_line":395,"grpc_status":14}]}"
>
2020-02-07 17:39:10,116 INFO download_runner.impl.historical_runner:32 sending - historical data request : ACRE 2019-01-01 2020-01-01
2020-02-07 17:39:21,850 INFO download_runner.impl.historical_runner:35 sent - historical data request : ACRE 2019-01-01 2020-01-01
2020-02-07 17:39:21,850 DEBUG download_runner.impl.historical_runner:36 request accounted for...
2020-02-07 17:39:21,850 INFO download_runner.impl.historical_runner:37 status : True
2020-02-07 17:39:21,850 INFO download_runner.impl.historical_runner:42 Historical data request sent : ACRE 2019-01-01 2020-01-01
2020-02-07 17:39:21,850 DEBUG download_runner.impl.historical_end_reader:37 poll stock ? => True
2020-02-07 17:39:21,850 ERROR root:30 unhandled exception getting latest timestamp for ACRS
Traceback (most recent call last):
  File "/Users/dali/workspace/ib_python/runner/services/historical_data_service.py", line 24, in get_latest_timestamp
    response = self.stub.GetLatestTimeStamp(request)
  File "/Users/dali/workspace/ib_python/runner/venv/lib/python3.7/site-packages/grpc/_channel.py", line 604, in __call__
    return _end_unary_response_blocking(state, call, False, None)
  File "/Users/dali/workspace/ib_python/runner/venv/lib/python3.7/site-packages/grpc/_channel.py", line 506, in _end_unary_response_blocking
    raise _Rendezvous(state, None, None, deadline)
grpc._channel._Rendezvous: <_Rendezvous of RPC that terminated with:
	status = StatusCode.UNAVAILABLE
	details = "failed to connect to all addresses"
	debug_error_string = "{"created":"@1581097161.850530000","description":"Failed to pick subchannel","file":"src/core/ext/filters/client_channel/client_channel.cc","file_line":3876,"referenced_errors":[{"created":"@1581097155.044247000","description":"failed to connect to all addresses","file":"src/core/ext/filters/client_channel/lb_policy/pick_first/pick_first.cc","file_line":395,"grpc_status":14}]}"
>
2020-02-07 17:39:21,850 INFO download_runner.impl.historical_runner:32 sending - historical data request : ACRS 2019-01-01 2020-01-01
2020-02-07 17:39:33,802 INFO download_runner.impl.historical_runner:35 sent - historical data request : ACRS 2019-01-01 2020-01-01
2020-02-07 17:39:33,802 DEBUG download_runner.impl.historical_runner:36 request accounted for...
2020-02-07 17:39:33,803 INFO download_runner.impl.historical_runner:37 status : True
2020-02-07 17:39:33,803 INFO download_runner.impl.historical_runner:42 Historical data request sent : ACRS 2019-01-01 2020-01-01
2020-02-07 17:39:33,803 DEBUG download_runner.impl.historical_end_reader:37 poll stock ? => True
2020-02-07 17:39:33,803 ERROR root:30 unhandled exception getting latest timestamp for ACRX
Traceback (most recent call last):
  File "/Users/dali/workspace/ib_python/runner/services/historical_data_service.py", line 24, in get_latest_timestamp
    response = self.stub.GetLatestTimeStamp(request)
  File "/Users/dali/workspace/ib_python/runner/venv/lib/python3.7/site-packages/grpc/_channel.py", line 604, in __call__
    return _end_unary_response_blocking(state, call, False, None)
  File "/Users/dali/workspace/ib_python/runner/venv/lib/python3.7/site-packages/grpc/_channel.py", line 506, in _end_unary_response_blocking
    raise _Rendezvous(state, None, None, deadline)
grpc._channel._Rendezvous: <_Rendezvous of RPC that terminated with:
	status = StatusCode.UNAVAILABLE
	details = "failed to connect to all addresses"
	debug_error_string = "{"created":"@1581097173.803473000","description":"Failed to pick subchannel","file":"src/core/ext/filters/client_channel/client_channel.cc","file_line":3876,"referenced_errors":[{"created":"@1581097170.053953000","description":"failed to connect to all addresses","file":"src/core/ext/filters/client_channel/lb_policy/pick_first/pick_first.cc","file_line":395,"grpc_status":14}]}"
>
2020-02-07 17:39:33,803 INFO download_runner.impl.historical_runner:32 sending - historical data request : ACRX 2019-01-01 2020-01-01
2020-02-07 17:39:46,306 INFO download_runner.impl.historical_runner:35 sent - historical data request : ACRX 2019-01-01 2020-01-01
2020-02-07 17:39:46,307 DEBUG download_runner.impl.historical_runner:36 request accounted for...
2020-02-07 17:39:46,307 INFO download_runner.impl.historical_runner:37 status : True
2020-02-07 17:39:46,307 INFO download_runner.impl.historical_runner:42 Historical data request sent : ACRX 2019-01-01 2020-01-01
2020-02-07 17:39:46,307 DEBUG download_runner.impl.historical_end_reader:37 poll stock ? => True
2020-02-07 17:39:46,307 ERROR root:30 unhandled exception getting latest timestamp for ACSG
Traceback (most recent call last):
  File "/Users/dali/workspace/ib_python/runner/services/historical_data_service.py", line 24, in get_latest_timestamp
    response = self.stub.GetLatestTimeStamp(request)
  File "/Users/dali/workspace/ib_python/runner/venv/lib/python3.7/site-packages/grpc/_channel.py", line 604, in __call__
    return _end_unary_response_blocking(state, call, False, None)
  File "/Users/dali/workspace/ib_python/runner/venv/lib/python3.7/site-packages/grpc/_channel.py", line 506, in _end_unary_response_blocking
    raise _Rendezvous(state, None, None, deadline)
grpc._channel._Rendezvous: <_Rendezvous of RPC that terminated with:
	status = StatusCode.UNAVAILABLE
	details = "failed to connect to all addresses"
	debug_error_string = "{"created":"@1581097186.307376000","description":"Failed to pick subchannel","file":"src/core/ext/filters/client_channel/client_channel.cc","file_line":3876,"referenced_errors":[{"created":"@1581097170.053953000","description":"failed to connect to all addresses","file":"src/core/ext/filters/client_channel/lb_policy/pick_first/pick_first.cc","file_line":395,"grpc_status":14}]}"
>
2020-02-07 17:39:46,307 INFO download_runner.impl.historical_runner:32 sending - historical data request : ACSG 2019-01-01 2020-01-01
2020-02-07 17:39:47,101 INFO download_runner.impl.historical_runner:35 sent - historical data request : ACSG 2019-01-01 2020-01-01
2020-02-07 17:39:47,102 DEBUG download_runner.impl.historical_runner:36 request accounted for...
2020-02-07 17:39:47,102 INFO download_runner.impl.historical_runner:37 status : True
2020-02-07 17:39:47,102 INFO download_runner.impl.historical_runner:42 Historical data request sent : ACSG 2019-01-01 2020-01-01
2020-02-07 17:39:47,102 DEBUG download_runner.impl.historical_end_reader:37 poll stock ? => True
2020-02-07 17:39:47,103 ERROR root:30 unhandled exception getting latest timestamp for ACSI
Traceback (most recent call last):
  File "/Users/dali/workspace/ib_python/runner/services/historical_data_service.py", line 24, in get_latest_timestamp
    response = self.stub.GetLatestTimeStamp(request)
  File "/Users/dali/workspace/ib_python/runner/venv/lib/python3.7/site-packages/grpc/_channel.py", line 604, in __call__
    return _end_unary_response_blocking(state, call, False, None)
  File "/Users/dali/workspace/ib_python/runner/venv/lib/python3.7/site-packages/grpc/_channel.py", line 506, in _end_unary_response_blocking
    raise _Rendezvous(state, None, None, deadline)
grpc._channel._Rendezvous: <_Rendezvous of RPC that terminated with:
	status = StatusCode.UNAVAILABLE
	details = "failed to connect to all addresses"
	debug_error_string = "{"created":"@1581097187.102983000","description":"Failed to pick subchannel","file":"src/core/ext/filters/client_channel/client_channel.cc","file_line":3876,"referenced_errors":[{"created":"@1581097170.053953000","description":"failed to connect to all addresses","file":"src/core/ext/filters/client_channel/lb_policy/pick_first/pick_first.cc","file_line":395,"grpc_status":14}]}"
>
2020-02-07 17:39:47,104 INFO download_runner.impl.historical_runner:32 sending - historical data request : ACSI 2019-01-01 2020-01-01
2020-02-07 17:39:47,938 INFO download_runner.impl.historical_runner:35 sent - historical data request : ACSI 2019-01-01 2020-01-01
2020-02-07 17:39:47,938 DEBUG download_runner.impl.historical_runner:36 request accounted for...
2020-02-07 17:39:47,938 INFO download_runner.impl.historical_runner:37 status : True
2020-02-07 17:39:47,939 INFO download_runner.impl.historical_runner:42 Historical data request sent : ACSI 2019-01-01 2020-01-01
2020-02-07 17:39:47,939 DEBUG download_runner.impl.historical_end_reader:37 poll stock ? => True
2020-02-07 17:39:47,939 ERROR root:30 unhandled exception getting latest timestamp for ACST
Traceback (most recent call last):
  File "/Users/dali/workspace/ib_python/runner/services/historical_data_service.py", line 24, in get_latest_timestamp
    response = self.stub.GetLatestTimeStamp(request)
  File "/Users/dali/workspace/ib_python/runner/venv/lib/python3.7/site-packages/grpc/_channel.py", line 604, in __call__
    return _end_unary_response_blocking(state, call, False, None)
  File "/Users/dali/workspace/ib_python/runner/venv/lib/python3.7/site-packages/grpc/_channel.py", line 506, in _end_unary_response_blocking
    raise _Rendezvous(state, None, None, deadline)
grpc._channel._Rendezvous: <_Rendezvous of RPC that terminated with:
	status = StatusCode.UNAVAILABLE
	details = "failed to connect to all addresses"
	debug_error_string = "{"created":"@1581097187.939297000","description":"Failed to pick subchannel","file":"src/core/ext/filters/client_channel/client_channel.cc","file_line":3876,"referenced_errors":[{"created":"@1581097170.053953000","description":"failed to connect to all addresses","file":"src/core/ext/filters/client_channel/lb_policy/pick_first/pick_first.cc","file_line":395,"grpc_status":14}]}"
>
2020-02-07 17:39:47,939 INFO download_runner.impl.historical_runner:32 sending - historical data request : ACST 2019-01-01 2020-01-01
2020-02-07 17:39:48,646 INFO download_runner.impl.historical_runner:35 sent - historical data request : ACST 2019-01-01 2020-01-01
2020-02-07 17:39:48,646 DEBUG download_runner.impl.historical_runner:36 request accounted for...
2020-02-07 17:39:48,646 INFO download_runner.impl.historical_runner:37 status : True
2020-02-07 17:39:48,646 INFO download_runner.impl.historical_runner:42 Historical data request sent : ACST 2019-01-01 2020-01-01
2020-02-07 17:39:48,646 DEBUG download_runner.impl.historical_end_reader:37 poll stock ? => True
2020-02-07 17:39:48,647 ERROR root:30 unhandled exception getting latest timestamp for ACT
Traceback (most recent call last):
  File "/Users/dali/workspace/ib_python/runner/services/historical_data_service.py", line 24, in get_latest_timestamp
    response = self.stub.GetLatestTimeStamp(request)
  File "/Users/dali/workspace/ib_python/runner/venv/lib/python3.7/site-packages/grpc/_channel.py", line 604, in __call__
    return _end_unary_response_blocking(state, call, False, None)
  File "/Users/dali/workspace/ib_python/runner/venv/lib/python3.7/site-packages/grpc/_channel.py", line 506, in _end_unary_response_blocking
    raise _Rendezvous(state, None, None, deadline)
grpc._channel._Rendezvous: <_Rendezvous of RPC that terminated with:
	status = StatusCode.UNAVAILABLE
	details = "failed to connect to all addresses"
	debug_error_string = "{"created":"@1581097188.646975000","description":"Failed to pick subchannel","file":"src/core/ext/filters/client_channel/client_channel.cc","file_line":3876,"referenced_errors":[{"created":"@1581097170.053953000","description":"failed to connect to all addresses","file":"src/core/ext/filters/client_channel/lb_policy/pick_first/pick_first.cc","file_line":395,"grpc_status":14}]}"
>
2020-02-07 17:39:48,647 INFO download_runner.impl.historical_runner:32 sending - historical data request : ACT 2019-01-01 2020-01-01
2020-02-07 17:39:51,954 INFO download_runner.impl.historical_runner:35 sent - historical data request : ACT 2019-01-01 2020-01-01
2020-02-07 17:39:51,954 DEBUG download_runner.impl.historical_runner:36 request accounted for...
2020-02-07 17:39:51,954 INFO download_runner.impl.historical_runner:37 status : True
2020-02-07 17:39:51,954 INFO download_runner.impl.historical_runner:42 Historical data request sent : ACT 2019-01-01 2020-01-01
2020-02-07 17:39:51,954 DEBUG download_runner.impl.historical_end_reader:37 poll stock ? => True
2020-02-07 17:39:51,955 ERROR root:30 unhandled exception getting latest timestamp for ACTG
Traceback (most recent call last):
  File "/Users/dali/workspace/ib_python/runner/services/historical_data_service.py", line 24, in get_latest_timestamp
    response = self.stub.GetLatestTimeStamp(request)
  File "/Users/dali/workspace/ib_python/runner/venv/lib/python3.7/site-packages/grpc/_channel.py", line 604, in __call__
    return _end_unary_response_blocking(state, call, False, None)
  File "/Users/dali/workspace/ib_python/runner/venv/lib/python3.7/site-packages/grpc/_channel.py", line 506, in _end_unary_response_blocking
    raise _Rendezvous(state, None, None, deadline)
grpc._channel._Rendezvous: <_Rendezvous of RPC that terminated with:
	status = StatusCode.UNAVAILABLE
	details = "failed to connect to all addresses"
	debug_error_string = "{"created":"@1581097191.955080000","description":"Failed to pick subchannel","file":"src/core/ext/filters/client_channel/client_channel.cc","file_line":3876,"referenced_errors":[{"created":"@1581097170.053953000","description":"failed to connect to all addresses","file":"src/core/ext/filters/client_channel/lb_policy/pick_first/pick_first.cc","file_line":395,"grpc_status":14}]}"
>
2020-02-07 17:39:51,955 INFO download_runner.impl.historical_runner:32 sending - historical data request : ACTG 2019-01-01 2020-01-01
2020-02-07 17:39:52,685 INFO download_runner.impl.historical_runner:35 sent - historical data request : ACTG 2019-01-01 2020-01-01
2020-02-07 17:39:52,685 DEBUG download_runner.impl.historical_runner:36 request accounted for...
2020-02-07 17:39:52,685 INFO download_runner.impl.historical_runner:37 status : True
2020-02-07 17:39:52,685 INFO download_runner.impl.historical_runner:42 Historical data request sent : ACTG 2019-01-01 2020-01-01
2020-02-07 17:39:52,685 DEBUG download_runner.impl.historical_end_reader:37 poll stock ? => True
2020-02-07 17:39:52,686 ERROR root:30 unhandled exception getting latest timestamp for ACTT
Traceback (most recent call last):
  File "/Users/dali/workspace/ib_python/runner/services/historical_data_service.py", line 24, in get_latest_timestamp
    response = self.stub.GetLatestTimeStamp(request)
  File "/Users/dali/workspace/ib_python/runner/venv/lib/python3.7/site-packages/grpc/_channel.py", line 604, in __call__
    return _end_unary_response_blocking(state, call, False, None)
  File "/Users/dali/workspace/ib_python/runner/venv/lib/python3.7/site-packages/grpc/_channel.py", line 506, in _end_unary_response_blocking
    raise _Rendezvous(state, None, None, deadline)
grpc._channel._Rendezvous: <_Rendezvous of RPC that terminated with:
	status = StatusCode.UNAVAILABLE
	details = "failed to connect to all addresses"
	debug_error_string = "{"created":"@1581097192.686032000","description":"Failed to pick subchannel","file":"src/core/ext/filters/client_channel/client_channel.cc","file_line":3876,"referenced_errors":[{"created":"@1581097192.686030000","description":"failed to connect to all addresses","file":"src/core/ext/filters/client_channel/lb_policy/pick_first/pick_first.cc","file_line":395,"grpc_status":14}]}"
>
2020-02-07 17:39:52,686 INFO download_runner.impl.historical_runner:32 sending - historical data request : ACTT 2019-01-01 2020-01-01
2020-02-07 17:39:57,995 INFO download_runner.impl.historical_runner:35 sent - historical data request : ACTT 2019-01-01 2020-01-01
2020-02-07 17:39:57,995 DEBUG download_runner.impl.historical_runner:36 request accounted for...
2020-02-07 17:39:57,995 INFO download_runner.impl.historical_runner:37 status : True
2020-02-07 17:39:57,995 INFO download_runner.impl.historical_runner:42 Historical data request sent : ACTT 2019-01-01 2020-01-01
2020-02-07 17:39:57,995 DEBUG download_runner.impl.historical_end_reader:37 poll stock ? => True
2020-02-07 17:39:57,996 ERROR root:30 unhandled exception getting latest timestamp for ACTTU
Traceback (most recent call last):
  File "/Users/dali/workspace/ib_python/runner/services/historical_data_service.py", line 24, in get_latest_timestamp
    response = self.stub.GetLatestTimeStamp(request)
  File "/Users/dali/workspace/ib_python/runner/venv/lib/python3.7/site-packages/grpc/_channel.py", line 604, in __call__
    return _end_unary_response_blocking(state, call, False, None)
  File "/Users/dali/workspace/ib_python/runner/venv/lib/python3.7/site-packages/grpc/_channel.py", line 506, in _end_unary_response_blocking
    raise _Rendezvous(state, None, None, deadline)
grpc._channel._Rendezvous: <_Rendezvous of RPC that terminated with:
	status = StatusCode.UNAVAILABLE
	details = "failed to connect to all addresses"
	debug_error_string = "{"created":"@1581097197.996050000","description":"Failed to pick subchannel","file":"src/core/ext/filters/client_channel/client_channel.cc","file_line":3876,"referenced_errors":[{"created":"@1581097192.686030000","description":"failed to connect to all addresses","file":"src/core/ext/filters/client_channel/lb_policy/pick_first/pick_first.cc","file_line":395,"grpc_status":14}]}"
>
2020-02-07 17:39:57,996 INFO download_runner.impl.historical_runner:32 sending - historical data request : ACTTU 2019-01-01 2020-01-01
2020-02-07 17:39:59,135 INFO download_runner.impl.historical_runner:35 sent - historical data request : ACTTU 2019-01-01 2020-01-01
2020-02-07 17:39:59,135 DEBUG download_runner.impl.historical_runner:36 request accounted for...
2020-02-07 17:39:59,136 INFO download_runner.impl.historical_runner:37 status : True
2020-02-07 17:39:59,136 INFO download_runner.impl.historical_runner:42 Historical data request sent : ACTTU 2019-01-01 2020-01-01
2020-02-07 17:39:59,136 DEBUG download_runner.impl.historical_end_reader:37 poll stock ? => True
2020-02-07 17:39:59,136 ERROR root:30 unhandled exception getting latest timestamp for ACU
Traceback (most recent call last):
  File "/Users/dali/workspace/ib_python/runner/services/historical_data_service.py", line 24, in get_latest_timestamp
    response = self.stub.GetLatestTimeStamp(request)
  File "/Users/dali/workspace/ib_python/runner/venv/lib/python3.7/site-packages/grpc/_channel.py", line 604, in __call__
    return _end_unary_response_blocking(state, call, False, None)
  File "/Users/dali/workspace/ib_python/runner/venv/lib/python3.7/site-packages/grpc/_channel.py", line 506, in _end_unary_response_blocking
    raise _Rendezvous(state, None, None, deadline)
grpc._channel._Rendezvous: <_Rendezvous of RPC that terminated with:
	status = StatusCode.UNAVAILABLE
	details = "failed to connect to all addresses"
	debug_error_string = "{"created":"@1581097199.136446000","description":"Failed to pick subchannel","file":"src/core/ext/filters/client_channel/client_channel.cc","file_line":3876,"referenced_errors":[{"created":"@1581097192.686030000","description":"failed to connect to all addresses","file":"src/core/ext/filters/client_channel/lb_policy/pick_first/pick_first.cc","file_line":395,"grpc_status":14}]}"
>
2020-02-07 17:39:59,136 INFO download_runner.impl.historical_runner:32 sending - historical data request : ACU 2019-01-01 2020-01-01
2020-02-07 17:40:04,555 INFO download_runner.impl.historical_runner:35 sent - historical data request : ACU 2019-01-01 2020-01-01
2020-02-07 17:40:04,555 DEBUG download_runner.impl.historical_runner:36 request accounted for...
2020-02-07 17:40:04,555 INFO download_runner.impl.historical_runner:37 status : True
2020-02-07 17:40:04,555 INFO download_runner.impl.historical_runner:42 Historical data request sent : ACU 2019-01-01 2020-01-01
2020-02-07 17:40:04,555 DEBUG download_runner.impl.historical_end_reader:37 poll stock ? => True
2020-02-07 17:40:04,556 ERROR root:30 unhandled exception getting latest timestamp for ACV
Traceback (most recent call last):
  File "/Users/dali/workspace/ib_python/runner/services/historical_data_service.py", line 24, in get_latest_timestamp
    response = self.stub.GetLatestTimeStamp(request)
  File "/Users/dali/workspace/ib_python/runner/venv/lib/python3.7/site-packages/grpc/_channel.py", line 604, in __call__
    return _end_unary_response_blocking(state, call, False, None)
  File "/Users/dali/workspace/ib_python/runner/venv/lib/python3.7/site-packages/grpc/_channel.py", line 506, in _end_unary_response_blocking
    raise _Rendezvous(state, None, None, deadline)
grpc._channel._Rendezvous: <_Rendezvous of RPC that terminated with:
	status = StatusCode.UNAVAILABLE
	details = "failed to connect to all addresses"
	debug_error_string = "{"created":"@1581097204.555989000","description":"Failed to pick subchannel","file":"src/core/ext/filters/client_channel/client_channel.cc","file_line":3876,"referenced_errors":[{"created":"@1581097192.686030000","description":"failed to connect to all addresses","file":"src/core/ext/filters/client_channel/lb_policy/pick_first/pick_first.cc","file_line":395,"grpc_status":14}]}"
>
2020-02-07 17:40:04,556 INFO download_runner.impl.historical_runner:32 sending - historical data request : ACV 2019-01-01 2020-01-01
2020-02-07 17:40:05,163 INFO download_runner.impl.historical_runner:35 sent - historical data request : ACV 2019-01-01 2020-01-01
2020-02-07 17:40:05,163 DEBUG download_runner.impl.historical_runner:36 request accounted for...
2020-02-07 17:40:05,163 INFO download_runner.impl.historical_runner:37 status : True
2020-02-07 17:40:05,164 INFO download_runner.impl.historical_runner:42 Historical data request sent : ACV 2019-01-01 2020-01-01
2020-02-07 17:40:05,164 DEBUG download_runner.impl.historical_end_reader:37 poll stock ? => True
2020-02-07 17:40:05,164 ERROR root:30 unhandled exception getting latest timestamp for ACWF
Traceback (most recent call last):
  File "/Users/dali/workspace/ib_python/runner/services/historical_data_service.py", line 24, in get_latest_timestamp
    response = self.stub.GetLatestTimeStamp(request)
  File "/Users/dali/workspace/ib_python/runner/venv/lib/python3.7/site-packages/grpc/_channel.py", line 604, in __call__
    return _end_unary_response_blocking(state, call, False, None)
  File "/Users/dali/workspace/ib_python/runner/venv/lib/python3.7/site-packages/grpc/_channel.py", line 506, in _end_unary_response_blocking
    raise _Rendezvous(state, None, None, deadline)
grpc._channel._Rendezvous: <_Rendezvous of RPC that terminated with:
	status = StatusCode.UNAVAILABLE
	details = "failed to connect to all addresses"
	debug_error_string = "{"created":"@1581097205.164252000","description":"Failed to pick subchannel","file":"src/core/ext/filters/client_channel/client_channel.cc","file_line":3876,"referenced_errors":[{"created":"@1581097192.686030000","description":"failed to connect to all addresses","file":"src/core/ext/filters/client_channel/lb_policy/pick_first/pick_first.cc","file_line":395,"grpc_status":14}]}"
>
2020-02-07 17:40:05,164 INFO download_runner.impl.historical_runner:32 sending - historical data request : ACWF 2019-01-01 2020-01-01
2020-02-07 17:40:10,167 INFO download_runner.impl.historical_runner:35 sent - historical data request : ACWF 2019-01-01 2020-01-01
2020-02-07 17:40:10,167 DEBUG download_runner.impl.historical_runner:36 request accounted for...
2020-02-07 17:40:10,167 INFO download_runner.impl.historical_runner:37 status : True
2020-02-07 17:40:10,167 INFO download_runner.impl.historical_runner:42 Historical data request sent : ACWF 2019-01-01 2020-01-01
2020-02-07 17:40:10,167 DEBUG download_runner.impl.historical_end_reader:37 poll stock ? => True
2020-02-07 17:40:10,167 ERROR root:30 unhandled exception getting latest timestamp for ACWI
Traceback (most recent call last):
  File "/Users/dali/workspace/ib_python/runner/services/historical_data_service.py", line 24, in get_latest_timestamp
    response = self.stub.GetLatestTimeStamp(request)
  File "/Users/dali/workspace/ib_python/runner/venv/lib/python3.7/site-packages/grpc/_channel.py", line 604, in __call__
    return _end_unary_response_blocking(state, call, False, None)
  File "/Users/dali/workspace/ib_python/runner/venv/lib/python3.7/site-packages/grpc/_channel.py", line 506, in _end_unary_response_blocking
    raise _Rendezvous(state, None, None, deadline)
grpc._channel._Rendezvous: <_Rendezvous of RPC that terminated with:
	status = StatusCode.UNAVAILABLE
	details = "failed to connect to all addresses"
	debug_error_string = "{"created":"@1581097210.167929000","description":"Failed to pick subchannel","file":"src/core/ext/filters/client_channel/client_channel.cc","file_line":3876,"referenced_errors":[{"created":"@1581097192.686030000","description":"failed to connect to all addresses","file":"src/core/ext/filters/client_channel/lb_policy/pick_first/pick_first.cc","file_line":395,"grpc_status":14}]}"
>
2020-02-07 17:40:10,168 INFO download_runner.impl.historical_runner:32 sending - historical data request : ACWI 2019-01-01 2020-01-01
2020-02-07 17:40:10,487 INFO download_runner.impl.historical_runner:35 sent - historical data request : ACWI 2019-01-01 2020-01-01
2020-02-07 17:40:10,487 DEBUG download_runner.impl.historical_runner:36 request accounted for...
2020-02-07 17:40:10,487 INFO download_runner.impl.historical_runner:37 status : True
2020-02-07 17:40:10,487 INFO download_runner.impl.historical_runner:42 Historical data request sent : ACWI 2019-01-01 2020-01-01
2020-02-07 17:40:10,487 DEBUG download_runner.impl.historical_end_reader:37 poll stock ? => True
2020-02-07 17:40:10,487 ERROR root:30 unhandled exception getting latest timestamp for ACWV
Traceback (most recent call last):
  File "/Users/dali/workspace/ib_python/runner/services/historical_data_service.py", line 24, in get_latest_timestamp
    response = self.stub.GetLatestTimeStamp(request)
  File "/Users/dali/workspace/ib_python/runner/venv/lib/python3.7/site-packages/grpc/_channel.py", line 604, in __call__
    return _end_unary_response_blocking(state, call, False, None)
  File "/Users/dali/workspace/ib_python/runner/venv/lib/python3.7/site-packages/grpc/_channel.py", line 506, in _end_unary_response_blocking
    raise _Rendezvous(state, None, None, deadline)
grpc._channel._Rendezvous: <_Rendezvous of RPC that terminated with:
	status = StatusCode.UNAVAILABLE
	details = "failed to connect to all addresses"
	debug_error_string = "{"created":"@1581097210.487622000","description":"Failed to pick subchannel","file":"src/core/ext/filters/client_channel/client_channel.cc","file_line":3876,"referenced_errors":[{"created":"@1581097192.686030000","description":"failed to connect to all addresses","file":"src/core/ext/filters/client_channel/lb_policy/pick_first/pick_first.cc","file_line":395,"grpc_status":14}]}"
>
2020-02-07 17:40:10,487 INFO download_runner.impl.historical_runner:32 sending - historical data request : ACWV 2019-01-01 2020-01-01
2020-02-07 17:40:10,580 INFO download_runner.impl.historical_runner:35 sent - historical data request : ACWV 2019-01-01 2020-01-01
2020-02-07 17:40:10,580 DEBUG download_runner.impl.historical_runner:36 request accounted for...
2020-02-07 17:40:10,581 INFO download_runner.impl.historical_runner:37 status : True
2020-02-07 17:40:10,581 INFO download_runner.impl.historical_runner:42 Historical data request sent : ACWV 2019-01-01 2020-01-01
2020-02-07 17:40:10,581 DEBUG download_runner.impl.historical_end_reader:37 poll stock ? => True
2020-02-07 17:40:10,581 ERROR root:30 unhandled exception getting latest timestamp for ACWX
Traceback (most recent call last):
  File "/Users/dali/workspace/ib_python/runner/services/historical_data_service.py", line 24, in get_latest_timestamp
    response = self.stub.GetLatestTimeStamp(request)
  File "/Users/dali/workspace/ib_python/runner/venv/lib/python3.7/site-packages/grpc/_channel.py", line 604, in __call__
    return _end_unary_response_blocking(state, call, False, None)
  File "/Users/dali/workspace/ib_python/runner/venv/lib/python3.7/site-packages/grpc/_channel.py", line 506, in _end_unary_response_blocking
    raise _Rendezvous(state, None, None, deadline)
grpc._channel._Rendezvous: <_Rendezvous of RPC that terminated with:
	status = StatusCode.UNAVAILABLE
	details = "failed to connect to all addresses"
	debug_error_string = "{"created":"@1581097210.581385000","description":"Failed to pick subchannel","file":"src/core/ext/filters/client_channel/client_channel.cc","file_line":3876,"referenced_errors":[{"created":"@1581097192.686030000","description":"failed to connect to all addresses","file":"src/core/ext/filters/client_channel/lb_policy/pick_first/pick_first.cc","file_line":395,"grpc_status":14}]}"
>
2020-02-07 17:40:10,581 INFO download_runner.impl.historical_runner:32 sending - historical data request : ACWX 2019-01-01 2020-01-01
2020-02-07 17:40:21,903 INFO download_runner.impl.historical_runner:35 sent - historical data request : ACWX 2019-01-01 2020-01-01
2020-02-07 17:40:21,903 DEBUG download_runner.impl.historical_runner:36 request accounted for...
2020-02-07 17:40:21,903 INFO download_runner.impl.historical_runner:37 status : True
2020-02-07 17:40:21,903 INFO download_runner.impl.historical_runner:42 Historical data request sent : ACWX 2019-01-01 2020-01-01
2020-02-07 17:40:21,903 DEBUG download_runner.impl.historical_end_reader:37 poll stock ? => True
2020-02-07 17:40:21,903 ERROR root:30 unhandled exception getting latest timestamp for ACY
Traceback (most recent call last):
  File "/Users/dali/workspace/ib_python/runner/services/historical_data_service.py", line 24, in get_latest_timestamp
    response = self.stub.GetLatestTimeStamp(request)
  File "/Users/dali/workspace/ib_python/runner/venv/lib/python3.7/site-packages/grpc/_channel.py", line 604, in __call__
    return _end_unary_response_blocking(state, call, False, None)
  File "/Users/dali/workspace/ib_python/runner/venv/lib/python3.7/site-packages/grpc/_channel.py", line 506, in _end_unary_response_blocking
    raise _Rendezvous(state, None, None, deadline)
grpc._channel._Rendezvous: <_Rendezvous of RPC that terminated with:
	status = StatusCode.UNAVAILABLE
	details = "failed to connect to all addresses"
	debug_error_string = "{"created":"@1581097221.903623000","description":"Failed to pick subchannel","file":"src/core/ext/filters/client_channel/client_channel.cc","file_line":3876,"referenced_errors":[{"created":"@1581097192.686030000","description":"failed to connect to all addresses","file":"src/core/ext/filters/client_channel/lb_policy/pick_first/pick_first.cc","file_line":395,"grpc_status":14}]}"
>
2020-02-07 17:40:21,903 INFO download_runner.impl.historical_runner:32 sending - historical data request : ACY 2019-01-01 2020-01-01
2020-02-07 17:40:34,002 INFO download_runner.impl.historical_runner:35 sent - historical data request : ACY 2019-01-01 2020-01-01
2020-02-07 17:40:34,002 DEBUG download_runner.impl.historical_runner:36 request accounted for...
2020-02-07 17:40:34,002 INFO download_runner.impl.historical_runner:37 status : True
2020-02-07 17:40:34,002 INFO download_runner.impl.historical_runner:42 Historical data request sent : ACY 2019-01-01 2020-01-01
2020-02-07 17:40:34,003 DEBUG download_runner.impl.historical_end_reader:37 poll stock ? => True
2020-02-07 17:40:34,003 ERROR root:30 unhandled exception getting latest timestamp for ADAP
Traceback (most recent call last):
  File "/Users/dali/workspace/ib_python/runner/services/historical_data_service.py", line 24, in get_latest_timestamp
    response = self.stub.GetLatestTimeStamp(request)
  File "/Users/dali/workspace/ib_python/runner/venv/lib/python3.7/site-packages/grpc/_channel.py", line 604, in __call__
    return _end_unary_response_blocking(state, call, False, None)
  File "/Users/dali/workspace/ib_python/runner/venv/lib/python3.7/site-packages/grpc/_channel.py", line 506, in _end_unary_response_blocking
    raise _Rendezvous(state, None, None, deadline)
grpc._channel._Rendezvous: <_Rendezvous of RPC that terminated with:
	status = StatusCode.UNAVAILABLE
	details = "failed to connect to all addresses"
	debug_error_string = "{"created":"@1581097234.003230000","description":"Failed to pick subchannel","file":"src/core/ext/filters/client_channel/client_channel.cc","file_line":3876,"referenced_errors":[{"created":"@1581097230.079434000","description":"failed to connect to all addresses","file":"src/core/ext/filters/client_channel/lb_policy/pick_first/pick_first.cc","file_line":395,"grpc_status":14}]}"
>
2020-02-07 17:40:34,003 INFO download_runner.impl.historical_runner:32 sending - historical data request : ADAP 2019-01-01 2020-01-01
2020-02-07 17:40:47,578 INFO download_runner.impl.historical_runner:35 sent - historical data request : ADAP 2019-01-01 2020-01-01
2020-02-07 17:40:47,578 DEBUG download_runner.impl.historical_runner:36 request accounted for...
2020-02-07 17:40:47,578 INFO download_runner.impl.historical_runner:37 status : True
2020-02-07 17:40:47,578 INFO download_runner.impl.historical_runner:42 Historical data request sent : ADAP 2019-01-01 2020-01-01
2020-02-07 17:40:47,578 DEBUG download_runner.impl.historical_end_reader:37 poll stock ? => True
2020-02-07 17:40:47,579 ERROR root:30 unhandled exception getting latest timestamp for ADBE
Traceback (most recent call last):
  File "/Users/dali/workspace/ib_python/runner/services/historical_data_service.py", line 24, in get_latest_timestamp
    response = self.stub.GetLatestTimeStamp(request)
  File "/Users/dali/workspace/ib_python/runner/venv/lib/python3.7/site-packages/grpc/_channel.py", line 604, in __call__
    return _end_unary_response_blocking(state, call, False, None)
  File "/Users/dali/workspace/ib_python/runner/venv/lib/python3.7/site-packages/grpc/_channel.py", line 506, in _end_unary_response_blocking
    raise _Rendezvous(state, None, None, deadline)
grpc._channel._Rendezvous: <_Rendezvous of RPC that terminated with:
	status = StatusCode.UNAVAILABLE
	details = "failed to connect to all addresses"
	debug_error_string = "{"created":"@1581097247.579158000","description":"Failed to pick subchannel","file":"src/core/ext/filters/client_channel/client_channel.cc","file_line":3876,"referenced_errors":[{"created":"@1581097230.079434000","description":"failed to connect to all addresses","file":"src/core/ext/filters/client_channel/lb_policy/pick_first/pick_first.cc","file_line":395,"grpc_status":14}]}"
>
2020-02-07 17:40:47,579 INFO download_runner.impl.historical_runner:32 sending - historical data request : ADBE 2019-01-01 2020-01-01
2020-02-07 17:40:49,396 INFO download_runner.impl.historical_runner:35 sent - historical data request : ADBE 2019-01-01 2020-01-01
2020-02-07 17:40:49,396 DEBUG download_runner.impl.historical_runner:36 request accounted for...
2020-02-07 17:40:49,396 INFO download_runner.impl.historical_runner:37 status : True
2020-02-07 17:40:49,396 INFO download_runner.impl.historical_runner:42 Historical data request sent : ADBE 2019-01-01 2020-01-01
2020-02-07 17:40:49,396 DEBUG download_runner.impl.historical_end_reader:37 poll stock ? => True
2020-02-07 17:40:49,397 ERROR root:30 unhandled exception getting latest timestamp for ADC
Traceback (most recent call last):
  File "/Users/dali/workspace/ib_python/runner/services/historical_data_service.py", line 24, in get_latest_timestamp
    response = self.stub.GetLatestTimeStamp(request)
  File "/Users/dali/workspace/ib_python/runner/venv/lib/python3.7/site-packages/grpc/_channel.py", line 604, in __call__
    return _end_unary_response_blocking(state, call, False, None)
  File "/Users/dali/workspace/ib_python/runner/venv/lib/python3.7/site-packages/grpc/_channel.py", line 506, in _end_unary_response_blocking
    raise _Rendezvous(state, None, None, deadline)
grpc._channel._Rendezvous: <_Rendezvous of RPC that terminated with:
	status = StatusCode.UNAVAILABLE
	details = "failed to connect to all addresses"
	debug_error_string = "{"created":"@1581097249.397141000","description":"Failed to pick subchannel","file":"src/core/ext/filters/client_channel/client_channel.cc","file_line":3876,"referenced_errors":[{"created":"@1581097230.079434000","description":"failed to connect to all addresses","file":"src/core/ext/filters/client_channel/lb_policy/pick_first/pick_first.cc","file_line":395,"grpc_status":14}]}"
>
2020-02-07 17:40:49,397 INFO download_runner.impl.historical_runner:32 sending - historical data request : ADC 2019-01-01 2020-01-01
2020-02-07 17:40:50,461 INFO download_runner.impl.historical_runner:35 sent - historical data request : ADC 2019-01-01 2020-01-01
2020-02-07 17:40:50,461 DEBUG download_runner.impl.historical_runner:36 request accounted for...
2020-02-07 17:40:50,462 INFO download_runner.impl.historical_runner:37 status : True
2020-02-07 17:40:50,462 INFO download_runner.impl.historical_runner:42 Historical data request sent : ADC 2019-01-01 2020-01-01
2020-02-07 17:40:50,462 DEBUG download_runner.impl.historical_end_reader:37 poll stock ? => True
2020-02-07 17:40:50,462 ERROR root:30 unhandled exception getting latest timestamp for ADES
Traceback (most recent call last):
  File "/Users/dali/workspace/ib_python/runner/services/historical_data_service.py", line 24, in get_latest_timestamp
    response = self.stub.GetLatestTimeStamp(request)
  File "/Users/dali/workspace/ib_python/runner/venv/lib/python3.7/site-packages/grpc/_channel.py", line 604, in __call__
    return _end_unary_response_blocking(state, call, False, None)
  File "/Users/dali/workspace/ib_python/runner/venv/lib/python3.7/site-packages/grpc/_channel.py", line 506, in _end_unary_response_blocking
    raise _Rendezvous(state, None, None, deadline)
grpc._channel._Rendezvous: <_Rendezvous of RPC that terminated with:
	status = StatusCode.UNAVAILABLE
	details = "failed to connect to all addresses"
	debug_error_string = "{"created":"@1581097250.462314000","description":"Failed to pick subchannel","file":"src/core/ext/filters/client_channel/client_channel.cc","file_line":3876,"referenced_errors":[{"created":"@1581097230.079434000","description":"failed to connect to all addresses","file":"src/core/ext/filters/client_channel/lb_policy/pick_first/pick_first.cc","file_line":395,"grpc_status":14}]}"
>
2020-02-07 17:40:50,462 INFO download_runner.impl.historical_runner:32 sending - historical data request : ADES 2019-01-01 2020-01-01
2020-02-07 17:40:52,241 INFO download_runner.impl.historical_runner:35 sent - historical data request : ADES 2019-01-01 2020-01-01
2020-02-07 17:40:52,241 DEBUG download_runner.impl.historical_runner:36 request accounted for...
2020-02-07 17:40:52,242 INFO download_runner.impl.historical_runner:37 status : True
2020-02-07 17:40:52,242 INFO download_runner.impl.historical_runner:42 Historical data request sent : ADES 2019-01-01 2020-01-01
2020-02-07 17:40:52,242 DEBUG download_runner.impl.historical_end_reader:37 poll stock ? => True
2020-02-07 17:40:52,242 ERROR root:30 unhandled exception getting latest timestamp for ADI
Traceback (most recent call last):
  File "/Users/dali/workspace/ib_python/runner/services/historical_data_service.py", line 24, in get_latest_timestamp
    response = self.stub.GetLatestTimeStamp(request)
  File "/Users/dali/workspace/ib_python/runner/venv/lib/python3.7/site-packages/grpc/_channel.py", line 604, in __call__
    return _end_unary_response_blocking(state, call, False, None)
  File "/Users/dali/workspace/ib_python/runner/venv/lib/python3.7/site-packages/grpc/_channel.py", line 506, in _end_unary_response_blocking
    raise _Rendezvous(state, None, None, deadline)
grpc._channel._Rendezvous: <_Rendezvous of RPC that terminated with:
	status = StatusCode.UNAVAILABLE
	details = "failed to connect to all addresses"
	debug_error_string = "{"created":"@1581097252.242294000","description":"Failed to pick subchannel","file":"src/core/ext/filters/client_channel/client_channel.cc","file_line":3876,"referenced_errors":[{"created":"@1581097230.079434000","description":"failed to connect to all addresses","file":"src/core/ext/filters/client_channel/lb_policy/pick_first/pick_first.cc","file_line":395,"grpc_status":14}]}"
>
2020-02-07 17:40:52,242 INFO download_runner.impl.historical_runner:32 sending - historical data request : ADI 2019-01-01 2020-01-01
2020-02-07 17:40:53,941 INFO download_runner.impl.historical_runner:35 sent - historical data request : ADI 2019-01-01 2020-01-01
2020-02-07 17:40:53,941 DEBUG download_runner.impl.historical_runner:36 request accounted for...
2020-02-07 17:40:53,941 INFO download_runner.impl.historical_runner:37 status : True
2020-02-07 17:40:53,941 INFO download_runner.impl.historical_runner:42 Historical data request sent : ADI 2019-01-01 2020-01-01
2020-02-07 17:40:53,942 DEBUG download_runner.impl.historical_end_reader:37 poll stock ? => True
2020-02-07 17:40:53,942 ERROR root:30 unhandled exception getting latest timestamp for ADIL
Traceback (most recent call last):
  File "/Users/dali/workspace/ib_python/runner/services/historical_data_service.py", line 24, in get_latest_timestamp
    response = self.stub.GetLatestTimeStamp(request)
  File "/Users/dali/workspace/ib_python/runner/venv/lib/python3.7/site-packages/grpc/_channel.py", line 604, in __call__
    return _end_unary_response_blocking(state, call, False, None)
  File "/Users/dali/workspace/ib_python/runner/venv/lib/python3.7/site-packages/grpc/_channel.py", line 506, in _end_unary_response_blocking
    raise _Rendezvous(state, None, None, deadline)
grpc._channel._Rendezvous: <_Rendezvous of RPC that terminated with:
	status = StatusCode.UNAVAILABLE
	details = "failed to connect to all addresses"
	debug_error_string = "{"created":"@1581097253.942265000","description":"Failed to pick subchannel","file":"src/core/ext/filters/client_channel/client_channel.cc","file_line":3876,"referenced_errors":[{"created":"@1581097230.079434000","description":"failed to connect to all addresses","file":"src/core/ext/filters/client_channel/lb_policy/pick_first/pick_first.cc","file_line":395,"grpc_status":14}]}"
>
2020-02-07 17:40:53,942 INFO download_runner.impl.historical_runner:32 sending - historical data request : ADIL 2019-01-01 2020-01-01
2020-02-07 17:40:58,095 INFO download_runner.impl.historical_runner:35 sent - historical data request : ADIL 2019-01-01 2020-01-01
2020-02-07 17:40:58,095 DEBUG download_runner.impl.historical_runner:36 request accounted for...
2020-02-07 17:40:58,095 INFO download_runner.impl.historical_runner:37 status : True
2020-02-07 17:40:58,095 INFO download_runner.impl.historical_runner:42 Historical data request sent : ADIL 2019-01-01 2020-01-01
2020-02-07 17:40:58,095 DEBUG download_runner.impl.historical_end_reader:37 poll stock ? => True
2020-02-07 17:40:58,095 ERROR root:30 unhandled exception getting latest timestamp for ADM
Traceback (most recent call last):
  File "/Users/dali/workspace/ib_python/runner/services/historical_data_service.py", line 24, in get_latest_timestamp
    response = self.stub.GetLatestTimeStamp(request)
  File "/Users/dali/workspace/ib_python/runner/venv/lib/python3.7/site-packages/grpc/_channel.py", line 604, in __call__
    return _end_unary_response_blocking(state, call, False, None)
  File "/Users/dali/workspace/ib_python/runner/venv/lib/python3.7/site-packages/grpc/_channel.py", line 506, in _end_unary_response_blocking
    raise _Rendezvous(state, None, None, deadline)
grpc._channel._Rendezvous: <_Rendezvous of RPC that terminated with:
	status = StatusCode.UNAVAILABLE
	details = "failed to connect to all addresses"
	debug_error_string = "{"created":"@1581097258.095676000","description":"Failed to pick subchannel","file":"src/core/ext/filters/client_channel/client_channel.cc","file_line":3876,"referenced_errors":[{"created":"@1581097230.079434000","description":"failed to connect to all addresses","file":"src/core/ext/filters/client_channel/lb_policy/pick_first/pick_first.cc","file_line":395,"grpc_status":14}]}"
>
2020-02-07 17:40:58,095 INFO download_runner.impl.historical_runner:32 sending - historical data request : ADM 2019-01-01 2020-01-01
2020-02-07 17:40:59,764 INFO download_runner.impl.historical_runner:35 sent - historical data request : ADM 2019-01-01 2020-01-01
2020-02-07 17:40:59,764 DEBUG download_runner.impl.historical_runner:36 request accounted for...
2020-02-07 17:40:59,764 INFO download_runner.impl.historical_runner:37 status : True
2020-02-07 17:40:59,764 INFO download_runner.impl.historical_runner:42 Historical data request sent : ADM 2019-01-01 2020-01-01
2020-02-07 17:40:59,764 DEBUG download_runner.impl.historical_end_reader:37 poll stock ? => True
2020-02-07 17:40:59,764 ERROR root:30 unhandled exception getting latest timestamp for ADMA
Traceback (most recent call last):
  File "/Users/dali/workspace/ib_python/runner/services/historical_data_service.py", line 24, in get_latest_timestamp
    response = self.stub.GetLatestTimeStamp(request)
  File "/Users/dali/workspace/ib_python/runner/venv/lib/python3.7/site-packages/grpc/_channel.py", line 604, in __call__
    return _end_unary_response_blocking(state, call, False, None)
  File "/Users/dali/workspace/ib_python/runner/venv/lib/python3.7/site-packages/grpc/_channel.py", line 506, in _end_unary_response_blocking
    raise _Rendezvous(state, None, None, deadline)
grpc._channel._Rendezvous: <_Rendezvous of RPC that terminated with:
	status = StatusCode.UNAVAILABLE
	details = "failed to connect to all addresses"
	debug_error_string = "{"created":"@1581097259.764477000","description":"Failed to pick subchannel","file":"src/core/ext/filters/client_channel/client_channel.cc","file_line":3876,"referenced_errors":[{"created":"@1581097230.079434000","description":"failed to connect to all addresses","file":"src/core/ext/filters/client_channel/lb_policy/pick_first/pick_first.cc","file_line":395,"grpc_status":14}]}"
>
2020-02-07 17:40:59,764 INFO download_runner.impl.historical_runner:32 sending - historical data request : ADMA 2019-01-01 2020-01-01
2020-02-07 17:40:59,901 INFO download_runner.impl.historical_runner:35 sent - historical data request : ADMA 2019-01-01 2020-01-01
2020-02-07 17:40:59,902 DEBUG download_runner.impl.historical_runner:36 request accounted for...
2020-02-07 17:40:59,902 INFO download_runner.impl.historical_runner:37 status : True
2020-02-07 17:40:59,902 INFO download_runner.impl.historical_runner:42 Historical data request sent : ADMA 2019-01-01 2020-01-01
2020-02-07 17:40:59,902 DEBUG download_runner.impl.historical_end_reader:37 poll stock ? => True
2020-02-07 17:40:59,902 ERROR root:30 unhandled exception getting latest timestamp for ADME
Traceback (most recent call last):
  File "/Users/dali/workspace/ib_python/runner/services/historical_data_service.py", line 24, in get_latest_timestamp
    response = self.stub.GetLatestTimeStamp(request)
  File "/Users/dali/workspace/ib_python/runner/venv/lib/python3.7/site-packages/grpc/_channel.py", line 604, in __call__
    return _end_unary_response_blocking(state, call, False, None)
  File "/Users/dali/workspace/ib_python/runner/venv/lib/python3.7/site-packages/grpc/_channel.py", line 506, in _end_unary_response_blocking
    raise _Rendezvous(state, None, None, deadline)
grpc._channel._Rendezvous: <_Rendezvous of RPC that terminated with:
	status = StatusCode.UNAVAILABLE
	details = "failed to connect to all addresses"
	debug_error_string = "{"created":"@1581097259.902351000","description":"Failed to pick subchannel","file":"src/core/ext/filters/client_channel/client_channel.cc","file_line":3876,"referenced_errors":[{"created":"@1581097230.079434000","description":"failed to connect to all addresses","file":"src/core/ext/filters/client_channel/lb_policy/pick_first/pick_first.cc","file_line":395,"grpc_status":14}]}"
>
2020-02-07 17:40:59,902 INFO download_runner.impl.historical_runner:32 sending - historical data request : ADME 2019-01-01 2020-01-01
2020-02-07 17:41:04,918 INFO download_runner.impl.historical_runner:35 sent - historical data request : ADME 2019-01-01 2020-01-01
2020-02-07 17:41:04,918 DEBUG download_runner.impl.historical_runner:36 request accounted for...
2020-02-07 17:41:04,918 INFO download_runner.impl.historical_runner:37 status : True
2020-02-07 17:41:04,918 INFO download_runner.impl.historical_runner:42 Historical data request sent : ADME 2019-01-01 2020-01-01
2020-02-07 17:41:04,918 DEBUG download_runner.impl.historical_end_reader:37 poll stock ? => True
2020-02-07 17:41:04,919 ERROR root:30 unhandled exception getting latest timestamp for ADMP
Traceback (most recent call last):
  File "/Users/dali/workspace/ib_python/runner/services/historical_data_service.py", line 24, in get_latest_timestamp
    response = self.stub.GetLatestTimeStamp(request)
  File "/Users/dali/workspace/ib_python/runner/venv/lib/python3.7/site-packages/grpc/_channel.py", line 604, in __call__
    return _end_unary_response_blocking(state, call, False, None)
  File "/Users/dali/workspace/ib_python/runner/venv/lib/python3.7/site-packages/grpc/_channel.py", line 506, in _end_unary_response_blocking
    raise _Rendezvous(state, None, None, deadline)
grpc._channel._Rendezvous: <_Rendezvous of RPC that terminated with:
	status = StatusCode.UNAVAILABLE
	details = "failed to connect to all addresses"
	debug_error_string = "{"created":"@1581097264.919104000","description":"Failed to pick subchannel","file":"src/core/ext/filters/client_channel/client_channel.cc","file_line":3876,"referenced_errors":[{"created":"@1581097230.079434000","description":"failed to connect to all addresses","file":"src/core/ext/filters/client_channel/lb_policy/pick_first/pick_first.cc","file_line":395,"grpc_status":14}]}"
>
2020-02-07 17:41:04,919 INFO download_runner.impl.historical_runner:32 sending - historical data request : ADMP 2019-01-01 2020-01-01
2020-02-07 17:41:10,079 INFO download_runner.impl.historical_runner:35 sent - historical data request : ADMP 2019-01-01 2020-01-01
2020-02-07 17:41:10,079 DEBUG download_runner.impl.historical_runner:36 request accounted for...
2020-02-07 17:41:10,079 INFO download_runner.impl.historical_runner:37 status : True
2020-02-07 17:41:10,079 INFO download_runner.impl.historical_runner:42 Historical data request sent : ADMP 2019-01-01 2020-01-01
2020-02-07 17:41:10,079 DEBUG download_runner.impl.historical_end_reader:37 poll stock ? => True
2020-02-07 17:41:10,080 ERROR root:30 unhandled exception getting latest timestamp for ADMS
Traceback (most recent call last):
  File "/Users/dali/workspace/ib_python/runner/services/historical_data_service.py", line 24, in get_latest_timestamp
    response = self.stub.GetLatestTimeStamp(request)
  File "/Users/dali/workspace/ib_python/runner/venv/lib/python3.7/site-packages/grpc/_channel.py", line 604, in __call__
    return _end_unary_response_blocking(state, call, False, None)
  File "/Users/dali/workspace/ib_python/runner/venv/lib/python3.7/site-packages/grpc/_channel.py", line 506, in _end_unary_response_blocking
    raise _Rendezvous(state, None, None, deadline)
grpc._channel._Rendezvous: <_Rendezvous of RPC that terminated with:
	status = StatusCode.UNAVAILABLE
	details = "failed to connect to all addresses"
	debug_error_string = "{"created":"@1581097270.080068000","description":"Failed to pick subchannel","file":"src/core/ext/filters/client_channel/client_channel.cc","file_line":3876,"referenced_errors":[{"created":"@1581097230.079434000","description":"failed to connect to all addresses","file":"src/core/ext/filters/client_channel/lb_policy/pick_first/pick_first.cc","file_line":395,"grpc_status":14}]}"
>
2020-02-07 17:41:10,080 INFO download_runner.impl.historical_runner:32 sending - historical data request : ADMS 2019-01-01 2020-01-01
2020-02-07 17:41:22,065 INFO download_runner.impl.historical_runner:35 sent - historical data request : ADMS 2019-01-01 2020-01-01
2020-02-07 17:41:22,066 DEBUG download_runner.impl.historical_runner:36 request accounted for...
2020-02-07 17:41:22,066 INFO download_runner.impl.historical_runner:37 status : True
2020-02-07 17:41:22,066 INFO download_runner.impl.historical_runner:42 Historical data request sent : ADMS 2019-01-01 2020-01-01
2020-02-07 17:41:22,066 DEBUG download_runner.impl.historical_end_reader:37 poll stock ? => True
2020-02-07 17:41:22,067 ERROR root:30 unhandled exception getting latest timestamp for ADNT
Traceback (most recent call last):
  File "/Users/dali/workspace/ib_python/runner/services/historical_data_service.py", line 24, in get_latest_timestamp
    response = self.stub.GetLatestTimeStamp(request)
  File "/Users/dali/workspace/ib_python/runner/venv/lib/python3.7/site-packages/grpc/_channel.py", line 604, in __call__
    return _end_unary_response_blocking(state, call, False, None)
  File "/Users/dali/workspace/ib_python/runner/venv/lib/python3.7/site-packages/grpc/_channel.py", line 506, in _end_unary_response_blocking
    raise _Rendezvous(state, None, None, deadline)
grpc._channel._Rendezvous: <_Rendezvous of RPC that terminated with:
	status = StatusCode.UNAVAILABLE
	details = "failed to connect to all addresses"
	debug_error_string = "{"created":"@1581097282.067015000","description":"Failed to pick subchannel","file":"src/core/ext/filters/client_channel/client_channel.cc","file_line":3876,"referenced_errors":[{"created":"@1581097230.079434000","description":"failed to connect to all addresses","file":"src/core/ext/filters/client_channel/lb_policy/pick_first/pick_first.cc","file_line":395,"grpc_status":14}]}"
>
2020-02-07 17:41:22,067 INFO download_runner.impl.historical_runner:32 sending - historical data request : ADNT 2019-01-01 2020-01-01
2020-02-07 17:41:34,325 INFO download_runner.impl.historical_runner:35 sent - historical data request : ADNT 2019-01-01 2020-01-01
2020-02-07 17:41:34,325 DEBUG download_runner.impl.historical_runner:36 request accounted for...
2020-02-07 17:41:34,325 INFO download_runner.impl.historical_runner:37 status : True
2020-02-07 17:41:34,325 INFO download_runner.impl.historical_runner:42 Historical data request sent : ADNT 2019-01-01 2020-01-01
2020-02-07 17:41:34,325 DEBUG download_runner.impl.historical_end_reader:37 poll stock ? => True
2020-02-07 17:41:34,325 ERROR root:30 unhandled exception getting latest timestamp for ADP
Traceback (most recent call last):
  File "/Users/dali/workspace/ib_python/runner/services/historical_data_service.py", line 24, in get_latest_timestamp
    response = self.stub.GetLatestTimeStamp(request)
  File "/Users/dali/workspace/ib_python/runner/venv/lib/python3.7/site-packages/grpc/_channel.py", line 604, in __call__
    return _end_unary_response_blocking(state, call, False, None)
  File "/Users/dali/workspace/ib_python/runner/venv/lib/python3.7/site-packages/grpc/_channel.py", line 506, in _end_unary_response_blocking
    raise _Rendezvous(state, None, None, deadline)
grpc._channel._Rendezvous: <_Rendezvous of RPC that terminated with:
	status = StatusCode.UNAVAILABLE
	details = "failed to connect to all addresses"
	debug_error_string = "{"created":"@1581097294.325814000","description":"Failed to pick subchannel","file":"src/core/ext/filters/client_channel/client_channel.cc","file_line":3876,"referenced_errors":[{"created":"@1581097230.079434000","description":"failed to connect to all addresses","file":"src/core/ext/filters/client_channel/lb_policy/pick_first/pick_first.cc","file_line":395,"grpc_status":14}]}"
>
2020-02-07 17:41:34,326 INFO download_runner.impl.historical_runner:32 sending - historical data request : ADP 2019-01-01 2020-01-01
2020-02-07 17:41:46,150 INFO download_runner.impl.historical_runner:35 sent - historical data request : ADP 2019-01-01 2020-01-01
2020-02-07 17:41:46,151 DEBUG download_runner.impl.historical_runner:36 request accounted for...
2020-02-07 17:41:46,151 INFO download_runner.impl.historical_runner:37 status : True
2020-02-07 17:41:46,151 INFO download_runner.impl.historical_runner:42 Historical data request sent : ADP 2019-01-01 2020-01-01
2020-02-07 17:41:46,151 DEBUG download_runner.impl.historical_end_reader:37 poll stock ? => True
2020-02-07 17:41:46,151 ERROR root:30 unhandled exception getting latest timestamp for ADPT
Traceback (most recent call last):
  File "/Users/dali/workspace/ib_python/runner/services/historical_data_service.py", line 24, in get_latest_timestamp
    response = self.stub.GetLatestTimeStamp(request)
  File "/Users/dali/workspace/ib_python/runner/venv/lib/python3.7/site-packages/grpc/_channel.py", line 604, in __call__
    return _end_unary_response_blocking(state, call, False, None)
  File "/Users/dali/workspace/ib_python/runner/venv/lib/python3.7/site-packages/grpc/_channel.py", line 506, in _end_unary_response_blocking
    raise _Rendezvous(state, None, None, deadline)
grpc._channel._Rendezvous: <_Rendezvous of RPC that terminated with:
	status = StatusCode.UNAVAILABLE
	details = "failed to connect to all addresses"
	debug_error_string = "{"created":"@1581097306.151680000","description":"Failed to pick subchannel","file":"src/core/ext/filters/client_channel/client_channel.cc","file_line":3876,"referenced_errors":[{"created":"@1581097305.108311000","description":"failed to connect to all addresses","file":"src/core/ext/filters/client_channel/lb_policy/pick_first/pick_first.cc","file_line":395,"grpc_status":14}]}"
>
2020-02-07 17:41:46,151 INFO download_runner.impl.historical_runner:32 sending - historical data request : ADPT 2019-01-01 2020-01-01
2020-02-07 17:41:47,889 INFO download_runner.impl.historical_runner:35 sent - historical data request : ADPT 2019-01-01 2020-01-01
2020-02-07 17:41:47,889 DEBUG download_runner.impl.historical_runner:36 request accounted for...
2020-02-07 17:41:47,889 INFO download_runner.impl.historical_runner:37 status : True
2020-02-07 17:41:47,889 INFO download_runner.impl.historical_runner:42 Historical data request sent : ADPT 2019-01-01 2020-01-01
2020-02-07 17:41:47,889 DEBUG download_runner.impl.historical_end_reader:37 poll stock ? => True
2020-02-07 17:41:47,890 ERROR root:30 unhandled exception getting latest timestamp for ADRA
Traceback (most recent call last):
  File "/Users/dali/workspace/ib_python/runner/services/historical_data_service.py", line 24, in get_latest_timestamp
    response = self.stub.GetLatestTimeStamp(request)
  File "/Users/dali/workspace/ib_python/runner/venv/lib/python3.7/site-packages/grpc/_channel.py", line 604, in __call__
    return _end_unary_response_blocking(state, call, False, None)
  File "/Users/dali/workspace/ib_python/runner/venv/lib/python3.7/site-packages/grpc/_channel.py", line 506, in _end_unary_response_blocking
    raise _Rendezvous(state, None, None, deadline)
grpc._channel._Rendezvous: <_Rendezvous of RPC that terminated with:
	status = StatusCode.UNAVAILABLE
	details = "failed to connect to all addresses"
	debug_error_string = "{"created":"@1581097307.889978000","description":"Failed to pick subchannel","file":"src/core/ext/filters/client_channel/client_channel.cc","file_line":3876,"referenced_errors":[{"created":"@1581097305.108311000","description":"failed to connect to all addresses","file":"src/core/ext/filters/client_channel/lb_policy/pick_first/pick_first.cc","file_line":395,"grpc_status":14}]}"
>
2020-02-07 17:41:47,890 INFO download_runner.impl.historical_runner:32 sending - historical data request : ADRA 2019-01-01 2020-01-01
2020-02-07 17:41:48,715 INFO download_runner.impl.historical_runner:35 sent - historical data request : ADRA 2019-01-01 2020-01-01
2020-02-07 17:41:48,715 DEBUG download_runner.impl.historical_runner:36 request accounted for...
2020-02-07 17:41:48,715 INFO download_runner.impl.historical_runner:37 status : True
2020-02-07 17:41:48,715 INFO download_runner.impl.historical_runner:42 Historical data request sent : ADRA 2019-01-01 2020-01-01
2020-02-07 17:41:48,715 DEBUG download_runner.impl.historical_end_reader:37 poll stock ? => True
2020-02-07 17:41:48,715 ERROR root:30 unhandled exception getting latest timestamp for ADRD
Traceback (most recent call last):
  File "/Users/dali/workspace/ib_python/runner/services/historical_data_service.py", line 24, in get_latest_timestamp
    response = self.stub.GetLatestTimeStamp(request)
  File "/Users/dali/workspace/ib_python/runner/venv/lib/python3.7/site-packages/grpc/_channel.py", line 604, in __call__
    return _end_unary_response_blocking(state, call, False, None)
  File "/Users/dali/workspace/ib_python/runner/venv/lib/python3.7/site-packages/grpc/_channel.py", line 506, in _end_unary_response_blocking
    raise _Rendezvous(state, None, None, deadline)
grpc._channel._Rendezvous: <_Rendezvous of RPC that terminated with:
	status = StatusCode.UNAVAILABLE
	details = "failed to connect to all addresses"
	debug_error_string = "{"created":"@1581097308.715573000","description":"Failed to pick subchannel","file":"src/core/ext/filters/client_channel/client_channel.cc","file_line":3876,"referenced_errors":[{"created":"@1581097305.108311000","description":"failed to connect to all addresses","file":"src/core/ext/filters/client_channel/lb_policy/pick_first/pick_first.cc","file_line":395,"grpc_status":14}]}"
>
2020-02-07 17:41:48,715 INFO download_runner.impl.historical_runner:32 sending - historical data request : ADRD 2019-01-01 2020-01-01
2020-02-07 17:41:49,302 INFO download_runner.impl.historical_runner:35 sent - historical data request : ADRD 2019-01-01 2020-01-01
2020-02-07 17:41:49,302 DEBUG download_runner.impl.historical_runner:36 request accounted for...
2020-02-07 17:41:49,302 INFO download_runner.impl.historical_runner:37 status : True
2020-02-07 17:41:49,302 INFO download_runner.impl.historical_runner:42 Historical data request sent : ADRD 2019-01-01 2020-01-01
2020-02-07 17:41:49,302 DEBUG download_runner.impl.historical_end_reader:37 poll stock ? => True
2020-02-07 17:41:49,303 ERROR root:30 unhandled exception getting latest timestamp for ADRE
Traceback (most recent call last):
  File "/Users/dali/workspace/ib_python/runner/services/historical_data_service.py", line 24, in get_latest_timestamp
    response = self.stub.GetLatestTimeStamp(request)
  File "/Users/dali/workspace/ib_python/runner/venv/lib/python3.7/site-packages/grpc/_channel.py", line 604, in __call__
    return _end_unary_response_blocking(state, call, False, None)
  File "/Users/dali/workspace/ib_python/runner/venv/lib/python3.7/site-packages/grpc/_channel.py", line 506, in _end_unary_response_blocking
    raise _Rendezvous(state, None, None, deadline)
grpc._channel._Rendezvous: <_Rendezvous of RPC that terminated with:
	status = StatusCode.UNAVAILABLE
	details = "failed to connect to all addresses"
	debug_error_string = "{"created":"@1581097309.303059000","description":"Failed to pick subchannel","file":"src/core/ext/filters/client_channel/client_channel.cc","file_line":3876,"referenced_errors":[{"created":"@1581097305.108311000","description":"failed to connect to all addresses","file":"src/core/ext/filters/client_channel/lb_policy/pick_first/pick_first.cc","file_line":395,"grpc_status":14}]}"
>
2020-02-07 17:41:49,303 INFO download_runner.impl.historical_runner:32 sending - historical data request : ADRE 2019-01-01 2020-01-01
2020-02-07 17:41:51,920 INFO download_runner.impl.historical_runner:35 sent - historical data request : ADRE 2019-01-01 2020-01-01
2020-02-07 17:41:51,920 DEBUG download_runner.impl.historical_runner:36 request accounted for...
2020-02-07 17:41:51,920 INFO download_runner.impl.historical_runner:37 status : True
2020-02-07 17:41:51,920 INFO download_runner.impl.historical_runner:42 Historical data request sent : ADRE 2019-01-01 2020-01-01
2020-02-07 17:41:51,920 DEBUG download_runner.impl.historical_end_reader:37 poll stock ? => True
2020-02-07 17:41:51,921 ERROR root:30 unhandled exception getting latest timestamp for ADRO
Traceback (most recent call last):
  File "/Users/dali/workspace/ib_python/runner/services/historical_data_service.py", line 24, in get_latest_timestamp
    response = self.stub.GetLatestTimeStamp(request)
  File "/Users/dali/workspace/ib_python/runner/venv/lib/python3.7/site-packages/grpc/_channel.py", line 604, in __call__
    return _end_unary_response_blocking(state, call, False, None)
  File "/Users/dali/workspace/ib_python/runner/venv/lib/python3.7/site-packages/grpc/_channel.py", line 506, in _end_unary_response_blocking
    raise _Rendezvous(state, None, None, deadline)
grpc._channel._Rendezvous: <_Rendezvous of RPC that terminated with:
	status = StatusCode.UNAVAILABLE
	details = "failed to connect to all addresses"
	debug_error_string = "{"created":"@1581097311.920962000","description":"Failed to pick subchannel","file":"src/core/ext/filters/client_channel/client_channel.cc","file_line":3876,"referenced_errors":[{"created":"@1581097305.108311000","description":"failed to connect to all addresses","file":"src/core/ext/filters/client_channel/lb_policy/pick_first/pick_first.cc","file_line":395,"grpc_status":14}]}"
>
2020-02-07 17:41:51,921 INFO download_runner.impl.historical_runner:32 sending - historical data request : ADRO 2019-01-01 2020-01-01
2020-02-07 17:41:53,117 INFO download_runner.impl.historical_runner:35 sent - historical data request : ADRO 2019-01-01 2020-01-01
2020-02-07 17:41:53,117 DEBUG download_runner.impl.historical_runner:36 request accounted for...
2020-02-07 17:41:53,118 INFO download_runner.impl.historical_runner:37 status : True
2020-02-07 17:41:53,118 INFO download_runner.impl.historical_runner:42 Historical data request sent : ADRO 2019-01-01 2020-01-01
2020-02-07 17:41:53,118 DEBUG download_runner.impl.historical_end_reader:37 poll stock ? => True
2020-02-07 17:41:53,118 ERROR root:30 unhandled exception getting latest timestamp for ADRU
Traceback (most recent call last):
  File "/Users/dali/workspace/ib_python/runner/services/historical_data_service.py", line 24, in get_latest_timestamp
    response = self.stub.GetLatestTimeStamp(request)
  File "/Users/dali/workspace/ib_python/runner/venv/lib/python3.7/site-packages/grpc/_channel.py", line 604, in __call__
    return _end_unary_response_blocking(state, call, False, None)
  File "/Users/dali/workspace/ib_python/runner/venv/lib/python3.7/site-packages/grpc/_channel.py", line 506, in _end_unary_response_blocking
    raise _Rendezvous(state, None, None, deadline)
grpc._channel._Rendezvous: <_Rendezvous of RPC that terminated with:
	status = StatusCode.UNAVAILABLE
	details = "failed to connect to all addresses"
	debug_error_string = "{"created":"@1581097313.118289000","description":"Failed to pick subchannel","file":"src/core/ext/filters/client_channel/client_channel.cc","file_line":3876,"referenced_errors":[{"created":"@1581097305.108311000","description":"failed to connect to all addresses","file":"src/core/ext/filters/client_channel/lb_policy/pick_first/pick_first.cc","file_line":395,"grpc_status":14}]}"
>
2020-02-07 17:41:53,118 INFO download_runner.impl.historical_runner:32 sending - historical data request : ADRU 2019-01-01 2020-01-01
2020-02-07 17:41:58,115 INFO download_runner.impl.historical_runner:35 sent - historical data request : ADRU 2019-01-01 2020-01-01
2020-02-07 17:41:58,115 DEBUG download_runner.impl.historical_runner:36 request accounted for...
2020-02-07 17:41:58,115 INFO download_runner.impl.historical_runner:37 status : True
2020-02-07 17:41:58,115 INFO download_runner.impl.historical_runner:42 Historical data request sent : ADRU 2019-01-01 2020-01-01
2020-02-07 17:41:58,116 DEBUG download_runner.impl.historical_end_reader:37 poll stock ? => True
2020-02-07 17:41:58,116 ERROR root:30 unhandled exception getting latest timestamp for ADS
Traceback (most recent call last):
  File "/Users/dali/workspace/ib_python/runner/services/historical_data_service.py", line 24, in get_latest_timestamp
    response = self.stub.GetLatestTimeStamp(request)
  File "/Users/dali/workspace/ib_python/runner/venv/lib/python3.7/site-packages/grpc/_channel.py", line 604, in __call__
    return _end_unary_response_blocking(state, call, False, None)
  File "/Users/dali/workspace/ib_python/runner/venv/lib/python3.7/site-packages/grpc/_channel.py", line 506, in _end_unary_response_blocking
    raise _Rendezvous(state, None, None, deadline)
grpc._channel._Rendezvous: <_Rendezvous of RPC that terminated with:
	status = StatusCode.UNAVAILABLE
	details = "failed to connect to all addresses"
	debug_error_string = "{"created":"@1581097318.116261000","description":"Failed to pick subchannel","file":"src/core/ext/filters/client_channel/client_channel.cc","file_line":3876,"referenced_errors":[{"created":"@1581097305.108311000","description":"failed to connect to all addresses","file":"src/core/ext/filters/client_channel/lb_policy/pick_first/pick_first.cc","file_line":395,"grpc_status":14}]}"
>
2020-02-07 17:41:58,116 INFO download_runner.impl.historical_runner:32 sending - historical data request : ADS 2019-01-01 2020-01-01
2020-02-07 17:41:58,593 INFO download_runner.impl.historical_runner:35 sent - historical data request : ADS 2019-01-01 2020-01-01
2020-02-07 17:41:58,593 DEBUG download_runner.impl.historical_runner:36 request accounted for...
2020-02-07 17:41:58,593 INFO download_runner.impl.historical_runner:37 status : True
2020-02-07 17:41:58,593 INFO download_runner.impl.historical_runner:42 Historical data request sent : ADS 2019-01-01 2020-01-01
2020-02-07 17:41:58,593 DEBUG download_runner.impl.historical_end_reader:37 poll stock ? => True
2020-02-07 17:41:58,594 ERROR root:30 unhandled exception getting latest timestamp for ADSK
Traceback (most recent call last):
  File "/Users/dali/workspace/ib_python/runner/services/historical_data_service.py", line 24, in get_latest_timestamp
    response = self.stub.GetLatestTimeStamp(request)
  File "/Users/dali/workspace/ib_python/runner/venv/lib/python3.7/site-packages/grpc/_channel.py", line 604, in __call__
    return _end_unary_response_blocking(state, call, False, None)
  File "/Users/dali/workspace/ib_python/runner/venv/lib/python3.7/site-packages/grpc/_channel.py", line 506, in _end_unary_response_blocking
    raise _Rendezvous(state, None, None, deadline)
grpc._channel._Rendezvous: <_Rendezvous of RPC that terminated with:
	status = StatusCode.UNAVAILABLE
	details = "failed to connect to all addresses"
	debug_error_string = "{"created":"@1581097318.594162000","description":"Failed to pick subchannel","file":"src/core/ext/filters/client_channel/client_channel.cc","file_line":3876,"referenced_errors":[{"created":"@1581097305.108311000","description":"failed to connect to all addresses","file":"src/core/ext/filters/client_channel/lb_policy/pick_first/pick_first.cc","file_line":395,"grpc_status":14}]}"
>
2020-02-07 17:41:58,594 INFO download_runner.impl.historical_runner:32 sending - historical data request : ADSK 2019-01-01 2020-01-01
2020-02-07 17:41:59,910 INFO download_runner.impl.historical_runner:35 sent - historical data request : ADSK 2019-01-01 2020-01-01
2020-02-07 17:41:59,910 DEBUG download_runner.impl.historical_runner:36 request accounted for...
2020-02-07 17:41:59,910 INFO download_runner.impl.historical_runner:37 status : True
2020-02-07 17:41:59,910 INFO download_runner.impl.historical_runner:42 Historical data request sent : ADSK 2019-01-01 2020-01-01
2020-02-07 17:41:59,910 DEBUG download_runner.impl.historical_end_reader:37 poll stock ? => True
2020-02-07 17:41:59,910 ERROR root:30 unhandled exception getting latest timestamp for ADSW
Traceback (most recent call last):
  File "/Users/dali/workspace/ib_python/runner/services/historical_data_service.py", line 24, in get_latest_timestamp
    response = self.stub.GetLatestTimeStamp(request)
  File "/Users/dali/workspace/ib_python/runner/venv/lib/python3.7/site-packages/grpc/_channel.py", line 604, in __call__
    return _end_unary_response_blocking(state, call, False, None)
  File "/Users/dali/workspace/ib_python/runner/venv/lib/python3.7/site-packages/grpc/_channel.py", line 506, in _end_unary_response_blocking
    raise _Rendezvous(state, None, None, deadline)
grpc._channel._Rendezvous: <_Rendezvous of RPC that terminated with:
	status = StatusCode.UNAVAILABLE
	details = "failed to connect to all addresses"
	debug_error_string = "{"created":"@1581097319.910590000","description":"Failed to pick subchannel","file":"src/core/ext/filters/client_channel/client_channel.cc","file_line":3876,"referenced_errors":[{"created":"@1581097305.108311000","description":"failed to connect to all addresses","file":"src/core/ext/filters/client_channel/lb_policy/pick_first/pick_first.cc","file_line":395,"grpc_status":14}]}"
>
2020-02-07 17:41:59,910 INFO download_runner.impl.historical_runner:32 sending - historical data request : ADSW 2019-01-01 2020-01-01
2020-02-07 17:42:05,055 INFO download_runner.impl.historical_runner:35 sent - historical data request : ADSW 2019-01-01 2020-01-01
2020-02-07 17:42:05,056 DEBUG download_runner.impl.historical_runner:36 request accounted for...
2020-02-07 17:42:05,056 INFO download_runner.impl.historical_runner:37 status : True
2020-02-07 17:42:05,056 INFO download_runner.impl.historical_runner:42 Historical data request sent : ADSW 2019-01-01 2020-01-01
2020-02-07 17:42:05,056 DEBUG download_runner.impl.historical_end_reader:37 poll stock ? => True
2020-02-07 17:42:05,056 ERROR root:30 unhandled exception getting latest timestamp for ADT
Traceback (most recent call last):
  File "/Users/dali/workspace/ib_python/runner/services/historical_data_service.py", line 24, in get_latest_timestamp
    response = self.stub.GetLatestTimeStamp(request)
  File "/Users/dali/workspace/ib_python/runner/venv/lib/python3.7/site-packages/grpc/_channel.py", line 604, in __call__
    return _end_unary_response_blocking(state, call, False, None)
  File "/Users/dali/workspace/ib_python/runner/venv/lib/python3.7/site-packages/grpc/_channel.py", line 506, in _end_unary_response_blocking
    raise _Rendezvous(state, None, None, deadline)
grpc._channel._Rendezvous: <_Rendezvous of RPC that terminated with:
	status = StatusCode.UNAVAILABLE
	details = "failed to connect to all addresses"
	debug_error_string = "{"created":"@1581097325.056584000","description":"Failed to pick subchannel","file":"src/core/ext/filters/client_channel/client_channel.cc","file_line":3876,"referenced_errors":[{"created":"@1581097305.108311000","description":"failed to connect to all addresses","file":"src/core/ext/filters/client_channel/lb_policy/pick_first/pick_first.cc","file_line":395,"grpc_status":14}]}"
>
2020-02-07 17:42:05,056 INFO download_runner.impl.historical_runner:32 sending - historical data request : ADT 2019-01-01 2020-01-01
2020-02-07 17:42:05,542 INFO download_runner.impl.historical_runner:35 sent - historical data request : ADT 2019-01-01 2020-01-01
2020-02-07 17:42:05,542 DEBUG download_runner.impl.historical_runner:36 request accounted for...
2020-02-07 17:42:05,542 INFO download_runner.impl.historical_runner:37 status : True
2020-02-07 17:42:05,542 INFO download_runner.impl.historical_runner:42 Historical data request sent : ADT 2019-01-01 2020-01-01
2020-02-07 17:42:05,542 DEBUG download_runner.impl.historical_end_reader:37 poll stock ? => True
2020-02-07 17:42:05,543 ERROR root:30 unhandled exception getting latest timestamp for ADTN
Traceback (most recent call last):
  File "/Users/dali/workspace/ib_python/runner/services/historical_data_service.py", line 24, in get_latest_timestamp
    response = self.stub.GetLatestTimeStamp(request)
  File "/Users/dali/workspace/ib_python/runner/venv/lib/python3.7/site-packages/grpc/_channel.py", line 604, in __call__
    return _end_unary_response_blocking(state, call, False, None)
  File "/Users/dali/workspace/ib_python/runner/venv/lib/python3.7/site-packages/grpc/_channel.py", line 506, in _end_unary_response_blocking
    raise _Rendezvous(state, None, None, deadline)
grpc._channel._Rendezvous: <_Rendezvous of RPC that terminated with:
	status = StatusCode.UNAVAILABLE
	details = "failed to connect to all addresses"
	debug_error_string = "{"created":"@1581097325.543017000","description":"Failed to pick subchannel","file":"src/core/ext/filters/client_channel/client_channel.cc","file_line":3876,"referenced_errors":[{"created":"@1581097305.108311000","description":"failed to connect to all addresses","file":"src/core/ext/filters/client_channel/lb_policy/pick_first/pick_first.cc","file_line":395,"grpc_status":14}]}"
>
2020-02-07 17:42:05,543 INFO download_runner.impl.historical_runner:32 sending - historical data request : ADTN 2019-01-01 2020-01-01
2020-02-07 17:42:10,399 INFO download_runner.impl.historical_runner:35 sent - historical data request : ADTN 2019-01-01 2020-01-01
2020-02-07 17:42:10,399 DEBUG download_runner.impl.historical_runner:36 request accounted for...
2020-02-07 17:42:10,399 INFO download_runner.impl.historical_runner:37 status : True
2020-02-07 17:42:10,399 INFO download_runner.impl.historical_runner:42 Historical data request sent : ADTN 2019-01-01 2020-01-01
2020-02-07 17:42:10,399 DEBUG download_runner.impl.historical_end_reader:37 poll stock ? => True
2020-02-07 17:42:10,400 ERROR root:30 unhandled exception getting latest timestamp for ADUS
Traceback (most recent call last):
  File "/Users/dali/workspace/ib_python/runner/services/historical_data_service.py", line 24, in get_latest_timestamp
    response = self.stub.GetLatestTimeStamp(request)
  File "/Users/dali/workspace/ib_python/runner/venv/lib/python3.7/site-packages/grpc/_channel.py", line 604, in __call__
    return _end_unary_response_blocking(state, call, False, None)
  File "/Users/dali/workspace/ib_python/runner/venv/lib/python3.7/site-packages/grpc/_channel.py", line 506, in _end_unary_response_blocking
    raise _Rendezvous(state, None, None, deadline)
grpc._channel._Rendezvous: <_Rendezvous of RPC that terminated with:
	status = StatusCode.UNAVAILABLE
	details = "failed to connect to all addresses"
	debug_error_string = "{"created":"@1581097330.400061000","description":"Failed to pick subchannel","file":"src/core/ext/filters/client_channel/client_channel.cc","file_line":3876,"referenced_errors":[{"created":"@1581097305.108311000","description":"failed to connect to all addresses","file":"src/core/ext/filters/client_channel/lb_policy/pick_first/pick_first.cc","file_line":395,"grpc_status":14}]}"
>
2020-02-07 17:42:10,400 INFO download_runner.impl.historical_runner:32 sending - historical data request : ADUS 2019-01-01 2020-01-01
2020-02-07 17:42:22,173 INFO download_runner.impl.historical_runner:35 sent - historical data request : ADUS 2019-01-01 2020-01-01
2020-02-07 17:42:22,174 DEBUG download_runner.impl.historical_runner:36 request accounted for...
2020-02-07 17:42:22,174 INFO download_runner.impl.historical_runner:37 status : True
2020-02-07 17:42:22,174 INFO download_runner.impl.historical_runner:42 Historical data request sent : ADUS 2019-01-01 2020-01-01
2020-02-07 17:42:22,174 DEBUG download_runner.impl.historical_end_reader:37 poll stock ? => True
2020-02-07 17:42:22,174 ERROR root:30 unhandled exception getting latest timestamp for ADVM
Traceback (most recent call last):
  File "/Users/dali/workspace/ib_python/runner/services/historical_data_service.py", line 24, in get_latest_timestamp
    response = self.stub.GetLatestTimeStamp(request)
  File "/Users/dali/workspace/ib_python/runner/venv/lib/python3.7/site-packages/grpc/_channel.py", line 604, in __call__
    return _end_unary_response_blocking(state, call, False, None)
  File "/Users/dali/workspace/ib_python/runner/venv/lib/python3.7/site-packages/grpc/_channel.py", line 506, in _end_unary_response_blocking
    raise _Rendezvous(state, None, None, deadline)
grpc._channel._Rendezvous: <_Rendezvous of RPC that terminated with:
	status = StatusCode.UNAVAILABLE
	details = "failed to connect to all addresses"
	debug_error_string = "{"created":"@1581097342.174510000","description":"Failed to pick subchannel","file":"src/core/ext/filters/client_channel/client_channel.cc","file_line":3876,"referenced_errors":[{"created":"@1581097305.108311000","description":"failed to connect to all addresses","file":"src/core/ext/filters/client_channel/lb_policy/pick_first/pick_first.cc","file_line":395,"grpc_status":14}]}"
>
2020-02-07 17:42:22,174 INFO download_runner.impl.historical_runner:32 sending - historical data request : ADVM 2019-01-01 2020-01-01
2020-02-07 17:42:34,107 INFO download_runner.impl.historical_runner:35 sent - historical data request : ADVM 2019-01-01 2020-01-01
2020-02-07 17:42:34,107 DEBUG download_runner.impl.historical_runner:36 request accounted for...
2020-02-07 17:42:34,107 INFO download_runner.impl.historical_runner:37 status : True
2020-02-07 17:42:34,107 INFO download_runner.impl.historical_runner:42 Historical data request sent : ADVM 2019-01-01 2020-01-01
2020-02-07 17:42:34,107 DEBUG download_runner.impl.historical_end_reader:37 poll stock ? => True
2020-02-07 17:42:34,107 ERROR root:30 unhandled exception getting latest timestamp for ADX
Traceback (most recent call last):
  File "/Users/dali/workspace/ib_python/runner/services/historical_data_service.py", line 24, in get_latest_timestamp
    response = self.stub.GetLatestTimeStamp(request)
  File "/Users/dali/workspace/ib_python/runner/venv/lib/python3.7/site-packages/grpc/_channel.py", line 604, in __call__
    return _end_unary_response_blocking(state, call, False, None)
  File "/Users/dali/workspace/ib_python/runner/venv/lib/python3.7/site-packages/grpc/_channel.py", line 506, in _end_unary_response_blocking
    raise _Rendezvous(state, None, None, deadline)
grpc._channel._Rendezvous: <_Rendezvous of RPC that terminated with:
	status = StatusCode.UNAVAILABLE
	details = "failed to connect to all addresses"
	debug_error_string = "{"created":"@1581097354.107770000","description":"Failed to pick subchannel","file":"src/core/ext/filters/client_channel/client_channel.cc","file_line":3876,"referenced_errors":[{"created":"@1581097305.108311000","description":"failed to connect to all addresses","file":"src/core/ext/filters/client_channel/lb_policy/pick_first/pick_first.cc","file_line":395,"grpc_status":14}]}"
>
2020-02-07 17:42:34,108 INFO download_runner.impl.historical_runner:32 sending - historical data request : ADX 2019-01-01 2020-01-01
2020-02-07 17:42:46,815 INFO download_runner.impl.historical_runner:35 sent - historical data request : ADX 2019-01-01 2020-01-01
2020-02-07 17:42:46,815 DEBUG download_runner.impl.historical_runner:36 request accounted for...
2020-02-07 17:42:46,815 INFO download_runner.impl.historical_runner:37 status : True
2020-02-07 17:42:46,815 INFO download_runner.impl.historical_runner:42 Historical data request sent : ADX 2019-01-01 2020-01-01
2020-02-07 17:42:46,815 DEBUG download_runner.impl.historical_end_reader:37 poll stock ? => True
2020-02-07 17:42:46,815 ERROR root:30 unhandled exception getting latest timestamp for ADXS
Traceback (most recent call last):
  File "/Users/dali/workspace/ib_python/runner/services/historical_data_service.py", line 24, in get_latest_timestamp
    response = self.stub.GetLatestTimeStamp(request)
  File "/Users/dali/workspace/ib_python/runner/venv/lib/python3.7/site-packages/grpc/_channel.py", line 604, in __call__
    return _end_unary_response_blocking(state, call, False, None)
  File "/Users/dali/workspace/ib_python/runner/venv/lib/python3.7/site-packages/grpc/_channel.py", line 506, in _end_unary_response_blocking
    raise _Rendezvous(state, None, None, deadline)
grpc._channel._Rendezvous: <_Rendezvous of RPC that terminated with:
	status = StatusCode.UNAVAILABLE
	details = "failed to connect to all addresses"
	debug_error_string = "{"created":"@1581097366.815547000","description":"Failed to pick subchannel","file":"src/core/ext/filters/client_channel/client_channel.cc","file_line":3876,"referenced_errors":[{"created":"@1581097305.108311000","description":"failed to connect to all addresses","file":"src/core/ext/filters/client_channel/lb_policy/pick_first/pick_first.cc","file_line":395,"grpc_status":14}]}"
>
2020-02-07 17:42:46,815 INFO download_runner.impl.historical_runner:32 sending - historical data request : ADXS 2019-01-01 2020-01-01
2020-02-07 17:42:47,807 INFO download_runner.impl.historical_runner:35 sent - historical data request : ADXS 2019-01-01 2020-01-01
2020-02-07 17:42:47,807 DEBUG download_runner.impl.historical_runner:36 request accounted for...
2020-02-07 17:42:47,807 INFO download_runner.impl.historical_runner:37 status : True
2020-02-07 17:42:47,807 INFO download_runner.impl.historical_runner:42 Historical data request sent : ADXS 2019-01-01 2020-01-01
2020-02-07 17:42:47,807 DEBUG download_runner.impl.historical_end_reader:37 poll stock ? => True
2020-02-07 17:42:47,808 ERROR root:30 unhandled exception getting latest timestamp for AE
Traceback (most recent call last):
  File "/Users/dali/workspace/ib_python/runner/services/historical_data_service.py", line 24, in get_latest_timestamp
    response = self.stub.GetLatestTimeStamp(request)
  File "/Users/dali/workspace/ib_python/runner/venv/lib/python3.7/site-packages/grpc/_channel.py", line 604, in __call__
    return _end_unary_response_blocking(state, call, False, None)
  File "/Users/dali/workspace/ib_python/runner/venv/lib/python3.7/site-packages/grpc/_channel.py", line 506, in _end_unary_response_blocking
    raise _Rendezvous(state, None, None, deadline)
grpc._channel._Rendezvous: <_Rendezvous of RPC that terminated with:
	status = StatusCode.UNAVAILABLE
	details = "failed to connect to all addresses"
	debug_error_string = "{"created":"@1581097367.808050000","description":"Failed to pick subchannel","file":"src/core/ext/filters/client_channel/client_channel.cc","file_line":3876,"referenced_errors":[{"created":"@1581097305.108311000","description":"failed to connect to all addresses","file":"src/core/ext/filters/client_channel/lb_policy/pick_first/pick_first.cc","file_line":395,"grpc_status":14}]}"
>
2020-02-07 17:42:47,808 INFO download_runner.impl.historical_runner:32 sending - historical data request : AE 2019-01-01 2020-01-01
2020-02-07 17:42:49,005 INFO download_runner.impl.historical_runner:35 sent - historical data request : AE 2019-01-01 2020-01-01
2020-02-07 17:42:49,005 DEBUG download_runner.impl.historical_runner:36 request accounted for...
2020-02-07 17:42:49,005 INFO download_runner.impl.historical_runner:37 status : True
2020-02-07 17:42:49,005 INFO download_runner.impl.historical_runner:42 Historical data request sent : AE 2019-01-01 2020-01-01
2020-02-07 17:42:49,005 DEBUG download_runner.impl.historical_end_reader:37 poll stock ? => True
2020-02-07 17:42:49,005 ERROR root:30 unhandled exception getting latest timestamp for AEB
Traceback (most recent call last):
  File "/Users/dali/workspace/ib_python/runner/services/historical_data_service.py", line 24, in get_latest_timestamp
    response = self.stub.GetLatestTimeStamp(request)
  File "/Users/dali/workspace/ib_python/runner/venv/lib/python3.7/site-packages/grpc/_channel.py", line 604, in __call__
    return _end_unary_response_blocking(state, call, False, None)
  File "/Users/dali/workspace/ib_python/runner/venv/lib/python3.7/site-packages/grpc/_channel.py", line 506, in _end_unary_response_blocking
    raise _Rendezvous(state, None, None, deadline)
grpc._channel._Rendezvous: <_Rendezvous of RPC that terminated with:
	status = StatusCode.UNAVAILABLE
	details = "failed to connect to all addresses"
	debug_error_string = "{"created":"@1581097369.005837000","description":"Failed to pick subchannel","file":"src/core/ext/filters/client_channel/client_channel.cc","file_line":3876,"referenced_errors":[{"created":"@1581097305.108311000","description":"failed to connect to all addresses","file":"src/core/ext/filters/client_channel/lb_policy/pick_first/pick_first.cc","file_line":395,"grpc_status":14}]}"
>
2020-02-07 17:42:49,006 INFO download_runner.impl.historical_runner:32 sending - historical data request : AEB 2019-01-01 2020-01-01
2020-02-07 17:42:49,804 INFO download_runner.impl.historical_runner:35 sent - historical data request : AEB 2019-01-01 2020-01-01
2020-02-07 17:42:49,804 DEBUG download_runner.impl.historical_runner:36 request accounted for...
2020-02-07 17:42:49,804 INFO download_runner.impl.historical_runner:37 status : True
2020-02-07 17:42:49,804 INFO download_runner.impl.historical_runner:42 Historical data request sent : AEB 2019-01-01 2020-01-01
2020-02-07 17:42:49,804 DEBUG download_runner.impl.historical_end_reader:37 poll stock ? => True
2020-02-07 17:42:49,804 ERROR root:30 unhandled exception getting latest timestamp for AEE
Traceback (most recent call last):
  File "/Users/dali/workspace/ib_python/runner/services/historical_data_service.py", line 24, in get_latest_timestamp
    response = self.stub.GetLatestTimeStamp(request)
  File "/Users/dali/workspace/ib_python/runner/venv/lib/python3.7/site-packages/grpc/_channel.py", line 604, in __call__
    return _end_unary_response_blocking(state, call, False, None)
  File "/Users/dali/workspace/ib_python/runner/venv/lib/python3.7/site-packages/grpc/_channel.py", line 506, in _end_unary_response_blocking
    raise _Rendezvous(state, None, None, deadline)
grpc._channel._Rendezvous: <_Rendezvous of RPC that terminated with:
	status = StatusCode.UNAVAILABLE
	details = "failed to connect to all addresses"
	debug_error_string = "{"created":"@1581097369.804494000","description":"Failed to pick subchannel","file":"src/core/ext/filters/client_channel/client_channel.cc","file_line":3876,"referenced_errors":[{"created":"@1581097305.108311000","description":"failed to connect to all addresses","file":"src/core/ext/filters/client_channel/lb_policy/pick_first/pick_first.cc","file_line":395,"grpc_status":14}]}"
>
2020-02-07 17:42:49,804 INFO download_runner.impl.historical_runner:32 sending - historical data request : AEE 2019-01-01 2020-01-01
2020-02-07 17:42:52,013 INFO download_runner.impl.historical_runner:35 sent - historical data request : AEE 2019-01-01 2020-01-01
2020-02-07 17:42:52,013 DEBUG download_runner.impl.historical_runner:36 request accounted for...
2020-02-07 17:42:52,013 INFO download_runner.impl.historical_runner:37 status : True
2020-02-07 17:42:52,014 INFO download_runner.impl.historical_runner:42 Historical data request sent : AEE 2019-01-01 2020-01-01
2020-02-07 17:42:52,014 DEBUG download_runner.impl.historical_end_reader:37 poll stock ? => True
2020-02-07 17:42:52,014 ERROR root:30 unhandled exception getting latest timestamp for AEF
Traceback (most recent call last):
  File "/Users/dali/workspace/ib_python/runner/services/historical_data_service.py", line 24, in get_latest_timestamp
    response = self.stub.GetLatestTimeStamp(request)
  File "/Users/dali/workspace/ib_python/runner/venv/lib/python3.7/site-packages/grpc/_channel.py", line 604, in __call__
    return _end_unary_response_blocking(state, call, False, None)
  File "/Users/dali/workspace/ib_python/runner/venv/lib/python3.7/site-packages/grpc/_channel.py", line 506, in _end_unary_response_blocking
    raise _Rendezvous(state, None, None, deadline)
grpc._channel._Rendezvous: <_Rendezvous of RPC that terminated with:
	status = StatusCode.UNAVAILABLE
	details = "failed to connect to all addresses"
	debug_error_string = "{"created":"@1581097372.014295000","description":"Failed to pick subchannel","file":"src/core/ext/filters/client_channel/client_channel.cc","file_line":3876,"referenced_errors":[{"created":"@1581097305.108311000","description":"failed to connect to all addresses","file":"src/core/ext/filters/client_channel/lb_policy/pick_first/pick_first.cc","file_line":395,"grpc_status":14}]}"
>
2020-02-07 17:42:52,014 INFO download_runner.impl.historical_runner:32 sending - historical data request : AEF 2019-01-01 2020-01-01
2020-02-07 17:42:53,223 INFO download_runner.impl.historical_runner:35 sent - historical data request : AEF 2019-01-01 2020-01-01
2020-02-07 17:42:53,223 DEBUG download_runner.impl.historical_runner:36 request accounted for...
2020-02-07 17:42:53,223 INFO download_runner.impl.historical_runner:37 status : True
2020-02-07 17:42:53,223 INFO download_runner.impl.historical_runner:42 Historical data request sent : AEF 2019-01-01 2020-01-01
2020-02-07 17:42:53,223 DEBUG download_runner.impl.historical_end_reader:37 poll stock ? => True
2020-02-07 17:42:53,223 ERROR root:30 unhandled exception getting latest timestamp for AEFC
Traceback (most recent call last):
  File "/Users/dali/workspace/ib_python/runner/services/historical_data_service.py", line 24, in get_latest_timestamp
    response = self.stub.GetLatestTimeStamp(request)
  File "/Users/dali/workspace/ib_python/runner/venv/lib/python3.7/site-packages/grpc/_channel.py", line 604, in __call__
    return _end_unary_response_blocking(state, call, False, None)
  File "/Users/dali/workspace/ib_python/runner/venv/lib/python3.7/site-packages/grpc/_channel.py", line 506, in _end_unary_response_blocking
    raise _Rendezvous(state, None, None, deadline)
grpc._channel._Rendezvous: <_Rendezvous of RPC that terminated with:
	status = StatusCode.UNAVAILABLE
	details = "failed to connect to all addresses"
	debug_error_string = "{"created":"@1581097373.223784000","description":"Failed to pick subchannel","file":"src/core/ext/filters/client_channel/client_channel.cc","file_line":3876,"referenced_errors":[{"created":"@1581097305.108311000","description":"failed to connect to all addresses","file":"src/core/ext/filters/client_channel/lb_policy/pick_first/pick_first.cc","file_line":395,"grpc_status":14}]}"
>
2020-02-07 17:42:53,224 INFO download_runner.impl.historical_runner:32 sending - historical data request : AEFC 2019-01-01 2020-01-01
2020-02-07 17:42:53,753 INFO download_runner.impl.historical_runner:35 sent - historical data request : AEFC 2019-01-01 2020-01-01
2020-02-07 17:42:53,753 DEBUG download_runner.impl.historical_runner:36 request accounted for...
2020-02-07 17:42:53,753 INFO download_runner.impl.historical_runner:37 status : True
2020-02-07 17:42:53,753 INFO download_runner.impl.historical_runner:42 Historical data request sent : AEFC 2019-01-01 2020-01-01
2020-02-07 17:42:53,753 DEBUG download_runner.impl.historical_end_reader:37 poll stock ? => True
2020-02-07 17:42:53,754 ERROR root:30 unhandled exception getting latest timestamp for AEG
Traceback (most recent call last):
  File "/Users/dali/workspace/ib_python/runner/services/historical_data_service.py", line 24, in get_latest_timestamp
    response = self.stub.GetLatestTimeStamp(request)
  File "/Users/dali/workspace/ib_python/runner/venv/lib/python3.7/site-packages/grpc/_channel.py", line 604, in __call__
    return _end_unary_response_blocking(state, call, False, None)
  File "/Users/dali/workspace/ib_python/runner/venv/lib/python3.7/site-packages/grpc/_channel.py", line 506, in _end_unary_response_blocking
    raise _Rendezvous(state, None, None, deadline)
grpc._channel._Rendezvous: <_Rendezvous of RPC that terminated with:
	status = StatusCode.UNAVAILABLE
	details = "failed to connect to all addresses"
	debug_error_string = "{"created":"@1581097373.754085000","description":"Failed to pick subchannel","file":"src/core/ext/filters/client_channel/client_channel.cc","file_line":3876,"referenced_errors":[{"created":"@1581097305.108311000","description":"failed to connect to all addresses","file":"src/core/ext/filters/client_channel/lb_policy/pick_first/pick_first.cc","file_line":395,"grpc_status":14}]}"
>
2020-02-07 17:42:53,754 INFO download_runner.impl.historical_runner:32 sending - historical data request : AEG 2019-01-01 2020-01-01
2020-02-07 17:42:58,503 INFO download_runner.impl.historical_runner:35 sent - historical data request : AEG 2019-01-01 2020-01-01
2020-02-07 17:42:58,504 DEBUG download_runner.impl.historical_runner:36 request accounted for...
2020-02-07 17:42:58,504 INFO download_runner.impl.historical_runner:37 status : True
2020-02-07 17:42:58,504 INFO download_runner.impl.historical_runner:42 Historical data request sent : AEG 2019-01-01 2020-01-01
2020-02-07 17:42:58,504 DEBUG download_runner.impl.historical_end_reader:37 poll stock ? => True
2020-02-07 17:42:58,504 ERROR root:30 unhandled exception getting latest timestamp for AEGN
Traceback (most recent call last):
  File "/Users/dali/workspace/ib_python/runner/services/historical_data_service.py", line 24, in get_latest_timestamp
    response = self.stub.GetLatestTimeStamp(request)
  File "/Users/dali/workspace/ib_python/runner/venv/lib/python3.7/site-packages/grpc/_channel.py", line 604, in __call__
    return _end_unary_response_blocking(state, call, False, None)
  File "/Users/dali/workspace/ib_python/runner/venv/lib/python3.7/site-packages/grpc/_channel.py", line 506, in _end_unary_response_blocking
    raise _Rendezvous(state, None, None, deadline)
grpc._channel._Rendezvous: <_Rendezvous of RPC that terminated with:
	status = StatusCode.UNAVAILABLE
	details = "failed to connect to all addresses"
	debug_error_string = "{"created":"@1581097378.504560000","description":"Failed to pick subchannel","file":"src/core/ext/filters/client_channel/client_channel.cc","file_line":3876,"referenced_errors":[{"created":"@1581097305.108311000","description":"failed to connect to all addresses","file":"src/core/ext/filters/client_channel/lb_policy/pick_first/pick_first.cc","file_line":395,"grpc_status":14}]}"
>
2020-02-07 17:42:58,504 INFO download_runner.impl.historical_runner:32 sending - historical data request : AEGN 2019-01-01 2020-01-01
2020-02-07 17:42:58,871 INFO download_runner.impl.historical_runner:35 sent - historical data request : AEGN 2019-01-01 2020-01-01
2020-02-07 17:42:58,871 DEBUG download_runner.impl.historical_runner:36 request accounted for...
2020-02-07 17:42:58,871 INFO download_runner.impl.historical_runner:37 status : True
2020-02-07 17:42:58,871 INFO download_runner.impl.historical_runner:42 Historical data request sent : AEGN 2019-01-01 2020-01-01
2020-02-07 17:42:58,871 DEBUG download_runner.impl.historical_end_reader:37 poll stock ? => True
2020-02-07 17:42:58,872 ERROR root:30 unhandled exception getting latest timestamp for AEH CL
Traceback (most recent call last):
  File "/Users/dali/workspace/ib_python/runner/services/historical_data_service.py", line 24, in get_latest_timestamp
    response = self.stub.GetLatestTimeStamp(request)
  File "/Users/dali/workspace/ib_python/runner/venv/lib/python3.7/site-packages/grpc/_channel.py", line 604, in __call__
    return _end_unary_response_blocking(state, call, False, None)
  File "/Users/dali/workspace/ib_python/runner/venv/lib/python3.7/site-packages/grpc/_channel.py", line 506, in _end_unary_response_blocking
    raise _Rendezvous(state, None, None, deadline)
grpc._channel._Rendezvous: <_Rendezvous of RPC that terminated with:
	status = StatusCode.UNAVAILABLE
	details = "failed to connect to all addresses"
	debug_error_string = "{"created":"@1581097378.872060000","description":"Failed to pick subchannel","file":"src/core/ext/filters/client_channel/client_channel.cc","file_line":3876,"referenced_errors":[{"created":"@1581097305.108311000","description":"failed to connect to all addresses","file":"src/core/ext/filters/client_channel/lb_policy/pick_first/pick_first.cc","file_line":395,"grpc_status":14}]}"
>
2020-02-07 17:42:58,872 INFO download_runner.impl.historical_runner:32 sending - historical data request : AEH CL 2019-01-01 2020-01-01
2020-02-07 17:42:59,557 INFO download_runner.impl.historical_runner:35 sent - historical data request : AEH CL 2019-01-01 2020-01-01
2020-02-07 17:42:59,557 DEBUG download_runner.impl.historical_runner:36 request accounted for...
2020-02-07 17:42:59,557 INFO download_runner.impl.historical_runner:37 status : True
2020-02-07 17:42:59,557 INFO download_runner.impl.historical_runner:42 Historical data request sent : AEH CL 2019-01-01 2020-01-01
2020-02-07 17:42:59,558 DEBUG download_runner.impl.historical_end_reader:37 poll stock ? => True
2020-02-07 17:42:59,558 ERROR root:30 unhandled exception getting latest timestamp for AEHR
Traceback (most recent call last):
  File "/Users/dali/workspace/ib_python/runner/services/historical_data_service.py", line 24, in get_latest_timestamp
    response = self.stub.GetLatestTimeStamp(request)
  File "/Users/dali/workspace/ib_python/runner/venv/lib/python3.7/site-packages/grpc/_channel.py", line 604, in __call__
    return _end_unary_response_blocking(state, call, False, None)
  File "/Users/dali/workspace/ib_python/runner/venv/lib/python3.7/site-packages/grpc/_channel.py", line 506, in _end_unary_response_blocking
    raise _Rendezvous(state, None, None, deadline)
grpc._channel._Rendezvous: <_Rendezvous of RPC that terminated with:
	status = StatusCode.UNAVAILABLE
	details = "failed to connect to all addresses"
	debug_error_string = "{"created":"@1581097379.558251000","description":"Failed to pick subchannel","file":"src/core/ext/filters/client_channel/client_channel.cc","file_line":3876,"referenced_errors":[{"created":"@1581097305.108311000","description":"failed to connect to all addresses","file":"src/core/ext/filters/client_channel/lb_policy/pick_first/pick_first.cc","file_line":395,"grpc_status":14}]}"
>
2020-02-07 17:42:59,558 INFO download_runner.impl.historical_runner:32 sending - historical data request : AEHR 2019-01-01 2020-01-01
2020-02-07 17:42:59,715 INFO download_runner.impl.historical_runner:35 sent - historical data request : AEHR 2019-01-01 2020-01-01
2020-02-07 17:42:59,715 DEBUG download_runner.impl.historical_runner:36 request accounted for...
2020-02-07 17:42:59,715 INFO download_runner.impl.historical_runner:37 status : True
2020-02-07 17:42:59,715 INFO download_runner.impl.historical_runner:42 Historical data request sent : AEHR 2019-01-01 2020-01-01
2020-02-07 17:42:59,715 DEBUG download_runner.impl.historical_end_reader:37 poll stock ? => True
2020-02-07 17:42:59,716 ERROR root:30 unhandled exception getting latest timestamp for AEIS
Traceback (most recent call last):
  File "/Users/dali/workspace/ib_python/runner/services/historical_data_service.py", line 24, in get_latest_timestamp
    response = self.stub.GetLatestTimeStamp(request)
  File "/Users/dali/workspace/ib_python/runner/venv/lib/python3.7/site-packages/grpc/_channel.py", line 604, in __call__
    return _end_unary_response_blocking(state, call, False, None)
  File "/Users/dali/workspace/ib_python/runner/venv/lib/python3.7/site-packages/grpc/_channel.py", line 506, in _end_unary_response_blocking
    raise _Rendezvous(state, None, None, deadline)
grpc._channel._Rendezvous: <_Rendezvous of RPC that terminated with:
	status = StatusCode.UNAVAILABLE
	details = "failed to connect to all addresses"
	debug_error_string = "{"created":"@1581097379.716298000","description":"Failed to pick subchannel","file":"src/core/ext/filters/client_channel/client_channel.cc","file_line":3876,"referenced_errors":[{"created":"@1581097305.108311000","description":"failed to connect to all addresses","file":"src/core/ext/filters/client_channel/lb_policy/pick_first/pick_first.cc","file_line":395,"grpc_status":14}]}"
>
2020-02-07 17:42:59,716 INFO download_runner.impl.historical_runner:32 sending - historical data request : AEIS 2019-01-01 2020-01-01
2020-02-07 17:43:04,973 INFO download_runner.impl.historical_runner:35 sent - historical data request : AEIS 2019-01-01 2020-01-01
2020-02-07 17:43:04,974 DEBUG download_runner.impl.historical_runner:36 request accounted for...
2020-02-07 17:43:04,974 INFO download_runner.impl.historical_runner:37 status : True
2020-02-07 17:43:04,974 INFO download_runner.impl.historical_runner:42 Historical data request sent : AEIS 2019-01-01 2020-01-01
2020-02-07 17:43:04,974 DEBUG download_runner.impl.historical_end_reader:37 poll stock ? => True
2020-02-07 17:43:04,974 ERROR root:30 unhandled exception getting latest timestamp for AEL
Traceback (most recent call last):
  File "/Users/dali/workspace/ib_python/runner/services/historical_data_service.py", line 24, in get_latest_timestamp
    response = self.stub.GetLatestTimeStamp(request)
  File "/Users/dali/workspace/ib_python/runner/venv/lib/python3.7/site-packages/grpc/_channel.py", line 604, in __call__
    return _end_unary_response_blocking(state, call, False, None)
  File "/Users/dali/workspace/ib_python/runner/venv/lib/python3.7/site-packages/grpc/_channel.py", line 506, in _end_unary_response_blocking
    raise _Rendezvous(state, None, None, deadline)
grpc._channel._Rendezvous: <_Rendezvous of RPC that terminated with:
	status = StatusCode.UNAVAILABLE
	details = "failed to connect to all addresses"
	debug_error_string = "{"created":"@1581097384.974418000","description":"Failed to pick subchannel","file":"src/core/ext/filters/client_channel/client_channel.cc","file_line":3876,"referenced_errors":[{"created":"@1581097305.108311000","description":"failed to connect to all addresses","file":"src/core/ext/filters/client_channel/lb_policy/pick_first/pick_first.cc","file_line":395,"grpc_status":14}]}"
>
2020-02-07 17:43:04,974 INFO download_runner.impl.historical_runner:32 sending - historical data request : AEL 2019-01-01 2020-01-01
2020-02-07 17:43:10,295 INFO download_runner.impl.historical_runner:35 sent - historical data request : AEL 2019-01-01 2020-01-01
2020-02-07 17:43:10,295 DEBUG download_runner.impl.historical_runner:36 request accounted for...
2020-02-07 17:43:10,295 INFO download_runner.impl.historical_runner:37 status : True
2020-02-07 17:43:10,295 INFO download_runner.impl.historical_runner:42 Historical data request sent : AEL 2019-01-01 2020-01-01
2020-02-07 17:43:10,296 DEBUG download_runner.impl.historical_end_reader:37 poll stock ? => True
2020-02-07 17:43:10,296 ERROR root:30 unhandled exception getting latest timestamp for AEM
Traceback (most recent call last):
  File "/Users/dali/workspace/ib_python/runner/services/historical_data_service.py", line 24, in get_latest_timestamp
    response = self.stub.GetLatestTimeStamp(request)
  File "/Users/dali/workspace/ib_python/runner/venv/lib/python3.7/site-packages/grpc/_channel.py", line 604, in __call__
    return _end_unary_response_blocking(state, call, False, None)
  File "/Users/dali/workspace/ib_python/runner/venv/lib/python3.7/site-packages/grpc/_channel.py", line 506, in _end_unary_response_blocking
    raise _Rendezvous(state, None, None, deadline)
grpc._channel._Rendezvous: <_Rendezvous of RPC that terminated with:
	status = StatusCode.UNAVAILABLE
	details = "failed to connect to all addresses"
	debug_error_string = "{"created":"@1581097390.296303000","description":"Failed to pick subchannel","file":"src/core/ext/filters/client_channel/client_channel.cc","file_line":3876,"referenced_errors":[{"created":"@1581097305.108311000","description":"failed to connect to all addresses","file":"src/core/ext/filters/client_channel/lb_policy/pick_first/pick_first.cc","file_line":395,"grpc_status":14}]}"
>
2020-02-07 17:43:10,296 INFO download_runner.impl.historical_runner:32 sending - historical data request : AEM 2019-01-01 2020-01-01
2020-02-07 17:43:10,893 INFO download_runner.impl.historical_runner:35 sent - historical data request : AEM 2019-01-01 2020-01-01
2020-02-07 17:43:10,893 DEBUG download_runner.impl.historical_runner:36 request accounted for...
2020-02-07 17:43:10,893 INFO download_runner.impl.historical_runner:37 status : True
2020-02-07 17:43:10,893 INFO download_runner.impl.historical_runner:42 Historical data request sent : AEM 2019-01-01 2020-01-01
2020-02-07 17:43:10,893 DEBUG download_runner.impl.historical_end_reader:37 poll stock ? => True
2020-02-07 17:43:10,893 ERROR root:30 unhandled exception getting latest timestamp for AEMD
Traceback (most recent call last):
  File "/Users/dali/workspace/ib_python/runner/services/historical_data_service.py", line 24, in get_latest_timestamp
    response = self.stub.GetLatestTimeStamp(request)
  File "/Users/dali/workspace/ib_python/runner/venv/lib/python3.7/site-packages/grpc/_channel.py", line 604, in __call__
    return _end_unary_response_blocking(state, call, False, None)
  File "/Users/dali/workspace/ib_python/runner/venv/lib/python3.7/site-packages/grpc/_channel.py", line 506, in _end_unary_response_blocking
    raise _Rendezvous(state, None, None, deadline)
grpc._channel._Rendezvous: <_Rendezvous of RPC that terminated with:
	status = StatusCode.UNAVAILABLE
	details = "failed to connect to all addresses"
	debug_error_string = "{"created":"@1581097390.893883000","description":"Failed to pick subchannel","file":"src/core/ext/filters/client_channel/client_channel.cc","file_line":3876,"referenced_errors":[{"created":"@1581097305.108311000","description":"failed to connect to all addresses","file":"src/core/ext/filters/client_channel/lb_policy/pick_first/pick_first.cc","file_line":395,"grpc_status":14}]}"
>
2020-02-07 17:43:10,894 INFO download_runner.impl.historical_runner:32 sending - historical data request : AEMD 2019-01-01 2020-01-01
2020-02-07 17:43:16,311 INFO download_runner.impl.historical_runner:35 sent - historical data request : AEMD 2019-01-01 2020-01-01
2020-02-07 17:43:16,311 DEBUG download_runner.impl.historical_runner:36 request accounted for...
2020-02-07 17:43:16,311 INFO download_runner.impl.historical_runner:37 status : True
2020-02-07 17:43:16,311 INFO download_runner.impl.historical_runner:42 Historical data request sent : AEMD 2019-01-01 2020-01-01
2020-02-07 17:43:16,311 DEBUG download_runner.impl.historical_end_reader:37 poll stock ? => True
2020-02-07 17:43:16,311 ERROR root:30 unhandled exception getting latest timestamp for AEO
Traceback (most recent call last):
  File "/Users/dali/workspace/ib_python/runner/services/historical_data_service.py", line 24, in get_latest_timestamp
    response = self.stub.GetLatestTimeStamp(request)
  File "/Users/dali/workspace/ib_python/runner/venv/lib/python3.7/site-packages/grpc/_channel.py", line 604, in __call__
    return _end_unary_response_blocking(state, call, False, None)
  File "/Users/dali/workspace/ib_python/runner/venv/lib/python3.7/site-packages/grpc/_channel.py", line 506, in _end_unary_response_blocking
    raise _Rendezvous(state, None, None, deadline)
grpc._channel._Rendezvous: <_Rendezvous of RPC that terminated with:
	status = StatusCode.UNAVAILABLE
	details = "failed to connect to all addresses"
	debug_error_string = "{"created":"@1581097396.311712000","description":"Failed to pick subchannel","file":"src/core/ext/filters/client_channel/client_channel.cc","file_line":3876,"referenced_errors":[{"created":"@1581097305.108311000","description":"failed to connect to all addresses","file":"src/core/ext/filters/client_channel/lb_policy/pick_first/pick_first.cc","file_line":395,"grpc_status":14}]}"
>
2020-02-07 17:43:16,312 INFO download_runner.impl.historical_runner:32 sending - historical data request : AEO 2019-01-01 2020-01-01
2020-02-07 17:43:28,016 INFO download_runner.impl.historical_runner:35 sent - historical data request : AEO 2019-01-01 2020-01-01
2020-02-07 17:43:28,017 DEBUG download_runner.impl.historical_runner:36 request accounted for...
2020-02-07 17:43:28,017 INFO download_runner.impl.historical_runner:37 status : True
2020-02-07 17:43:28,017 INFO download_runner.impl.historical_runner:42 Historical data request sent : AEO 2019-01-01 2020-01-01
2020-02-07 17:43:28,017 DEBUG download_runner.impl.historical_end_reader:37 poll stock ? => True
2020-02-07 17:43:28,017 ERROR root:30 unhandled exception getting latest timestamp for AEP
Traceback (most recent call last):
  File "/Users/dali/workspace/ib_python/runner/services/historical_data_service.py", line 24, in get_latest_timestamp
    response = self.stub.GetLatestTimeStamp(request)
  File "/Users/dali/workspace/ib_python/runner/venv/lib/python3.7/site-packages/grpc/_channel.py", line 604, in __call__
    return _end_unary_response_blocking(state, call, False, None)
  File "/Users/dali/workspace/ib_python/runner/venv/lib/python3.7/site-packages/grpc/_channel.py", line 506, in _end_unary_response_blocking
    raise _Rendezvous(state, None, None, deadline)
grpc._channel._Rendezvous: <_Rendezvous of RPC that terminated with:
	status = StatusCode.UNAVAILABLE
	details = "failed to connect to all addresses"
	debug_error_string = "{"created":"@1581097408.017769000","description":"Failed to pick subchannel","file":"src/core/ext/filters/client_channel/client_channel.cc","file_line":3876,"referenced_errors":[{"created":"@1581097305.108311000","description":"failed to connect to all addresses","file":"src/core/ext/filters/client_channel/lb_policy/pick_first/pick_first.cc","file_line":395,"grpc_status":14}]}"
>
2020-02-07 17:43:28,018 INFO download_runner.impl.historical_runner:32 sending - historical data request : AEP 2019-01-01 2020-01-01
2020-02-07 17:43:28,176 INFO download_runner.impl.historical_runner:35 sent - historical data request : AEP 2019-01-01 2020-01-01
2020-02-07 17:43:28,176 DEBUG download_runner.impl.historical_runner:36 request accounted for...
2020-02-07 17:43:28,176 INFO download_runner.impl.historical_runner:37 status : True
2020-02-07 17:43:28,176 INFO download_runner.impl.historical_runner:42 Historical data request sent : AEP 2019-01-01 2020-01-01
2020-02-07 17:43:28,176 DEBUG download_runner.impl.historical_end_reader:37 poll stock ? => True
2020-02-07 17:43:28,177 ERROR root:30 unhandled exception getting latest timestamp for AEP PRB
Traceback (most recent call last):
  File "/Users/dali/workspace/ib_python/runner/services/historical_data_service.py", line 24, in get_latest_timestamp
    response = self.stub.GetLatestTimeStamp(request)
  File "/Users/dali/workspace/ib_python/runner/venv/lib/python3.7/site-packages/grpc/_channel.py", line 604, in __call__
    return _end_unary_response_blocking(state, call, False, None)
  File "/Users/dali/workspace/ib_python/runner/venv/lib/python3.7/site-packages/grpc/_channel.py", line 506, in _end_unary_response_blocking
    raise _Rendezvous(state, None, None, deadline)
grpc._channel._Rendezvous: <_Rendezvous of RPC that terminated with:
	status = StatusCode.UNAVAILABLE
	details = "failed to connect to all addresses"
	debug_error_string = "{"created":"@1581097408.176970000","description":"Failed to pick subchannel","file":"src/core/ext/filters/client_channel/client_channel.cc","file_line":3876,"referenced_errors":[{"created":"@1581097305.108311000","description":"failed to connect to all addresses","file":"src/core/ext/filters/client_channel/lb_policy/pick_first/pick_first.cc","file_line":395,"grpc_status":14}]}"
>
2020-02-07 17:43:28,177 INFO download_runner.impl.historical_runner:32 sending - historical data request : AEP PRB 2019-01-01 2020-01-01
2020-02-07 17:43:28,279 INFO download_runner.impl.historical_runner:35 sent - historical data request : AEP PRB 2019-01-01 2020-01-01
2020-02-07 17:43:28,280 DEBUG download_runner.impl.historical_runner:36 request accounted for...
2020-02-07 17:43:28,280 INFO download_runner.impl.historical_runner:37 status : True
2020-02-07 17:43:28,280 INFO download_runner.impl.historical_runner:42 Historical data request sent : AEP PRB 2019-01-01 2020-01-01
2020-02-07 17:43:28,280 DEBUG download_runner.impl.historical_end_reader:37 poll stock ? => True
2020-02-07 17:43:28,280 ERROR root:30 unhandled exception getting latest timestamp for AER
Traceback (most recent call last):
  File "/Users/dali/workspace/ib_python/runner/services/historical_data_service.py", line 24, in get_latest_timestamp
    response = self.stub.GetLatestTimeStamp(request)
  File "/Users/dali/workspace/ib_python/runner/venv/lib/python3.7/site-packages/grpc/_channel.py", line 604, in __call__
    return _end_unary_response_blocking(state, call, False, None)
  File "/Users/dali/workspace/ib_python/runner/venv/lib/python3.7/site-packages/grpc/_channel.py", line 506, in _end_unary_response_blocking
    raise _Rendezvous(state, None, None, deadline)
grpc._channel._Rendezvous: <_Rendezvous of RPC that terminated with:
	status = StatusCode.UNAVAILABLE
	details = "failed to connect to all addresses"
	debug_error_string = "{"created":"@1581097408.280599000","description":"Failed to pick subchannel","file":"src/core/ext/filters/client_channel/client_channel.cc","file_line":3876,"referenced_errors":[{"created":"@1581097305.108311000","description":"failed to connect to all addresses","file":"src/core/ext/filters/client_channel/lb_policy/pick_first/pick_first.cc","file_line":395,"grpc_status":14}]}"
>
2020-02-07 17:43:28,281 INFO download_runner.impl.historical_runner:32 sending - historical data request : AER 2019-01-01 2020-01-01
2020-02-07 17:43:28,499 INFO download_runner.impl.historical_runner:35 sent - historical data request : AER 2019-01-01 2020-01-01
2020-02-07 17:43:28,499 DEBUG download_runner.impl.historical_runner:36 request accounted for...
2020-02-07 17:43:28,499 INFO download_runner.impl.historical_runner:37 status : True
2020-02-07 17:43:28,499 INFO download_runner.impl.historical_runner:42 Historical data request sent : AER 2019-01-01 2020-01-01
2020-02-07 17:43:28,499 DEBUG download_runner.impl.historical_end_reader:37 poll stock ? => True
2020-02-07 17:43:28,500 ERROR root:30 unhandled exception getting latest timestamp for AERI
Traceback (most recent call last):
  File "/Users/dali/workspace/ib_python/runner/services/historical_data_service.py", line 24, in get_latest_timestamp
    response = self.stub.GetLatestTimeStamp(request)
  File "/Users/dali/workspace/ib_python/runner/venv/lib/python3.7/site-packages/grpc/_channel.py", line 604, in __call__
    return _end_unary_response_blocking(state, call, False, None)
  File "/Users/dali/workspace/ib_python/runner/venv/lib/python3.7/site-packages/grpc/_channel.py", line 506, in _end_unary_response_blocking
    raise _Rendezvous(state, None, None, deadline)
grpc._channel._Rendezvous: <_Rendezvous of RPC that terminated with:
	status = StatusCode.UNAVAILABLE
	details = "failed to connect to all addresses"
	debug_error_string = "{"created":"@1581097408.500127000","description":"Failed to pick subchannel","file":"src/core/ext/filters/client_channel/client_channel.cc","file_line":3876,"referenced_errors":[{"created":"@1581097305.108311000","description":"failed to connect to all addresses","file":"src/core/ext/filters/client_channel/lb_policy/pick_first/pick_first.cc","file_line":395,"grpc_status":14}]}"
>
2020-02-07 17:43:28,500 INFO download_runner.impl.historical_runner:32 sending - historical data request : AERI 2019-01-01 2020-01-01
2020-02-07 17:43:28,661 INFO download_runner.impl.historical_runner:35 sent - historical data request : AERI 2019-01-01 2020-01-01
2020-02-07 17:43:28,661 DEBUG download_runner.impl.historical_runner:36 request accounted for...
2020-02-07 17:43:28,661 INFO download_runner.impl.historical_runner:37 status : True
2020-02-07 17:43:28,661 INFO download_runner.impl.historical_runner:42 Historical data request sent : AERI 2019-01-01 2020-01-01
2020-02-07 17:43:28,661 DEBUG download_runner.impl.historical_end_reader:37 poll stock ? => True
2020-02-07 17:43:28,661 ERROR root:30 unhandled exception getting latest timestamp for AES
Traceback (most recent call last):
  File "/Users/dali/workspace/ib_python/runner/services/historical_data_service.py", line 24, in get_latest_timestamp
    response = self.stub.GetLatestTimeStamp(request)
  File "/Users/dali/workspace/ib_python/runner/venv/lib/python3.7/site-packages/grpc/_channel.py", line 604, in __call__
    return _end_unary_response_blocking(state, call, False, None)
  File "/Users/dali/workspace/ib_python/runner/venv/lib/python3.7/site-packages/grpc/_channel.py", line 506, in _end_unary_response_blocking
    raise _Rendezvous(state, None, None, deadline)
grpc._channel._Rendezvous: <_Rendezvous of RPC that terminated with:
	status = StatusCode.UNAVAILABLE
	details = "failed to connect to all addresses"
	debug_error_string = "{"created":"@1581097408.661739000","description":"Failed to pick subchannel","file":"src/core/ext/filters/client_channel/client_channel.cc","file_line":3876,"referenced_errors":[{"created":"@1581097305.108311000","description":"failed to connect to all addresses","file":"src/core/ext/filters/client_channel/lb_policy/pick_first/pick_first.cc","file_line":395,"grpc_status":14}]}"
>
2020-02-07 17:43:28,662 INFO download_runner.impl.historical_runner:32 sending - historical data request : AES 2019-01-01 2020-01-01
2020-02-07 17:43:47,069 INFO download_runner.impl.historical_runner:35 sent - historical data request : AES 2019-01-01 2020-01-01
2020-02-07 17:43:47,069 DEBUG download_runner.impl.historical_runner:36 request accounted for...
2020-02-07 17:43:47,070 INFO download_runner.impl.historical_runner:37 status : True
2020-02-07 17:43:47,070 INFO download_runner.impl.historical_runner:42 Historical data request sent : AES 2019-01-01 2020-01-01
2020-02-07 17:43:47,070 DEBUG download_runner.impl.historical_end_reader:37 poll stock ? => True
2020-02-07 17:43:47,071 ERROR root:30 unhandled exception getting latest timestamp for AESE
Traceback (most recent call last):
  File "/Users/dali/workspace/ib_python/runner/services/historical_data_service.py", line 24, in get_latest_timestamp
    response = self.stub.GetLatestTimeStamp(request)
  File "/Users/dali/workspace/ib_python/runner/venv/lib/python3.7/site-packages/grpc/_channel.py", line 604, in __call__
    return _end_unary_response_blocking(state, call, False, None)
  File "/Users/dali/workspace/ib_python/runner/venv/lib/python3.7/site-packages/grpc/_channel.py", line 506, in _end_unary_response_blocking
    raise _Rendezvous(state, None, None, deadline)
grpc._channel._Rendezvous: <_Rendezvous of RPC that terminated with:
	status = StatusCode.UNAVAILABLE
	details = "failed to connect to all addresses"
	debug_error_string = "{"created":"@1581097427.070976000","description":"Failed to pick subchannel","file":"src/core/ext/filters/client_channel/client_channel.cc","file_line":3876,"referenced_errors":[{"created":"@1581097420.165087000","description":"failed to connect to all addresses","file":"src/core/ext/filters/client_channel/lb_policy/pick_first/pick_first.cc","file_line":395,"grpc_status":14}]}"
>
2020-02-07 17:43:47,071 INFO download_runner.impl.historical_runner:32 sending - historical data request : AESE 2019-01-01 2020-01-01
2020-02-07 17:43:47,967 INFO download_runner.impl.historical_runner:35 sent - historical data request : AESE 2019-01-01 2020-01-01
2020-02-07 17:43:47,967 DEBUG download_runner.impl.historical_runner:36 request accounted for...
2020-02-07 17:43:47,968 INFO download_runner.impl.historical_runner:37 status : True
2020-02-07 17:43:47,968 INFO download_runner.impl.historical_runner:42 Historical data request sent : AESE 2019-01-01 2020-01-01
2020-02-07 17:43:47,968 DEBUG download_runner.impl.historical_end_reader:37 poll stock ? => True
2020-02-07 17:43:47,968 ERROR root:30 unhandled exception getting latest timestamp for AEY
Traceback (most recent call last):
  File "/Users/dali/workspace/ib_python/runner/services/historical_data_service.py", line 24, in get_latest_timestamp
    response = self.stub.GetLatestTimeStamp(request)
  File "/Users/dali/workspace/ib_python/runner/venv/lib/python3.7/site-packages/grpc/_channel.py", line 604, in __call__
    return _end_unary_response_blocking(state, call, False, None)
  File "/Users/dali/workspace/ib_python/runner/venv/lib/python3.7/site-packages/grpc/_channel.py", line 506, in _end_unary_response_blocking
    raise _Rendezvous(state, None, None, deadline)
grpc._channel._Rendezvous: <_Rendezvous of RPC that terminated with:
	status = StatusCode.UNAVAILABLE
	details = "failed to connect to all addresses"
	debug_error_string = "{"created":"@1581097427.968421000","description":"Failed to pick subchannel","file":"src/core/ext/filters/client_channel/client_channel.cc","file_line":3876,"referenced_errors":[{"created":"@1581097420.165087000","description":"failed to connect to all addresses","file":"src/core/ext/filters/client_channel/lb_policy/pick_first/pick_first.cc","file_line":395,"grpc_status":14}]}"
>
2020-02-07 17:43:47,968 INFO download_runner.impl.historical_runner:32 sending - historical data request : AEY 2019-01-01 2020-01-01
