2020-02-07 16:46:29,879 DEBUG download_runner.impl.historical_end_reader:37 poll stock ? => True
2020-02-07 16:46:29,988 ERROR root:30 unhandled exception getting latest timestamp for ACIA
Traceback (most recent call last):
  File "/Users/dali/workspace/ib_python/runner/services/historical_data_service.py", line 24, in get_latest_timestamp
    response = self.stub.GetLatestTimeStamp(request)
  File "/Users/dali/workspace/ib_python/runner/venv/lib/python3.7/site-packages/grpc/_channel.py", line 604, in __call__
    return _end_unary_response_blocking(state, call, False, None)
  File "/Users/dali/workspace/ib_python/runner/venv/lib/python3.7/site-packages/grpc/_channel.py", line 506, in _end_unary_response_blocking
    raise _Rendezvous(state, None, None, deadline)
grpc._channel._Rendezvous: <_Rendezvous of RPC that terminated with:
	status = StatusCode.UNAVAILABLE
	details = "failed to connect to all addresses"
	debug_error_string = "{"created":"@1581093989.988104000","description":"Failed to pick subchannel","file":"src/core/ext/filters/client_channel/client_channel.cc","file_line":3876,"referenced_errors":[{"created":"@1581093989.988103000","description":"failed to connect to all addresses","file":"src/core/ext/filters/client_channel/lb_policy/pick_first/pick_first.cc","file_line":395,"grpc_status":14}]}"
>
2020-02-07 16:46:29,989 INFO download_runner.impl.historical_runner:32 sending - historical data request : ACIA 2019-01-01 2020-01-01
2020-02-07 16:46:30,284 INFO download_runner.impl.historical_runner:35 sent - historical data request : ACIA 2019-01-01 2020-01-01
2020-02-07 16:46:30,284 DEBUG download_runner.impl.historical_runner:36 request accounted for...
2020-02-07 16:46:30,284 INFO download_runner.impl.historical_runner:37 status : True
2020-02-07 16:46:30,284 INFO download_runner.impl.historical_runner:42 Historical data request sent : ACIA 2019-01-01 2020-01-01
2020-02-07 16:46:30,284 DEBUG download_runner.impl.historical_end_reader:37 poll stock ? => True
2020-02-07 16:46:30,284 ERROR root:30 unhandled exception getting latest timestamp for AEE
Traceback (most recent call last):
  File "/Users/dali/workspace/ib_python/runner/services/historical_data_service.py", line 24, in get_latest_timestamp
    response = self.stub.GetLatestTimeStamp(request)
  File "/Users/dali/workspace/ib_python/runner/venv/lib/python3.7/site-packages/grpc/_channel.py", line 604, in __call__
    return _end_unary_response_blocking(state, call, False, None)
  File "/Users/dali/workspace/ib_python/runner/venv/lib/python3.7/site-packages/grpc/_channel.py", line 506, in _end_unary_response_blocking
    raise _Rendezvous(state, None, None, deadline)
grpc._channel._Rendezvous: <_Rendezvous of RPC that terminated with:
	status = StatusCode.UNAVAILABLE
	details = "failed to connect to all addresses"
	debug_error_string = "{"created":"@1581093990.284803000","description":"Failed to pick subchannel","file":"src/core/ext/filters/client_channel/client_channel.cc","file_line":3876,"referenced_errors":[{"created":"@1581093989.988103000","description":"failed to connect to all addresses","file":"src/core/ext/filters/client_channel/lb_policy/pick_first/pick_first.cc","file_line":395,"grpc_status":14}]}"
>
2020-02-07 16:46:30,285 INFO download_runner.impl.historical_runner:32 sending - historical data request : AEE 2019-01-01 2020-01-01
2020-02-07 16:46:30,989 INFO download_runner.impl.historical_runner:35 sent - historical data request : AEE 2019-01-01 2020-01-01
2020-02-07 16:46:30,990 DEBUG download_runner.impl.historical_runner:36 request accounted for...
2020-02-07 16:46:30,990 INFO download_runner.impl.historical_runner:37 status : True
2020-02-07 16:46:30,990 INFO download_runner.impl.historical_runner:42 Historical data request sent : AEE 2019-01-01 2020-01-01
2020-02-07 16:46:30,990 DEBUG download_runner.impl.historical_end_reader:37 poll stock ? => True
2020-02-07 16:46:30,990 ERROR root:30 unhandled exception getting latest timestamp for AEF
Traceback (most recent call last):
  File "/Users/dali/workspace/ib_python/runner/services/historical_data_service.py", line 24, in get_latest_timestamp
    response = self.stub.GetLatestTimeStamp(request)
  File "/Users/dali/workspace/ib_python/runner/venv/lib/python3.7/site-packages/grpc/_channel.py", line 604, in __call__
    return _end_unary_response_blocking(state, call, False, None)
  File "/Users/dali/workspace/ib_python/runner/venv/lib/python3.7/site-packages/grpc/_channel.py", line 506, in _end_unary_response_blocking
    raise _Rendezvous(state, None, None, deadline)
grpc._channel._Rendezvous: <_Rendezvous of RPC that terminated with:
	status = StatusCode.UNAVAILABLE
	details = "failed to connect to all addresses"
	debug_error_string = "{"created":"@1581093990.990631000","description":"Failed to pick subchannel","file":"src/core/ext/filters/client_channel/client_channel.cc","file_line":3876,"referenced_errors":[{"created":"@1581093990.990630000","description":"failed to connect to all addresses","file":"src/core/ext/filters/client_channel/lb_policy/pick_first/pick_first.cc","file_line":395,"grpc_status":14}]}"
>
2020-02-07 16:46:30,990 INFO download_runner.impl.historical_runner:32 sending - historical data request : AEF 2019-01-01 2020-01-01
2020-02-07 16:46:31,643 INFO download_runner.impl.historical_runner:35 sent - historical data request : AEF 2019-01-01 2020-01-01
2020-02-07 16:46:31,643 DEBUG download_runner.impl.historical_runner:36 request accounted for...
2020-02-07 16:46:31,643 INFO download_runner.impl.historical_runner:37 status : True
2020-02-07 16:46:31,643 INFO download_runner.impl.historical_runner:42 Historical data request sent : AEF 2019-01-01 2020-01-01
2020-02-07 16:46:31,643 DEBUG download_runner.impl.historical_end_reader:37 poll stock ? => True
2020-02-07 16:46:31,644 ERROR root:30 unhandled exception getting latest timestamp for AEFC
Traceback (most recent call last):
  File "/Users/dali/workspace/ib_python/runner/services/historical_data_service.py", line 24, in get_latest_timestamp
    response = self.stub.GetLatestTimeStamp(request)
  File "/Users/dali/workspace/ib_python/runner/venv/lib/python3.7/site-packages/grpc/_channel.py", line 604, in __call__
    return _end_unary_response_blocking(state, call, False, None)
  File "/Users/dali/workspace/ib_python/runner/venv/lib/python3.7/site-packages/grpc/_channel.py", line 506, in _end_unary_response_blocking
    raise _Rendezvous(state, None, None, deadline)
grpc._channel._Rendezvous: <_Rendezvous of RPC that terminated with:
	status = StatusCode.UNAVAILABLE
	details = "failed to connect to all addresses"
	debug_error_string = "{"created":"@1581093991.644008000","description":"Failed to pick subchannel","file":"src/core/ext/filters/client_channel/client_channel.cc","file_line":3876,"referenced_errors":[{"created":"@1581093990.990630000","description":"failed to connect to all addresses","file":"src/core/ext/filters/client_channel/lb_policy/pick_first/pick_first.cc","file_line":395,"grpc_status":14}]}"
>
2020-02-07 16:46:31,644 INFO download_runner.impl.historical_runner:32 sending - historical data request : AEFC 2019-01-01 2020-01-01
2020-02-07 16:46:32,179 INFO download_runner.impl.historical_runner:35 sent - historical data request : AEFC 2019-01-01 2020-01-01
2020-02-07 16:46:32,180 DEBUG download_runner.impl.historical_runner:36 request accounted for...
2020-02-07 16:46:32,180 INFO download_runner.impl.historical_runner:37 status : True
2020-02-07 16:46:32,181 INFO download_runner.impl.historical_runner:42 Historical data request sent : AEFC 2019-01-01 2020-01-01
2020-02-07 16:46:32,181 DEBUG download_runner.impl.historical_end_reader:37 poll stock ? => True
2020-02-07 16:46:32,183 ERROR root:30 unhandled exception getting latest timestamp for AEG
Traceback (most recent call last):
  File "/Users/dali/workspace/ib_python/runner/services/historical_data_service.py", line 24, in get_latest_timestamp
    response = self.stub.GetLatestTimeStamp(request)
  File "/Users/dali/workspace/ib_python/runner/venv/lib/python3.7/site-packages/grpc/_channel.py", line 604, in __call__
    return _end_unary_response_blocking(state, call, False, None)
  File "/Users/dali/workspace/ib_python/runner/venv/lib/python3.7/site-packages/grpc/_channel.py", line 506, in _end_unary_response_blocking
    raise _Rendezvous(state, None, None, deadline)
grpc._channel._Rendezvous: <_Rendezvous of RPC that terminated with:
	status = StatusCode.UNAVAILABLE
	details = "failed to connect to all addresses"
	debug_error_string = "{"created":"@1581093992.183557000","description":"Failed to pick subchannel","file":"src/core/ext/filters/client_channel/client_channel.cc","file_line":3876,"referenced_errors":[{"created":"@1581093990.990630000","description":"failed to connect to all addresses","file":"src/core/ext/filters/client_channel/lb_policy/pick_first/pick_first.cc","file_line":395,"grpc_status":14}]}"
>
2020-02-07 16:46:32,185 INFO download_runner.impl.historical_runner:32 sending - historical data request : AEG 2019-01-01 2020-01-01
2020-02-07 16:46:32,866 INFO download_runner.impl.historical_runner:35 sent - historical data request : AEG 2019-01-01 2020-01-01
2020-02-07 16:46:32,866 DEBUG download_runner.impl.historical_runner:36 request accounted for...
2020-02-07 16:46:32,866 INFO download_runner.impl.historical_runner:37 status : True
2020-02-07 16:46:32,866 INFO download_runner.impl.historical_runner:42 Historical data request sent : AEG 2019-01-01 2020-01-01
2020-02-07 16:46:32,866 DEBUG download_runner.impl.historical_end_reader:37 poll stock ? => True
2020-02-07 16:46:32,867 ERROR root:30 unhandled exception getting latest timestamp for AEGN
Traceback (most recent call last):
  File "/Users/dali/workspace/ib_python/runner/services/historical_data_service.py", line 24, in get_latest_timestamp
    response = self.stub.GetLatestTimeStamp(request)
  File "/Users/dali/workspace/ib_python/runner/venv/lib/python3.7/site-packages/grpc/_channel.py", line 604, in __call__
    return _end_unary_response_blocking(state, call, False, None)
  File "/Users/dali/workspace/ib_python/runner/venv/lib/python3.7/site-packages/grpc/_channel.py", line 506, in _end_unary_response_blocking
    raise _Rendezvous(state, None, None, deadline)
grpc._channel._Rendezvous: <_Rendezvous of RPC that terminated with:
	status = StatusCode.UNAVAILABLE
	details = "failed to connect to all addresses"
	debug_error_string = "{"created":"@1581093992.867047000","description":"Failed to pick subchannel","file":"src/core/ext/filters/client_channel/client_channel.cc","file_line":3876,"referenced_errors":[{"created":"@1581093992.867045000","description":"failed to connect to all addresses","file":"src/core/ext/filters/client_channel/lb_policy/pick_first/pick_first.cc","file_line":395,"grpc_status":14}]}"
>
2020-02-07 16:46:32,867 INFO download_runner.impl.historical_runner:32 sending - historical data request : AEGN 2019-01-01 2020-01-01
2020-02-07 16:46:36,530 INFO download_runner.impl.historical_runner:35 sent - historical data request : AEGN 2019-01-01 2020-01-01
2020-02-07 16:46:36,530 DEBUG download_runner.impl.historical_runner:36 request accounted for...
2020-02-07 16:46:36,530 INFO download_runner.impl.historical_runner:37 status : True
2020-02-07 16:46:36,530 INFO download_runner.impl.historical_runner:42 Historical data request sent : AEGN 2019-01-01 2020-01-01
2020-02-07 16:46:36,530 DEBUG download_runner.impl.historical_end_reader:37 poll stock ? => True
2020-02-07 16:46:36,530 ERROR root:30 unhandled exception getting latest timestamp for AEH CL
Traceback (most recent call last):
  File "/Users/dali/workspace/ib_python/runner/services/historical_data_service.py", line 24, in get_latest_timestamp
    response = self.stub.GetLatestTimeStamp(request)
  File "/Users/dali/workspace/ib_python/runner/venv/lib/python3.7/site-packages/grpc/_channel.py", line 604, in __call__
    return _end_unary_response_blocking(state, call, False, None)
  File "/Users/dali/workspace/ib_python/runner/venv/lib/python3.7/site-packages/grpc/_channel.py", line 506, in _end_unary_response_blocking
    raise _Rendezvous(state, None, None, deadline)
grpc._channel._Rendezvous: <_Rendezvous of RPC that terminated with:
	status = StatusCode.UNAVAILABLE
	details = "failed to connect to all addresses"
	debug_error_string = "{"created":"@1581093996.530503000","description":"Failed to pick subchannel","file":"src/core/ext/filters/client_channel/client_channel.cc","file_line":3876,"referenced_errors":[{"created":"@1581093996.530502000","description":"failed to connect to all addresses","file":"src/core/ext/filters/client_channel/lb_policy/pick_first/pick_first.cc","file_line":395,"grpc_status":14}]}"
>
2020-02-07 16:46:36,530 INFO download_runner.impl.historical_runner:32 sending - historical data request : AEH CL 2019-01-01 2020-01-01
2020-02-07 16:46:37,299 INFO download_runner.impl.historical_runner:35 sent - historical data request : AEH CL 2019-01-01 2020-01-01
2020-02-07 16:46:37,299 DEBUG download_runner.impl.historical_runner:36 request accounted for...
2020-02-07 16:46:37,299 INFO download_runner.impl.historical_runner:37 status : True
2020-02-07 16:46:37,299 INFO download_runner.impl.historical_runner:42 Historical data request sent : AEH CL 2019-01-01 2020-01-01
2020-02-07 16:46:37,300 DEBUG download_runner.impl.historical_end_reader:37 poll stock ? => True
2020-02-07 16:46:37,300 ERROR root:30 unhandled exception getting latest timestamp for AEHR
Traceback (most recent call last):
  File "/Users/dali/workspace/ib_python/runner/services/historical_data_service.py", line 24, in get_latest_timestamp
    response = self.stub.GetLatestTimeStamp(request)
  File "/Users/dali/workspace/ib_python/runner/venv/lib/python3.7/site-packages/grpc/_channel.py", line 604, in __call__
    return _end_unary_response_blocking(state, call, False, None)
  File "/Users/dali/workspace/ib_python/runner/venv/lib/python3.7/site-packages/grpc/_channel.py", line 506, in _end_unary_response_blocking
    raise _Rendezvous(state, None, None, deadline)
grpc._channel._Rendezvous: <_Rendezvous of RPC that terminated with:
	status = StatusCode.UNAVAILABLE
	details = "failed to connect to all addresses"
	debug_error_string = "{"created":"@1581093997.300218000","description":"Failed to pick subchannel","file":"src/core/ext/filters/client_channel/client_channel.cc","file_line":3876,"referenced_errors":[{"created":"@1581093996.530502000","description":"failed to connect to all addresses","file":"src/core/ext/filters/client_channel/lb_policy/pick_first/pick_first.cc","file_line":395,"grpc_status":14}]}"
>
2020-02-07 16:46:37,300 INFO download_runner.impl.historical_runner:32 sending - historical data request : AEHR 2019-01-01 2020-01-01
2020-02-07 16:46:38,036 INFO download_runner.impl.historical_runner:35 sent - historical data request : AEHR 2019-01-01 2020-01-01
2020-02-07 16:46:38,036 DEBUG download_runner.impl.historical_runner:36 request accounted for...
2020-02-07 16:46:38,036 INFO download_runner.impl.historical_runner:37 status : True
2020-02-07 16:46:38,036 INFO download_runner.impl.historical_runner:42 Historical data request sent : AEHR 2019-01-01 2020-01-01
2020-02-07 16:46:38,036 DEBUG download_runner.impl.historical_end_reader:37 poll stock ? => True
2020-02-07 16:46:38,036 ERROR root:30 unhandled exception getting latest timestamp for AEIS
Traceback (most recent call last):
  File "/Users/dali/workspace/ib_python/runner/services/historical_data_service.py", line 24, in get_latest_timestamp
    response = self.stub.GetLatestTimeStamp(request)
  File "/Users/dali/workspace/ib_python/runner/venv/lib/python3.7/site-packages/grpc/_channel.py", line 604, in __call__
    return _end_unary_response_blocking(state, call, False, None)
  File "/Users/dali/workspace/ib_python/runner/venv/lib/python3.7/site-packages/grpc/_channel.py", line 506, in _end_unary_response_blocking
    raise _Rendezvous(state, None, None, deadline)
grpc._channel._Rendezvous: <_Rendezvous of RPC that terminated with:
	status = StatusCode.UNAVAILABLE
	details = "failed to connect to all addresses"
	debug_error_string = "{"created":"@1581093998.036877000","description":"Failed to pick subchannel","file":"src/core/ext/filters/client_channel/client_channel.cc","file_line":3876,"referenced_errors":[{"created":"@1581093996.530502000","description":"failed to connect to all addresses","file":"src/core/ext/filters/client_channel/lb_policy/pick_first/pick_first.cc","file_line":395,"grpc_status":14}]}"
>
2020-02-07 16:46:38,037 INFO download_runner.impl.historical_runner:32 sending - historical data request : AEIS 2019-01-01 2020-01-01
2020-02-07 16:46:42,954 INFO download_runner.impl.historical_runner:35 sent - historical data request : AEIS 2019-01-01 2020-01-01
2020-02-07 16:46:42,954 DEBUG download_runner.impl.historical_runner:36 request accounted for...
2020-02-07 16:46:42,954 INFO download_runner.impl.historical_runner:37 status : True
2020-02-07 16:46:42,954 INFO download_runner.impl.historical_runner:42 Historical data request sent : AEIS 2019-01-01 2020-01-01
2020-02-07 16:46:42,954 DEBUG download_runner.impl.historical_end_reader:37 poll stock ? => True
2020-02-07 16:46:42,955 ERROR root:30 unhandled exception getting latest timestamp for AEL
Traceback (most recent call last):
  File "/Users/dali/workspace/ib_python/runner/services/historical_data_service.py", line 24, in get_latest_timestamp
    response = self.stub.GetLatestTimeStamp(request)
  File "/Users/dali/workspace/ib_python/runner/venv/lib/python3.7/site-packages/grpc/_channel.py", line 604, in __call__
    return _end_unary_response_blocking(state, call, False, None)
  File "/Users/dali/workspace/ib_python/runner/venv/lib/python3.7/site-packages/grpc/_channel.py", line 506, in _end_unary_response_blocking
    raise _Rendezvous(state, None, None, deadline)
grpc._channel._Rendezvous: <_Rendezvous of RPC that terminated with:
	status = StatusCode.UNAVAILABLE
	details = "failed to connect to all addresses"
	debug_error_string = "{"created":"@1581094002.955402000","description":"Failed to pick subchannel","file":"src/core/ext/filters/client_channel/client_channel.cc","file_line":3876,"referenced_errors":[{"created":"@1581093999.881742000","description":"failed to connect to all addresses","file":"src/core/ext/filters/client_channel/lb_policy/pick_first/pick_first.cc","file_line":395,"grpc_status":14}]}"
>
2020-02-07 16:46:42,956 INFO download_runner.impl.historical_runner:32 sending - historical data request : AEL 2019-01-01 2020-01-01
2020-02-07 16:46:43,854 INFO download_runner.impl.historical_runner:35 sent - historical data request : AEL 2019-01-01 2020-01-01
2020-02-07 16:46:43,854 DEBUG download_runner.impl.historical_runner:36 request accounted for...
2020-02-07 16:46:43,854 INFO download_runner.impl.historical_runner:37 status : True
2020-02-07 16:46:43,854 INFO download_runner.impl.historical_runner:42 Historical data request sent : AEL 2019-01-01 2020-01-01
2020-02-07 16:46:43,854 DEBUG download_runner.impl.historical_end_reader:37 poll stock ? => True
2020-02-07 16:46:43,855 ERROR root:30 unhandled exception getting latest timestamp for AEM
Traceback (most recent call last):
  File "/Users/dali/workspace/ib_python/runner/services/historical_data_service.py", line 24, in get_latest_timestamp
    response = self.stub.GetLatestTimeStamp(request)
  File "/Users/dali/workspace/ib_python/runner/venv/lib/python3.7/site-packages/grpc/_channel.py", line 604, in __call__
    return _end_unary_response_blocking(state, call, False, None)
  File "/Users/dali/workspace/ib_python/runner/venv/lib/python3.7/site-packages/grpc/_channel.py", line 506, in _end_unary_response_blocking
    raise _Rendezvous(state, None, None, deadline)
grpc._channel._Rendezvous: <_Rendezvous of RPC that terminated with:
	status = StatusCode.UNAVAILABLE
	details = "failed to connect to all addresses"
	debug_error_string = "{"created":"@1581094003.855003000","description":"Failed to pick subchannel","file":"src/core/ext/filters/client_channel/client_channel.cc","file_line":3876,"referenced_errors":[{"created":"@1581093999.881742000","description":"failed to connect to all addresses","file":"src/core/ext/filters/client_channel/lb_policy/pick_first/pick_first.cc","file_line":395,"grpc_status":14}]}"
>
2020-02-07 16:46:43,855 INFO download_runner.impl.historical_runner:32 sending - historical data request : AEM 2019-01-01 2020-01-01
2020-02-07 16:46:48,629 INFO download_runner.impl.historical_runner:35 sent - historical data request : AEM 2019-01-01 2020-01-01
2020-02-07 16:46:48,629 DEBUG download_runner.impl.historical_runner:36 request accounted for...
2020-02-07 16:46:48,629 INFO download_runner.impl.historical_runner:37 status : True
2020-02-07 16:46:48,629 INFO download_runner.impl.historical_runner:42 Historical data request sent : AEM 2019-01-01 2020-01-01
2020-02-07 16:46:48,629 DEBUG download_runner.impl.historical_end_reader:37 poll stock ? => True
2020-02-07 16:46:48,629 ERROR root:30 unhandled exception getting latest timestamp for AEMD
Traceback (most recent call last):
  File "/Users/dali/workspace/ib_python/runner/services/historical_data_service.py", line 24, in get_latest_timestamp
    response = self.stub.GetLatestTimeStamp(request)
  File "/Users/dali/workspace/ib_python/runner/venv/lib/python3.7/site-packages/grpc/_channel.py", line 604, in __call__
    return _end_unary_response_blocking(state, call, False, None)
  File "/Users/dali/workspace/ib_python/runner/venv/lib/python3.7/site-packages/grpc/_channel.py", line 506, in _end_unary_response_blocking
    raise _Rendezvous(state, None, None, deadline)
grpc._channel._Rendezvous: <_Rendezvous of RPC that terminated with:
	status = StatusCode.UNAVAILABLE
	details = "failed to connect to all addresses"
	debug_error_string = "{"created":"@1581094008.629606000","description":"Failed to pick subchannel","file":"src/core/ext/filters/client_channel/client_channel.cc","file_line":3876,"referenced_errors":[{"created":"@1581094004.882000000","description":"failed to connect to all addresses","file":"src/core/ext/filters/client_channel/lb_policy/pick_first/pick_first.cc","file_line":395,"grpc_status":14}]}"
>
2020-02-07 16:46:48,630 INFO download_runner.impl.historical_runner:32 sending - historical data request : AEMD 2019-01-01 2020-01-01
2020-02-07 16:46:54,745 INFO download_runner.impl.historical_runner:35 sent - historical data request : AEMD 2019-01-01 2020-01-01
2020-02-07 16:46:54,745 DEBUG download_runner.impl.historical_runner:36 request accounted for...
2020-02-07 16:46:54,746 INFO download_runner.impl.historical_runner:37 status : True
2020-02-07 16:46:54,746 INFO download_runner.impl.historical_runner:42 Historical data request sent : AEMD 2019-01-01 2020-01-01
2020-02-07 16:46:54,746 DEBUG download_runner.impl.historical_end_reader:37 poll stock ? => True
2020-02-07 16:46:54,746 ERROR root:30 unhandled exception getting latest timestamp for AEO
Traceback (most recent call last):
  File "/Users/dali/workspace/ib_python/runner/services/historical_data_service.py", line 24, in get_latest_timestamp
    response = self.stub.GetLatestTimeStamp(request)
  File "/Users/dali/workspace/ib_python/runner/venv/lib/python3.7/site-packages/grpc/_channel.py", line 604, in __call__
    return _end_unary_response_blocking(state, call, False, None)
  File "/Users/dali/workspace/ib_python/runner/venv/lib/python3.7/site-packages/grpc/_channel.py", line 506, in _end_unary_response_blocking
    raise _Rendezvous(state, None, None, deadline)
grpc._channel._Rendezvous: <_Rendezvous of RPC that terminated with:
	status = StatusCode.UNAVAILABLE
	details = "failed to connect to all addresses"
	debug_error_string = "{"created":"@1581094014.746392000","description":"Failed to pick subchannel","file":"src/core/ext/filters/client_channel/client_channel.cc","file_line":3876,"referenced_errors":[{"created":"@1581094014.746390000","description":"failed to connect to all addresses","file":"src/core/ext/filters/client_channel/lb_policy/pick_first/pick_first.cc","file_line":395,"grpc_status":14}]}"
>
2020-02-07 16:46:54,746 INFO download_runner.impl.historical_runner:32 sending - historical data request : AEO 2019-01-01 2020-01-01
2020-02-07 16:47:00,587 INFO download_runner.impl.historical_runner:35 sent - historical data request : AEO 2019-01-01 2020-01-01
2020-02-07 16:47:00,587 DEBUG download_runner.impl.historical_runner:36 request accounted for...
2020-02-07 16:47:00,587 INFO download_runner.impl.historical_runner:37 status : True
2020-02-07 16:47:00,588 INFO download_runner.impl.historical_runner:42 Historical data request sent : AEO 2019-01-01 2020-01-01
2020-02-07 16:47:00,588 DEBUG download_runner.impl.historical_end_reader:37 poll stock ? => True
2020-02-07 16:47:00,588 ERROR root:30 unhandled exception getting latest timestamp for AEP
Traceback (most recent call last):
  File "/Users/dali/workspace/ib_python/runner/services/historical_data_service.py", line 24, in get_latest_timestamp
    response = self.stub.GetLatestTimeStamp(request)
  File "/Users/dali/workspace/ib_python/runner/venv/lib/python3.7/site-packages/grpc/_channel.py", line 604, in __call__
    return _end_unary_response_blocking(state, call, False, None)
  File "/Users/dali/workspace/ib_python/runner/venv/lib/python3.7/site-packages/grpc/_channel.py", line 506, in _end_unary_response_blocking
    raise _Rendezvous(state, None, None, deadline)
grpc._channel._Rendezvous: <_Rendezvous of RPC that terminated with:
	status = StatusCode.UNAVAILABLE
	details = "failed to connect to all addresses"
	debug_error_string = "{"created":"@1581094020.588253000","description":"Failed to pick subchannel","file":"src/core/ext/filters/client_channel/client_channel.cc","file_line":3876,"referenced_errors":[{"created":"@1581094014.746390000","description":"failed to connect to all addresses","file":"src/core/ext/filters/client_channel/lb_policy/pick_first/pick_first.cc","file_line":395,"grpc_status":14}]}"
>
2020-02-07 16:47:00,588 INFO download_runner.impl.historical_runner:32 sending - historical data request : AEP 2019-01-01 2020-01-01
2020-02-07 16:47:12,631 INFO download_runner.impl.historical_runner:35 sent - historical data request : AEP 2019-01-01 2020-01-01
2020-02-07 16:47:12,632 DEBUG download_runner.impl.historical_runner:36 request accounted for...
2020-02-07 16:47:12,632 INFO download_runner.impl.historical_runner:37 status : True
2020-02-07 16:47:12,632 INFO download_runner.impl.historical_runner:42 Historical data request sent : AEP 2019-01-01 2020-01-01
2020-02-07 16:47:12,632 DEBUG download_runner.impl.historical_end_reader:37 poll stock ? => True
2020-02-07 16:47:12,632 ERROR root:30 unhandled exception getting latest timestamp for AEP PRB
Traceback (most recent call last):
  File "/Users/dali/workspace/ib_python/runner/services/historical_data_service.py", line 24, in get_latest_timestamp
    response = self.stub.GetLatestTimeStamp(request)
  File "/Users/dali/workspace/ib_python/runner/venv/lib/python3.7/site-packages/grpc/_channel.py", line 604, in __call__
    return _end_unary_response_blocking(state, call, False, None)
  File "/Users/dali/workspace/ib_python/runner/venv/lib/python3.7/site-packages/grpc/_channel.py", line 506, in _end_unary_response_blocking
    raise _Rendezvous(state, None, None, deadline)
grpc._channel._Rendezvous: <_Rendezvous of RPC that terminated with:
	status = StatusCode.UNAVAILABLE
	details = "failed to connect to all addresses"
	debug_error_string = "{"created":"@1581094032.632428000","description":"Failed to pick subchannel","file":"src/core/ext/filters/client_channel/client_channel.cc","file_line":3876,"referenced_errors":[{"created":"@1581094029.903451000","description":"failed to connect to all addresses","file":"src/core/ext/filters/client_channel/lb_policy/pick_first/pick_first.cc","file_line":395,"grpc_status":14}]}"
>
2020-02-07 16:47:12,632 INFO download_runner.impl.historical_runner:32 sending - historical data request : AEP PRB 2019-01-01 2020-01-01
2020-02-07 16:47:30,597 INFO download_runner.impl.historical_runner:35 sent - historical data request : AEP PRB 2019-01-01 2020-01-01
2020-02-07 16:47:30,597 DEBUG download_runner.impl.historical_runner:36 request accounted for...
2020-02-07 16:47:30,597 INFO download_runner.impl.historical_runner:37 status : True
2020-02-07 16:47:30,597 INFO download_runner.impl.historical_runner:42 Historical data request sent : AEP PRB 2019-01-01 2020-01-01
2020-02-07 16:47:30,597 DEBUG download_runner.impl.historical_end_reader:37 poll stock ? => True
2020-02-07 16:47:30,598 ERROR root:30 unhandled exception getting latest timestamp for AER
Traceback (most recent call last):
  File "/Users/dali/workspace/ib_python/runner/services/historical_data_service.py", line 24, in get_latest_timestamp
    response = self.stub.GetLatestTimeStamp(request)
  File "/Users/dali/workspace/ib_python/runner/venv/lib/python3.7/site-packages/grpc/_channel.py", line 604, in __call__
    return _end_unary_response_blocking(state, call, False, None)
  File "/Users/dali/workspace/ib_python/runner/venv/lib/python3.7/site-packages/grpc/_channel.py", line 506, in _end_unary_response_blocking
    raise _Rendezvous(state, None, None, deadline)
grpc._channel._Rendezvous: <_Rendezvous of RPC that terminated with:
	status = StatusCode.UNAVAILABLE
	details = "failed to connect to all addresses"
	debug_error_string = "{"created":"@1581094050.597985000","description":"Failed to pick subchannel","file":"src/core/ext/filters/client_channel/client_channel.cc","file_line":3876,"referenced_errors":[{"created":"@1581094029.903451000","description":"failed to connect to all addresses","file":"src/core/ext/filters/client_channel/lb_policy/pick_first/pick_first.cc","file_line":395,"grpc_status":14}]}"
>
2020-02-07 16:47:30,598 INFO download_runner.impl.historical_runner:32 sending - historical data request : AER 2019-01-01 2020-01-01
2020-02-07 16:47:31,435 INFO download_runner.impl.historical_runner:35 sent - historical data request : AER 2019-01-01 2020-01-01
2020-02-07 16:47:31,435 DEBUG download_runner.impl.historical_runner:36 request accounted for...
2020-02-07 16:47:31,435 INFO download_runner.impl.historical_runner:37 status : True
2020-02-07 16:47:31,435 INFO download_runner.impl.historical_runner:42 Historical data request sent : AER 2019-01-01 2020-01-01
2020-02-07 16:47:31,435 DEBUG download_runner.impl.historical_end_reader:37 poll stock ? => True
2020-02-07 16:47:31,437 ERROR root:30 unhandled exception getting latest timestamp for AERI
Traceback (most recent call last):
  File "/Users/dali/workspace/ib_python/runner/services/historical_data_service.py", line 24, in get_latest_timestamp
    response = self.stub.GetLatestTimeStamp(request)
  File "/Users/dali/workspace/ib_python/runner/venv/lib/python3.7/site-packages/grpc/_channel.py", line 604, in __call__
    return _end_unary_response_blocking(state, call, False, None)
  File "/Users/dali/workspace/ib_python/runner/venv/lib/python3.7/site-packages/grpc/_channel.py", line 506, in _end_unary_response_blocking
    raise _Rendezvous(state, None, None, deadline)
grpc._channel._Rendezvous: <_Rendezvous of RPC that terminated with:
	status = StatusCode.UNAVAILABLE
	details = "failed to connect to all addresses"
	debug_error_string = "{"created":"@1581094051.436828000","description":"Failed to pick subchannel","file":"src/core/ext/filters/client_channel/client_channel.cc","file_line":3876,"referenced_errors":[{"created":"@1581094029.903451000","description":"failed to connect to all addresses","file":"src/core/ext/filters/client_channel/lb_policy/pick_first/pick_first.cc","file_line":395,"grpc_status":14}]}"
>
2020-02-07 16:47:31,438 INFO download_runner.impl.historical_runner:32 sending - historical data request : AERI 2019-01-01 2020-01-01
2020-02-07 16:47:32,263 INFO download_runner.impl.historical_runner:35 sent - historical data request : AERI 2019-01-01 2020-01-01
2020-02-07 16:47:32,263 DEBUG download_runner.impl.historical_runner:36 request accounted for...
2020-02-07 16:47:32,263 INFO download_runner.impl.historical_runner:37 status : True
2020-02-07 16:47:32,264 INFO download_runner.impl.historical_runner:42 Historical data request sent : AERI 2019-01-01 2020-01-01
2020-02-07 16:47:32,264 DEBUG download_runner.impl.historical_end_reader:37 poll stock ? => True
2020-02-07 16:47:32,264 ERROR root:30 unhandled exception getting latest timestamp for AES
Traceback (most recent call last):
  File "/Users/dali/workspace/ib_python/runner/services/historical_data_service.py", line 24, in get_latest_timestamp
    response = self.stub.GetLatestTimeStamp(request)
  File "/Users/dali/workspace/ib_python/runner/venv/lib/python3.7/site-packages/grpc/_channel.py", line 604, in __call__
    return _end_unary_response_blocking(state, call, False, None)
  File "/Users/dali/workspace/ib_python/runner/venv/lib/python3.7/site-packages/grpc/_channel.py", line 506, in _end_unary_response_blocking
    raise _Rendezvous(state, None, None, deadline)
grpc._channel._Rendezvous: <_Rendezvous of RPC that terminated with:
	status = StatusCode.UNAVAILABLE
	details = "failed to connect to all addresses"
	debug_error_string = "{"created":"@1581094052.264271000","description":"Failed to pick subchannel","file":"src/core/ext/filters/client_channel/client_channel.cc","file_line":3876,"referenced_errors":[{"created":"@1581094029.903451000","description":"failed to connect to all addresses","file":"src/core/ext/filters/client_channel/lb_policy/pick_first/pick_first.cc","file_line":395,"grpc_status":14}]}"
>
2020-02-07 16:47:32,264 INFO download_runner.impl.historical_runner:32 sending - historical data request : AES 2019-01-01 2020-01-01
2020-02-07 16:47:33,184 INFO download_runner.impl.historical_runner:35 sent - historical data request : AES 2019-01-01 2020-01-01
2020-02-07 16:47:33,185 DEBUG download_runner.impl.historical_runner:36 request accounted for...
2020-02-07 16:47:33,185 INFO download_runner.impl.historical_runner:37 status : True
2020-02-07 16:47:33,185 INFO download_runner.impl.historical_runner:42 Historical data request sent : AES 2019-01-01 2020-01-01
2020-02-07 16:47:33,185 DEBUG download_runner.impl.historical_end_reader:37 poll stock ? => True
2020-02-07 16:47:33,186 ERROR root:30 unhandled exception getting latest timestamp for AESE
Traceback (most recent call last):
  File "/Users/dali/workspace/ib_python/runner/services/historical_data_service.py", line 24, in get_latest_timestamp
    response = self.stub.GetLatestTimeStamp(request)
  File "/Users/dali/workspace/ib_python/runner/venv/lib/python3.7/site-packages/grpc/_channel.py", line 604, in __call__
    return _end_unary_response_blocking(state, call, False, None)
  File "/Users/dali/workspace/ib_python/runner/venv/lib/python3.7/site-packages/grpc/_channel.py", line 506, in _end_unary_response_blocking
    raise _Rendezvous(state, None, None, deadline)
grpc._channel._Rendezvous: <_Rendezvous of RPC that terminated with:
	status = StatusCode.UNAVAILABLE
	details = "failed to connect to all addresses"
	debug_error_string = "{"created":"@1581094053.186493000","description":"Failed to pick subchannel","file":"src/core/ext/filters/client_channel/client_channel.cc","file_line":3876,"referenced_errors":[{"created":"@1581094029.903451000","description":"failed to connect to all addresses","file":"src/core/ext/filters/client_channel/lb_policy/pick_first/pick_first.cc","file_line":395,"grpc_status":14}]}"
>
2020-02-07 16:47:33,188 INFO download_runner.impl.historical_runner:32 sending - historical data request : AESE 2019-01-01 2020-01-01
2020-02-07 16:47:36,659 INFO download_runner.impl.historical_runner:35 sent - historical data request : AESE 2019-01-01 2020-01-01
2020-02-07 16:47:36,659 DEBUG download_runner.impl.historical_runner:36 request accounted for...
2020-02-07 16:47:36,659 INFO download_runner.impl.historical_runner:37 status : True
2020-02-07 16:47:36,659 INFO download_runner.impl.historical_runner:42 Historical data request sent : AESE 2019-01-01 2020-01-01
2020-02-07 16:47:36,660 DEBUG download_runner.impl.historical_end_reader:37 poll stock ? => True
2020-02-07 16:47:36,663 ERROR root:30 unhandled exception getting latest timestamp for AEY
Traceback (most recent call last):
  File "/Users/dali/workspace/ib_python/runner/services/historical_data_service.py", line 24, in get_latest_timestamp
    response = self.stub.GetLatestTimeStamp(request)
  File "/Users/dali/workspace/ib_python/runner/venv/lib/python3.7/site-packages/grpc/_channel.py", line 604, in __call__
    return _end_unary_response_blocking(state, call, False, None)
  File "/Users/dali/workspace/ib_python/runner/venv/lib/python3.7/site-packages/grpc/_channel.py", line 506, in _end_unary_response_blocking
    raise _Rendezvous(state, None, None, deadline)
grpc._channel._Rendezvous: <_Rendezvous of RPC that terminated with:
	status = StatusCode.UNAVAILABLE
	details = "failed to connect to all addresses"
	debug_error_string = "{"created":"@1581094056.662892000","description":"Failed to pick subchannel","file":"src/core/ext/filters/client_channel/client_channel.cc","file_line":3876,"referenced_errors":[{"created":"@1581094029.903451000","description":"failed to connect to all addresses","file":"src/core/ext/filters/client_channel/lb_policy/pick_first/pick_first.cc","file_line":395,"grpc_status":14}]}"
>
2020-02-07 16:47:36,665 INFO download_runner.impl.historical_runner:32 sending - historical data request : AEY 2019-01-01 2020-01-01
2020-02-07 16:47:37,526 INFO download_runner.impl.historical_runner:35 sent - historical data request : AEY 2019-01-01 2020-01-01
2020-02-07 16:47:37,526 DEBUG download_runner.impl.historical_runner:36 request accounted for...
2020-02-07 16:47:37,526 INFO download_runner.impl.historical_runner:37 status : True
2020-02-07 16:47:37,527 INFO download_runner.impl.historical_runner:42 Historical data request sent : AEY 2019-01-01 2020-01-01
2020-02-07 16:47:37,527 DEBUG download_runner.impl.historical_end_reader:37 poll stock ? => True
2020-02-07 16:47:37,527 ERROR root:30 unhandled exception getting latest timestamp for AEYE
Traceback (most recent call last):
  File "/Users/dali/workspace/ib_python/runner/services/historical_data_service.py", line 24, in get_latest_timestamp
    response = self.stub.GetLatestTimeStamp(request)
  File "/Users/dali/workspace/ib_python/runner/venv/lib/python3.7/site-packages/grpc/_channel.py", line 604, in __call__
    return _end_unary_response_blocking(state, call, False, None)
  File "/Users/dali/workspace/ib_python/runner/venv/lib/python3.7/site-packages/grpc/_channel.py", line 506, in _end_unary_response_blocking
    raise _Rendezvous(state, None, None, deadline)
grpc._channel._Rendezvous: <_Rendezvous of RPC that terminated with:
	status = StatusCode.UNAVAILABLE
	details = "failed to connect to all addresses"
	debug_error_string = "{"created":"@1581094057.527582000","description":"Failed to pick subchannel","file":"src/core/ext/filters/client_channel/client_channel.cc","file_line":3876,"referenced_errors":[{"created":"@1581094057.527580000","description":"failed to connect to all addresses","file":"src/core/ext/filters/client_channel/lb_policy/pick_first/pick_first.cc","file_line":395,"grpc_status":14}]}"
>
2020-02-07 16:47:37,528 INFO download_runner.impl.historical_runner:32 sending - historical data request : AEYE 2019-01-01 2020-01-01
2020-02-07 16:47:37,734 INFO download_runner.impl.historical_runner:35 sent - historical data request : AEYE 2019-01-01 2020-01-01
2020-02-07 16:47:37,734 DEBUG download_runner.impl.historical_runner:36 request accounted for...
2020-02-07 16:47:37,734 INFO download_runner.impl.historical_runner:37 status : True
2020-02-07 16:47:37,735 INFO download_runner.impl.historical_runner:42 Historical data request sent : AEYE 2019-01-01 2020-01-01
2020-02-07 16:47:37,735 DEBUG download_runner.impl.historical_end_reader:37 poll stock ? => True
2020-02-07 16:47:37,735 ERROR root:30 unhandled exception getting latest timestamp for AEZS
Traceback (most recent call last):
  File "/Users/dali/workspace/ib_python/runner/services/historical_data_service.py", line 24, in get_latest_timestamp
    response = self.stub.GetLatestTimeStamp(request)
  File "/Users/dali/workspace/ib_python/runner/venv/lib/python3.7/site-packages/grpc/_channel.py", line 604, in __call__
    return _end_unary_response_blocking(state, call, False, None)
  File "/Users/dali/workspace/ib_python/runner/venv/lib/python3.7/site-packages/grpc/_channel.py", line 506, in _end_unary_response_blocking
    raise _Rendezvous(state, None, None, deadline)
grpc._channel._Rendezvous: <_Rendezvous of RPC that terminated with:
	status = StatusCode.UNAVAILABLE
	details = "failed to connect to all addresses"
	debug_error_string = "{"created":"@1581094057.735597000","description":"Failed to pick subchannel","file":"src/core/ext/filters/client_channel/client_channel.cc","file_line":3876,"referenced_errors":[{"created":"@1581094057.527580000","description":"failed to connect to all addresses","file":"src/core/ext/filters/client_channel/lb_policy/pick_first/pick_first.cc","file_line":395,"grpc_status":14}]}"
>
2020-02-07 16:47:37,736 INFO download_runner.impl.historical_runner:32 sending - historical data request : AEZS 2019-01-01 2020-01-01
2020-02-07 16:47:42,779 INFO download_runner.impl.historical_runner:35 sent - historical data request : AEZS 2019-01-01 2020-01-01
2020-02-07 16:47:42,779 DEBUG download_runner.impl.historical_runner:36 request accounted for...
2020-02-07 16:47:42,779 INFO download_runner.impl.historical_runner:37 status : True
2020-02-07 16:47:42,779 INFO download_runner.impl.historical_runner:42 Historical data request sent : AEZS 2019-01-01 2020-01-01
2020-02-07 16:47:42,780 DEBUG download_runner.impl.historical_end_reader:37 poll stock ? => True
2020-02-07 16:47:42,780 ERROR root:30 unhandled exception getting latest timestamp for AFB
Traceback (most recent call last):
  File "/Users/dali/workspace/ib_python/runner/services/historical_data_service.py", line 24, in get_latest_timestamp
    response = self.stub.GetLatestTimeStamp(request)
  File "/Users/dali/workspace/ib_python/runner/venv/lib/python3.7/site-packages/grpc/_channel.py", line 604, in __call__
    return _end_unary_response_blocking(state, call, False, None)
  File "/Users/dali/workspace/ib_python/runner/venv/lib/python3.7/site-packages/grpc/_channel.py", line 506, in _end_unary_response_blocking
    raise _Rendezvous(state, None, None, deadline)
grpc._channel._Rendezvous: <_Rendezvous of RPC that terminated with:
	status = StatusCode.UNAVAILABLE
	details = "failed to connect to all addresses"
	debug_error_string = "{"created":"@1581094062.780321000","description":"Failed to pick subchannel","file":"src/core/ext/filters/client_channel/client_channel.cc","file_line":3876,"referenced_errors":[{"created":"@1581094057.527580000","description":"failed to connect to all addresses","file":"src/core/ext/filters/client_channel/lb_policy/pick_first/pick_first.cc","file_line":395,"grpc_status":14}]}"
>
2020-02-07 16:47:42,780 INFO download_runner.impl.historical_runner:32 sending - historical data request : AFB 2019-01-01 2020-01-01
2020-02-07 16:47:43,916 INFO download_runner.impl.historical_runner:35 sent - historical data request : AFB 2019-01-01 2020-01-01
2020-02-07 16:47:43,916 DEBUG download_runner.impl.historical_runner:36 request accounted for...
2020-02-07 16:47:43,916 INFO download_runner.impl.historical_runner:37 status : True
2020-02-07 16:47:43,916 INFO download_runner.impl.historical_runner:42 Historical data request sent : AFB 2019-01-01 2020-01-01
2020-02-07 16:47:43,916 DEBUG download_runner.impl.historical_end_reader:37 poll stock ? => True
2020-02-07 16:47:43,916 ERROR root:30 unhandled exception getting latest timestamp for AFC
Traceback (most recent call last):
  File "/Users/dali/workspace/ib_python/runner/services/historical_data_service.py", line 24, in get_latest_timestamp
    response = self.stub.GetLatestTimeStamp(request)
  File "/Users/dali/workspace/ib_python/runner/venv/lib/python3.7/site-packages/grpc/_channel.py", line 604, in __call__
    return _end_unary_response_blocking(state, call, False, None)
  File "/Users/dali/workspace/ib_python/runner/venv/lib/python3.7/site-packages/grpc/_channel.py", line 506, in _end_unary_response_blocking
    raise _Rendezvous(state, None, None, deadline)
grpc._channel._Rendezvous: <_Rendezvous of RPC that terminated with:
	status = StatusCode.UNAVAILABLE
	details = "failed to connect to all addresses"
	debug_error_string = "{"created":"@1581094063.916569000","description":"Failed to pick subchannel","file":"src/core/ext/filters/client_channel/client_channel.cc","file_line":3876,"referenced_errors":[{"created":"@1581094057.527580000","description":"failed to connect to all addresses","file":"src/core/ext/filters/client_channel/lb_policy/pick_first/pick_first.cc","file_line":395,"grpc_status":14}]}"
>
2020-02-07 16:47:43,916 INFO download_runner.impl.historical_runner:32 sending - historical data request : AFC 2019-01-01 2020-01-01
2020-02-07 16:47:48,815 INFO download_runner.impl.historical_runner:35 sent - historical data request : AFC 2019-01-01 2020-01-01
2020-02-07 16:47:48,815 DEBUG download_runner.impl.historical_runner:36 request accounted for...
2020-02-07 16:47:48,815 INFO download_runner.impl.historical_runner:37 status : True
2020-02-07 16:47:48,815 INFO download_runner.impl.historical_runner:42 Historical data request sent : AFC 2019-01-01 2020-01-01
2020-02-07 16:47:48,815 DEBUG download_runner.impl.historical_end_reader:37 poll stock ? => True
2020-02-07 16:47:48,815 ERROR root:30 unhandled exception getting latest timestamp for AFG
Traceback (most recent call last):
  File "/Users/dali/workspace/ib_python/runner/services/historical_data_service.py", line 24, in get_latest_timestamp
    response = self.stub.GetLatestTimeStamp(request)
  File "/Users/dali/workspace/ib_python/runner/venv/lib/python3.7/site-packages/grpc/_channel.py", line 604, in __call__
    return _end_unary_response_blocking(state, call, False, None)
  File "/Users/dali/workspace/ib_python/runner/venv/lib/python3.7/site-packages/grpc/_channel.py", line 506, in _end_unary_response_blocking
    raise _Rendezvous(state, None, None, deadline)
grpc._channel._Rendezvous: <_Rendezvous of RPC that terminated with:
	status = StatusCode.UNAVAILABLE
	details = "failed to connect to all addresses"
	debug_error_string = "{"created":"@1581094068.815558000","description":"Failed to pick subchannel","file":"src/core/ext/filters/client_channel/client_channel.cc","file_line":3876,"referenced_errors":[{"created":"@1581094057.527580000","description":"failed to connect to all addresses","file":"src/core/ext/filters/client_channel/lb_policy/pick_first/pick_first.cc","file_line":395,"grpc_status":14}]}"
>
2020-02-07 16:47:48,815 INFO download_runner.impl.historical_runner:32 sending - historical data request : AFG 2019-01-01 2020-01-01
2020-02-07 16:47:49,477 INFO download_runner.impl.historical_runner:35 sent - historical data request : AFG 2019-01-01 2020-01-01
2020-02-07 16:47:49,477 DEBUG download_runner.impl.historical_runner:36 request accounted for...
2020-02-07 16:47:49,477 INFO download_runner.impl.historical_runner:37 status : True
2020-02-07 16:47:49,477 INFO download_runner.impl.historical_runner:42 Historical data request sent : AFG 2019-01-01 2020-01-01
2020-02-07 16:47:49,477 DEBUG download_runner.impl.historical_end_reader:37 poll stock ? => True
2020-02-07 16:47:49,477 ERROR root:30 unhandled exception getting latest timestamp for AFGB
Traceback (most recent call last):
  File "/Users/dali/workspace/ib_python/runner/services/historical_data_service.py", line 24, in get_latest_timestamp
    response = self.stub.GetLatestTimeStamp(request)
  File "/Users/dali/workspace/ib_python/runner/venv/lib/python3.7/site-packages/grpc/_channel.py", line 604, in __call__
    return _end_unary_response_blocking(state, call, False, None)
  File "/Users/dali/workspace/ib_python/runner/venv/lib/python3.7/site-packages/grpc/_channel.py", line 506, in _end_unary_response_blocking
    raise _Rendezvous(state, None, None, deadline)
grpc._channel._Rendezvous: <_Rendezvous of RPC that terminated with:
	status = StatusCode.UNAVAILABLE
	details = "failed to connect to all addresses"
	debug_error_string = "{"created":"@1581094069.477710000","description":"Failed to pick subchannel","file":"src/core/ext/filters/client_channel/client_channel.cc","file_line":3876,"referenced_errors":[{"created":"@1581094057.527580000","description":"failed to connect to all addresses","file":"src/core/ext/filters/client_channel/lb_policy/pick_first/pick_first.cc","file_line":395,"grpc_status":14}]}"
>
2020-02-07 16:47:49,478 INFO download_runner.impl.historical_runner:32 sending - historical data request : AFGB 2019-01-01 2020-01-01
2020-02-07 16:47:54,641 INFO download_runner.impl.historical_runner:35 sent - historical data request : AFGB 2019-01-01 2020-01-01
2020-02-07 16:47:54,641 DEBUG download_runner.impl.historical_runner:36 request accounted for...
2020-02-07 16:47:54,641 INFO download_runner.impl.historical_runner:37 status : True
2020-02-07 16:47:54,641 INFO download_runner.impl.historical_runner:42 Historical data request sent : AFGB 2019-01-01 2020-01-01
2020-02-07 16:47:54,641 DEBUG download_runner.impl.historical_end_reader:37 poll stock ? => True
2020-02-07 16:47:54,641 ERROR root:30 unhandled exception getting latest timestamp for AFGE
Traceback (most recent call last):
  File "/Users/dali/workspace/ib_python/runner/services/historical_data_service.py", line 24, in get_latest_timestamp
    response = self.stub.GetLatestTimeStamp(request)
  File "/Users/dali/workspace/ib_python/runner/venv/lib/python3.7/site-packages/grpc/_channel.py", line 604, in __call__
    return _end_unary_response_blocking(state, call, False, None)
  File "/Users/dali/workspace/ib_python/runner/venv/lib/python3.7/site-packages/grpc/_channel.py", line 506, in _end_unary_response_blocking
    raise _Rendezvous(state, None, None, deadline)
grpc._channel._Rendezvous: <_Rendezvous of RPC that terminated with:
	status = StatusCode.UNAVAILABLE
	details = "failed to connect to all addresses"
	debug_error_string = "{"created":"@1581094074.641547000","description":"Failed to pick subchannel","file":"src/core/ext/filters/client_channel/client_channel.cc","file_line":3876,"referenced_errors":[{"created":"@1581094057.527580000","description":"failed to connect to all addresses","file":"src/core/ext/filters/client_channel/lb_policy/pick_first/pick_first.cc","file_line":395,"grpc_status":14}]}"
>
2020-02-07 16:47:54,641 INFO download_runner.impl.historical_runner:32 sending - historical data request : AFGE 2019-01-01 2020-01-01
2020-02-07 16:47:55,184 INFO download_runner.impl.historical_runner:35 sent - historical data request : AFGE 2019-01-01 2020-01-01
2020-02-07 16:47:55,184 DEBUG download_runner.impl.historical_runner:36 request accounted for...
2020-02-07 16:47:55,184 INFO download_runner.impl.historical_runner:37 status : True
2020-02-07 16:47:55,184 INFO download_runner.impl.historical_runner:42 Historical data request sent : AFGE 2019-01-01 2020-01-01
2020-02-07 16:47:55,184 DEBUG download_runner.impl.historical_end_reader:37 poll stock ? => True
2020-02-07 16:47:55,185 ERROR root:30 unhandled exception getting latest timestamp for AFGH
Traceback (most recent call last):
  File "/Users/dali/workspace/ib_python/runner/services/historical_data_service.py", line 24, in get_latest_timestamp
    response = self.stub.GetLatestTimeStamp(request)
  File "/Users/dali/workspace/ib_python/runner/venv/lib/python3.7/site-packages/grpc/_channel.py", line 604, in __call__
    return _end_unary_response_blocking(state, call, False, None)
  File "/Users/dali/workspace/ib_python/runner/venv/lib/python3.7/site-packages/grpc/_channel.py", line 506, in _end_unary_response_blocking
    raise _Rendezvous(state, None, None, deadline)
grpc._channel._Rendezvous: <_Rendezvous of RPC that terminated with:
	status = StatusCode.UNAVAILABLE
	details = "failed to connect to all addresses"
	debug_error_string = "{"created":"@1581094075.184980000","description":"Failed to pick subchannel","file":"src/core/ext/filters/client_channel/client_channel.cc","file_line":3876,"referenced_errors":[{"created":"@1581094057.527580000","description":"failed to connect to all addresses","file":"src/core/ext/filters/client_channel/lb_policy/pick_first/pick_first.cc","file_line":395,"grpc_status":14}]}"
>
2020-02-07 16:47:55,185 INFO download_runner.impl.historical_runner:32 sending - historical data request : AFGH 2019-01-01 2020-01-01
2020-02-07 16:48:06,695 INFO download_runner.impl.historical_runner:35 sent - historical data request : AFGH 2019-01-01 2020-01-01
2020-02-07 16:48:06,695 DEBUG download_runner.impl.historical_runner:36 request accounted for...
2020-02-07 16:48:06,695 INFO download_runner.impl.historical_runner:37 status : True
2020-02-07 16:48:06,695 INFO download_runner.impl.historical_runner:42 Historical data request sent : AFGH 2019-01-01 2020-01-01
2020-02-07 16:48:06,695 DEBUG download_runner.impl.historical_end_reader:37 poll stock ? => True
2020-02-07 16:48:06,695 ERROR root:30 unhandled exception getting latest timestamp for AFH
Traceback (most recent call last):
  File "/Users/dali/workspace/ib_python/runner/services/historical_data_service.py", line 24, in get_latest_timestamp
    response = self.stub.GetLatestTimeStamp(request)
  File "/Users/dali/workspace/ib_python/runner/venv/lib/python3.7/site-packages/grpc/_channel.py", line 604, in __call__
    return _end_unary_response_blocking(state, call, False, None)
  File "/Users/dali/workspace/ib_python/runner/venv/lib/python3.7/site-packages/grpc/_channel.py", line 506, in _end_unary_response_blocking
    raise _Rendezvous(state, None, None, deadline)
grpc._channel._Rendezvous: <_Rendezvous of RPC that terminated with:
	status = StatusCode.UNAVAILABLE
	details = "failed to connect to all addresses"
	debug_error_string = "{"created":"@1581094086.695610000","description":"Failed to pick subchannel","file":"src/core/ext/filters/client_channel/client_channel.cc","file_line":3876,"referenced_errors":[{"created":"@1581094057.527580000","description":"failed to connect to all addresses","file":"src/core/ext/filters/client_channel/lb_policy/pick_first/pick_first.cc","file_line":395,"grpc_status":14}]}"
>
2020-02-07 16:48:06,695 INFO download_runner.impl.historical_runner:32 sending - historical data request : AFH 2019-01-01 2020-01-01
2020-02-07 16:48:18,754 INFO download_runner.impl.historical_runner:35 sent - historical data request : AFH 2019-01-01 2020-01-01
2020-02-07 16:48:18,754 DEBUG download_runner.impl.historical_runner:36 request accounted for...
2020-02-07 16:48:18,754 INFO download_runner.impl.historical_runner:37 status : True
2020-02-07 16:48:18,754 INFO download_runner.impl.historical_runner:42 Historical data request sent : AFH 2019-01-01 2020-01-01
2020-02-07 16:48:18,754 DEBUG download_runner.impl.historical_end_reader:37 poll stock ? => True
2020-02-07 16:48:18,755 ERROR root:30 unhandled exception getting latest timestamp for AFI
Traceback (most recent call last):
  File "/Users/dali/workspace/ib_python/runner/services/historical_data_service.py", line 24, in get_latest_timestamp
    response = self.stub.GetLatestTimeStamp(request)
  File "/Users/dali/workspace/ib_python/runner/venv/lib/python3.7/site-packages/grpc/_channel.py", line 604, in __call__
    return _end_unary_response_blocking(state, call, False, None)
  File "/Users/dali/workspace/ib_python/runner/venv/lib/python3.7/site-packages/grpc/_channel.py", line 506, in _end_unary_response_blocking
    raise _Rendezvous(state, None, None, deadline)
grpc._channel._Rendezvous: <_Rendezvous of RPC that terminated with:
	status = StatusCode.UNAVAILABLE
	details = "failed to connect to all addresses"
	debug_error_string = "{"created":"@1581094098.754949000","description":"Failed to pick subchannel","file":"src/core/ext/filters/client_channel/client_channel.cc","file_line":3876,"referenced_errors":[{"created":"@1581094057.527580000","description":"failed to connect to all addresses","file":"src/core/ext/filters/client_channel/lb_policy/pick_first/pick_first.cc","file_line":395,"grpc_status":14}]}"
>
2020-02-07 16:48:18,755 INFO download_runner.impl.historical_runner:32 sending - historical data request : AFI 2019-01-01 2020-01-01
2020-02-07 16:48:31,516 INFO download_runner.impl.historical_runner:35 sent - historical data request : AFI 2019-01-01 2020-01-01
2020-02-07 16:48:31,517 DEBUG download_runner.impl.historical_runner:36 request accounted for...
2020-02-07 16:48:31,517 INFO download_runner.impl.historical_runner:37 status : True
2020-02-07 16:48:31,517 INFO download_runner.impl.historical_runner:42 Historical data request sent : AFI 2019-01-01 2020-01-01
2020-02-07 16:48:31,517 DEBUG download_runner.impl.historical_end_reader:37 poll stock ? => True
2020-02-07 16:48:31,517 ERROR root:30 unhandled exception getting latest timestamp for AFIF
Traceback (most recent call last):
  File "/Users/dali/workspace/ib_python/runner/services/historical_data_service.py", line 24, in get_latest_timestamp
    response = self.stub.GetLatestTimeStamp(request)
  File "/Users/dali/workspace/ib_python/runner/venv/lib/python3.7/site-packages/grpc/_channel.py", line 604, in __call__
    return _end_unary_response_blocking(state, call, False, None)
  File "/Users/dali/workspace/ib_python/runner/venv/lib/python3.7/site-packages/grpc/_channel.py", line 506, in _end_unary_response_blocking
    raise _Rendezvous(state, None, None, deadline)
grpc._channel._Rendezvous: <_Rendezvous of RPC that terminated with:
	status = StatusCode.UNAVAILABLE
	details = "failed to connect to all addresses"
	debug_error_string = "{"created":"@1581094111.517582000","description":"Failed to pick subchannel","file":"src/core/ext/filters/client_channel/client_channel.cc","file_line":3876,"referenced_errors":[{"created":"@1581094099.927044000","description":"failed to connect to all addresses","file":"src/core/ext/filters/client_channel/lb_policy/pick_first/pick_first.cc","file_line":395,"grpc_status":14}]}"
>
2020-02-07 16:48:31,518 INFO download_runner.impl.historical_runner:32 sending - historical data request : AFIF 2019-01-01 2020-01-01
2020-02-07 16:48:31,803 INFO download_runner.impl.historical_runner:35 sent - historical data request : AFIF 2019-01-01 2020-01-01
2020-02-07 16:48:31,803 DEBUG download_runner.impl.historical_runner:36 request accounted for...
2020-02-07 16:48:31,803 INFO download_runner.impl.historical_runner:37 status : True
2020-02-07 16:48:31,803 INFO download_runner.impl.historical_runner:42 Historical data request sent : AFIF 2019-01-01 2020-01-01
2020-02-07 16:48:31,803 DEBUG download_runner.impl.historical_end_reader:37 poll stock ? => True
2020-02-07 16:48:31,804 ERROR root:30 unhandled exception getting latest timestamp for AFIN
Traceback (most recent call last):
  File "/Users/dali/workspace/ib_python/runner/services/historical_data_service.py", line 24, in get_latest_timestamp
    response = self.stub.GetLatestTimeStamp(request)
  File "/Users/dali/workspace/ib_python/runner/venv/lib/python3.7/site-packages/grpc/_channel.py", line 604, in __call__
    return _end_unary_response_blocking(state, call, False, None)
  File "/Users/dali/workspace/ib_python/runner/venv/lib/python3.7/site-packages/grpc/_channel.py", line 506, in _end_unary_response_blocking
    raise _Rendezvous(state, None, None, deadline)
grpc._channel._Rendezvous: <_Rendezvous of RPC that terminated with:
	status = StatusCode.UNAVAILABLE
	details = "failed to connect to all addresses"
	debug_error_string = "{"created":"@1581094111.804044000","description":"Failed to pick subchannel","file":"src/core/ext/filters/client_channel/client_channel.cc","file_line":3876,"referenced_errors":[{"created":"@1581094099.927044000","description":"failed to connect to all addresses","file":"src/core/ext/filters/client_channel/lb_policy/pick_first/pick_first.cc","file_line":395,"grpc_status":14}]}"
>
2020-02-07 16:48:31,804 INFO download_runner.impl.historical_runner:32 sending - historical data request : AFIN 2019-01-01 2020-01-01
2020-02-07 16:48:32,795 INFO download_runner.impl.historical_runner:35 sent - historical data request : AFIN 2019-01-01 2020-01-01
2020-02-07 16:48:32,795 DEBUG download_runner.impl.historical_runner:36 request accounted for...
2020-02-07 16:48:32,795 INFO download_runner.impl.historical_runner:37 status : True
2020-02-07 16:48:32,795 INFO download_runner.impl.historical_runner:42 Historical data request sent : AFIN 2019-01-01 2020-01-01
2020-02-07 16:48:32,796 DEBUG download_runner.impl.historical_end_reader:37 poll stock ? => True
2020-02-07 16:48:32,797 ERROR root:30 unhandled exception getting latest timestamp for AFINP
Traceback (most recent call last):
  File "/Users/dali/workspace/ib_python/runner/services/historical_data_service.py", line 24, in get_latest_timestamp
    response = self.stub.GetLatestTimeStamp(request)
  File "/Users/dali/workspace/ib_python/runner/venv/lib/python3.7/site-packages/grpc/_channel.py", line 604, in __call__
    return _end_unary_response_blocking(state, call, False, None)
  File "/Users/dali/workspace/ib_python/runner/venv/lib/python3.7/site-packages/grpc/_channel.py", line 506, in _end_unary_response_blocking
    raise _Rendezvous(state, None, None, deadline)
grpc._channel._Rendezvous: <_Rendezvous of RPC that terminated with:
	status = StatusCode.UNAVAILABLE
	details = "failed to connect to all addresses"
	debug_error_string = "{"created":"@1581094112.797178000","description":"Failed to pick subchannel","file":"src/core/ext/filters/client_channel/client_channel.cc","file_line":3876,"referenced_errors":[{"created":"@1581094099.927044000","description":"failed to connect to all addresses","file":"src/core/ext/filters/client_channel/lb_policy/pick_first/pick_first.cc","file_line":395,"grpc_status":14}]}"
>
2020-02-07 16:48:32,799 INFO download_runner.impl.historical_runner:32 sending - historical data request : AFINP 2019-01-01 2020-01-01
2020-02-07 16:48:33,600 INFO download_runner.impl.historical_runner:35 sent - historical data request : AFINP 2019-01-01 2020-01-01
2020-02-07 16:48:33,600 DEBUG download_runner.impl.historical_runner:36 request accounted for...
2020-02-07 16:48:33,600 INFO download_runner.impl.historical_runner:37 status : True
2020-02-07 16:48:33,600 INFO download_runner.impl.historical_runner:42 Historical data request sent : AFINP 2019-01-01 2020-01-01
2020-02-07 16:48:33,600 DEBUG download_runner.impl.historical_end_reader:37 poll stock ? => True
2020-02-07 16:48:33,600 ERROR root:30 unhandled exception getting latest timestamp for AFK
Traceback (most recent call last):
  File "/Users/dali/workspace/ib_python/runner/services/historical_data_service.py", line 24, in get_latest_timestamp
    response = self.stub.GetLatestTimeStamp(request)
  File "/Users/dali/workspace/ib_python/runner/venv/lib/python3.7/site-packages/grpc/_channel.py", line 604, in __call__
    return _end_unary_response_blocking(state, call, False, None)
  File "/Users/dali/workspace/ib_python/runner/venv/lib/python3.7/site-packages/grpc/_channel.py", line 506, in _end_unary_response_blocking
    raise _Rendezvous(state, None, None, deadline)
grpc._channel._Rendezvous: <_Rendezvous of RPC that terminated with:
	status = StatusCode.UNAVAILABLE
	details = "failed to connect to all addresses"
	debug_error_string = "{"created":"@1581094113.600596000","description":"Failed to pick subchannel","file":"src/core/ext/filters/client_channel/client_channel.cc","file_line":3876,"referenced_errors":[{"created":"@1581094099.927044000","description":"failed to connect to all addresses","file":"src/core/ext/filters/client_channel/lb_policy/pick_first/pick_first.cc","file_line":395,"grpc_status":14}]}"
>
2020-02-07 16:48:33,600 INFO download_runner.impl.historical_runner:32 sending - historical data request : AFK 2019-01-01 2020-01-01
2020-02-07 16:48:36,536 INFO download_runner.impl.historical_runner:35 sent - historical data request : AFK 2019-01-01 2020-01-01
2020-02-07 16:48:36,536 DEBUG download_runner.impl.historical_runner:36 request accounted for...
2020-02-07 16:48:36,536 INFO download_runner.impl.historical_runner:37 status : True
2020-02-07 16:48:36,536 INFO download_runner.impl.historical_runner:42 Historical data request sent : AFK 2019-01-01 2020-01-01
2020-02-07 16:48:36,537 DEBUG download_runner.impl.historical_end_reader:37 poll stock ? => True
2020-02-07 16:48:36,537 ERROR root:30 unhandled exception getting latest timestamp for AFL
Traceback (most recent call last):
  File "/Users/dali/workspace/ib_python/runner/services/historical_data_service.py", line 24, in get_latest_timestamp
    response = self.stub.GetLatestTimeStamp(request)
  File "/Users/dali/workspace/ib_python/runner/venv/lib/python3.7/site-packages/grpc/_channel.py", line 604, in __call__
    return _end_unary_response_blocking(state, call, False, None)
  File "/Users/dali/workspace/ib_python/runner/venv/lib/python3.7/site-packages/grpc/_channel.py", line 506, in _end_unary_response_blocking
    raise _Rendezvous(state, None, None, deadline)
grpc._channel._Rendezvous: <_Rendezvous of RPC that terminated with:
	status = StatusCode.UNAVAILABLE
	details = "failed to connect to all addresses"
	debug_error_string = "{"created":"@1581094116.537255000","description":"Failed to pick subchannel","file":"src/core/ext/filters/client_channel/client_channel.cc","file_line":3876,"referenced_errors":[{"created":"@1581094099.927044000","description":"failed to connect to all addresses","file":"src/core/ext/filters/client_channel/lb_policy/pick_first/pick_first.cc","file_line":395,"grpc_status":14}]}"
>
2020-02-07 16:48:36,537 INFO download_runner.impl.historical_runner:32 sending - historical data request : AFL 2019-01-01 2020-01-01
2020-02-07 16:48:37,314 INFO download_runner.impl.historical_runner:35 sent - historical data request : AFL 2019-01-01 2020-01-01
2020-02-07 16:48:37,314 DEBUG download_runner.impl.historical_runner:36 request accounted for...
2020-02-07 16:48:37,314 INFO download_runner.impl.historical_runner:37 status : True
2020-02-07 16:48:37,314 INFO download_runner.impl.historical_runner:42 Historical data request sent : AFL 2019-01-01 2020-01-01
2020-02-07 16:48:37,314 DEBUG download_runner.impl.historical_end_reader:37 poll stock ? => True
2020-02-07 16:48:37,315 ERROR root:30 unhandled exception getting latest timestamp for AFMD
Traceback (most recent call last):
  File "/Users/dali/workspace/ib_python/runner/services/historical_data_service.py", line 24, in get_latest_timestamp
    response = self.stub.GetLatestTimeStamp(request)
  File "/Users/dali/workspace/ib_python/runner/venv/lib/python3.7/site-packages/grpc/_channel.py", line 604, in __call__
    return _end_unary_response_blocking(state, call, False, None)
  File "/Users/dali/workspace/ib_python/runner/venv/lib/python3.7/site-packages/grpc/_channel.py", line 506, in _end_unary_response_blocking
    raise _Rendezvous(state, None, None, deadline)
grpc._channel._Rendezvous: <_Rendezvous of RPC that terminated with:
	status = StatusCode.UNAVAILABLE
	details = "failed to connect to all addresses"
	debug_error_string = "{"created":"@1581094117.315139000","description":"Failed to pick subchannel","file":"src/core/ext/filters/client_channel/client_channel.cc","file_line":3876,"referenced_errors":[{"created":"@1581094099.927044000","description":"failed to connect to all addresses","file":"src/core/ext/filters/client_channel/lb_policy/pick_first/pick_first.cc","file_line":395,"grpc_status":14}]}"
>
2020-02-07 16:48:37,315 INFO download_runner.impl.historical_runner:32 sending - historical data request : AFMD 2019-01-01 2020-01-01
2020-02-07 16:48:37,684 INFO download_runner.impl.historical_runner:35 sent - historical data request : AFMD 2019-01-01 2020-01-01
2020-02-07 16:48:37,685 DEBUG download_runner.impl.historical_runner:36 request accounted for...
2020-02-07 16:48:37,685 INFO download_runner.impl.historical_runner:37 status : True
2020-02-07 16:48:37,685 INFO download_runner.impl.historical_runner:42 Historical data request sent : AFMD 2019-01-01 2020-01-01
2020-02-07 16:48:37,685 DEBUG download_runner.impl.historical_end_reader:37 poll stock ? => True
2020-02-07 16:48:37,685 ERROR root:30 unhandled exception getting latest timestamp for AFT
Traceback (most recent call last):
  File "/Users/dali/workspace/ib_python/runner/services/historical_data_service.py", line 24, in get_latest_timestamp
    response = self.stub.GetLatestTimeStamp(request)
  File "/Users/dali/workspace/ib_python/runner/venv/lib/python3.7/site-packages/grpc/_channel.py", line 604, in __call__
    return _end_unary_response_blocking(state, call, False, None)
  File "/Users/dali/workspace/ib_python/runner/venv/lib/python3.7/site-packages/grpc/_channel.py", line 506, in _end_unary_response_blocking
    raise _Rendezvous(state, None, None, deadline)
grpc._channel._Rendezvous: <_Rendezvous of RPC that terminated with:
	status = StatusCode.UNAVAILABLE
	details = "failed to connect to all addresses"
	debug_error_string = "{"created":"@1581094117.685332000","description":"Failed to pick subchannel","file":"src/core/ext/filters/client_channel/client_channel.cc","file_line":3876,"referenced_errors":[{"created":"@1581094099.927044000","description":"failed to connect to all addresses","file":"src/core/ext/filters/client_channel/lb_policy/pick_first/pick_first.cc","file_line":395,"grpc_status":14}]}"
>
2020-02-07 16:48:37,685 INFO download_runner.impl.historical_runner:32 sending - historical data request : AFT 2019-01-01 2020-01-01
2020-02-07 16:48:37,842 INFO download_runner.impl.historical_runner:35 sent - historical data request : AFT 2019-01-01 2020-01-01
2020-02-07 16:48:37,843 DEBUG download_runner.impl.historical_runner:36 request accounted for...
2020-02-07 16:48:37,843 INFO download_runner.impl.historical_runner:37 status : True
2020-02-07 16:48:37,843 INFO download_runner.impl.historical_runner:42 Historical data request sent : AFT 2019-01-01 2020-01-01
2020-02-07 16:48:37,843 DEBUG download_runner.impl.historical_end_reader:37 poll stock ? => True
2020-02-07 16:48:37,843 ERROR root:30 unhandled exception getting latest timestamp for AFTY
Traceback (most recent call last):
  File "/Users/dali/workspace/ib_python/runner/services/historical_data_service.py", line 24, in get_latest_timestamp
    response = self.stub.GetLatestTimeStamp(request)
  File "/Users/dali/workspace/ib_python/runner/venv/lib/python3.7/site-packages/grpc/_channel.py", line 604, in __call__
    return _end_unary_response_blocking(state, call, False, None)
  File "/Users/dali/workspace/ib_python/runner/venv/lib/python3.7/site-packages/grpc/_channel.py", line 506, in _end_unary_response_blocking
    raise _Rendezvous(state, None, None, deadline)
grpc._channel._Rendezvous: <_Rendezvous of RPC that terminated with:
	status = StatusCode.UNAVAILABLE
	details = "failed to connect to all addresses"
	debug_error_string = "{"created":"@1581094117.843345000","description":"Failed to pick subchannel","file":"src/core/ext/filters/client_channel/client_channel.cc","file_line":3876,"referenced_errors":[{"created":"@1581094099.927044000","description":"failed to connect to all addresses","file":"src/core/ext/filters/client_channel/lb_policy/pick_first/pick_first.cc","file_line":395,"grpc_status":14}]}"
>
2020-02-07 16:48:37,843 INFO download_runner.impl.historical_runner:32 sending - historical data request : AFTY 2019-01-01 2020-01-01
2020-02-07 16:48:38,005 INFO download_runner.impl.historical_runner:35 sent - historical data request : AFTY 2019-01-01 2020-01-01
2020-02-07 16:48:38,005 DEBUG download_runner.impl.historical_runner:36 request accounted for...
2020-02-07 16:48:38,005 INFO download_runner.impl.historical_runner:37 status : True
2020-02-07 16:48:38,005 INFO download_runner.impl.historical_runner:42 Historical data request sent : AFTY 2019-01-01 2020-01-01
2020-02-07 16:48:38,005 DEBUG download_runner.impl.historical_end_reader:37 poll stock ? => True
2020-02-07 16:48:38,006 ERROR root:30 unhandled exception getting latest timestamp for AFYA
Traceback (most recent call last):
  File "/Users/dali/workspace/ib_python/runner/services/historical_data_service.py", line 24, in get_latest_timestamp
    response = self.stub.GetLatestTimeStamp(request)
  File "/Users/dali/workspace/ib_python/runner/venv/lib/python3.7/site-packages/grpc/_channel.py", line 604, in __call__
    return _end_unary_response_blocking(state, call, False, None)
  File "/Users/dali/workspace/ib_python/runner/venv/lib/python3.7/site-packages/grpc/_channel.py", line 506, in _end_unary_response_blocking
    raise _Rendezvous(state, None, None, deadline)
grpc._channel._Rendezvous: <_Rendezvous of RPC that terminated with:
	status = StatusCode.UNAVAILABLE
	details = "failed to connect to all addresses"
	debug_error_string = "{"created":"@1581094118.006205000","description":"Failed to pick subchannel","file":"src/core/ext/filters/client_channel/client_channel.cc","file_line":3876,"referenced_errors":[{"created":"@1581094099.927044000","description":"failed to connect to all addresses","file":"src/core/ext/filters/client_channel/lb_policy/pick_first/pick_first.cc","file_line":395,"grpc_status":14}]}"
>
2020-02-07 16:48:38,006 INFO download_runner.impl.historical_runner:32 sending - historical data request : AFYA 2019-01-01 2020-01-01
2020-02-07 16:48:42,612 INFO download_runner.impl.historical_runner:35 sent - historical data request : AFYA 2019-01-01 2020-01-01
2020-02-07 16:48:42,612 DEBUG download_runner.impl.historical_runner:36 request accounted for...
2020-02-07 16:48:42,612 INFO download_runner.impl.historical_runner:37 status : True
2020-02-07 16:48:42,612 INFO download_runner.impl.historical_runner:42 Historical data request sent : AFYA 2019-01-01 2020-01-01
2020-02-07 16:48:42,612 DEBUG download_runner.impl.historical_end_reader:37 poll stock ? => True
2020-02-07 16:48:42,612 ERROR root:30 unhandled exception getting latest timestamp for AG
Traceback (most recent call last):
  File "/Users/dali/workspace/ib_python/runner/services/historical_data_service.py", line 24, in get_latest_timestamp
    response = self.stub.GetLatestTimeStamp(request)
  File "/Users/dali/workspace/ib_python/runner/venv/lib/python3.7/site-packages/grpc/_channel.py", line 604, in __call__
    return _end_unary_response_blocking(state, call, False, None)
  File "/Users/dali/workspace/ib_python/runner/venv/lib/python3.7/site-packages/grpc/_channel.py", line 506, in _end_unary_response_blocking
    raise _Rendezvous(state, None, None, deadline)
grpc._channel._Rendezvous: <_Rendezvous of RPC that terminated with:
	status = StatusCode.UNAVAILABLE
	details = "failed to connect to all addresses"
	debug_error_string = "{"created":"@1581094122.612786000","description":"Failed to pick subchannel","file":"src/core/ext/filters/client_channel/client_channel.cc","file_line":3876,"referenced_errors":[{"created":"@1581094099.927044000","description":"failed to connect to all addresses","file":"src/core/ext/filters/client_channel/lb_policy/pick_first/pick_first.cc","file_line":395,"grpc_status":14}]}"
>
2020-02-07 16:48:42,613 INFO download_runner.impl.historical_runner:32 sending - historical data request : AG 2019-01-01 2020-01-01
2020-02-07 16:48:48,806 INFO download_runner.impl.historical_runner:35 sent - historical data request : AG 2019-01-01 2020-01-01
2020-02-07 16:48:48,806 DEBUG download_runner.impl.historical_runner:36 request accounted for...
2020-02-07 16:48:48,806 INFO download_runner.impl.historical_runner:37 status : True
2020-02-07 16:48:48,806 INFO download_runner.impl.historical_runner:42 Historical data request sent : AG 2019-01-01 2020-01-01
2020-02-07 16:48:48,806 DEBUG download_runner.impl.historical_end_reader:37 poll stock ? => True
2020-02-07 16:48:48,807 ERROR root:30 unhandled exception getting latest timestamp for AGBA
Traceback (most recent call last):
  File "/Users/dali/workspace/ib_python/runner/services/historical_data_service.py", line 24, in get_latest_timestamp
    response = self.stub.GetLatestTimeStamp(request)
  File "/Users/dali/workspace/ib_python/runner/venv/lib/python3.7/site-packages/grpc/_channel.py", line 604, in __call__
    return _end_unary_response_blocking(state, call, False, None)
  File "/Users/dali/workspace/ib_python/runner/venv/lib/python3.7/site-packages/grpc/_channel.py", line 506, in _end_unary_response_blocking
    raise _Rendezvous(state, None, None, deadline)
grpc._channel._Rendezvous: <_Rendezvous of RPC that terminated with:
	status = StatusCode.UNAVAILABLE
	details = "failed to connect to all addresses"
	debug_error_string = "{"created":"@1581094128.807259000","description":"Failed to pick subchannel","file":"src/core/ext/filters/client_channel/client_channel.cc","file_line":3876,"referenced_errors":[{"created":"@1581094099.927044000","description":"failed to connect to all addresses","file":"src/core/ext/filters/client_channel/lb_policy/pick_first/pick_first.cc","file_line":395,"grpc_status":14}]}"
>
2020-02-07 16:48:48,807 INFO download_runner.impl.historical_runner:32 sending - historical data request : AGBA 2019-01-01 2020-01-01
2020-02-07 16:48:49,281 INFO download_runner.impl.historical_runner:35 sent - historical data request : AGBA 2019-01-01 2020-01-01
2020-02-07 16:48:49,281 DEBUG download_runner.impl.historical_runner:36 request accounted for...
2020-02-07 16:48:49,281 INFO download_runner.impl.historical_runner:37 status : True
2020-02-07 16:48:49,282 INFO download_runner.impl.historical_runner:42 Historical data request sent : AGBA 2019-01-01 2020-01-01
2020-02-07 16:48:49,282 DEBUG download_runner.impl.historical_end_reader:37 poll stock ? => True
2020-02-07 16:48:49,282 ERROR root:30 unhandled exception getting latest timestamp for AGBAR
Traceback (most recent call last):
  File "/Users/dali/workspace/ib_python/runner/services/historical_data_service.py", line 24, in get_latest_timestamp
    response = self.stub.GetLatestTimeStamp(request)
  File "/Users/dali/workspace/ib_python/runner/venv/lib/python3.7/site-packages/grpc/_channel.py", line 604, in __call__
    return _end_unary_response_blocking(state, call, False, None)
  File "/Users/dali/workspace/ib_python/runner/venv/lib/python3.7/site-packages/grpc/_channel.py", line 506, in _end_unary_response_blocking
    raise _Rendezvous(state, None, None, deadline)
grpc._channel._Rendezvous: <_Rendezvous of RPC that terminated with:
	status = StatusCode.UNAVAILABLE
	details = "failed to connect to all addresses"
	debug_error_string = "{"created":"@1581094129.282453000","description":"Failed to pick subchannel","file":"src/core/ext/filters/client_channel/client_channel.cc","file_line":3876,"referenced_errors":[{"created":"@1581094099.927044000","description":"failed to connect to all addresses","file":"src/core/ext/filters/client_channel/lb_policy/pick_first/pick_first.cc","file_line":395,"grpc_status":14}]}"
>
2020-02-07 16:48:49,283 INFO download_runner.impl.historical_runner:32 sending - historical data request : AGBAR 2019-01-01 2020-01-01
2020-02-07 16:48:54,554 INFO download_runner.impl.historical_runner:35 sent - historical data request : AGBAR 2019-01-01 2020-01-01
2020-02-07 16:48:54,554 DEBUG download_runner.impl.historical_runner:36 request accounted for...
2020-02-07 16:48:54,554 INFO download_runner.impl.historical_runner:37 status : True
2020-02-07 16:48:54,554 INFO download_runner.impl.historical_runner:42 Historical data request sent : AGBAR 2019-01-01 2020-01-01
2020-02-07 16:48:54,554 DEBUG download_runner.impl.historical_end_reader:37 poll stock ? => True
2020-02-07 16:48:54,554 ERROR root:30 unhandled exception getting latest timestamp for AGBAU
Traceback (most recent call last):
  File "/Users/dali/workspace/ib_python/runner/services/historical_data_service.py", line 24, in get_latest_timestamp
    response = self.stub.GetLatestTimeStamp(request)
  File "/Users/dali/workspace/ib_python/runner/venv/lib/python3.7/site-packages/grpc/_channel.py", line 604, in __call__
    return _end_unary_response_blocking(state, call, False, None)
  File "/Users/dali/workspace/ib_python/runner/venv/lib/python3.7/site-packages/grpc/_channel.py", line 506, in _end_unary_response_blocking
    raise _Rendezvous(state, None, None, deadline)
grpc._channel._Rendezvous: <_Rendezvous of RPC that terminated with:
	status = StatusCode.UNAVAILABLE
	details = "failed to connect to all addresses"
	debug_error_string = "{"created":"@1581094134.554874000","description":"Failed to pick subchannel","file":"src/core/ext/filters/client_channel/client_channel.cc","file_line":3876,"referenced_errors":[{"created":"@1581094099.927044000","description":"failed to connect to all addresses","file":"src/core/ext/filters/client_channel/lb_policy/pick_first/pick_first.cc","file_line":395,"grpc_status":14}]}"
>
2020-02-07 16:48:54,555 INFO download_runner.impl.historical_runner:32 sending - historical data request : AGBAU 2019-01-01 2020-01-01
2020-02-07 16:49:00,605 INFO download_runner.impl.historical_runner:35 sent - historical data request : AGBAU 2019-01-01 2020-01-01
2020-02-07 16:49:00,605 DEBUG download_runner.impl.historical_runner:36 request accounted for...
2020-02-07 16:49:00,606 INFO download_runner.impl.historical_runner:37 status : True
2020-02-07 16:49:00,606 INFO download_runner.impl.historical_runner:42 Historical data request sent : AGBAU 2019-01-01 2020-01-01
2020-02-07 16:49:00,606 DEBUG download_runner.impl.historical_end_reader:37 poll stock ? => True
2020-02-07 16:49:00,607 ERROR root:30 unhandled exception getting latest timestamp for AGCO
Traceback (most recent call last):
  File "/Users/dali/workspace/ib_python/runner/services/historical_data_service.py", line 24, in get_latest_timestamp
    response = self.stub.GetLatestTimeStamp(request)
  File "/Users/dali/workspace/ib_python/runner/venv/lib/python3.7/site-packages/grpc/_channel.py", line 604, in __call__
    return _end_unary_response_blocking(state, call, False, None)
  File "/Users/dali/workspace/ib_python/runner/venv/lib/python3.7/site-packages/grpc/_channel.py", line 506, in _end_unary_response_blocking
    raise _Rendezvous(state, None, None, deadline)
grpc._channel._Rendezvous: <_Rendezvous of RPC that terminated with:
	status = StatusCode.UNAVAILABLE
	details = "failed to connect to all addresses"
	debug_error_string = "{"created":"@1581094140.607345000","description":"Failed to pick subchannel","file":"src/core/ext/filters/client_channel/client_channel.cc","file_line":3876,"referenced_errors":[{"created":"@1581094099.927044000","description":"failed to connect to all addresses","file":"src/core/ext/filters/client_channel/lb_policy/pick_first/pick_first.cc","file_line":395,"grpc_status":14}]}"
>
2020-02-07 16:49:00,607 INFO download_runner.impl.historical_runner:32 sending - historical data request : AGCO 2019-01-01 2020-01-01
2020-02-07 16:49:12,932 INFO download_runner.impl.historical_runner:35 sent - historical data request : AGCO 2019-01-01 2020-01-01
2020-02-07 16:49:12,933 DEBUG download_runner.impl.historical_runner:36 request accounted for...
2020-02-07 16:49:12,934 INFO download_runner.impl.historical_runner:37 status : True
2020-02-07 16:49:12,934 INFO download_runner.impl.historical_runner:42 Historical data request sent : AGCO 2019-01-01 2020-01-01
2020-02-07 16:49:12,934 DEBUG download_runner.impl.historical_end_reader:37 poll stock ? => True
2020-02-07 16:49:12,934 ERROR root:30 unhandled exception getting latest timestamp for AGD
Traceback (most recent call last):
  File "/Users/dali/workspace/ib_python/runner/services/historical_data_service.py", line 24, in get_latest_timestamp
    response = self.stub.GetLatestTimeStamp(request)
  File "/Users/dali/workspace/ib_python/runner/venv/lib/python3.7/site-packages/grpc/_channel.py", line 604, in __call__
    return _end_unary_response_blocking(state, call, False, None)
  File "/Users/dali/workspace/ib_python/runner/venv/lib/python3.7/site-packages/grpc/_channel.py", line 506, in _end_unary_response_blocking
    raise _Rendezvous(state, None, None, deadline)
grpc._channel._Rendezvous: <_Rendezvous of RPC that terminated with:
	status = StatusCode.UNAVAILABLE
	details = "failed to connect to all addresses"
	debug_error_string = "{"created":"@1581094152.934560000","description":"Failed to pick subchannel","file":"src/core/ext/filters/client_channel/client_channel.cc","file_line":3876,"referenced_errors":[{"created":"@1581094099.927044000","description":"failed to connect to all addresses","file":"src/core/ext/filters/client_channel/lb_policy/pick_first/pick_first.cc","file_line":395,"grpc_status":14}]}"
>
2020-02-07 16:49:12,935 INFO download_runner.impl.historical_runner:32 sending - historical data request : AGD 2019-01-01 2020-01-01
2020-02-07 16:49:30,583 INFO download_runner.impl.historical_runner:35 sent - historical data request : AGD 2019-01-01 2020-01-01
2020-02-07 16:49:30,584 DEBUG download_runner.impl.historical_runner:36 request accounted for...
2020-02-07 16:49:30,585 INFO download_runner.impl.historical_runner:37 status : True
2020-02-07 16:49:30,585 INFO download_runner.impl.historical_runner:42 Historical data request sent : AGD 2019-01-01 2020-01-01
2020-02-07 16:49:30,585 DEBUG download_runner.impl.historical_end_reader:37 poll stock ? => True
2020-02-07 16:49:30,585 ERROR root:30 unhandled exception getting latest timestamp for AGE
Traceback (most recent call last):
  File "/Users/dali/workspace/ib_python/runner/services/historical_data_service.py", line 24, in get_latest_timestamp
    response = self.stub.GetLatestTimeStamp(request)
  File "/Users/dali/workspace/ib_python/runner/venv/lib/python3.7/site-packages/grpc/_channel.py", line 604, in __call__
    return _end_unary_response_blocking(state, call, False, None)
  File "/Users/dali/workspace/ib_python/runner/venv/lib/python3.7/site-packages/grpc/_channel.py", line 506, in _end_unary_response_blocking
    raise _Rendezvous(state, None, None, deadline)
grpc._channel._Rendezvous: <_Rendezvous of RPC that terminated with:
	status = StatusCode.UNAVAILABLE
	details = "failed to connect to all addresses"
	debug_error_string = "{"created":"@1581094170.585406000","description":"Failed to pick subchannel","file":"src/core/ext/filters/client_channel/client_channel.cc","file_line":3876,"referenced_errors":[{"created":"@1581094169.966891000","description":"failed to connect to all addresses","file":"src/core/ext/filters/client_channel/lb_policy/pick_first/pick_first.cc","file_line":395,"grpc_status":14}]}"
>
2020-02-07 16:49:30,585 INFO download_runner.impl.historical_runner:32 sending - historical data request : AGE 2019-01-01 2020-01-01
2020-02-07 16:49:31,633 INFO download_runner.impl.historical_runner:35 sent - historical data request : AGE 2019-01-01 2020-01-01
2020-02-07 16:49:31,634 DEBUG download_runner.impl.historical_runner:36 request accounted for...
2020-02-07 16:49:31,634 INFO download_runner.impl.historical_runner:37 status : True
2020-02-07 16:49:31,634 INFO download_runner.impl.historical_runner:42 Historical data request sent : AGE 2019-01-01 2020-01-01
2020-02-07 16:49:31,634 DEBUG download_runner.impl.historical_end_reader:37 poll stock ? => True
2020-02-07 16:49:31,634 ERROR root:30 unhandled exception getting latest timestamp for AGEN
Traceback (most recent call last):
  File "/Users/dali/workspace/ib_python/runner/services/historical_data_service.py", line 24, in get_latest_timestamp
    response = self.stub.GetLatestTimeStamp(request)
  File "/Users/dali/workspace/ib_python/runner/venv/lib/python3.7/site-packages/grpc/_channel.py", line 604, in __call__
    return _end_unary_response_blocking(state, call, False, None)
  File "/Users/dali/workspace/ib_python/runner/venv/lib/python3.7/site-packages/grpc/_channel.py", line 506, in _end_unary_response_blocking
    raise _Rendezvous(state, None, None, deadline)
grpc._channel._Rendezvous: <_Rendezvous of RPC that terminated with:
	status = StatusCode.UNAVAILABLE
	details = "failed to connect to all addresses"
	debug_error_string = "{"created":"@1581094171.634384000","description":"Failed to pick subchannel","file":"src/core/ext/filters/client_channel/client_channel.cc","file_line":3876,"referenced_errors":[{"created":"@1581094169.966891000","description":"failed to connect to all addresses","file":"src/core/ext/filters/client_channel/lb_policy/pick_first/pick_first.cc","file_line":395,"grpc_status":14}]}"
>
2020-02-07 16:49:31,634 INFO download_runner.impl.historical_runner:32 sending - historical data request : AGEN 2019-01-01 2020-01-01
2020-02-07 16:49:32,573 INFO download_runner.impl.historical_runner:35 sent - historical data request : AGEN 2019-01-01 2020-01-01
2020-02-07 16:49:32,573 DEBUG download_runner.impl.historical_runner:36 request accounted for...
2020-02-07 16:49:32,573 INFO download_runner.impl.historical_runner:37 status : True
2020-02-07 16:49:32,573 INFO download_runner.impl.historical_runner:42 Historical data request sent : AGEN 2019-01-01 2020-01-01
2020-02-07 16:49:32,573 DEBUG download_runner.impl.historical_end_reader:37 poll stock ? => True
2020-02-07 16:49:32,573 ERROR root:30 unhandled exception getting latest timestamp for AGFS
Traceback (most recent call last):
  File "/Users/dali/workspace/ib_python/runner/services/historical_data_service.py", line 24, in get_latest_timestamp
    response = self.stub.GetLatestTimeStamp(request)
  File "/Users/dali/workspace/ib_python/runner/venv/lib/python3.7/site-packages/grpc/_channel.py", line 604, in __call__
    return _end_unary_response_blocking(state, call, False, None)
  File "/Users/dali/workspace/ib_python/runner/venv/lib/python3.7/site-packages/grpc/_channel.py", line 506, in _end_unary_response_blocking
    raise _Rendezvous(state, None, None, deadline)
grpc._channel._Rendezvous: <_Rendezvous of RPC that terminated with:
	status = StatusCode.UNAVAILABLE
	details = "failed to connect to all addresses"
	debug_error_string = "{"created":"@1581094172.573693000","description":"Failed to pick subchannel","file":"src/core/ext/filters/client_channel/client_channel.cc","file_line":3876,"referenced_errors":[{"created":"@1581094169.966891000","description":"failed to connect to all addresses","file":"src/core/ext/filters/client_channel/lb_policy/pick_first/pick_first.cc","file_line":395,"grpc_status":14}]}"
>
2020-02-07 16:49:32,574 INFO download_runner.impl.historical_runner:32 sending - historical data request : AGFS 2019-01-01 2020-01-01
2020-02-07 16:49:33,328 INFO download_runner.impl.historical_runner:35 sent - historical data request : AGFS 2019-01-01 2020-01-01
2020-02-07 16:49:33,329 DEBUG download_runner.impl.historical_runner:36 request accounted for...
2020-02-07 16:49:33,329 INFO download_runner.impl.historical_runner:37 status : True
2020-02-07 16:49:33,329 INFO download_runner.impl.historical_runner:42 Historical data request sent : AGFS 2019-01-01 2020-01-01
2020-02-07 16:49:33,329 DEBUG download_runner.impl.historical_end_reader:37 poll stock ? => True
2020-02-07 16:49:33,329 ERROR root:30 unhandled exception getting latest timestamp for AGG
Traceback (most recent call last):
  File "/Users/dali/workspace/ib_python/runner/services/historical_data_service.py", line 24, in get_latest_timestamp
    response = self.stub.GetLatestTimeStamp(request)
  File "/Users/dali/workspace/ib_python/runner/venv/lib/python3.7/site-packages/grpc/_channel.py", line 604, in __call__
    return _end_unary_response_blocking(state, call, False, None)
  File "/Users/dali/workspace/ib_python/runner/venv/lib/python3.7/site-packages/grpc/_channel.py", line 506, in _end_unary_response_blocking
    raise _Rendezvous(state, None, None, deadline)
grpc._channel._Rendezvous: <_Rendezvous of RPC that terminated with:
	status = StatusCode.UNAVAILABLE
	details = "failed to connect to all addresses"
	debug_error_string = "{"created":"@1581094173.329438000","description":"Failed to pick subchannel","file":"src/core/ext/filters/client_channel/client_channel.cc","file_line":3876,"referenced_errors":[{"created":"@1581094169.966891000","description":"failed to connect to all addresses","file":"src/core/ext/filters/client_channel/lb_policy/pick_first/pick_first.cc","file_line":395,"grpc_status":14}]}"
>
2020-02-07 16:49:33,329 INFO download_runner.impl.historical_runner:32 sending - historical data request : AGG 2019-01-01 2020-01-01
2020-02-07 16:49:37,011 INFO download_runner.impl.historical_runner:35 sent - historical data request : AGG 2019-01-01 2020-01-01
2020-02-07 16:49:37,011 DEBUG download_runner.impl.historical_runner:36 request accounted for...
2020-02-07 16:49:37,011 INFO download_runner.impl.historical_runner:37 status : True
2020-02-07 16:49:37,011 INFO download_runner.impl.historical_runner:42 Historical data request sent : AGG 2019-01-01 2020-01-01
2020-02-07 16:49:37,011 DEBUG download_runner.impl.historical_end_reader:37 poll stock ? => True
2020-02-07 16:49:37,011 ERROR root:30 unhandled exception getting latest timestamp for AGGE
Traceback (most recent call last):
  File "/Users/dali/workspace/ib_python/runner/services/historical_data_service.py", line 24, in get_latest_timestamp
    response = self.stub.GetLatestTimeStamp(request)
  File "/Users/dali/workspace/ib_python/runner/venv/lib/python3.7/site-packages/grpc/_channel.py", line 604, in __call__
    return _end_unary_response_blocking(state, call, False, None)
  File "/Users/dali/workspace/ib_python/runner/venv/lib/python3.7/site-packages/grpc/_channel.py", line 506, in _end_unary_response_blocking
    raise _Rendezvous(state, None, None, deadline)
grpc._channel._Rendezvous: <_Rendezvous of RPC that terminated with:
	status = StatusCode.UNAVAILABLE
	details = "failed to connect to all addresses"
	debug_error_string = "{"created":"@1581094177.011734000","description":"Failed to pick subchannel","file":"src/core/ext/filters/client_channel/client_channel.cc","file_line":3876,"referenced_errors":[{"created":"@1581094169.966891000","description":"failed to connect to all addresses","file":"src/core/ext/filters/client_channel/lb_policy/pick_first/pick_first.cc","file_line":395,"grpc_status":14}]}"
>
2020-02-07 16:49:37,012 INFO download_runner.impl.historical_runner:32 sending - historical data request : AGGE 2019-01-01 2020-01-01
2020-02-07 16:49:37,337 INFO download_runner.impl.historical_runner:35 sent - historical data request : AGGE 2019-01-01 2020-01-01
2020-02-07 16:49:37,337 DEBUG download_runner.impl.historical_runner:36 request accounted for...
2020-02-07 16:49:37,338 INFO download_runner.impl.historical_runner:37 status : True
2020-02-07 16:49:37,338 INFO download_runner.impl.historical_runner:42 Historical data request sent : AGGE 2019-01-01 2020-01-01
2020-02-07 16:49:37,338 DEBUG download_runner.impl.historical_end_reader:37 poll stock ? => True
2020-02-07 16:49:37,338 ERROR root:30 unhandled exception getting latest timestamp for AGGP
Traceback (most recent call last):
  File "/Users/dali/workspace/ib_python/runner/services/historical_data_service.py", line 24, in get_latest_timestamp
    response = self.stub.GetLatestTimeStamp(request)
  File "/Users/dali/workspace/ib_python/runner/venv/lib/python3.7/site-packages/grpc/_channel.py", line 604, in __call__
    return _end_unary_response_blocking(state, call, False, None)
  File "/Users/dali/workspace/ib_python/runner/venv/lib/python3.7/site-packages/grpc/_channel.py", line 506, in _end_unary_response_blocking
    raise _Rendezvous(state, None, None, deadline)
grpc._channel._Rendezvous: <_Rendezvous of RPC that terminated with:
	status = StatusCode.UNAVAILABLE
	details = "failed to connect to all addresses"
	debug_error_string = "{"created":"@1581094177.338290000","description":"Failed to pick subchannel","file":"src/core/ext/filters/client_channel/client_channel.cc","file_line":3876,"referenced_errors":[{"created":"@1581094169.966891000","description":"failed to connect to all addresses","file":"src/core/ext/filters/client_channel/lb_policy/pick_first/pick_first.cc","file_line":395,"grpc_status":14}]}"
>
2020-02-07 16:49:37,338 INFO download_runner.impl.historical_runner:32 sending - historical data request : AGGP 2019-01-01 2020-01-01
2020-02-07 16:49:38,266 INFO download_runner.impl.historical_runner:35 sent - historical data request : AGGP 2019-01-01 2020-01-01
2020-02-07 16:49:38,266 DEBUG download_runner.impl.historical_runner:36 request accounted for...
2020-02-07 16:49:38,266 INFO download_runner.impl.historical_runner:37 status : True
2020-02-07 16:49:38,266 INFO download_runner.impl.historical_runner:42 Historical data request sent : AGGP 2019-01-01 2020-01-01
2020-02-07 16:49:38,266 DEBUG download_runner.impl.historical_end_reader:37 poll stock ? => True
2020-02-07 16:49:38,266 ERROR root:30 unhandled exception getting latest timestamp for AGGY
Traceback (most recent call last):
  File "/Users/dali/workspace/ib_python/runner/services/historical_data_service.py", line 24, in get_latest_timestamp
    response = self.stub.GetLatestTimeStamp(request)
  File "/Users/dali/workspace/ib_python/runner/venv/lib/python3.7/site-packages/grpc/_channel.py", line 604, in __call__
    return _end_unary_response_blocking(state, call, False, None)
  File "/Users/dali/workspace/ib_python/runner/venv/lib/python3.7/site-packages/grpc/_channel.py", line 506, in _end_unary_response_blocking
    raise _Rendezvous(state, None, None, deadline)
grpc._channel._Rendezvous: <_Rendezvous of RPC that terminated with:
	status = StatusCode.UNAVAILABLE
	details = "failed to connect to all addresses"
	debug_error_string = "{"created":"@1581094178.266535000","description":"Failed to pick subchannel","file":"src/core/ext/filters/client_channel/client_channel.cc","file_line":3876,"referenced_errors":[{"created":"@1581094169.966891000","description":"failed to connect to all addresses","file":"src/core/ext/filters/client_channel/lb_policy/pick_first/pick_first.cc","file_line":395,"grpc_status":14}]}"
>
2020-02-07 16:49:38,266 INFO download_runner.impl.historical_runner:32 sending - historical data request : AGGY 2019-01-01 2020-01-01
2020-02-07 16:49:42,764 INFO download_runner.impl.historical_runner:35 sent - historical data request : AGGY 2019-01-01 2020-01-01
2020-02-07 16:49:42,764 DEBUG download_runner.impl.historical_runner:36 request accounted for...
2020-02-07 16:49:42,764 INFO download_runner.impl.historical_runner:37 status : True
2020-02-07 16:49:42,764 INFO download_runner.impl.historical_runner:42 Historical data request sent : AGGY 2019-01-01 2020-01-01
2020-02-07 16:49:42,764 DEBUG download_runner.impl.historical_end_reader:37 poll stock ? => True
2020-02-07 16:49:42,764 ERROR root:30 unhandled exception getting latest timestamp for AGI
Traceback (most recent call last):
  File "/Users/dali/workspace/ib_python/runner/services/historical_data_service.py", line 24, in get_latest_timestamp
    response = self.stub.GetLatestTimeStamp(request)
  File "/Users/dali/workspace/ib_python/runner/venv/lib/python3.7/site-packages/grpc/_channel.py", line 604, in __call__
    return _end_unary_response_blocking(state, call, False, None)
  File "/Users/dali/workspace/ib_python/runner/venv/lib/python3.7/site-packages/grpc/_channel.py", line 506, in _end_unary_response_blocking
    raise _Rendezvous(state, None, None, deadline)
grpc._channel._Rendezvous: <_Rendezvous of RPC that terminated with:
	status = StatusCode.UNAVAILABLE
	details = "failed to connect to all addresses"
	debug_error_string = "{"created":"@1581094182.764916000","description":"Failed to pick subchannel","file":"src/core/ext/filters/client_channel/client_channel.cc","file_line":3876,"referenced_errors":[{"created":"@1581094169.966891000","description":"failed to connect to all addresses","file":"src/core/ext/filters/client_channel/lb_policy/pick_first/pick_first.cc","file_line":395,"grpc_status":14}]}"
>
2020-02-07 16:49:42,765 INFO download_runner.impl.historical_runner:32 sending - historical data request : AGI 2019-01-01 2020-01-01
2020-02-07 16:49:43,560 INFO download_runner.impl.historical_runner:35 sent - historical data request : AGI 2019-01-01 2020-01-01
2020-02-07 16:49:43,560 DEBUG download_runner.impl.historical_runner:36 request accounted for...
2020-02-07 16:49:43,560 INFO download_runner.impl.historical_runner:37 status : True
2020-02-07 16:49:43,560 INFO download_runner.impl.historical_runner:42 Historical data request sent : AGI 2019-01-01 2020-01-01
2020-02-07 16:49:43,560 DEBUG download_runner.impl.historical_end_reader:37 poll stock ? => True
2020-02-07 16:49:43,560 ERROR root:30 unhandled exception getting latest timestamp for AGIO
Traceback (most recent call last):
  File "/Users/dali/workspace/ib_python/runner/services/historical_data_service.py", line 24, in get_latest_timestamp
    response = self.stub.GetLatestTimeStamp(request)
  File "/Users/dali/workspace/ib_python/runner/venv/lib/python3.7/site-packages/grpc/_channel.py", line 604, in __call__
    return _end_unary_response_blocking(state, call, False, None)
  File "/Users/dali/workspace/ib_python/runner/venv/lib/python3.7/site-packages/grpc/_channel.py", line 506, in _end_unary_response_blocking
    raise _Rendezvous(state, None, None, deadline)
grpc._channel._Rendezvous: <_Rendezvous of RPC that terminated with:
	status = StatusCode.UNAVAILABLE
	details = "failed to connect to all addresses"
	debug_error_string = "{"created":"@1581094183.560757000","description":"Failed to pick subchannel","file":"src/core/ext/filters/client_channel/client_channel.cc","file_line":3876,"referenced_errors":[{"created":"@1581094169.966891000","description":"failed to connect to all addresses","file":"src/core/ext/filters/client_channel/lb_policy/pick_first/pick_first.cc","file_line":395,"grpc_status":14}]}"
>
2020-02-07 16:49:43,561 INFO download_runner.impl.historical_runner:32 sending - historical data request : AGIO 2019-01-01 2020-01-01
2020-02-07 16:49:48,978 INFO download_runner.impl.historical_runner:35 sent - historical data request : AGIO 2019-01-01 2020-01-01
2020-02-07 16:49:48,978 DEBUG download_runner.impl.historical_runner:36 request accounted for...
2020-02-07 16:49:48,978 INFO download_runner.impl.historical_runner:37 status : True
2020-02-07 16:49:48,978 INFO download_runner.impl.historical_runner:42 Historical data request sent : AGIO 2019-01-01 2020-01-01
2020-02-07 16:49:48,978 DEBUG download_runner.impl.historical_end_reader:37 poll stock ? => True
2020-02-07 16:49:48,978 ERROR root:30 unhandled exception getting latest timestamp for AGLE
Traceback (most recent call last):
  File "/Users/dali/workspace/ib_python/runner/services/historical_data_service.py", line 24, in get_latest_timestamp
    response = self.stub.GetLatestTimeStamp(request)
  File "/Users/dali/workspace/ib_python/runner/venv/lib/python3.7/site-packages/grpc/_channel.py", line 604, in __call__
    return _end_unary_response_blocking(state, call, False, None)
  File "/Users/dali/workspace/ib_python/runner/venv/lib/python3.7/site-packages/grpc/_channel.py", line 506, in _end_unary_response_blocking
    raise _Rendezvous(state, None, None, deadline)
grpc._channel._Rendezvous: <_Rendezvous of RPC that terminated with:
	status = StatusCode.UNAVAILABLE
	details = "failed to connect to all addresses"
	debug_error_string = "{"created":"@1581094188.978496000","description":"Failed to pick subchannel","file":"src/core/ext/filters/client_channel/client_channel.cc","file_line":3876,"referenced_errors":[{"created":"@1581094169.966891000","description":"failed to connect to all addresses","file":"src/core/ext/filters/client_channel/lb_policy/pick_first/pick_first.cc","file_line":395,"grpc_status":14}]}"
>
2020-02-07 16:49:48,978 INFO download_runner.impl.historical_runner:32 sending - historical data request : AGLE 2019-01-01 2020-01-01
