2020-02-07 17:11:47,122 DEBUG download_runner.impl.historical_end_reader:37 poll stock ? => True
2020-02-07 17:11:47,320 ERROR root:30 unhandled exception getting latest timestamp for A
Traceback (most recent call last):
  File "/Users/dali/workspace/ib_python/runner/services/historical_data_service.py", line 24, in get_latest_timestamp
    response = self.stub.GetLatestTimeStamp(request)
  File "/Users/dali/workspace/ib_python/runner/venv/lib/python3.7/site-packages/grpc/_channel.py", line 604, in __call__
    return _end_unary_response_blocking(state, call, False, None)
  File "/Users/dali/workspace/ib_python/runner/venv/lib/python3.7/site-packages/grpc/_channel.py", line 506, in _end_unary_response_blocking
    raise _Rendezvous(state, None, None, deadline)
grpc._channel._Rendezvous: <_Rendezvous of RPC that terminated with:
	status = StatusCode.UNAVAILABLE
	details = "failed to connect to all addresses"
	debug_error_string = "{"created":"@1581095507.320417000","description":"Failed to pick subchannel","file":"src/core/ext/filters/client_channel/client_channel.cc","file_line":3876,"referenced_errors":[{"created":"@1581095507.320416000","description":"failed to connect to all addresses","file":"src/core/ext/filters/client_channel/lb_policy/pick_first/pick_first.cc","file_line":395,"grpc_status":14}]}"
>
2020-02-07 17:11:47,322 INFO download_runner.impl.historical_runner:32 sending - historical data request : A 2019-01-01 2020-01-01
2020-02-07 17:11:47,651 INFO download_runner.impl.historical_runner:35 sent - historical data request : A 2019-01-01 2020-01-01
2020-02-07 17:11:47,651 DEBUG download_runner.impl.historical_runner:36 request accounted for...
2020-02-07 17:11:47,651 INFO download_runner.impl.historical_runner:37 status : True
2020-02-07 17:11:47,651 INFO download_runner.impl.historical_runner:42 Historical data request sent : A 2019-01-01 2020-01-01
2020-02-07 17:11:47,651 DEBUG download_runner.impl.historical_end_reader:37 poll stock ? => True
2020-02-07 17:11:47,652 ERROR root:30 unhandled exception getting latest timestamp for ACIA
Traceback (most recent call last):
  File "/Users/dali/workspace/ib_python/runner/services/historical_data_service.py", line 24, in get_latest_timestamp
    response = self.stub.GetLatestTimeStamp(request)
  File "/Users/dali/workspace/ib_python/runner/venv/lib/python3.7/site-packages/grpc/_channel.py", line 604, in __call__
    return _end_unary_response_blocking(state, call, False, None)
  File "/Users/dali/workspace/ib_python/runner/venv/lib/python3.7/site-packages/grpc/_channel.py", line 506, in _end_unary_response_blocking
    raise _Rendezvous(state, None, None, deadline)
grpc._channel._Rendezvous: <_Rendezvous of RPC that terminated with:
	status = StatusCode.UNAVAILABLE
	details = "failed to connect to all addresses"
	debug_error_string = "{"created":"@1581095507.652087000","description":"Failed to pick subchannel","file":"src/core/ext/filters/client_channel/client_channel.cc","file_line":3876,"referenced_errors":[{"created":"@1581095507.320416000","description":"failed to connect to all addresses","file":"src/core/ext/filters/client_channel/lb_policy/pick_first/pick_first.cc","file_line":395,"grpc_status":14}]}"
>
2020-02-07 17:11:47,652 INFO download_runner.impl.historical_runner:32 sending - historical data request : ACIA 2019-01-01 2020-01-01
2020-02-07 17:11:48,108 INFO download_runner.impl.historical_runner:35 sent - historical data request : ACIA 2019-01-01 2020-01-01
2020-02-07 17:11:48,108 DEBUG download_runner.impl.historical_runner:36 request accounted for...
2020-02-07 17:11:48,108 INFO download_runner.impl.historical_runner:37 status : True
2020-02-07 17:11:48,108 INFO download_runner.impl.historical_runner:42 Historical data request sent : ACIA 2019-01-01 2020-01-01
2020-02-07 17:11:48,108 DEBUG download_runner.impl.historical_end_reader:37 poll stock ? => True
2020-02-07 17:11:48,108 ERROR root:30 unhandled exception getting latest timestamp for ACIO
Traceback (most recent call last):
  File "/Users/dali/workspace/ib_python/runner/services/historical_data_service.py", line 24, in get_latest_timestamp
    response = self.stub.GetLatestTimeStamp(request)
  File "/Users/dali/workspace/ib_python/runner/venv/lib/python3.7/site-packages/grpc/_channel.py", line 604, in __call__
    return _end_unary_response_blocking(state, call, False, None)
  File "/Users/dali/workspace/ib_python/runner/venv/lib/python3.7/site-packages/grpc/_channel.py", line 506, in _end_unary_response_blocking
    raise _Rendezvous(state, None, None, deadline)
grpc._channel._Rendezvous: <_Rendezvous of RPC that terminated with:
	status = StatusCode.UNAVAILABLE
	details = "failed to connect to all addresses"
	debug_error_string = "{"created":"@1581095508.108763000","description":"Failed to pick subchannel","file":"src/core/ext/filters/client_channel/client_channel.cc","file_line":3876,"referenced_errors":[{"created":"@1581095507.320416000","description":"failed to connect to all addresses","file":"src/core/ext/filters/client_channel/lb_policy/pick_first/pick_first.cc","file_line":395,"grpc_status":14}]}"
>
2020-02-07 17:11:48,109 INFO download_runner.impl.historical_runner:32 sending - historical data request : ACIO 2019-01-01 2020-01-01
2020-02-07 17:11:48,511 INFO download_runner.impl.historical_runner:35 sent - historical data request : ACIO 2019-01-01 2020-01-01
2020-02-07 17:11:48,511 DEBUG download_runner.impl.historical_runner:36 request accounted for...
2020-02-07 17:11:48,511 INFO download_runner.impl.historical_runner:37 status : True
2020-02-07 17:11:48,512 INFO download_runner.impl.historical_runner:42 Historical data request sent : ACIO 2019-01-01 2020-01-01
2020-02-07 17:11:48,512 DEBUG download_runner.impl.historical_end_reader:37 poll stock ? => True
2020-02-07 17:11:48,512 ERROR root:30 unhandled exception getting latest timestamp for ACIU
Traceback (most recent call last):
  File "/Users/dali/workspace/ib_python/runner/services/historical_data_service.py", line 24, in get_latest_timestamp
    response = self.stub.GetLatestTimeStamp(request)
  File "/Users/dali/workspace/ib_python/runner/venv/lib/python3.7/site-packages/grpc/_channel.py", line 604, in __call__
    return _end_unary_response_blocking(state, call, False, None)
  File "/Users/dali/workspace/ib_python/runner/venv/lib/python3.7/site-packages/grpc/_channel.py", line 506, in _end_unary_response_blocking
    raise _Rendezvous(state, None, None, deadline)
grpc._channel._Rendezvous: <_Rendezvous of RPC that terminated with:
	status = StatusCode.UNAVAILABLE
	details = "failed to connect to all addresses"
	debug_error_string = "{"created":"@1581095508.512372000","description":"Failed to pick subchannel","file":"src/core/ext/filters/client_channel/client_channel.cc","file_line":3876,"referenced_errors":[{"created":"@1581095508.512370000","description":"failed to connect to all addresses","file":"src/core/ext/filters/client_channel/lb_policy/pick_first/pick_first.cc","file_line":395,"grpc_status":14}]}"
>
2020-02-07 17:11:48,512 INFO download_runner.impl.historical_runner:32 sending - historical data request : ACIU 2019-01-01 2020-01-01
2020-02-07 17:11:49,068 INFO download_runner.impl.historical_runner:35 sent - historical data request : ACIU 2019-01-01 2020-01-01
2020-02-07 17:11:49,068 DEBUG download_runner.impl.historical_runner:36 request accounted for...
2020-02-07 17:11:49,068 INFO download_runner.impl.historical_runner:37 status : True
2020-02-07 17:11:49,068 INFO download_runner.impl.historical_runner:42 Historical data request sent : ACIU 2019-01-01 2020-01-01
2020-02-07 17:11:49,068 DEBUG download_runner.impl.historical_end_reader:37 poll stock ? => True
2020-02-07 17:11:49,068 ERROR root:30 unhandled exception getting latest timestamp for ACIW
Traceback (most recent call last):
  File "/Users/dali/workspace/ib_python/runner/services/historical_data_service.py", line 24, in get_latest_timestamp
    response = self.stub.GetLatestTimeStamp(request)
  File "/Users/dali/workspace/ib_python/runner/venv/lib/python3.7/site-packages/grpc/_channel.py", line 604, in __call__
    return _end_unary_response_blocking(state, call, False, None)
  File "/Users/dali/workspace/ib_python/runner/venv/lib/python3.7/site-packages/grpc/_channel.py", line 506, in _end_unary_response_blocking
    raise _Rendezvous(state, None, None, deadline)
grpc._channel._Rendezvous: <_Rendezvous of RPC that terminated with:
	status = StatusCode.UNAVAILABLE
	details = "failed to connect to all addresses"
	debug_error_string = "{"created":"@1581095509.068715000","description":"Failed to pick subchannel","file":"src/core/ext/filters/client_channel/client_channel.cc","file_line":3876,"referenced_errors":[{"created":"@1581095508.512370000","description":"failed to connect to all addresses","file":"src/core/ext/filters/client_channel/lb_policy/pick_first/pick_first.cc","file_line":395,"grpc_status":14}]}"
>
2020-02-07 17:11:49,069 INFO download_runner.impl.historical_runner:32 sending - historical data request : ACIW 2019-01-01 2020-01-01
2020-02-07 17:11:49,631 INFO download_runner.impl.historical_runner:35 sent - historical data request : ACIW 2019-01-01 2020-01-01
2020-02-07 17:11:49,631 DEBUG download_runner.impl.historical_runner:36 request accounted for...
2020-02-07 17:11:49,631 INFO download_runner.impl.historical_runner:37 status : True
2020-02-07 17:11:49,631 INFO download_runner.impl.historical_runner:42 Historical data request sent : ACIW 2019-01-01 2020-01-01
2020-02-07 17:11:49,631 DEBUG download_runner.impl.historical_end_reader:37 poll stock ? => True
2020-02-07 17:11:49,632 ERROR root:30 unhandled exception getting latest timestamp for ACLS
Traceback (most recent call last):
  File "/Users/dali/workspace/ib_python/runner/services/historical_data_service.py", line 24, in get_latest_timestamp
    response = self.stub.GetLatestTimeStamp(request)
  File "/Users/dali/workspace/ib_python/runner/venv/lib/python3.7/site-packages/grpc/_channel.py", line 604, in __call__
    return _end_unary_response_blocking(state, call, False, None)
  File "/Users/dali/workspace/ib_python/runner/venv/lib/python3.7/site-packages/grpc/_channel.py", line 506, in _end_unary_response_blocking
    raise _Rendezvous(state, None, None, deadline)
grpc._channel._Rendezvous: <_Rendezvous of RPC that terminated with:
	status = StatusCode.UNAVAILABLE
	details = "failed to connect to all addresses"
	debug_error_string = "{"created":"@1581095509.632055000","description":"Failed to pick subchannel","file":"src/core/ext/filters/client_channel/client_channel.cc","file_line":3876,"referenced_errors":[{"created":"@1581095508.512370000","description":"failed to connect to all addresses","file":"src/core/ext/filters/client_channel/lb_policy/pick_first/pick_first.cc","file_line":395,"grpc_status":14}]}"
>
2020-02-07 17:11:49,632 INFO download_runner.impl.historical_runner:32 sending - historical data request : ACLS 2019-01-01 2020-01-01
2020-02-07 17:11:53,981 INFO download_runner.impl.historical_runner:35 sent - historical data request : ACLS 2019-01-01 2020-01-01
2020-02-07 17:11:53,981 DEBUG download_runner.impl.historical_runner:36 request accounted for...
2020-02-07 17:11:53,981 INFO download_runner.impl.historical_runner:37 status : True
2020-02-07 17:11:53,981 INFO download_runner.impl.historical_runner:42 Historical data request sent : ACLS 2019-01-01 2020-01-01
2020-02-07 17:11:53,981 DEBUG download_runner.impl.historical_end_reader:37 poll stock ? => True
2020-02-07 17:11:53,982 ERROR root:30 unhandled exception getting latest timestamp for ACM
Traceback (most recent call last):
  File "/Users/dali/workspace/ib_python/runner/services/historical_data_service.py", line 24, in get_latest_timestamp
    response = self.stub.GetLatestTimeStamp(request)
  File "/Users/dali/workspace/ib_python/runner/venv/lib/python3.7/site-packages/grpc/_channel.py", line 604, in __call__
    return _end_unary_response_blocking(state, call, False, None)
  File "/Users/dali/workspace/ib_python/runner/venv/lib/python3.7/site-packages/grpc/_channel.py", line 506, in _end_unary_response_blocking
    raise _Rendezvous(state, None, None, deadline)
grpc._channel._Rendezvous: <_Rendezvous of RPC that terminated with:
	status = StatusCode.UNAVAILABLE
	details = "failed to connect to all addresses"
	debug_error_string = "{"created":"@1581095513.982203000","description":"Failed to pick subchannel","file":"src/core/ext/filters/client_channel/client_channel.cc","file_line":3876,"referenced_errors":[{"created":"@1581095513.982200000","description":"failed to connect to all addresses","file":"src/core/ext/filters/client_channel/lb_policy/pick_first/pick_first.cc","file_line":395,"grpc_status":14}]}"
>
2020-02-07 17:11:53,982 INFO download_runner.impl.historical_runner:32 sending - historical data request : ACM 2019-01-01 2020-01-01
2020-02-07 17:11:54,169 INFO download_runner.impl.historical_runner:35 sent - historical data request : ACM 2019-01-01 2020-01-01
2020-02-07 17:11:54,169 DEBUG download_runner.impl.historical_runner:36 request accounted for...
2020-02-07 17:11:54,169 INFO download_runner.impl.historical_runner:37 status : True
2020-02-07 17:11:54,169 INFO download_runner.impl.historical_runner:42 Historical data request sent : ACM 2019-01-01 2020-01-01
2020-02-07 17:11:54,169 DEBUG download_runner.impl.historical_end_reader:37 poll stock ? => True
2020-02-07 17:11:54,170 ERROR root:30 unhandled exception getting latest timestamp for ACMR
Traceback (most recent call last):
  File "/Users/dali/workspace/ib_python/runner/services/historical_data_service.py", line 24, in get_latest_timestamp
    response = self.stub.GetLatestTimeStamp(request)
  File "/Users/dali/workspace/ib_python/runner/venv/lib/python3.7/site-packages/grpc/_channel.py", line 604, in __call__
    return _end_unary_response_blocking(state, call, False, None)
  File "/Users/dali/workspace/ib_python/runner/venv/lib/python3.7/site-packages/grpc/_channel.py", line 506, in _end_unary_response_blocking
    raise _Rendezvous(state, None, None, deadline)
grpc._channel._Rendezvous: <_Rendezvous of RPC that terminated with:
	status = StatusCode.UNAVAILABLE
	details = "failed to connect to all addresses"
	debug_error_string = "{"created":"@1581095514.170189000","description":"Failed to pick subchannel","file":"src/core/ext/filters/client_channel/client_channel.cc","file_line":3876,"referenced_errors":[{"created":"@1581095513.982200000","description":"failed to connect to all addresses","file":"src/core/ext/filters/client_channel/lb_policy/pick_first/pick_first.cc","file_line":395,"grpc_status":14}]}"
>
2020-02-07 17:11:54,170 INFO download_runner.impl.historical_runner:32 sending - historical data request : ACMR 2019-01-01 2020-01-01
2020-02-07 17:11:54,782 INFO download_runner.impl.historical_runner:35 sent - historical data request : ACMR 2019-01-01 2020-01-01
2020-02-07 17:11:54,782 DEBUG download_runner.impl.historical_runner:36 request accounted for...
2020-02-07 17:11:54,782 INFO download_runner.impl.historical_runner:37 status : True
2020-02-07 17:11:54,782 INFO download_runner.impl.historical_runner:42 Historical data request sent : ACMR 2019-01-01 2020-01-01
2020-02-07 17:11:54,782 DEBUG download_runner.impl.historical_end_reader:37 poll stock ? => True
2020-02-07 17:11:54,783 ERROR root:30 unhandled exception getting latest timestamp for ACN
Traceback (most recent call last):
  File "/Users/dali/workspace/ib_python/runner/services/historical_data_service.py", line 24, in get_latest_timestamp
    response = self.stub.GetLatestTimeStamp(request)
  File "/Users/dali/workspace/ib_python/runner/venv/lib/python3.7/site-packages/grpc/_channel.py", line 604, in __call__
    return _end_unary_response_blocking(state, call, False, None)
  File "/Users/dali/workspace/ib_python/runner/venv/lib/python3.7/site-packages/grpc/_channel.py", line 506, in _end_unary_response_blocking
    raise _Rendezvous(state, None, None, deadline)
grpc._channel._Rendezvous: <_Rendezvous of RPC that terminated with:
	status = StatusCode.UNAVAILABLE
	details = "failed to connect to all addresses"
	debug_error_string = "{"created":"@1581095514.783137000","description":"Failed to pick subchannel","file":"src/core/ext/filters/client_channel/client_channel.cc","file_line":3876,"referenced_errors":[{"created":"@1581095513.982200000","description":"failed to connect to all addresses","file":"src/core/ext/filters/client_channel/lb_policy/pick_first/pick_first.cc","file_line":395,"grpc_status":14}]}"
>
2020-02-07 17:11:54,783 INFO download_runner.impl.historical_runner:32 sending - historical data request : ACN 2019-01-01 2020-01-01
2020-02-07 17:12:00,441 INFO download_runner.impl.historical_runner:35 sent - historical data request : ACN 2019-01-01 2020-01-01
2020-02-07 17:12:00,442 DEBUG download_runner.impl.historical_runner:36 request accounted for...
2020-02-07 17:12:00,442 INFO download_runner.impl.historical_runner:37 status : True
2020-02-07 17:12:00,442 INFO download_runner.impl.historical_runner:42 Historical data request sent : ACN 2019-01-01 2020-01-01
2020-02-07 17:12:00,442 DEBUG download_runner.impl.historical_end_reader:37 poll stock ? => True
2020-02-07 17:12:00,442 ERROR root:30 unhandled exception getting latest timestamp for ACNB
Traceback (most recent call last):
  File "/Users/dali/workspace/ib_python/runner/services/historical_data_service.py", line 24, in get_latest_timestamp
    response = self.stub.GetLatestTimeStamp(request)
  File "/Users/dali/workspace/ib_python/runner/venv/lib/python3.7/site-packages/grpc/_channel.py", line 604, in __call__
    return _end_unary_response_blocking(state, call, False, None)
  File "/Users/dali/workspace/ib_python/runner/venv/lib/python3.7/site-packages/grpc/_channel.py", line 506, in _end_unary_response_blocking
    raise _Rendezvous(state, None, None, deadline)
grpc._channel._Rendezvous: <_Rendezvous of RPC that terminated with:
	status = StatusCode.UNAVAILABLE
	details = "failed to connect to all addresses"
	debug_error_string = "{"created":"@1581095520.442673000","description":"Failed to pick subchannel","file":"src/core/ext/filters/client_channel/client_channel.cc","file_line":3876,"referenced_errors":[{"created":"@1581095517.128900000","description":"failed to connect to all addresses","file":"src/core/ext/filters/client_channel/lb_policy/pick_first/pick_first.cc","file_line":395,"grpc_status":14}]}"
>
2020-02-07 17:12:00,443 INFO download_runner.impl.historical_runner:32 sending - historical data request : ACNB 2019-01-01 2020-01-01
2020-02-07 17:12:00,993 INFO download_runner.impl.historical_runner:35 sent - historical data request : ACNB 2019-01-01 2020-01-01
2020-02-07 17:12:00,993 DEBUG download_runner.impl.historical_runner:36 request accounted for...
2020-02-07 17:12:00,994 INFO download_runner.impl.historical_runner:37 status : True
2020-02-07 17:12:00,995 INFO download_runner.impl.historical_runner:42 Historical data request sent : ACNB 2019-01-01 2020-01-01
2020-02-07 17:12:00,995 DEBUG download_runner.impl.historical_end_reader:37 poll stock ? => True
2020-02-07 17:12:00,995 ERROR root:30 unhandled exception getting latest timestamp for ACOR
Traceback (most recent call last):
  File "/Users/dali/workspace/ib_python/runner/services/historical_data_service.py", line 24, in get_latest_timestamp
    response = self.stub.GetLatestTimeStamp(request)
  File "/Users/dali/workspace/ib_python/runner/venv/lib/python3.7/site-packages/grpc/_channel.py", line 604, in __call__
    return _end_unary_response_blocking(state, call, False, None)
  File "/Users/dali/workspace/ib_python/runner/venv/lib/python3.7/site-packages/grpc/_channel.py", line 506, in _end_unary_response_blocking
    raise _Rendezvous(state, None, None, deadline)
grpc._channel._Rendezvous: <_Rendezvous of RPC that terminated with:
	status = StatusCode.UNAVAILABLE
	details = "failed to connect to all addresses"
	debug_error_string = "{"created":"@1581095520.995776000","description":"Failed to pick subchannel","file":"src/core/ext/filters/client_channel/client_channel.cc","file_line":3876,"referenced_errors":[{"created":"@1581095517.128900000","description":"failed to connect to all addresses","file":"src/core/ext/filters/client_channel/lb_policy/pick_first/pick_first.cc","file_line":395,"grpc_status":14}]}"
>
2020-02-07 17:12:00,996 INFO download_runner.impl.historical_runner:32 sending - historical data request : ACOR 2019-01-01 2020-01-01
2020-02-07 17:12:06,078 INFO download_runner.impl.historical_runner:35 sent - historical data request : ACOR 2019-01-01 2020-01-01
2020-02-07 17:12:06,079 DEBUG download_runner.impl.historical_runner:36 request accounted for...
2020-02-07 17:12:06,079 INFO download_runner.impl.historical_runner:37 status : True
2020-02-07 17:12:06,079 INFO download_runner.impl.historical_runner:42 Historical data request sent : ACOR 2019-01-01 2020-01-01
2020-02-07 17:12:06,079 DEBUG download_runner.impl.historical_end_reader:37 poll stock ? => True
2020-02-07 17:12:06,079 ERROR root:30 unhandled exception getting latest timestamp for ACP
Traceback (most recent call last):
  File "/Users/dali/workspace/ib_python/runner/services/historical_data_service.py", line 24, in get_latest_timestamp
    response = self.stub.GetLatestTimeStamp(request)
  File "/Users/dali/workspace/ib_python/runner/venv/lib/python3.7/site-packages/grpc/_channel.py", line 604, in __call__
    return _end_unary_response_blocking(state, call, False, None)
  File "/Users/dali/workspace/ib_python/runner/venv/lib/python3.7/site-packages/grpc/_channel.py", line 506, in _end_unary_response_blocking
    raise _Rendezvous(state, None, None, deadline)
grpc._channel._Rendezvous: <_Rendezvous of RPC that terminated with:
	status = StatusCode.UNAVAILABLE
	details = "failed to connect to all addresses"
	debug_error_string = "{"created":"@1581095526.079489000","description":"Failed to pick subchannel","file":"src/core/ext/filters/client_channel/client_channel.cc","file_line":3876,"referenced_errors":[{"created":"@1581095526.079487000","description":"failed to connect to all addresses","file":"src/core/ext/filters/client_channel/lb_policy/pick_first/pick_first.cc","file_line":395,"grpc_status":14}]}"
>
2020-02-07 17:12:06,079 INFO download_runner.impl.historical_runner:32 sending - historical data request : ACP 2019-01-01 2020-01-01
2020-02-07 17:12:06,781 INFO download_runner.impl.historical_runner:35 sent - historical data request : ACP 2019-01-01 2020-01-01
2020-02-07 17:12:06,782 DEBUG download_runner.impl.historical_runner:36 request accounted for...
2020-02-07 17:12:06,782 INFO download_runner.impl.historical_runner:37 status : True
2020-02-07 17:12:06,782 INFO download_runner.impl.historical_runner:42 Historical data request sent : ACP 2019-01-01 2020-01-01
2020-02-07 17:12:06,782 DEBUG download_runner.impl.historical_end_reader:37 poll stock ? => True
2020-02-07 17:12:06,782 ERROR root:30 unhandled exception getting latest timestamp for ACRE
Traceback (most recent call last):
  File "/Users/dali/workspace/ib_python/runner/services/historical_data_service.py", line 24, in get_latest_timestamp
    response = self.stub.GetLatestTimeStamp(request)
  File "/Users/dali/workspace/ib_python/runner/venv/lib/python3.7/site-packages/grpc/_channel.py", line 604, in __call__
    return _end_unary_response_blocking(state, call, False, None)
  File "/Users/dali/workspace/ib_python/runner/venv/lib/python3.7/site-packages/grpc/_channel.py", line 506, in _end_unary_response_blocking
    raise _Rendezvous(state, None, None, deadline)
grpc._channel._Rendezvous: <_Rendezvous of RPC that terminated with:
	status = StatusCode.UNAVAILABLE
	details = "failed to connect to all addresses"
	debug_error_string = "{"created":"@1581095526.782422000","description":"Failed to pick subchannel","file":"src/core/ext/filters/client_channel/client_channel.cc","file_line":3876,"referenced_errors":[{"created":"@1581095526.079487000","description":"failed to connect to all addresses","file":"src/core/ext/filters/client_channel/lb_policy/pick_first/pick_first.cc","file_line":395,"grpc_status":14}]}"
>
2020-02-07 17:12:06,782 INFO download_runner.impl.historical_runner:32 sending - historical data request : ACRE 2019-01-01 2020-01-01
2020-02-07 17:12:12,154 INFO download_runner.impl.historical_runner:35 sent - historical data request : ACRE 2019-01-01 2020-01-01
2020-02-07 17:12:12,154 DEBUG download_runner.impl.historical_runner:36 request accounted for...
2020-02-07 17:12:12,155 INFO download_runner.impl.historical_runner:37 status : True
2020-02-07 17:12:12,155 INFO download_runner.impl.historical_runner:42 Historical data request sent : ACRE 2019-01-01 2020-01-01
2020-02-07 17:12:12,155 DEBUG download_runner.impl.historical_end_reader:37 poll stock ? => True
2020-02-07 17:12:12,155 ERROR root:30 unhandled exception getting latest timestamp for ACRS
Traceback (most recent call last):
  File "/Users/dali/workspace/ib_python/runner/services/historical_data_service.py", line 24, in get_latest_timestamp
    response = self.stub.GetLatestTimeStamp(request)
  File "/Users/dali/workspace/ib_python/runner/venv/lib/python3.7/site-packages/grpc/_channel.py", line 604, in __call__
    return _end_unary_response_blocking(state, call, False, None)
  File "/Users/dali/workspace/ib_python/runner/venv/lib/python3.7/site-packages/grpc/_channel.py", line 506, in _end_unary_response_blocking
    raise _Rendezvous(state, None, None, deadline)
grpc._channel._Rendezvous: <_Rendezvous of RPC that terminated with:
	status = StatusCode.UNAVAILABLE
	details = "failed to connect to all addresses"
	debug_error_string = "{"created":"@1581095532.155422000","description":"Failed to pick subchannel","file":"src/core/ext/filters/client_channel/client_channel.cc","file_line":3876,"referenced_errors":[{"created":"@1581095526.079487000","description":"failed to connect to all addresses","file":"src/core/ext/filters/client_channel/lb_policy/pick_first/pick_first.cc","file_line":395,"grpc_status":14}]}"
>
2020-02-07 17:12:12,155 INFO download_runner.impl.historical_runner:32 sending - historical data request : ACRS 2019-01-01 2020-01-01
2020-02-07 17:12:12,476 INFO download_runner.impl.historical_runner:35 sent - historical data request : ACRS 2019-01-01 2020-01-01
2020-02-07 17:12:12,476 DEBUG download_runner.impl.historical_runner:36 request accounted for...
2020-02-07 17:12:12,476 INFO download_runner.impl.historical_runner:37 status : True
2020-02-07 17:12:12,476 INFO download_runner.impl.historical_runner:42 Historical data request sent : ACRS 2019-01-01 2020-01-01
2020-02-07 17:12:12,476 DEBUG download_runner.impl.historical_end_reader:37 poll stock ? => True
2020-02-07 17:12:12,477 ERROR root:30 unhandled exception getting latest timestamp for ACRX
Traceback (most recent call last):
  File "/Users/dali/workspace/ib_python/runner/services/historical_data_service.py", line 24, in get_latest_timestamp
    response = self.stub.GetLatestTimeStamp(request)
  File "/Users/dali/workspace/ib_python/runner/venv/lib/python3.7/site-packages/grpc/_channel.py", line 604, in __call__
    return _end_unary_response_blocking(state, call, False, None)
  File "/Users/dali/workspace/ib_python/runner/venv/lib/python3.7/site-packages/grpc/_channel.py", line 506, in _end_unary_response_blocking
    raise _Rendezvous(state, None, None, deadline)
grpc._channel._Rendezvous: <_Rendezvous of RPC that terminated with:
	status = StatusCode.UNAVAILABLE
	details = "failed to connect to all addresses"
	debug_error_string = "{"created":"@1581095532.477181000","description":"Failed to pick subchannel","file":"src/core/ext/filters/client_channel/client_channel.cc","file_line":3876,"referenced_errors":[{"created":"@1581095526.079487000","description":"failed to connect to all addresses","file":"src/core/ext/filters/client_channel/lb_policy/pick_first/pick_first.cc","file_line":395,"grpc_status":14}]}"
>
2020-02-07 17:12:12,477 INFO download_runner.impl.historical_runner:32 sending - historical data request : ACRX 2019-01-01 2020-01-01
2020-02-07 17:12:24,022 INFO download_runner.impl.historical_runner:35 sent - historical data request : ACRX 2019-01-01 2020-01-01
2020-02-07 17:12:24,022 DEBUG download_runner.impl.historical_runner:36 request accounted for...
2020-02-07 17:12:24,022 INFO download_runner.impl.historical_runner:37 status : True
2020-02-07 17:12:24,022 INFO download_runner.impl.historical_runner:42 Historical data request sent : ACRX 2019-01-01 2020-01-01
2020-02-07 17:12:24,022 DEBUG download_runner.impl.historical_end_reader:37 poll stock ? => True
2020-02-07 17:12:24,023 ERROR root:30 unhandled exception getting latest timestamp for ACSG
Traceback (most recent call last):
  File "/Users/dali/workspace/ib_python/runner/services/historical_data_service.py", line 24, in get_latest_timestamp
    response = self.stub.GetLatestTimeStamp(request)
  File "/Users/dali/workspace/ib_python/runner/venv/lib/python3.7/site-packages/grpc/_channel.py", line 604, in __call__
    return _end_unary_response_blocking(state, call, False, None)
  File "/Users/dali/workspace/ib_python/runner/venv/lib/python3.7/site-packages/grpc/_channel.py", line 506, in _end_unary_response_blocking
    raise _Rendezvous(state, None, None, deadline)
grpc._channel._Rendezvous: <_Rendezvous of RPC that terminated with:
	status = StatusCode.UNAVAILABLE
	details = "failed to connect to all addresses"
	debug_error_string = "{"created":"@1581095544.023071000","description":"Failed to pick subchannel","file":"src/core/ext/filters/client_channel/client_channel.cc","file_line":3876,"referenced_errors":[{"created":"@1581095537.139060000","description":"failed to connect to all addresses","file":"src/core/ext/filters/client_channel/lb_policy/pick_first/pick_first.cc","file_line":395,"grpc_status":14}]}"
>
2020-02-07 17:12:24,023 INFO download_runner.impl.historical_runner:32 sending - historical data request : ACSG 2019-01-01 2020-01-01
2020-02-07 17:12:36,162 INFO download_runner.impl.historical_runner:35 sent - historical data request : ACSG 2019-01-01 2020-01-01
2020-02-07 17:12:36,163 DEBUG download_runner.impl.historical_runner:36 request accounted for...
2020-02-07 17:12:36,163 INFO download_runner.impl.historical_runner:37 status : True
2020-02-07 17:12:36,163 INFO download_runner.impl.historical_runner:42 Historical data request sent : ACSG 2019-01-01 2020-01-01
2020-02-07 17:12:36,163 DEBUG download_runner.impl.historical_end_reader:37 poll stock ? => True
2020-02-07 17:12:36,163 ERROR root:30 unhandled exception getting latest timestamp for ACSI
Traceback (most recent call last):
  File "/Users/dali/workspace/ib_python/runner/services/historical_data_service.py", line 24, in get_latest_timestamp
    response = self.stub.GetLatestTimeStamp(request)
  File "/Users/dali/workspace/ib_python/runner/venv/lib/python3.7/site-packages/grpc/_channel.py", line 604, in __call__
    return _end_unary_response_blocking(state, call, False, None)
  File "/Users/dali/workspace/ib_python/runner/venv/lib/python3.7/site-packages/grpc/_channel.py", line 506, in _end_unary_response_blocking
    raise _Rendezvous(state, None, None, deadline)
grpc._channel._Rendezvous: <_Rendezvous of RPC that terminated with:
	status = StatusCode.UNAVAILABLE
	details = "failed to connect to all addresses"
	debug_error_string = "{"created":"@1581095556.163776000","description":"Failed to pick subchannel","file":"src/core/ext/filters/client_channel/client_channel.cc","file_line":3876,"referenced_errors":[{"created":"@1581095556.163774000","description":"failed to connect to all addresses","file":"src/core/ext/filters/client_channel/lb_policy/pick_first/pick_first.cc","file_line":395,"grpc_status":14}]}"
>
2020-02-07 17:12:36,164 INFO download_runner.impl.historical_runner:32 sending - historical data request : ACSI 2019-01-01 2020-01-01
2020-02-07 17:12:48,628 INFO download_runner.impl.historical_runner:35 sent - historical data request : ACSI 2019-01-01 2020-01-01
2020-02-07 17:12:48,628 DEBUG download_runner.impl.historical_runner:36 request accounted for...
2020-02-07 17:12:48,628 INFO download_runner.impl.historical_runner:37 status : True
2020-02-07 17:12:48,628 INFO download_runner.impl.historical_runner:42 Historical data request sent : ACSI 2019-01-01 2020-01-01
2020-02-07 17:12:48,628 DEBUG download_runner.impl.historical_end_reader:37 poll stock ? => True
2020-02-07 17:12:48,629 ERROR root:30 unhandled exception getting latest timestamp for ACST
Traceback (most recent call last):
  File "/Users/dali/workspace/ib_python/runner/services/historical_data_service.py", line 24, in get_latest_timestamp
    response = self.stub.GetLatestTimeStamp(request)
  File "/Users/dali/workspace/ib_python/runner/venv/lib/python3.7/site-packages/grpc/_channel.py", line 604, in __call__
    return _end_unary_response_blocking(state, call, False, None)
  File "/Users/dali/workspace/ib_python/runner/venv/lib/python3.7/site-packages/grpc/_channel.py", line 506, in _end_unary_response_blocking
    raise _Rendezvous(state, None, None, deadline)
grpc._channel._Rendezvous: <_Rendezvous of RPC that terminated with:
	status = StatusCode.UNAVAILABLE
	details = "failed to connect to all addresses"
	debug_error_string = "{"created":"@1581095568.629069000","description":"Failed to pick subchannel","file":"src/core/ext/filters/client_channel/client_channel.cc","file_line":3876,"referenced_errors":[{"created":"@1581095556.163774000","description":"failed to connect to all addresses","file":"src/core/ext/filters/client_channel/lb_policy/pick_first/pick_first.cc","file_line":395,"grpc_status":14}]}"
>
2020-02-07 17:12:48,629 INFO download_runner.impl.historical_runner:32 sending - historical data request : ACST 2019-01-01 2020-01-01
2020-02-07 17:12:48,914 INFO download_runner.impl.historical_runner:35 sent - historical data request : ACST 2019-01-01 2020-01-01
2020-02-07 17:12:48,914 DEBUG download_runner.impl.historical_runner:36 request accounted for...
2020-02-07 17:12:48,914 INFO download_runner.impl.historical_runner:37 status : True
2020-02-07 17:12:48,914 INFO download_runner.impl.historical_runner:42 Historical data request sent : ACST 2019-01-01 2020-01-01
2020-02-07 17:12:48,914 DEBUG download_runner.impl.historical_end_reader:37 poll stock ? => True
2020-02-07 17:12:48,914 ERROR root:30 unhandled exception getting latest timestamp for ACT
Traceback (most recent call last):
  File "/Users/dali/workspace/ib_python/runner/services/historical_data_service.py", line 24, in get_latest_timestamp
    response = self.stub.GetLatestTimeStamp(request)
  File "/Users/dali/workspace/ib_python/runner/venv/lib/python3.7/site-packages/grpc/_channel.py", line 604, in __call__
    return _end_unary_response_blocking(state, call, False, None)
  File "/Users/dali/workspace/ib_python/runner/venv/lib/python3.7/site-packages/grpc/_channel.py", line 506, in _end_unary_response_blocking
    raise _Rendezvous(state, None, None, deadline)
grpc._channel._Rendezvous: <_Rendezvous of RPC that terminated with:
	status = StatusCode.UNAVAILABLE
	details = "failed to connect to all addresses"
	debug_error_string = "{"created":"@1581095568.914691000","description":"Failed to pick subchannel","file":"src/core/ext/filters/client_channel/client_channel.cc","file_line":3876,"referenced_errors":[{"created":"@1581095556.163774000","description":"failed to connect to all addresses","file":"src/core/ext/filters/client_channel/lb_policy/pick_first/pick_first.cc","file_line":395,"grpc_status":14}]}"
>
2020-02-07 17:12:48,915 INFO download_runner.impl.historical_runner:32 sending - historical data request : ACT 2019-01-01 2020-01-01
2020-02-07 17:12:49,682 INFO download_runner.impl.historical_runner:35 sent - historical data request : ACT 2019-01-01 2020-01-01
2020-02-07 17:12:49,682 DEBUG download_runner.impl.historical_runner:36 request accounted for...
2020-02-07 17:12:49,682 INFO download_runner.impl.historical_runner:37 status : True
2020-02-07 17:12:49,682 INFO download_runner.impl.historical_runner:42 Historical data request sent : ACT 2019-01-01 2020-01-01
2020-02-07 17:12:49,682 DEBUG download_runner.impl.historical_end_reader:37 poll stock ? => True
2020-02-07 17:12:49,683 ERROR root:30 unhandled exception getting latest timestamp for ACTG
Traceback (most recent call last):
  File "/Users/dali/workspace/ib_python/runner/services/historical_data_service.py", line 24, in get_latest_timestamp
    response = self.stub.GetLatestTimeStamp(request)
  File "/Users/dali/workspace/ib_python/runner/venv/lib/python3.7/site-packages/grpc/_channel.py", line 604, in __call__
    return _end_unary_response_blocking(state, call, False, None)
  File "/Users/dali/workspace/ib_python/runner/venv/lib/python3.7/site-packages/grpc/_channel.py", line 506, in _end_unary_response_blocking
    raise _Rendezvous(state, None, None, deadline)
grpc._channel._Rendezvous: <_Rendezvous of RPC that terminated with:
	status = StatusCode.UNAVAILABLE
	details = "failed to connect to all addresses"
	debug_error_string = "{"created":"@1581095569.683011000","description":"Failed to pick subchannel","file":"src/core/ext/filters/client_channel/client_channel.cc","file_line":3876,"referenced_errors":[{"created":"@1581095556.163774000","description":"failed to connect to all addresses","file":"src/core/ext/filters/client_channel/lb_policy/pick_first/pick_first.cc","file_line":395,"grpc_status":14}]}"
>
2020-02-07 17:12:49,683 INFO download_runner.impl.historical_runner:32 sending - historical data request : ACTG 2019-01-01 2020-01-01
2020-02-07 17:12:50,365 INFO download_runner.impl.historical_runner:35 sent - historical data request : ACTG 2019-01-01 2020-01-01
2020-02-07 17:12:50,365 DEBUG download_runner.impl.historical_runner:36 request accounted for...
2020-02-07 17:12:50,365 INFO download_runner.impl.historical_runner:37 status : True
2020-02-07 17:12:50,365 INFO download_runner.impl.historical_runner:42 Historical data request sent : ACTG 2019-01-01 2020-01-01
2020-02-07 17:12:50,365 DEBUG download_runner.impl.historical_end_reader:37 poll stock ? => True
2020-02-07 17:12:50,365 ERROR root:30 unhandled exception getting latest timestamp for ACTT
Traceback (most recent call last):
  File "/Users/dali/workspace/ib_python/runner/services/historical_data_service.py", line 24, in get_latest_timestamp
    response = self.stub.GetLatestTimeStamp(request)
  File "/Users/dali/workspace/ib_python/runner/venv/lib/python3.7/site-packages/grpc/_channel.py", line 604, in __call__
    return _end_unary_response_blocking(state, call, False, None)
  File "/Users/dali/workspace/ib_python/runner/venv/lib/python3.7/site-packages/grpc/_channel.py", line 506, in _end_unary_response_blocking
    raise _Rendezvous(state, None, None, deadline)
grpc._channel._Rendezvous: <_Rendezvous of RPC that terminated with:
	status = StatusCode.UNAVAILABLE
	details = "failed to connect to all addresses"
	debug_error_string = "{"created":"@1581095570.365797000","description":"Failed to pick subchannel","file":"src/core/ext/filters/client_channel/client_channel.cc","file_line":3876,"referenced_errors":[{"created":"@1581095556.163774000","description":"failed to connect to all addresses","file":"src/core/ext/filters/client_channel/lb_policy/pick_first/pick_first.cc","file_line":395,"grpc_status":14}]}"
>
2020-02-07 17:12:50,366 INFO download_runner.impl.historical_runner:32 sending - historical data request : ACTT 2019-01-01 2020-01-01
2020-02-07 17:12:53,983 INFO download_runner.impl.historical_runner:35 sent - historical data request : ACTT 2019-01-01 2020-01-01
2020-02-07 17:12:53,983 DEBUG download_runner.impl.historical_runner:36 request accounted for...
2020-02-07 17:12:53,983 INFO download_runner.impl.historical_runner:37 status : True
2020-02-07 17:12:53,983 INFO download_runner.impl.historical_runner:42 Historical data request sent : ACTT 2019-01-01 2020-01-01
2020-02-07 17:12:53,983 DEBUG download_runner.impl.historical_end_reader:37 poll stock ? => True
2020-02-07 17:12:53,983 ERROR root:30 unhandled exception getting latest timestamp for ACTTU
Traceback (most recent call last):
  File "/Users/dali/workspace/ib_python/runner/services/historical_data_service.py", line 24, in get_latest_timestamp
    response = self.stub.GetLatestTimeStamp(request)
  File "/Users/dali/workspace/ib_python/runner/venv/lib/python3.7/site-packages/grpc/_channel.py", line 604, in __call__
    return _end_unary_response_blocking(state, call, False, None)
  File "/Users/dali/workspace/ib_python/runner/venv/lib/python3.7/site-packages/grpc/_channel.py", line 506, in _end_unary_response_blocking
    raise _Rendezvous(state, None, None, deadline)
grpc._channel._Rendezvous: <_Rendezvous of RPC that terminated with:
	status = StatusCode.UNAVAILABLE
	details = "failed to connect to all addresses"
	debug_error_string = "{"created":"@1581095573.983507000","description":"Failed to pick subchannel","file":"src/core/ext/filters/client_channel/client_channel.cc","file_line":3876,"referenced_errors":[{"created":"@1581095556.163774000","description":"failed to connect to all addresses","file":"src/core/ext/filters/client_channel/lb_policy/pick_first/pick_first.cc","file_line":395,"grpc_status":14}]}"
>
2020-02-07 17:12:53,983 INFO download_runner.impl.historical_runner:32 sending - historical data request : ACTTU 2019-01-01 2020-01-01
2020-02-07 17:12:54,843 INFO download_runner.impl.historical_runner:35 sent - historical data request : ACTTU 2019-01-01 2020-01-01
2020-02-07 17:12:54,844 DEBUG download_runner.impl.historical_runner:36 request accounted for...
2020-02-07 17:12:54,844 INFO download_runner.impl.historical_runner:37 status : True
2020-02-07 17:12:54,844 INFO download_runner.impl.historical_runner:42 Historical data request sent : ACTTU 2019-01-01 2020-01-01
2020-02-07 17:12:54,844 DEBUG download_runner.impl.historical_end_reader:37 poll stock ? => True
2020-02-07 17:12:54,844 ERROR root:30 unhandled exception getting latest timestamp for ACU
Traceback (most recent call last):
  File "/Users/dali/workspace/ib_python/runner/services/historical_data_service.py", line 24, in get_latest_timestamp
    response = self.stub.GetLatestTimeStamp(request)
  File "/Users/dali/workspace/ib_python/runner/venv/lib/python3.7/site-packages/grpc/_channel.py", line 604, in __call__
    return _end_unary_response_blocking(state, call, False, None)
  File "/Users/dali/workspace/ib_python/runner/venv/lib/python3.7/site-packages/grpc/_channel.py", line 506, in _end_unary_response_blocking
    raise _Rendezvous(state, None, None, deadline)
grpc._channel._Rendezvous: <_Rendezvous of RPC that terminated with:
	status = StatusCode.UNAVAILABLE
	details = "failed to connect to all addresses"
	debug_error_string = "{"created":"@1581095574.844747000","description":"Failed to pick subchannel","file":"src/core/ext/filters/client_channel/client_channel.cc","file_line":3876,"referenced_errors":[{"created":"@1581095556.163774000","description":"failed to connect to all addresses","file":"src/core/ext/filters/client_channel/lb_policy/pick_first/pick_first.cc","file_line":395,"grpc_status":14}]}"
>
2020-02-07 17:12:54,845 INFO download_runner.impl.historical_runner:32 sending - historical data request : ACU 2019-01-01 2020-01-01
2020-02-07 17:12:55,127 INFO download_runner.impl.historical_runner:35 sent - historical data request : ACU 2019-01-01 2020-01-01
2020-02-07 17:12:55,128 DEBUG download_runner.impl.historical_runner:36 request accounted for...
2020-02-07 17:12:55,128 INFO download_runner.impl.historical_runner:37 status : True
2020-02-07 17:12:55,128 INFO download_runner.impl.historical_runner:42 Historical data request sent : ACU 2019-01-01 2020-01-01
2020-02-07 17:12:55,128 DEBUG download_runner.impl.historical_end_reader:37 poll stock ? => True
2020-02-07 17:12:55,128 ERROR root:30 unhandled exception getting latest timestamp for ACV
Traceback (most recent call last):
  File "/Users/dali/workspace/ib_python/runner/services/historical_data_service.py", line 24, in get_latest_timestamp
    response = self.stub.GetLatestTimeStamp(request)
  File "/Users/dali/workspace/ib_python/runner/venv/lib/python3.7/site-packages/grpc/_channel.py", line 604, in __call__
    return _end_unary_response_blocking(state, call, False, None)
  File "/Users/dali/workspace/ib_python/runner/venv/lib/python3.7/site-packages/grpc/_channel.py", line 506, in _end_unary_response_blocking
    raise _Rendezvous(state, None, None, deadline)
grpc._channel._Rendezvous: <_Rendezvous of RPC that terminated with:
	status = StatusCode.UNAVAILABLE
	details = "failed to connect to all addresses"
	debug_error_string = "{"created":"@1581095575.128435000","description":"Failed to pick subchannel","file":"src/core/ext/filters/client_channel/client_channel.cc","file_line":3876,"referenced_errors":[{"created":"@1581095556.163774000","description":"failed to connect to all addresses","file":"src/core/ext/filters/client_channel/lb_policy/pick_first/pick_first.cc","file_line":395,"grpc_status":14}]}"
>
2020-02-07 17:12:55,128 INFO download_runner.impl.historical_runner:32 sending - historical data request : ACV 2019-01-01 2020-01-01
2020-02-07 17:13:00,090 INFO download_runner.impl.historical_runner:35 sent - historical data request : ACV 2019-01-01 2020-01-01
2020-02-07 17:13:00,090 DEBUG download_runner.impl.historical_runner:36 request accounted for...
2020-02-07 17:13:00,090 INFO download_runner.impl.historical_runner:37 status : True
2020-02-07 17:13:00,090 INFO download_runner.impl.historical_runner:42 Historical data request sent : ACV 2019-01-01 2020-01-01
2020-02-07 17:13:00,090 DEBUG download_runner.impl.historical_end_reader:37 poll stock ? => True
2020-02-07 17:13:00,090 ERROR root:30 unhandled exception getting latest timestamp for ACWF
Traceback (most recent call last):
  File "/Users/dali/workspace/ib_python/runner/services/historical_data_service.py", line 24, in get_latest_timestamp
    response = self.stub.GetLatestTimeStamp(request)
  File "/Users/dali/workspace/ib_python/runner/venv/lib/python3.7/site-packages/grpc/_channel.py", line 604, in __call__
    return _end_unary_response_blocking(state, call, False, None)
  File "/Users/dali/workspace/ib_python/runner/venv/lib/python3.7/site-packages/grpc/_channel.py", line 506, in _end_unary_response_blocking
    raise _Rendezvous(state, None, None, deadline)
grpc._channel._Rendezvous: <_Rendezvous of RPC that terminated with:
	status = StatusCode.UNAVAILABLE
	details = "failed to connect to all addresses"
	debug_error_string = "{"created":"@1581095580.090688000","description":"Failed to pick subchannel","file":"src/core/ext/filters/client_channel/client_channel.cc","file_line":3876,"referenced_errors":[{"created":"@1581095556.163774000","description":"failed to connect to all addresses","file":"src/core/ext/filters/client_channel/lb_policy/pick_first/pick_first.cc","file_line":395,"grpc_status":14}]}"
>
2020-02-07 17:13:00,090 INFO download_runner.impl.historical_runner:32 sending - historical data request : ACWF 2019-01-01 2020-01-01
2020-02-07 17:13:01,988 INFO download_runner.impl.historical_runner:35 sent - historical data request : ACWF 2019-01-01 2020-01-01
2020-02-07 17:13:01,988 DEBUG download_runner.impl.historical_runner:36 request accounted for...
2020-02-07 17:13:01,988 INFO download_runner.impl.historical_runner:37 status : True
2020-02-07 17:13:01,988 INFO download_runner.impl.historical_runner:42 Historical data request sent : ACWF 2019-01-01 2020-01-01
2020-02-07 17:13:01,988 DEBUG download_runner.impl.historical_end_reader:37 poll stock ? => True
2020-02-07 17:13:01,988 ERROR root:30 unhandled exception getting latest timestamp for ACWI
Traceback (most recent call last):
  File "/Users/dali/workspace/ib_python/runner/services/historical_data_service.py", line 24, in get_latest_timestamp
    response = self.stub.GetLatestTimeStamp(request)
  File "/Users/dali/workspace/ib_python/runner/venv/lib/python3.7/site-packages/grpc/_channel.py", line 604, in __call__
    return _end_unary_response_blocking(state, call, False, None)
  File "/Users/dali/workspace/ib_python/runner/venv/lib/python3.7/site-packages/grpc/_channel.py", line 506, in _end_unary_response_blocking
    raise _Rendezvous(state, None, None, deadline)
grpc._channel._Rendezvous: <_Rendezvous of RPC that terminated with:
	status = StatusCode.UNAVAILABLE
	details = "failed to connect to all addresses"
	debug_error_string = "{"created":"@1581095581.988885000","description":"Failed to pick subchannel","file":"src/core/ext/filters/client_channel/client_channel.cc","file_line":3876,"referenced_errors":[{"created":"@1581095556.163774000","description":"failed to connect to all addresses","file":"src/core/ext/filters/client_channel/lb_policy/pick_first/pick_first.cc","file_line":395,"grpc_status":14}]}"
>
2020-02-07 17:13:01,989 INFO download_runner.impl.historical_runner:32 sending - historical data request : ACWI 2019-01-01 2020-01-01
2020-02-07 17:13:06,447 INFO download_runner.impl.historical_runner:35 sent - historical data request : ACWI 2019-01-01 2020-01-01
2020-02-07 17:13:06,447 DEBUG download_runner.impl.historical_runner:36 request accounted for...
2020-02-07 17:13:06,447 INFO download_runner.impl.historical_runner:37 status : True
2020-02-07 17:13:06,447 INFO download_runner.impl.historical_runner:42 Historical data request sent : ACWI 2019-01-01 2020-01-01
2020-02-07 17:13:06,447 DEBUG download_runner.impl.historical_end_reader:37 poll stock ? => True
2020-02-07 17:13:06,447 ERROR root:30 unhandled exception getting latest timestamp for ACWV
Traceback (most recent call last):
  File "/Users/dali/workspace/ib_python/runner/services/historical_data_service.py", line 24, in get_latest_timestamp
    response = self.stub.GetLatestTimeStamp(request)
  File "/Users/dali/workspace/ib_python/runner/venv/lib/python3.7/site-packages/grpc/_channel.py", line 604, in __call__
    return _end_unary_response_blocking(state, call, False, None)
  File "/Users/dali/workspace/ib_python/runner/venv/lib/python3.7/site-packages/grpc/_channel.py", line 506, in _end_unary_response_blocking
    raise _Rendezvous(state, None, None, deadline)
grpc._channel._Rendezvous: <_Rendezvous of RPC that terminated with:
	status = StatusCode.UNAVAILABLE
	details = "failed to connect to all addresses"
	debug_error_string = "{"created":"@1581095586.447668000","description":"Failed to pick subchannel","file":"src/core/ext/filters/client_channel/client_channel.cc","file_line":3876,"referenced_errors":[{"created":"@1581095586.447667000","description":"failed to connect to all addresses","file":"src/core/ext/filters/client_channel/lb_policy/pick_first/pick_first.cc","file_line":395,"grpc_status":14}]}"
>
2020-02-07 17:13:06,447 INFO download_runner.impl.historical_runner:32 sending - historical data request : ACWV 2019-01-01 2020-01-01
2020-02-07 17:13:07,617 INFO download_runner.impl.historical_runner:35 sent - historical data request : ACWV 2019-01-01 2020-01-01
2020-02-07 17:13:07,617 DEBUG download_runner.impl.historical_runner:36 request accounted for...
2020-02-07 17:13:07,617 INFO download_runner.impl.historical_runner:37 status : True
2020-02-07 17:13:07,617 INFO download_runner.impl.historical_runner:42 Historical data request sent : ACWV 2019-01-01 2020-01-01
2020-02-07 17:13:07,617 DEBUG download_runner.impl.historical_end_reader:37 poll stock ? => True
2020-02-07 17:13:07,617 ERROR root:30 unhandled exception getting latest timestamp for ACWX
Traceback (most recent call last):
  File "/Users/dali/workspace/ib_python/runner/services/historical_data_service.py", line 24, in get_latest_timestamp
    response = self.stub.GetLatestTimeStamp(request)
  File "/Users/dali/workspace/ib_python/runner/venv/lib/python3.7/site-packages/grpc/_channel.py", line 604, in __call__
    return _end_unary_response_blocking(state, call, False, None)
  File "/Users/dali/workspace/ib_python/runner/venv/lib/python3.7/site-packages/grpc/_channel.py", line 506, in _end_unary_response_blocking
    raise _Rendezvous(state, None, None, deadline)
grpc._channel._Rendezvous: <_Rendezvous of RPC that terminated with:
	status = StatusCode.UNAVAILABLE
	details = "failed to connect to all addresses"
	debug_error_string = "{"created":"@1581095587.617832000","description":"Failed to pick subchannel","file":"src/core/ext/filters/client_channel/client_channel.cc","file_line":3876,"referenced_errors":[{"created":"@1581095586.447667000","description":"failed to connect to all addresses","file":"src/core/ext/filters/client_channel/lb_policy/pick_first/pick_first.cc","file_line":395,"grpc_status":14}]}"
>
2020-02-07 17:13:07,618 INFO download_runner.impl.historical_runner:32 sending - historical data request : ACWX 2019-01-01 2020-01-01
2020-02-07 17:13:12,262 INFO download_runner.impl.historical_runner:35 sent - historical data request : ACWX 2019-01-01 2020-01-01
2020-02-07 17:13:12,262 DEBUG download_runner.impl.historical_runner:36 request accounted for...
2020-02-07 17:13:12,262 INFO download_runner.impl.historical_runner:37 status : True
2020-02-07 17:13:12,262 INFO download_runner.impl.historical_runner:42 Historical data request sent : ACWX 2019-01-01 2020-01-01
2020-02-07 17:13:12,263 DEBUG download_runner.impl.historical_end_reader:37 poll stock ? => True
2020-02-07 17:13:12,263 ERROR root:30 unhandled exception getting latest timestamp for ACY
Traceback (most recent call last):
  File "/Users/dali/workspace/ib_python/runner/services/historical_data_service.py", line 24, in get_latest_timestamp
    response = self.stub.GetLatestTimeStamp(request)
  File "/Users/dali/workspace/ib_python/runner/venv/lib/python3.7/site-packages/grpc/_channel.py", line 604, in __call__
    return _end_unary_response_blocking(state, call, False, None)
  File "/Users/dali/workspace/ib_python/runner/venv/lib/python3.7/site-packages/grpc/_channel.py", line 506, in _end_unary_response_blocking
    raise _Rendezvous(state, None, None, deadline)
grpc._channel._Rendezvous: <_Rendezvous of RPC that terminated with:
	status = StatusCode.UNAVAILABLE
	details = "failed to connect to all addresses"
	debug_error_string = "{"created":"@1581095592.263364000","description":"Failed to pick subchannel","file":"src/core/ext/filters/client_channel/client_channel.cc","file_line":3876,"referenced_errors":[{"created":"@1581095586.447667000","description":"failed to connect to all addresses","file":"src/core/ext/filters/client_channel/lb_policy/pick_first/pick_first.cc","file_line":395,"grpc_status":14}]}"
>
2020-02-07 17:13:12,263 INFO download_runner.impl.historical_runner:32 sending - historical data request : ACY 2019-01-01 2020-01-01
2020-02-07 17:13:24,348 INFO download_runner.impl.historical_runner:35 sent - historical data request : ACY 2019-01-01 2020-01-01
2020-02-07 17:13:24,349 DEBUG download_runner.impl.historical_runner:36 request accounted for...
2020-02-07 17:13:24,349 INFO download_runner.impl.historical_runner:37 status : True
2020-02-07 17:13:24,349 INFO download_runner.impl.historical_runner:42 Historical data request sent : ACY 2019-01-01 2020-01-01
2020-02-07 17:13:24,349 DEBUG download_runner.impl.historical_end_reader:37 poll stock ? => True
2020-02-07 17:13:24,350 ERROR root:30 unhandled exception getting latest timestamp for ADAP
Traceback (most recent call last):
  File "/Users/dali/workspace/ib_python/runner/services/historical_data_service.py", line 24, in get_latest_timestamp
    response = self.stub.GetLatestTimeStamp(request)
  File "/Users/dali/workspace/ib_python/runner/venv/lib/python3.7/site-packages/grpc/_channel.py", line 604, in __call__
    return _end_unary_response_blocking(state, call, False, None)
  File "/Users/dali/workspace/ib_python/runner/venv/lib/python3.7/site-packages/grpc/_channel.py", line 506, in _end_unary_response_blocking
    raise _Rendezvous(state, None, None, deadline)
grpc._channel._Rendezvous: <_Rendezvous of RPC that terminated with:
	status = StatusCode.UNAVAILABLE
	details = "failed to connect to all addresses"
	debug_error_string = "{"created":"@1581095604.350148000","description":"Failed to pick subchannel","file":"src/core/ext/filters/client_channel/client_channel.cc","file_line":3876,"referenced_errors":[{"created":"@1581095586.447667000","description":"failed to connect to all addresses","file":"src/core/ext/filters/client_channel/lb_policy/pick_first/pick_first.cc","file_line":395,"grpc_status":14}]}"
>
2020-02-07 17:13:24,350 INFO download_runner.impl.historical_runner:32 sending - historical data request : ADAP 2019-01-01 2020-01-01
2020-02-07 17:13:36,251 INFO download_runner.impl.historical_runner:35 sent - historical data request : ADAP 2019-01-01 2020-01-01
2020-02-07 17:13:36,251 DEBUG download_runner.impl.historical_runner:36 request accounted for...
2020-02-07 17:13:36,251 INFO download_runner.impl.historical_runner:37 status : True
2020-02-07 17:13:36,251 INFO download_runner.impl.historical_runner:42 Historical data request sent : ADAP 2019-01-01 2020-01-01
2020-02-07 17:13:36,251 DEBUG download_runner.impl.historical_end_reader:37 poll stock ? => True
2020-02-07 17:13:36,251 ERROR root:30 unhandled exception getting latest timestamp for ADBE
Traceback (most recent call last):
  File "/Users/dali/workspace/ib_python/runner/services/historical_data_service.py", line 24, in get_latest_timestamp
    response = self.stub.GetLatestTimeStamp(request)
  File "/Users/dali/workspace/ib_python/runner/venv/lib/python3.7/site-packages/grpc/_channel.py", line 604, in __call__
    return _end_unary_response_blocking(state, call, False, None)
  File "/Users/dali/workspace/ib_python/runner/venv/lib/python3.7/site-packages/grpc/_channel.py", line 506, in _end_unary_response_blocking
    raise _Rendezvous(state, None, None, deadline)
grpc._channel._Rendezvous: <_Rendezvous of RPC that terminated with:
	status = StatusCode.UNAVAILABLE
	details = "failed to connect to all addresses"
	debug_error_string = "{"created":"@1581095616.251635000","description":"Failed to pick subchannel","file":"src/core/ext/filters/client_channel/client_channel.cc","file_line":3876,"referenced_errors":[{"created":"@1581095586.447667000","description":"failed to connect to all addresses","file":"src/core/ext/filters/client_channel/lb_policy/pick_first/pick_first.cc","file_line":395,"grpc_status":14}]}"
>
2020-02-07 17:13:36,251 INFO download_runner.impl.historical_runner:32 sending - historical data request : ADBE 2019-01-01 2020-01-01
2020-02-07 17:13:36,359 INFO download_runner.impl.historical_runner:35 sent - historical data request : ADBE 2019-01-01 2020-01-01
2020-02-07 17:13:36,359 DEBUG download_runner.impl.historical_runner:36 request accounted for...
2020-02-07 17:13:36,359 INFO download_runner.impl.historical_runner:37 status : True
2020-02-07 17:13:36,359 INFO download_runner.impl.historical_runner:42 Historical data request sent : ADBE 2019-01-01 2020-01-01
2020-02-07 17:13:36,359 DEBUG download_runner.impl.historical_end_reader:37 poll stock ? => True
2020-02-07 17:13:36,359 ERROR root:30 unhandled exception getting latest timestamp for ADC
Traceback (most recent call last):
  File "/Users/dali/workspace/ib_python/runner/services/historical_data_service.py", line 24, in get_latest_timestamp
    response = self.stub.GetLatestTimeStamp(request)
  File "/Users/dali/workspace/ib_python/runner/venv/lib/python3.7/site-packages/grpc/_channel.py", line 604, in __call__
    return _end_unary_response_blocking(state, call, False, None)
  File "/Users/dali/workspace/ib_python/runner/venv/lib/python3.7/site-packages/grpc/_channel.py", line 506, in _end_unary_response_blocking
    raise _Rendezvous(state, None, None, deadline)
grpc._channel._Rendezvous: <_Rendezvous of RPC that terminated with:
	status = StatusCode.UNAVAILABLE
	details = "failed to connect to all addresses"
	debug_error_string = "{"created":"@1581095616.359765000","description":"Failed to pick subchannel","file":"src/core/ext/filters/client_channel/client_channel.cc","file_line":3876,"referenced_errors":[{"created":"@1581095586.447667000","description":"failed to connect to all addresses","file":"src/core/ext/filters/client_channel/lb_policy/pick_first/pick_first.cc","file_line":395,"grpc_status":14}]}"
>
2020-02-07 17:13:36,360 INFO download_runner.impl.historical_runner:32 sending - historical data request : ADC 2019-01-01 2020-01-01
2020-02-07 17:13:49,035 INFO download_runner.impl.historical_runner:35 sent - historical data request : ADC 2019-01-01 2020-01-01
2020-02-07 17:13:49,035 DEBUG download_runner.impl.historical_runner:36 request accounted for...
2020-02-07 17:13:49,035 INFO download_runner.impl.historical_runner:37 status : True
2020-02-07 17:13:49,035 INFO download_runner.impl.historical_runner:42 Historical data request sent : ADC 2019-01-01 2020-01-01
2020-02-07 17:13:49,035 DEBUG download_runner.impl.historical_end_reader:37 poll stock ? => True
2020-02-07 17:13:49,035 ERROR root:30 unhandled exception getting latest timestamp for ADES
Traceback (most recent call last):
  File "/Users/dali/workspace/ib_python/runner/services/historical_data_service.py", line 24, in get_latest_timestamp
    response = self.stub.GetLatestTimeStamp(request)
  File "/Users/dali/workspace/ib_python/runner/venv/lib/python3.7/site-packages/grpc/_channel.py", line 604, in __call__
    return _end_unary_response_blocking(state, call, False, None)
  File "/Users/dali/workspace/ib_python/runner/venv/lib/python3.7/site-packages/grpc/_channel.py", line 506, in _end_unary_response_blocking
    raise _Rendezvous(state, None, None, deadline)
grpc._channel._Rendezvous: <_Rendezvous of RPC that terminated with:
	status = StatusCode.UNAVAILABLE
	details = "failed to connect to all addresses"
	debug_error_string = "{"created":"@1581095629.035793000","description":"Failed to pick subchannel","file":"src/core/ext/filters/client_channel/client_channel.cc","file_line":3876,"referenced_errors":[{"created":"@1581095586.447667000","description":"failed to connect to all addresses","file":"src/core/ext/filters/client_channel/lb_policy/pick_first/pick_first.cc","file_line":395,"grpc_status":14}]}"
>
2020-02-07 17:13:49,036 INFO download_runner.impl.historical_runner:32 sending - historical data request : ADES 2019-01-01 2020-01-01
2020-02-07 17:13:50,701 INFO download_runner.impl.historical_runner:35 sent - historical data request : ADES 2019-01-01 2020-01-01
2020-02-07 17:13:50,701 DEBUG download_runner.impl.historical_runner:36 request accounted for...
2020-02-07 17:13:50,701 INFO download_runner.impl.historical_runner:37 status : True
2020-02-07 17:13:50,701 INFO download_runner.impl.historical_runner:42 Historical data request sent : ADES 2019-01-01 2020-01-01
2020-02-07 17:13:50,701 DEBUG download_runner.impl.historical_end_reader:37 poll stock ? => True
2020-02-07 17:13:50,701 ERROR root:30 unhandled exception getting latest timestamp for ADI
Traceback (most recent call last):
  File "/Users/dali/workspace/ib_python/runner/services/historical_data_service.py", line 24, in get_latest_timestamp
    response = self.stub.GetLatestTimeStamp(request)
  File "/Users/dali/workspace/ib_python/runner/venv/lib/python3.7/site-packages/grpc/_channel.py", line 604, in __call__
    return _end_unary_response_blocking(state, call, False, None)
  File "/Users/dali/workspace/ib_python/runner/venv/lib/python3.7/site-packages/grpc/_channel.py", line 506, in _end_unary_response_blocking
    raise _Rendezvous(state, None, None, deadline)
grpc._channel._Rendezvous: <_Rendezvous of RPC that terminated with:
	status = StatusCode.UNAVAILABLE
	details = "failed to connect to all addresses"
	debug_error_string = "{"created":"@1581095630.701746000","description":"Failed to pick subchannel","file":"src/core/ext/filters/client_channel/client_channel.cc","file_line":3876,"referenced_errors":[{"created":"@1581095586.447667000","description":"failed to connect to all addresses","file":"src/core/ext/filters/client_channel/lb_policy/pick_first/pick_first.cc","file_line":395,"grpc_status":14}]}"
>
2020-02-07 17:13:50,702 INFO download_runner.impl.historical_runner:32 sending - historical data request : ADI 2019-01-01 2020-01-01
2020-02-07 17:13:51,686 INFO download_runner.impl.historical_runner:35 sent - historical data request : ADI 2019-01-01 2020-01-01
2020-02-07 17:13:51,686 DEBUG download_runner.impl.historical_runner:36 request accounted for...
2020-02-07 17:13:51,686 INFO download_runner.impl.historical_runner:37 status : True
2020-02-07 17:13:51,686 INFO download_runner.impl.historical_runner:42 Historical data request sent : ADI 2019-01-01 2020-01-01
2020-02-07 17:13:51,686 DEBUG download_runner.impl.historical_end_reader:37 poll stock ? => True
2020-02-07 17:13:51,686 ERROR root:30 unhandled exception getting latest timestamp for ADIL
Traceback (most recent call last):
  File "/Users/dali/workspace/ib_python/runner/services/historical_data_service.py", line 24, in get_latest_timestamp
    response = self.stub.GetLatestTimeStamp(request)
  File "/Users/dali/workspace/ib_python/runner/venv/lib/python3.7/site-packages/grpc/_channel.py", line 604, in __call__
    return _end_unary_response_blocking(state, call, False, None)
  File "/Users/dali/workspace/ib_python/runner/venv/lib/python3.7/site-packages/grpc/_channel.py", line 506, in _end_unary_response_blocking
    raise _Rendezvous(state, None, None, deadline)
grpc._channel._Rendezvous: <_Rendezvous of RPC that terminated with:
	status = StatusCode.UNAVAILABLE
	details = "failed to connect to all addresses"
	debug_error_string = "{"created":"@1581095631.686763000","description":"Failed to pick subchannel","file":"src/core/ext/filters/client_channel/client_channel.cc","file_line":3876,"referenced_errors":[{"created":"@1581095586.447667000","description":"failed to connect to all addresses","file":"src/core/ext/filters/client_channel/lb_policy/pick_first/pick_first.cc","file_line":395,"grpc_status":14}]}"
>
2020-02-07 17:13:51,687 INFO download_runner.impl.historical_runner:32 sending - historical data request : ADIL 2019-01-01 2020-01-01
2020-02-07 17:13:52,280 INFO download_runner.impl.historical_runner:35 sent - historical data request : ADIL 2019-01-01 2020-01-01
2020-02-07 17:13:52,281 DEBUG download_runner.impl.historical_runner:36 request accounted for...
2020-02-07 17:13:52,281 INFO download_runner.impl.historical_runner:37 status : True
2020-02-07 17:13:52,281 INFO download_runner.impl.historical_runner:42 Historical data request sent : ADIL 2019-01-01 2020-01-01
2020-02-07 17:13:52,281 DEBUG download_runner.impl.historical_end_reader:37 poll stock ? => True
2020-02-07 17:13:52,281 ERROR root:30 unhandled exception getting latest timestamp for ADM
Traceback (most recent call last):
  File "/Users/dali/workspace/ib_python/runner/services/historical_data_service.py", line 24, in get_latest_timestamp
    response = self.stub.GetLatestTimeStamp(request)
  File "/Users/dali/workspace/ib_python/runner/venv/lib/python3.7/site-packages/grpc/_channel.py", line 604, in __call__
    return _end_unary_response_blocking(state, call, False, None)
  File "/Users/dali/workspace/ib_python/runner/venv/lib/python3.7/site-packages/grpc/_channel.py", line 506, in _end_unary_response_blocking
    raise _Rendezvous(state, None, None, deadline)
grpc._channel._Rendezvous: <_Rendezvous of RPC that terminated with:
	status = StatusCode.UNAVAILABLE
	details = "failed to connect to all addresses"
	debug_error_string = "{"created":"@1581095632.281362000","description":"Failed to pick subchannel","file":"src/core/ext/filters/client_channel/client_channel.cc","file_line":3876,"referenced_errors":[{"created":"@1581095632.186816000","description":"failed to connect to all addresses","file":"src/core/ext/filters/client_channel/lb_policy/pick_first/pick_first.cc","file_line":395,"grpc_status":14}]}"
>
2020-02-07 17:13:52,281 INFO download_runner.impl.historical_runner:32 sending - historical data request : ADM 2019-01-01 2020-01-01
2020-02-07 17:13:55,059 INFO download_runner.impl.historical_runner:35 sent - historical data request : ADM 2019-01-01 2020-01-01
2020-02-07 17:13:55,059 DEBUG download_runner.impl.historical_runner:36 request accounted for...
2020-02-07 17:13:55,059 INFO download_runner.impl.historical_runner:37 status : True
2020-02-07 17:13:55,059 INFO download_runner.impl.historical_runner:42 Historical data request sent : ADM 2019-01-01 2020-01-01
2020-02-07 17:13:55,059 DEBUG download_runner.impl.historical_end_reader:37 poll stock ? => True
2020-02-07 17:13:55,059 ERROR root:30 unhandled exception getting latest timestamp for ADMA
Traceback (most recent call last):
  File "/Users/dali/workspace/ib_python/runner/services/historical_data_service.py", line 24, in get_latest_timestamp
    response = self.stub.GetLatestTimeStamp(request)
  File "/Users/dali/workspace/ib_python/runner/venv/lib/python3.7/site-packages/grpc/_channel.py", line 604, in __call__
    return _end_unary_response_blocking(state, call, False, None)
  File "/Users/dali/workspace/ib_python/runner/venv/lib/python3.7/site-packages/grpc/_channel.py", line 506, in _end_unary_response_blocking
    raise _Rendezvous(state, None, None, deadline)
grpc._channel._Rendezvous: <_Rendezvous of RPC that terminated with:
	status = StatusCode.UNAVAILABLE
	details = "failed to connect to all addresses"
	debug_error_string = "{"created":"@1581095635.059459000","description":"Failed to pick subchannel","file":"src/core/ext/filters/client_channel/client_channel.cc","file_line":3876,"referenced_errors":[{"created":"@1581095632.186816000","description":"failed to connect to all addresses","file":"src/core/ext/filters/client_channel/lb_policy/pick_first/pick_first.cc","file_line":395,"grpc_status":14}]}"
>
2020-02-07 17:13:55,059 INFO download_runner.impl.historical_runner:32 sending - historical data request : ADMA 2019-01-01 2020-01-01
2020-02-07 17:13:55,791 INFO download_runner.impl.historical_runner:35 sent - historical data request : ADMA 2019-01-01 2020-01-01
2020-02-07 17:13:55,791 DEBUG download_runner.impl.historical_runner:36 request accounted for...
2020-02-07 17:13:55,791 INFO download_runner.impl.historical_runner:37 status : True
2020-02-07 17:13:55,791 INFO download_runner.impl.historical_runner:42 Historical data request sent : ADMA 2019-01-01 2020-01-01
2020-02-07 17:13:55,791 DEBUG download_runner.impl.historical_end_reader:37 poll stock ? => True
2020-02-07 17:13:55,792 ERROR root:30 unhandled exception getting latest timestamp for ADME
Traceback (most recent call last):
  File "/Users/dali/workspace/ib_python/runner/services/historical_data_service.py", line 24, in get_latest_timestamp
    response = self.stub.GetLatestTimeStamp(request)
  File "/Users/dali/workspace/ib_python/runner/venv/lib/python3.7/site-packages/grpc/_channel.py", line 604, in __call__
    return _end_unary_response_blocking(state, call, False, None)
  File "/Users/dali/workspace/ib_python/runner/venv/lib/python3.7/site-packages/grpc/_channel.py", line 506, in _end_unary_response_blocking
    raise _Rendezvous(state, None, None, deadline)
grpc._channel._Rendezvous: <_Rendezvous of RPC that terminated with:
	status = StatusCode.UNAVAILABLE
	details = "failed to connect to all addresses"
	debug_error_string = "{"created":"@1581095635.791965000","description":"Failed to pick subchannel","file":"src/core/ext/filters/client_channel/client_channel.cc","file_line":3876,"referenced_errors":[{"created":"@1581095632.186816000","description":"failed to connect to all addresses","file":"src/core/ext/filters/client_channel/lb_policy/pick_first/pick_first.cc","file_line":395,"grpc_status":14}]}"
>
2020-02-07 17:13:55,792 INFO download_runner.impl.historical_runner:32 sending - historical data request : ADME 2019-01-01 2020-01-01
2020-02-07 17:14:00,353 INFO download_runner.impl.historical_runner:35 sent - historical data request : ADME 2019-01-01 2020-01-01
2020-02-07 17:14:00,353 DEBUG download_runner.impl.historical_runner:36 request accounted for...
2020-02-07 17:14:00,353 INFO download_runner.impl.historical_runner:37 status : True
2020-02-07 17:14:00,353 INFO download_runner.impl.historical_runner:42 Historical data request sent : ADME 2019-01-01 2020-01-01
2020-02-07 17:14:00,353 DEBUG download_runner.impl.historical_end_reader:37 poll stock ? => True
2020-02-07 17:14:00,354 ERROR root:30 unhandled exception getting latest timestamp for ADMP
Traceback (most recent call last):
  File "/Users/dali/workspace/ib_python/runner/services/historical_data_service.py", line 24, in get_latest_timestamp
    response = self.stub.GetLatestTimeStamp(request)
  File "/Users/dali/workspace/ib_python/runner/venv/lib/python3.7/site-packages/grpc/_channel.py", line 604, in __call__
    return _end_unary_response_blocking(state, call, False, None)
  File "/Users/dali/workspace/ib_python/runner/venv/lib/python3.7/site-packages/grpc/_channel.py", line 506, in _end_unary_response_blocking
    raise _Rendezvous(state, None, None, deadline)
grpc._channel._Rendezvous: <_Rendezvous of RPC that terminated with:
	status = StatusCode.UNAVAILABLE
	details = "failed to connect to all addresses"
	debug_error_string = "{"created":"@1581095640.354067000","description":"Failed to pick subchannel","file":"src/core/ext/filters/client_channel/client_channel.cc","file_line":3876,"referenced_errors":[{"created":"@1581095632.186816000","description":"failed to connect to all addresses","file":"src/core/ext/filters/client_channel/lb_policy/pick_first/pick_first.cc","file_line":395,"grpc_status":14}]}"
>
2020-02-07 17:14:00,354 INFO download_runner.impl.historical_runner:32 sending - historical data request : ADMP 2019-01-01 2020-01-01
2020-02-07 17:14:01,557 INFO download_runner.impl.historical_runner:35 sent - historical data request : ADMP 2019-01-01 2020-01-01
2020-02-07 17:14:01,557 DEBUG download_runner.impl.historical_runner:36 request accounted for...
2020-02-07 17:14:01,557 INFO download_runner.impl.historical_runner:37 status : True
2020-02-07 17:14:01,557 INFO download_runner.impl.historical_runner:42 Historical data request sent : ADMP 2019-01-01 2020-01-01
2020-02-07 17:14:01,557 DEBUG download_runner.impl.historical_end_reader:37 poll stock ? => True
2020-02-07 17:14:01,557 ERROR root:30 unhandled exception getting latest timestamp for ADMS
Traceback (most recent call last):
  File "/Users/dali/workspace/ib_python/runner/services/historical_data_service.py", line 24, in get_latest_timestamp
    response = self.stub.GetLatestTimeStamp(request)
  File "/Users/dali/workspace/ib_python/runner/venv/lib/python3.7/site-packages/grpc/_channel.py", line 604, in __call__
    return _end_unary_response_blocking(state, call, False, None)
  File "/Users/dali/workspace/ib_python/runner/venv/lib/python3.7/site-packages/grpc/_channel.py", line 506, in _end_unary_response_blocking
    raise _Rendezvous(state, None, None, deadline)
grpc._channel._Rendezvous: <_Rendezvous of RPC that terminated with:
	status = StatusCode.UNAVAILABLE
	details = "failed to connect to all addresses"
	debug_error_string = "{"created":"@1581095641.557462000","description":"Failed to pick subchannel","file":"src/core/ext/filters/client_channel/client_channel.cc","file_line":3876,"referenced_errors":[{"created":"@1581095632.186816000","description":"failed to connect to all addresses","file":"src/core/ext/filters/client_channel/lb_policy/pick_first/pick_first.cc","file_line":395,"grpc_status":14}]}"
>
2020-02-07 17:14:01,557 INFO download_runner.impl.historical_runner:32 sending - historical data request : ADMS 2019-01-01 2020-01-01
2020-02-07 17:14:02,255 INFO download_runner.impl.historical_runner:35 sent - historical data request : ADMS 2019-01-01 2020-01-01
2020-02-07 17:14:02,255 DEBUG download_runner.impl.historical_runner:36 request accounted for...
2020-02-07 17:14:02,255 INFO download_runner.impl.historical_runner:37 status : True
2020-02-07 17:14:02,255 INFO download_runner.impl.historical_runner:42 Historical data request sent : ADMS 2019-01-01 2020-01-01
2020-02-07 17:14:02,255 DEBUG download_runner.impl.historical_end_reader:37 poll stock ? => True
2020-02-07 17:14:02,255 ERROR root:30 unhandled exception getting latest timestamp for ADNT
Traceback (most recent call last):
  File "/Users/dali/workspace/ib_python/runner/services/historical_data_service.py", line 24, in get_latest_timestamp
    response = self.stub.GetLatestTimeStamp(request)
  File "/Users/dali/workspace/ib_python/runner/venv/lib/python3.7/site-packages/grpc/_channel.py", line 604, in __call__
    return _end_unary_response_blocking(state, call, False, None)
  File "/Users/dali/workspace/ib_python/runner/venv/lib/python3.7/site-packages/grpc/_channel.py", line 506, in _end_unary_response_blocking
    raise _Rendezvous(state, None, None, deadline)
grpc._channel._Rendezvous: <_Rendezvous of RPC that terminated with:
	status = StatusCode.UNAVAILABLE
	details = "failed to connect to all addresses"
	debug_error_string = "{"created":"@1581095642.255568000","description":"Failed to pick subchannel","file":"src/core/ext/filters/client_channel/client_channel.cc","file_line":3876,"referenced_errors":[{"created":"@1581095632.186816000","description":"failed to connect to all addresses","file":"src/core/ext/filters/client_channel/lb_policy/pick_first/pick_first.cc","file_line":395,"grpc_status":14}]}"
>
2020-02-07 17:14:02,255 INFO download_runner.impl.historical_runner:32 sending - historical data request : ADNT 2019-01-01 2020-01-01
2020-02-07 17:14:06,632 INFO download_runner.impl.historical_runner:35 sent - historical data request : ADNT 2019-01-01 2020-01-01
2020-02-07 17:14:06,632 DEBUG download_runner.impl.historical_runner:36 request accounted for...
2020-02-07 17:14:06,632 INFO download_runner.impl.historical_runner:37 status : True
2020-02-07 17:14:06,632 INFO download_runner.impl.historical_runner:42 Historical data request sent : ADNT 2019-01-01 2020-01-01
2020-02-07 17:14:06,632 DEBUG download_runner.impl.historical_end_reader:37 poll stock ? => True
2020-02-07 17:14:06,633 ERROR root:30 unhandled exception getting latest timestamp for ADP
Traceback (most recent call last):
  File "/Users/dali/workspace/ib_python/runner/services/historical_data_service.py", line 24, in get_latest_timestamp
    response = self.stub.GetLatestTimeStamp(request)
  File "/Users/dali/workspace/ib_python/runner/venv/lib/python3.7/site-packages/grpc/_channel.py", line 604, in __call__
    return _end_unary_response_blocking(state, call, False, None)
  File "/Users/dali/workspace/ib_python/runner/venv/lib/python3.7/site-packages/grpc/_channel.py", line 506, in _end_unary_response_blocking
    raise _Rendezvous(state, None, None, deadline)
grpc._channel._Rendezvous: <_Rendezvous of RPC that terminated with:
	status = StatusCode.UNAVAILABLE
	details = "failed to connect to all addresses"
	debug_error_string = "{"created":"@1581095646.633081000","description":"Failed to pick subchannel","file":"src/core/ext/filters/client_channel/client_channel.cc","file_line":3876,"referenced_errors":[{"created":"@1581095632.186816000","description":"failed to connect to all addresses","file":"src/core/ext/filters/client_channel/lb_policy/pick_first/pick_first.cc","file_line":395,"grpc_status":14}]}"
>
2020-02-07 17:14:06,633 INFO download_runner.impl.historical_runner:32 sending - historical data request : ADP 2019-01-01 2020-01-01
2020-02-07 17:14:07,252 INFO download_runner.impl.historical_runner:35 sent - historical data request : ADP 2019-01-01 2020-01-01
2020-02-07 17:14:07,252 DEBUG download_runner.impl.historical_runner:36 request accounted for...
2020-02-07 17:14:07,252 INFO download_runner.impl.historical_runner:37 status : True
2020-02-07 17:14:07,252 INFO download_runner.impl.historical_runner:42 Historical data request sent : ADP 2019-01-01 2020-01-01
2020-02-07 17:14:07,252 DEBUG download_runner.impl.historical_end_reader:37 poll stock ? => True
2020-02-07 17:14:07,252 ERROR root:30 unhandled exception getting latest timestamp for ADPT
Traceback (most recent call last):
  File "/Users/dali/workspace/ib_python/runner/services/historical_data_service.py", line 24, in get_latest_timestamp
    response = self.stub.GetLatestTimeStamp(request)
  File "/Users/dali/workspace/ib_python/runner/venv/lib/python3.7/site-packages/grpc/_channel.py", line 604, in __call__
    return _end_unary_response_blocking(state, call, False, None)
  File "/Users/dali/workspace/ib_python/runner/venv/lib/python3.7/site-packages/grpc/_channel.py", line 506, in _end_unary_response_blocking
    raise _Rendezvous(state, None, None, deadline)
grpc._channel._Rendezvous: <_Rendezvous of RPC that terminated with:
	status = StatusCode.UNAVAILABLE
	details = "failed to connect to all addresses"
	debug_error_string = "{"created":"@1581095647.252667000","description":"Failed to pick subchannel","file":"src/core/ext/filters/client_channel/client_channel.cc","file_line":3876,"referenced_errors":[{"created":"@1581095632.186816000","description":"failed to connect to all addresses","file":"src/core/ext/filters/client_channel/lb_policy/pick_first/pick_first.cc","file_line":395,"grpc_status":14}]}"
>
2020-02-07 17:14:07,252 INFO download_runner.impl.historical_runner:32 sending - historical data request : ADPT 2019-01-01 2020-01-01
2020-02-07 17:14:12,165 INFO download_runner.impl.historical_runner:35 sent - historical data request : ADPT 2019-01-01 2020-01-01
2020-02-07 17:14:12,165 DEBUG download_runner.impl.historical_runner:36 request accounted for...
2020-02-07 17:14:12,165 INFO download_runner.impl.historical_runner:37 status : True
2020-02-07 17:14:12,165 INFO download_runner.impl.historical_runner:42 Historical data request sent : ADPT 2019-01-01 2020-01-01
2020-02-07 17:14:12,165 DEBUG download_runner.impl.historical_end_reader:37 poll stock ? => True
2020-02-07 17:14:12,166 ERROR root:30 unhandled exception getting latest timestamp for ADRA
Traceback (most recent call last):
  File "/Users/dali/workspace/ib_python/runner/services/historical_data_service.py", line 24, in get_latest_timestamp
    response = self.stub.GetLatestTimeStamp(request)
  File "/Users/dali/workspace/ib_python/runner/venv/lib/python3.7/site-packages/grpc/_channel.py", line 604, in __call__
    return _end_unary_response_blocking(state, call, False, None)
  File "/Users/dali/workspace/ib_python/runner/venv/lib/python3.7/site-packages/grpc/_channel.py", line 506, in _end_unary_response_blocking
    raise _Rendezvous(state, None, None, deadline)
grpc._channel._Rendezvous: <_Rendezvous of RPC that terminated with:
	status = StatusCode.UNAVAILABLE
	details = "failed to connect to all addresses"
	debug_error_string = "{"created":"@1581095652.166075000","description":"Failed to pick subchannel","file":"src/core/ext/filters/client_channel/client_channel.cc","file_line":3876,"referenced_errors":[{"created":"@1581095632.186816000","description":"failed to connect to all addresses","file":"src/core/ext/filters/client_channel/lb_policy/pick_first/pick_first.cc","file_line":395,"grpc_status":14}]}"
>
2020-02-07 17:14:12,166 INFO download_runner.impl.historical_runner:32 sending - historical data request : ADRA 2019-01-01 2020-01-01
2020-02-07 17:14:24,092 INFO download_runner.impl.historical_runner:35 sent - historical data request : ADRA 2019-01-01 2020-01-01
2020-02-07 17:14:24,093 DEBUG download_runner.impl.historical_runner:36 request accounted for...
2020-02-07 17:14:24,093 INFO download_runner.impl.historical_runner:37 status : True
2020-02-07 17:14:24,093 INFO download_runner.impl.historical_runner:42 Historical data request sent : ADRA 2019-01-01 2020-01-01
2020-02-07 17:14:24,093 DEBUG download_runner.impl.historical_end_reader:37 poll stock ? => True
2020-02-07 17:14:24,094 ERROR root:30 unhandled exception getting latest timestamp for ADRD
Traceback (most recent call last):
  File "/Users/dali/workspace/ib_python/runner/services/historical_data_service.py", line 24, in get_latest_timestamp
    response = self.stub.GetLatestTimeStamp(request)
  File "/Users/dali/workspace/ib_python/runner/venv/lib/python3.7/site-packages/grpc/_channel.py", line 604, in __call__
    return _end_unary_response_blocking(state, call, False, None)
  File "/Users/dali/workspace/ib_python/runner/venv/lib/python3.7/site-packages/grpc/_channel.py", line 506, in _end_unary_response_blocking
    raise _Rendezvous(state, None, None, deadline)
grpc._channel._Rendezvous: <_Rendezvous of RPC that terminated with:
	status = StatusCode.UNAVAILABLE
	details = "failed to connect to all addresses"
	debug_error_string = "{"created":"@1581095664.094036000","description":"Failed to pick subchannel","file":"src/core/ext/filters/client_channel/client_channel.cc","file_line":3876,"referenced_errors":[{"created":"@1581095632.186816000","description":"failed to connect to all addresses","file":"src/core/ext/filters/client_channel/lb_policy/pick_first/pick_first.cc","file_line":395,"grpc_status":14}]}"
>
2020-02-07 17:14:24,094 INFO download_runner.impl.historical_runner:32 sending - historical data request : ADRD 2019-01-01 2020-01-01
2020-02-07 17:14:36,177 INFO download_runner.impl.historical_runner:35 sent - historical data request : ADRD 2019-01-01 2020-01-01
2020-02-07 17:14:36,177 DEBUG download_runner.impl.historical_runner:36 request accounted for...
2020-02-07 17:14:36,177 INFO download_runner.impl.historical_runner:37 status : True
2020-02-07 17:14:36,178 INFO download_runner.impl.historical_runner:42 Historical data request sent : ADRD 2019-01-01 2020-01-01
2020-02-07 17:14:36,178 DEBUG download_runner.impl.historical_end_reader:37 poll stock ? => True
2020-02-07 17:14:36,178 ERROR root:30 unhandled exception getting latest timestamp for ADRE
Traceback (most recent call last):
  File "/Users/dali/workspace/ib_python/runner/services/historical_data_service.py", line 24, in get_latest_timestamp
    response = self.stub.GetLatestTimeStamp(request)
  File "/Users/dali/workspace/ib_python/runner/venv/lib/python3.7/site-packages/grpc/_channel.py", line 604, in __call__
    return _end_unary_response_blocking(state, call, False, None)
  File "/Users/dali/workspace/ib_python/runner/venv/lib/python3.7/site-packages/grpc/_channel.py", line 506, in _end_unary_response_blocking
    raise _Rendezvous(state, None, None, deadline)
grpc._channel._Rendezvous: <_Rendezvous of RPC that terminated with:
	status = StatusCode.UNAVAILABLE
	details = "failed to connect to all addresses"
	debug_error_string = "{"created":"@1581095676.178340000","description":"Failed to pick subchannel","file":"src/core/ext/filters/client_channel/client_channel.cc","file_line":3876,"referenced_errors":[{"created":"@1581095632.186816000","description":"failed to connect to all addresses","file":"src/core/ext/filters/client_channel/lb_policy/pick_first/pick_first.cc","file_line":395,"grpc_status":14}]}"
>
2020-02-07 17:14:36,178 INFO download_runner.impl.historical_runner:32 sending - historical data request : ADRE 2019-01-01 2020-01-01
2020-02-07 17:14:48,273 INFO download_runner.impl.historical_runner:35 sent - historical data request : ADRE 2019-01-01 2020-01-01
2020-02-07 17:14:48,273 DEBUG download_runner.impl.historical_runner:36 request accounted for...
2020-02-07 17:14:48,273 INFO download_runner.impl.historical_runner:37 status : True
2020-02-07 17:14:48,273 INFO download_runner.impl.historical_runner:42 Historical data request sent : ADRE 2019-01-01 2020-01-01
2020-02-07 17:14:48,273 DEBUG download_runner.impl.historical_end_reader:37 poll stock ? => True
2020-02-07 17:14:48,273 ERROR root:30 unhandled exception getting latest timestamp for ADRO
Traceback (most recent call last):
  File "/Users/dali/workspace/ib_python/runner/services/historical_data_service.py", line 24, in get_latest_timestamp
    response = self.stub.GetLatestTimeStamp(request)
  File "/Users/dali/workspace/ib_python/runner/venv/lib/python3.7/site-packages/grpc/_channel.py", line 604, in __call__
    return _end_unary_response_blocking(state, call, False, None)
  File "/Users/dali/workspace/ib_python/runner/venv/lib/python3.7/site-packages/grpc/_channel.py", line 506, in _end_unary_response_blocking
    raise _Rendezvous(state, None, None, deadline)
grpc._channel._Rendezvous: <_Rendezvous of RPC that terminated with:
	status = StatusCode.UNAVAILABLE
	details = "failed to connect to all addresses"
	debug_error_string = "{"created":"@1581095688.273782000","description":"Failed to pick subchannel","file":"src/core/ext/filters/client_channel/client_channel.cc","file_line":3876,"referenced_errors":[{"created":"@1581095632.186816000","description":"failed to connect to all addresses","file":"src/core/ext/filters/client_channel/lb_policy/pick_first/pick_first.cc","file_line":395,"grpc_status":14}]}"
>
2020-02-07 17:14:48,274 INFO download_runner.impl.historical_runner:32 sending - historical data request : ADRO 2019-01-01 2020-01-01
2020-02-07 17:14:49,008 INFO download_runner.impl.historical_runner:35 sent - historical data request : ADRO 2019-01-01 2020-01-01
2020-02-07 17:14:49,008 DEBUG download_runner.impl.historical_runner:36 request accounted for...
2020-02-07 17:14:49,008 INFO download_runner.impl.historical_runner:37 status : True
2020-02-07 17:14:49,008 INFO download_runner.impl.historical_runner:42 Historical data request sent : ADRO 2019-01-01 2020-01-01
2020-02-07 17:14:49,008 DEBUG download_runner.impl.historical_end_reader:37 poll stock ? => True
2020-02-07 17:14:49,009 ERROR root:30 unhandled exception getting latest timestamp for ADRU
Traceback (most recent call last):
  File "/Users/dali/workspace/ib_python/runner/services/historical_data_service.py", line 24, in get_latest_timestamp
    response = self.stub.GetLatestTimeStamp(request)
  File "/Users/dali/workspace/ib_python/runner/venv/lib/python3.7/site-packages/grpc/_channel.py", line 604, in __call__
    return _end_unary_response_blocking(state, call, False, None)
  File "/Users/dali/workspace/ib_python/runner/venv/lib/python3.7/site-packages/grpc/_channel.py", line 506, in _end_unary_response_blocking
    raise _Rendezvous(state, None, None, deadline)
grpc._channel._Rendezvous: <_Rendezvous of RPC that terminated with:
	status = StatusCode.UNAVAILABLE
	details = "failed to connect to all addresses"
	debug_error_string = "{"created":"@1581095689.009123000","description":"Failed to pick subchannel","file":"src/core/ext/filters/client_channel/client_channel.cc","file_line":3876,"referenced_errors":[{"created":"@1581095632.186816000","description":"failed to connect to all addresses","file":"src/core/ext/filters/client_channel/lb_policy/pick_first/pick_first.cc","file_line":395,"grpc_status":14}]}"
>
2020-02-07 17:14:49,009 INFO download_runner.impl.historical_runner:32 sending - historical data request : ADRU 2019-01-01 2020-01-01
2020-02-07 17:14:49,241 INFO download_runner.impl.historical_runner:35 sent - historical data request : ADRU 2019-01-01 2020-01-01
2020-02-07 17:14:49,241 DEBUG download_runner.impl.historical_runner:36 request accounted for...
2020-02-07 17:14:49,241 INFO download_runner.impl.historical_runner:37 status : True
2020-02-07 17:14:49,241 INFO download_runner.impl.historical_runner:42 Historical data request sent : ADRU 2019-01-01 2020-01-01
2020-02-07 17:14:49,241 DEBUG download_runner.impl.historical_end_reader:37 poll stock ? => True
2020-02-07 17:14:49,241 ERROR root:30 unhandled exception getting latest timestamp for ADS
Traceback (most recent call last):
  File "/Users/dali/workspace/ib_python/runner/services/historical_data_service.py", line 24, in get_latest_timestamp
    response = self.stub.GetLatestTimeStamp(request)
  File "/Users/dali/workspace/ib_python/runner/venv/lib/python3.7/site-packages/grpc/_channel.py", line 604, in __call__
    return _end_unary_response_blocking(state, call, False, None)
  File "/Users/dali/workspace/ib_python/runner/venv/lib/python3.7/site-packages/grpc/_channel.py", line 506, in _end_unary_response_blocking
    raise _Rendezvous(state, None, None, deadline)
grpc._channel._Rendezvous: <_Rendezvous of RPC that terminated with:
	status = StatusCode.UNAVAILABLE
	details = "failed to connect to all addresses"
	debug_error_string = "{"created":"@1581095689.241528000","description":"Failed to pick subchannel","file":"src/core/ext/filters/client_channel/client_channel.cc","file_line":3876,"referenced_errors":[{"created":"@1581095632.186816000","description":"failed to connect to all addresses","file":"src/core/ext/filters/client_channel/lb_policy/pick_first/pick_first.cc","file_line":395,"grpc_status":14}]}"
>
2020-02-07 17:14:49,242 INFO download_runner.impl.historical_runner:32 sending - historical data request : ADS 2019-01-01 2020-01-01
2020-02-07 17:14:50,102 INFO download_runner.impl.historical_runner:35 sent - historical data request : ADS 2019-01-01 2020-01-01
2020-02-07 17:14:50,102 DEBUG download_runner.impl.historical_runner:36 request accounted for...
2020-02-07 17:14:50,102 INFO download_runner.impl.historical_runner:37 status : True
2020-02-07 17:14:50,102 INFO download_runner.impl.historical_runner:42 Historical data request sent : ADS 2019-01-01 2020-01-01
2020-02-07 17:14:50,102 DEBUG download_runner.impl.historical_end_reader:37 poll stock ? => True
2020-02-07 17:14:50,103 ERROR root:30 unhandled exception getting latest timestamp for ADSK
Traceback (most recent call last):
  File "/Users/dali/workspace/ib_python/runner/services/historical_data_service.py", line 24, in get_latest_timestamp
    response = self.stub.GetLatestTimeStamp(request)
  File "/Users/dali/workspace/ib_python/runner/venv/lib/python3.7/site-packages/grpc/_channel.py", line 604, in __call__
    return _end_unary_response_blocking(state, call, False, None)
  File "/Users/dali/workspace/ib_python/runner/venv/lib/python3.7/site-packages/grpc/_channel.py", line 506, in _end_unary_response_blocking
    raise _Rendezvous(state, None, None, deadline)
grpc._channel._Rendezvous: <_Rendezvous of RPC that terminated with:
	status = StatusCode.UNAVAILABLE
	details = "failed to connect to all addresses"
	debug_error_string = "{"created":"@1581095690.103022000","description":"Failed to pick subchannel","file":"src/core/ext/filters/client_channel/client_channel.cc","file_line":3876,"referenced_errors":[{"created":"@1581095632.186816000","description":"failed to connect to all addresses","file":"src/core/ext/filters/client_channel/lb_policy/pick_first/pick_first.cc","file_line":395,"grpc_status":14}]}"
>
2020-02-07 17:14:50,103 INFO download_runner.impl.historical_runner:32 sending - historical data request : ADSK 2019-01-01 2020-01-01
2020-02-07 17:14:54,161 INFO download_runner.impl.historical_runner:35 sent - historical data request : ADSK 2019-01-01 2020-01-01
2020-02-07 17:14:54,161 DEBUG download_runner.impl.historical_runner:36 request accounted for...
2020-02-07 17:14:54,162 INFO download_runner.impl.historical_runner:37 status : True
2020-02-07 17:14:54,162 INFO download_runner.impl.historical_runner:42 Historical data request sent : ADSK 2019-01-01 2020-01-01
2020-02-07 17:14:54,162 DEBUG download_runner.impl.historical_end_reader:37 poll stock ? => True
2020-02-07 17:14:54,164 ERROR root:30 unhandled exception getting latest timestamp for ADSW
Traceback (most recent call last):
  File "/Users/dali/workspace/ib_python/runner/services/historical_data_service.py", line 24, in get_latest_timestamp
    response = self.stub.GetLatestTimeStamp(request)
  File "/Users/dali/workspace/ib_python/runner/venv/lib/python3.7/site-packages/grpc/_channel.py", line 604, in __call__
    return _end_unary_response_blocking(state, call, False, None)
  File "/Users/dali/workspace/ib_python/runner/venv/lib/python3.7/site-packages/grpc/_channel.py", line 506, in _end_unary_response_blocking
    raise _Rendezvous(state, None, None, deadline)
grpc._channel._Rendezvous: <_Rendezvous of RPC that terminated with:
	status = StatusCode.UNAVAILABLE
	details = "failed to connect to all addresses"
	debug_error_string = "{"created":"@1581095694.163657000","description":"Failed to pick subchannel","file":"src/core/ext/filters/client_channel/client_channel.cc","file_line":3876,"referenced_errors":[{"created":"@1581095632.186816000","description":"failed to connect to all addresses","file":"src/core/ext/filters/client_channel/lb_policy/pick_first/pick_first.cc","file_line":395,"grpc_status":14}]}"
>
2020-02-07 17:14:54,165 INFO download_runner.impl.historical_runner:32 sending - historical data request : ADSW 2019-01-01 2020-01-01
2020-02-07 17:14:54,978 INFO download_runner.impl.historical_runner:35 sent - historical data request : ADSW 2019-01-01 2020-01-01
2020-02-07 17:14:54,978 DEBUG download_runner.impl.historical_runner:36 request accounted for...
2020-02-07 17:14:54,978 INFO download_runner.impl.historical_runner:37 status : True
2020-02-07 17:14:54,978 INFO download_runner.impl.historical_runner:42 Historical data request sent : ADSW 2019-01-01 2020-01-01
2020-02-07 17:14:54,978 DEBUG download_runner.impl.historical_end_reader:37 poll stock ? => True
2020-02-07 17:14:54,978 ERROR root:30 unhandled exception getting latest timestamp for ADT
Traceback (most recent call last):
  File "/Users/dali/workspace/ib_python/runner/services/historical_data_service.py", line 24, in get_latest_timestamp
    response = self.stub.GetLatestTimeStamp(request)
  File "/Users/dali/workspace/ib_python/runner/venv/lib/python3.7/site-packages/grpc/_channel.py", line 604, in __call__
    return _end_unary_response_blocking(state, call, False, None)
  File "/Users/dali/workspace/ib_python/runner/venv/lib/python3.7/site-packages/grpc/_channel.py", line 506, in _end_unary_response_blocking
    raise _Rendezvous(state, None, None, deadline)
grpc._channel._Rendezvous: <_Rendezvous of RPC that terminated with:
	status = StatusCode.UNAVAILABLE
	details = "failed to connect to all addresses"
	debug_error_string = "{"created":"@1581095694.978671000","description":"Failed to pick subchannel","file":"src/core/ext/filters/client_channel/client_channel.cc","file_line":3876,"referenced_errors":[{"created":"@1581095632.186816000","description":"failed to connect to all addresses","file":"src/core/ext/filters/client_channel/lb_policy/pick_first/pick_first.cc","file_line":395,"grpc_status":14}]}"
>
2020-02-07 17:14:54,979 INFO download_runner.impl.historical_runner:32 sending - historical data request : ADT 2019-01-01 2020-01-01
2020-02-07 17:14:59,979 INFO download_runner.impl.historical_runner:35 sent - historical data request : ADT 2019-01-01 2020-01-01
2020-02-07 17:14:59,979 DEBUG download_runner.impl.historical_runner:36 request accounted for...
2020-02-07 17:14:59,979 INFO download_runner.impl.historical_runner:37 status : True
2020-02-07 17:14:59,980 INFO download_runner.impl.historical_runner:42 Historical data request sent : ADT 2019-01-01 2020-01-01
2020-02-07 17:14:59,980 DEBUG download_runner.impl.historical_end_reader:37 poll stock ? => True
2020-02-07 17:14:59,980 ERROR root:30 unhandled exception getting latest timestamp for ADTN
Traceback (most recent call last):
  File "/Users/dali/workspace/ib_python/runner/services/historical_data_service.py", line 24, in get_latest_timestamp
    response = self.stub.GetLatestTimeStamp(request)
  File "/Users/dali/workspace/ib_python/runner/venv/lib/python3.7/site-packages/grpc/_channel.py", line 604, in __call__
    return _end_unary_response_blocking(state, call, False, None)
  File "/Users/dali/workspace/ib_python/runner/venv/lib/python3.7/site-packages/grpc/_channel.py", line 506, in _end_unary_response_blocking
    raise _Rendezvous(state, None, None, deadline)
grpc._channel._Rendezvous: <_Rendezvous of RPC that terminated with:
	status = StatusCode.UNAVAILABLE
	details = "failed to connect to all addresses"
	debug_error_string = "{"created":"@1581095699.980315000","description":"Failed to pick subchannel","file":"src/core/ext/filters/client_channel/client_channel.cc","file_line":3876,"referenced_errors":[{"created":"@1581095632.186816000","description":"failed to connect to all addresses","file":"src/core/ext/filters/client_channel/lb_policy/pick_first/pick_first.cc","file_line":395,"grpc_status":14}]}"
>
2020-02-07 17:14:59,980 INFO download_runner.impl.historical_runner:32 sending - historical data request : ADTN 2019-01-01 2020-01-01
2020-02-07 17:15:00,720 INFO download_runner.impl.historical_runner:35 sent - historical data request : ADTN 2019-01-01 2020-01-01
2020-02-07 17:15:00,720 DEBUG download_runner.impl.historical_runner:36 request accounted for...
2020-02-07 17:15:00,720 INFO download_runner.impl.historical_runner:37 status : True
2020-02-07 17:15:00,720 INFO download_runner.impl.historical_runner:42 Historical data request sent : ADTN 2019-01-01 2020-01-01
2020-02-07 17:15:00,720 DEBUG download_runner.impl.historical_end_reader:37 poll stock ? => True
2020-02-07 17:15:00,721 ERROR root:30 unhandled exception getting latest timestamp for ADUS
Traceback (most recent call last):
  File "/Users/dali/workspace/ib_python/runner/services/historical_data_service.py", line 24, in get_latest_timestamp
    response = self.stub.GetLatestTimeStamp(request)
  File "/Users/dali/workspace/ib_python/runner/venv/lib/python3.7/site-packages/grpc/_channel.py", line 604, in __call__
    return _end_unary_response_blocking(state, call, False, None)
  File "/Users/dali/workspace/ib_python/runner/venv/lib/python3.7/site-packages/grpc/_channel.py", line 506, in _end_unary_response_blocking
    raise _Rendezvous(state, None, None, deadline)
grpc._channel._Rendezvous: <_Rendezvous of RPC that terminated with:
	status = StatusCode.UNAVAILABLE
	details = "failed to connect to all addresses"
	debug_error_string = "{"created":"@1581095700.721212000","description":"Failed to pick subchannel","file":"src/core/ext/filters/client_channel/client_channel.cc","file_line":3876,"referenced_errors":[{"created":"@1581095632.186816000","description":"failed to connect to all addresses","file":"src/core/ext/filters/client_channel/lb_policy/pick_first/pick_first.cc","file_line":395,"grpc_status":14}]}"
>
2020-02-07 17:15:00,721 INFO download_runner.impl.historical_runner:32 sending - historical data request : ADUS 2019-01-01 2020-01-01
2020-02-07 17:15:05,939 INFO download_runner.impl.historical_runner:35 sent - historical data request : ADUS 2019-01-01 2020-01-01
2020-02-07 17:15:05,940 DEBUG download_runner.impl.historical_runner:36 request accounted for...
2020-02-07 17:15:05,940 INFO download_runner.impl.historical_runner:37 status : True
2020-02-07 17:15:05,940 INFO download_runner.impl.historical_runner:42 Historical data request sent : ADUS 2019-01-01 2020-01-01
2020-02-07 17:15:05,940 DEBUG download_runner.impl.historical_end_reader:37 poll stock ? => True
2020-02-07 17:15:05,940 ERROR root:30 unhandled exception getting latest timestamp for ADVM
Traceback (most recent call last):
  File "/Users/dali/workspace/ib_python/runner/services/historical_data_service.py", line 24, in get_latest_timestamp
    response = self.stub.GetLatestTimeStamp(request)
  File "/Users/dali/workspace/ib_python/runner/venv/lib/python3.7/site-packages/grpc/_channel.py", line 604, in __call__
    return _end_unary_response_blocking(state, call, False, None)
  File "/Users/dali/workspace/ib_python/runner/venv/lib/python3.7/site-packages/grpc/_channel.py", line 506, in _end_unary_response_blocking
    raise _Rendezvous(state, None, None, deadline)
grpc._channel._Rendezvous: <_Rendezvous of RPC that terminated with:
	status = StatusCode.UNAVAILABLE
	details = "failed to connect to all addresses"
	debug_error_string = "{"created":"@1581095705.940506000","description":"Failed to pick subchannel","file":"src/core/ext/filters/client_channel/client_channel.cc","file_line":3876,"referenced_errors":[{"created":"@1581095632.186816000","description":"failed to connect to all addresses","file":"src/core/ext/filters/client_channel/lb_policy/pick_first/pick_first.cc","file_line":395,"grpc_status":14}]}"
>
2020-02-07 17:15:05,940 INFO download_runner.impl.historical_runner:32 sending - historical data request : ADVM 2019-01-01 2020-01-01
2020-02-07 17:15:06,173 INFO download_runner.impl.historical_runner:35 sent - historical data request : ADVM 2019-01-01 2020-01-01
2020-02-07 17:15:06,173 DEBUG download_runner.impl.historical_runner:36 request accounted for...
2020-02-07 17:15:06,173 INFO download_runner.impl.historical_runner:37 status : True
2020-02-07 17:15:06,173 INFO download_runner.impl.historical_runner:42 Historical data request sent : ADVM 2019-01-01 2020-01-01
2020-02-07 17:15:06,173 DEBUG download_runner.impl.historical_end_reader:37 poll stock ? => True
2020-02-07 17:15:06,174 ERROR root:30 unhandled exception getting latest timestamp for ADX
Traceback (most recent call last):
  File "/Users/dali/workspace/ib_python/runner/services/historical_data_service.py", line 24, in get_latest_timestamp
    response = self.stub.GetLatestTimeStamp(request)
  File "/Users/dali/workspace/ib_python/runner/venv/lib/python3.7/site-packages/grpc/_channel.py", line 604, in __call__
    return _end_unary_response_blocking(state, call, False, None)
  File "/Users/dali/workspace/ib_python/runner/venv/lib/python3.7/site-packages/grpc/_channel.py", line 506, in _end_unary_response_blocking
    raise _Rendezvous(state, None, None, deadline)
grpc._channel._Rendezvous: <_Rendezvous of RPC that terminated with:
	status = StatusCode.UNAVAILABLE
	details = "failed to connect to all addresses"
	debug_error_string = "{"created":"@1581095706.174081000","description":"Failed to pick subchannel","file":"src/core/ext/filters/client_channel/client_channel.cc","file_line":3876,"referenced_errors":[{"created":"@1581095632.186816000","description":"failed to connect to all addresses","file":"src/core/ext/filters/client_channel/lb_policy/pick_first/pick_first.cc","file_line":395,"grpc_status":14}]}"
>
2020-02-07 17:15:06,174 INFO download_runner.impl.historical_runner:32 sending - historical data request : ADX 2019-01-01 2020-01-01
