2020-02-08 13:33:04,483 DEBUG download_runner.impl.historical_end_reader:37 poll stock ? => True
2020-02-08 13:33:04,616 ERROR root:30 unhandled exception getting latest timestamp for ACIA
Traceback (most recent call last):
  File "/Users/dali/workspace/ib_python/runner/services/historical_data_service.py", line 24, in get_latest_timestamp
    response = self.stub.GetLatestTimeStamp(request)
  File "/Users/dali/workspace/ib_python/runner/venv/lib/python3.7/site-packages/grpc/_channel.py", line 604, in __call__
    return _end_unary_response_blocking(state, call, False, None)
  File "/Users/dali/workspace/ib_python/runner/venv/lib/python3.7/site-packages/grpc/_channel.py", line 506, in _end_unary_response_blocking
    raise _Rendezvous(state, None, None, deadline)
grpc._channel._Rendezvous: <_Rendezvous of RPC that terminated with:
	status = StatusCode.UNAVAILABLE
	details = "failed to connect to all addresses"
	debug_error_string = "{"created":"@1581168784.616383000","description":"Failed to pick subchannel","file":"src/core/ext/filters/client_channel/client_channel.cc","file_line":3876,"referenced_errors":[{"created":"@1581168784.616382000","description":"failed to connect to all addresses","file":"src/core/ext/filters/client_channel/lb_policy/pick_first/pick_first.cc","file_line":395,"grpc_status":14}]}"
>
2020-02-08 13:33:04,618 INFO download_runner.impl.historical_runner:32 sending - historical data request : ACIA 2019-12-01 2020-01-01
2020-02-08 13:33:06,327 INFO download_runner.impl.historical_runner:35 sent - historical data request : ACIA 2019-12-01 2020-01-01
2020-02-08 13:33:06,327 DEBUG download_runner.impl.historical_runner:36 request accounted for...
2020-02-08 13:33:06,327 INFO download_runner.impl.historical_runner:37 status : True
2020-02-08 13:33:06,327 INFO download_runner.impl.historical_runner:42 Historical data request sent : ACIA 2019-12-01 2020-01-01
2020-02-08 13:33:06,327 DEBUG download_runner.impl.historical_end_reader:37 poll stock ? => True
2020-02-08 13:33:06,327 ERROR root:30 unhandled exception getting latest timestamp for A
Traceback (most recent call last):
  File "/Users/dali/workspace/ib_python/runner/services/historical_data_service.py", line 24, in get_latest_timestamp
    response = self.stub.GetLatestTimeStamp(request)
  File "/Users/dali/workspace/ib_python/runner/venv/lib/python3.7/site-packages/grpc/_channel.py", line 604, in __call__
    return _end_unary_response_blocking(state, call, False, None)
  File "/Users/dali/workspace/ib_python/runner/venv/lib/python3.7/site-packages/grpc/_channel.py", line 506, in _end_unary_response_blocking
    raise _Rendezvous(state, None, None, deadline)
grpc._channel._Rendezvous: <_Rendezvous of RPC that terminated with:
	status = StatusCode.UNAVAILABLE
	details = "failed to connect to all addresses"
	debug_error_string = "{"created":"@1581168786.327644000","description":"Failed to pick subchannel","file":"src/core/ext/filters/client_channel/client_channel.cc","file_line":3876,"referenced_errors":[{"created":"@1581168786.327642000","description":"failed to connect to all addresses","file":"src/core/ext/filters/client_channel/lb_policy/pick_first/pick_first.cc","file_line":395,"grpc_status":14}]}"
>
2020-02-08 13:33:06,327 INFO download_runner.impl.historical_runner:32 sending - historical data request : A 2019-12-01 2020-01-01
2020-02-08 13:33:07,291 INFO download_runner.impl.historical_runner:35 sent - historical data request : A 2019-12-01 2020-01-01
2020-02-08 13:33:07,291 DEBUG download_runner.impl.historical_runner:36 request accounted for...
2020-02-08 13:33:07,291 INFO download_runner.impl.historical_runner:37 status : True
2020-02-08 13:33:07,291 INFO download_runner.impl.historical_runner:42 Historical data request sent : A 2019-12-01 2020-01-01
2020-02-08 13:33:07,291 DEBUG download_runner.impl.historical_end_reader:37 poll stock ? => True
2020-02-08 13:33:07,291 ERROR root:30 unhandled exception getting latest timestamp for AA
Traceback (most recent call last):
  File "/Users/dali/workspace/ib_python/runner/services/historical_data_service.py", line 24, in get_latest_timestamp
    response = self.stub.GetLatestTimeStamp(request)
  File "/Users/dali/workspace/ib_python/runner/venv/lib/python3.7/site-packages/grpc/_channel.py", line 604, in __call__
    return _end_unary_response_blocking(state, call, False, None)
  File "/Users/dali/workspace/ib_python/runner/venv/lib/python3.7/site-packages/grpc/_channel.py", line 506, in _end_unary_response_blocking
    raise _Rendezvous(state, None, None, deadline)
grpc._channel._Rendezvous: <_Rendezvous of RPC that terminated with:
	status = StatusCode.UNAVAILABLE
	details = "failed to connect to all addresses"
	debug_error_string = "{"created":"@1581168787.291730000","description":"Failed to pick subchannel","file":"src/core/ext/filters/client_channel/client_channel.cc","file_line":3876,"referenced_errors":[{"created":"@1581168786.327642000","description":"failed to connect to all addresses","file":"src/core/ext/filters/client_channel/lb_policy/pick_first/pick_first.cc","file_line":395,"grpc_status":14}]}"
>
2020-02-08 13:33:07,292 INFO download_runner.impl.historical_runner:32 sending - historical data request : AA 2019-12-01 2020-01-01
2020-02-08 13:33:08,447 INFO download_runner.impl.historical_runner:35 sent - historical data request : AA 2019-12-01 2020-01-01
2020-02-08 13:33:08,447 DEBUG download_runner.impl.historical_runner:36 request accounted for...
2020-02-08 13:33:08,447 INFO download_runner.impl.historical_runner:37 status : True
2020-02-08 13:33:08,447 INFO download_runner.impl.historical_runner:42 Historical data request sent : AA 2019-12-01 2020-01-01
2020-02-08 13:33:08,447 DEBUG download_runner.impl.historical_end_reader:37 poll stock ? => True
2020-02-08 13:33:08,448 ERROR root:30 unhandled exception getting latest timestamp for AAAU
Traceback (most recent call last):
  File "/Users/dali/workspace/ib_python/runner/services/historical_data_service.py", line 24, in get_latest_timestamp
    response = self.stub.GetLatestTimeStamp(request)
  File "/Users/dali/workspace/ib_python/runner/venv/lib/python3.7/site-packages/grpc/_channel.py", line 604, in __call__
    return _end_unary_response_blocking(state, call, False, None)
  File "/Users/dali/workspace/ib_python/runner/venv/lib/python3.7/site-packages/grpc/_channel.py", line 506, in _end_unary_response_blocking
    raise _Rendezvous(state, None, None, deadline)
grpc._channel._Rendezvous: <_Rendezvous of RPC that terminated with:
	status = StatusCode.UNAVAILABLE
	details = "failed to connect to all addresses"
	debug_error_string = "{"created":"@1581168788.448012000","description":"Failed to pick subchannel","file":"src/core/ext/filters/client_channel/client_channel.cc","file_line":3876,"referenced_errors":[{"created":"@1581168788.448010000","description":"failed to connect to all addresses","file":"src/core/ext/filters/client_channel/lb_policy/pick_first/pick_first.cc","file_line":395,"grpc_status":14}]}"
>
2020-02-08 13:33:08,448 INFO download_runner.impl.historical_runner:32 sending - historical data request : AAAU 2019-12-01 2020-01-01
2020-02-08 13:33:09,585 INFO download_runner.impl.historical_runner:35 sent - historical data request : AAAU 2019-12-01 2020-01-01
2020-02-08 13:33:09,585 DEBUG download_runner.impl.historical_runner:36 request accounted for...
2020-02-08 13:33:09,585 INFO download_runner.impl.historical_runner:37 status : True
2020-02-08 13:33:09,585 INFO download_runner.impl.historical_runner:42 Historical data request sent : AAAU 2019-12-01 2020-01-01
2020-02-08 13:33:09,585 DEBUG download_runner.impl.historical_end_reader:37 poll stock ? => True
2020-02-08 13:33:09,585 ERROR root:30 unhandled exception getting latest timestamp for AACG
Traceback (most recent call last):
  File "/Users/dali/workspace/ib_python/runner/services/historical_data_service.py", line 24, in get_latest_timestamp
    response = self.stub.GetLatestTimeStamp(request)
  File "/Users/dali/workspace/ib_python/runner/venv/lib/python3.7/site-packages/grpc/_channel.py", line 604, in __call__
    return _end_unary_response_blocking(state, call, False, None)
  File "/Users/dali/workspace/ib_python/runner/venv/lib/python3.7/site-packages/grpc/_channel.py", line 506, in _end_unary_response_blocking
    raise _Rendezvous(state, None, None, deadline)
grpc._channel._Rendezvous: <_Rendezvous of RPC that terminated with:
	status = StatusCode.UNAVAILABLE
	details = "failed to connect to all addresses"
	debug_error_string = "{"created":"@1581168789.585420000","description":"Failed to pick subchannel","file":"src/core/ext/filters/client_channel/client_channel.cc","file_line":3876,"referenced_errors":[{"created":"@1581168788.448010000","description":"failed to connect to all addresses","file":"src/core/ext/filters/client_channel/lb_policy/pick_first/pick_first.cc","file_line":395,"grpc_status":14}]}"
>
2020-02-08 13:33:09,585 INFO download_runner.impl.historical_runner:32 sending - historical data request : AACG 2019-12-01 2020-01-01
2020-02-08 13:33:10,809 INFO download_runner.impl.historical_runner:35 sent - historical data request : AACG 2019-12-01 2020-01-01
2020-02-08 13:33:10,809 DEBUG download_runner.impl.historical_runner:36 request accounted for...
2020-02-08 13:33:10,809 INFO download_runner.impl.historical_runner:37 status : True
2020-02-08 13:33:10,809 INFO download_runner.impl.historical_runner:42 Historical data request sent : AACG 2019-12-01 2020-01-01
2020-02-08 13:33:10,809 DEBUG download_runner.impl.historical_end_reader:37 poll stock ? => True
2020-02-08 13:33:10,809 ERROR root:30 unhandled exception getting latest timestamp for AADR
Traceback (most recent call last):
  File "/Users/dali/workspace/ib_python/runner/services/historical_data_service.py", line 24, in get_latest_timestamp
    response = self.stub.GetLatestTimeStamp(request)
  File "/Users/dali/workspace/ib_python/runner/venv/lib/python3.7/site-packages/grpc/_channel.py", line 604, in __call__
    return _end_unary_response_blocking(state, call, False, None)
  File "/Users/dali/workspace/ib_python/runner/venv/lib/python3.7/site-packages/grpc/_channel.py", line 506, in _end_unary_response_blocking
    raise _Rendezvous(state, None, None, deadline)
grpc._channel._Rendezvous: <_Rendezvous of RPC that terminated with:
	status = StatusCode.UNAVAILABLE
	details = "failed to connect to all addresses"
	debug_error_string = "{"created":"@1581168790.809860000","description":"Failed to pick subchannel","file":"src/core/ext/filters/client_channel/client_channel.cc","file_line":3876,"referenced_errors":[{"created":"@1581168790.809858000","description":"failed to connect to all addresses","file":"src/core/ext/filters/client_channel/lb_policy/pick_first/pick_first.cc","file_line":395,"grpc_status":14}]}"
>
2020-02-08 13:33:10,810 INFO download_runner.impl.historical_runner:32 sending - historical data request : AADR 2019-12-01 2020-01-01
2020-02-08 13:33:12,080 INFO download_runner.impl.historical_runner:35 sent - historical data request : AADR 2019-12-01 2020-01-01
2020-02-08 13:33:12,080 DEBUG download_runner.impl.historical_runner:36 request accounted for...
2020-02-08 13:33:12,080 INFO download_runner.impl.historical_runner:37 status : True
2020-02-08 13:33:12,080 INFO download_runner.impl.historical_runner:42 Historical data request sent : AADR 2019-12-01 2020-01-01
2020-02-08 13:33:12,080 DEBUG download_runner.impl.historical_end_reader:37 poll stock ? => True
2020-02-08 13:33:12,080 ERROR root:30 unhandled exception getting latest timestamp for AAL
Traceback (most recent call last):
  File "/Users/dali/workspace/ib_python/runner/services/historical_data_service.py", line 24, in get_latest_timestamp
    response = self.stub.GetLatestTimeStamp(request)
  File "/Users/dali/workspace/ib_python/runner/venv/lib/python3.7/site-packages/grpc/_channel.py", line 604, in __call__
    return _end_unary_response_blocking(state, call, False, None)
  File "/Users/dali/workspace/ib_python/runner/venv/lib/python3.7/site-packages/grpc/_channel.py", line 506, in _end_unary_response_blocking
    raise _Rendezvous(state, None, None, deadline)
grpc._channel._Rendezvous: <_Rendezvous of RPC that terminated with:
	status = StatusCode.UNAVAILABLE
	details = "failed to connect to all addresses"
	debug_error_string = "{"created":"@1581168792.080673000","description":"Failed to pick subchannel","file":"src/core/ext/filters/client_channel/client_channel.cc","file_line":3876,"referenced_errors":[{"created":"@1581168790.809858000","description":"failed to connect to all addresses","file":"src/core/ext/filters/client_channel/lb_policy/pick_first/pick_first.cc","file_line":395,"grpc_status":14}]}"
>
2020-02-08 13:33:12,080 INFO download_runner.impl.historical_runner:32 sending - historical data request : AAL 2019-12-01 2020-01-01
2020-02-08 13:33:13,466 INFO download_runner.impl.historical_runner:35 sent - historical data request : AAL 2019-12-01 2020-01-01
2020-02-08 13:33:13,466 DEBUG download_runner.impl.historical_runner:36 request accounted for...
2020-02-08 13:33:13,466 INFO download_runner.impl.historical_runner:37 status : True
2020-02-08 13:33:13,466 INFO download_runner.impl.historical_runner:42 Historical data request sent : AAL 2019-12-01 2020-01-01
2020-02-08 13:33:13,466 DEBUG download_runner.impl.historical_end_reader:37 poll stock ? => True
2020-02-08 13:33:13,466 ERROR root:30 unhandled exception getting latest timestamp for AAMC
Traceback (most recent call last):
  File "/Users/dali/workspace/ib_python/runner/services/historical_data_service.py", line 24, in get_latest_timestamp
    response = self.stub.GetLatestTimeStamp(request)
  File "/Users/dali/workspace/ib_python/runner/venv/lib/python3.7/site-packages/grpc/_channel.py", line 604, in __call__
    return _end_unary_response_blocking(state, call, False, None)
  File "/Users/dali/workspace/ib_python/runner/venv/lib/python3.7/site-packages/grpc/_channel.py", line 506, in _end_unary_response_blocking
    raise _Rendezvous(state, None, None, deadline)
grpc._channel._Rendezvous: <_Rendezvous of RPC that terminated with:
	status = StatusCode.UNAVAILABLE
	details = "failed to connect to all addresses"
	debug_error_string = "{"created":"@1581168793.466832000","description":"Failed to pick subchannel","file":"src/core/ext/filters/client_channel/client_channel.cc","file_line":3876,"referenced_errors":[{"created":"@1581168790.809858000","description":"failed to connect to all addresses","file":"src/core/ext/filters/client_channel/lb_policy/pick_first/pick_first.cc","file_line":395,"grpc_status":14}]}"
>
2020-02-08 13:33:13,467 INFO download_runner.impl.historical_runner:32 sending - historical data request : AAMC 2019-12-01 2020-01-01
2020-02-08 13:33:14,709 INFO download_runner.impl.historical_runner:35 sent - historical data request : AAMC 2019-12-01 2020-01-01
2020-02-08 13:33:14,709 DEBUG download_runner.impl.historical_runner:36 request accounted for...
2020-02-08 13:33:14,709 INFO download_runner.impl.historical_runner:37 status : True
2020-02-08 13:33:14,709 INFO download_runner.impl.historical_runner:42 Historical data request sent : AAMC 2019-12-01 2020-01-01
2020-02-08 13:33:14,709 DEBUG download_runner.impl.historical_end_reader:37 poll stock ? => True
2020-02-08 13:33:14,710 ERROR root:30 unhandled exception getting latest timestamp for AAME
Traceback (most recent call last):
  File "/Users/dali/workspace/ib_python/runner/services/historical_data_service.py", line 24, in get_latest_timestamp
    response = self.stub.GetLatestTimeStamp(request)
  File "/Users/dali/workspace/ib_python/runner/venv/lib/python3.7/site-packages/grpc/_channel.py", line 604, in __call__
    return _end_unary_response_blocking(state, call, False, None)
  File "/Users/dali/workspace/ib_python/runner/venv/lib/python3.7/site-packages/grpc/_channel.py", line 506, in _end_unary_response_blocking
    raise _Rendezvous(state, None, None, deadline)
grpc._channel._Rendezvous: <_Rendezvous of RPC that terminated with:
	status = StatusCode.UNAVAILABLE
	details = "failed to connect to all addresses"
	debug_error_string = "{"created":"@1581168794.709994000","description":"Failed to pick subchannel","file":"src/core/ext/filters/client_channel/client_channel.cc","file_line":3876,"referenced_errors":[{"created":"@1581168794.485190000","description":"failed to connect to all addresses","file":"src/core/ext/filters/client_channel/lb_policy/pick_first/pick_first.cc","file_line":395,"grpc_status":14}]}"
>
2020-02-08 13:33:14,710 INFO download_runner.impl.historical_runner:32 sending - historical data request : AAME 2019-12-01 2020-01-01
2020-02-08 13:33:15,935 INFO download_runner.impl.historical_runner:35 sent - historical data request : AAME 2019-12-01 2020-01-01
2020-02-08 13:33:15,935 DEBUG download_runner.impl.historical_runner:36 request accounted for...
2020-02-08 13:33:15,935 INFO download_runner.impl.historical_runner:37 status : True
2020-02-08 13:33:15,935 INFO download_runner.impl.historical_runner:42 Historical data request sent : AAME 2019-12-01 2020-01-01
2020-02-08 13:33:15,935 DEBUG download_runner.impl.historical_end_reader:37 poll stock ? => True
2020-02-08 13:33:15,935 ERROR root:30 unhandled exception getting latest timestamp for AAN
Traceback (most recent call last):
  File "/Users/dali/workspace/ib_python/runner/services/historical_data_service.py", line 24, in get_latest_timestamp
    response = self.stub.GetLatestTimeStamp(request)
  File "/Users/dali/workspace/ib_python/runner/venv/lib/python3.7/site-packages/grpc/_channel.py", line 604, in __call__
    return _end_unary_response_blocking(state, call, False, None)
  File "/Users/dali/workspace/ib_python/runner/venv/lib/python3.7/site-packages/grpc/_channel.py", line 506, in _end_unary_response_blocking
    raise _Rendezvous(state, None, None, deadline)
grpc._channel._Rendezvous: <_Rendezvous of RPC that terminated with:
	status = StatusCode.UNAVAILABLE
	details = "failed to connect to all addresses"
	debug_error_string = "{"created":"@1581168795.935897000","description":"Failed to pick subchannel","file":"src/core/ext/filters/client_channel/client_channel.cc","file_line":3876,"referenced_errors":[{"created":"@1581168794.485190000","description":"failed to connect to all addresses","file":"src/core/ext/filters/client_channel/lb_policy/pick_first/pick_first.cc","file_line":395,"grpc_status":14}]}"
>
2020-02-08 13:33:15,936 INFO download_runner.impl.historical_runner:32 sending - historical data request : AAN 2019-12-01 2020-01-01
2020-02-08 13:33:17,015 INFO download_runner.impl.historical_runner:35 sent - historical data request : AAN 2019-12-01 2020-01-01
2020-02-08 13:33:17,015 DEBUG download_runner.impl.historical_runner:36 request accounted for...
2020-02-08 13:33:17,015 INFO download_runner.impl.historical_runner:37 status : True
2020-02-08 13:33:17,015 INFO download_runner.impl.historical_runner:42 Historical data request sent : AAN 2019-12-01 2020-01-01
2020-02-08 13:33:17,015 DEBUG download_runner.impl.historical_end_reader:37 poll stock ? => True
2020-02-08 13:33:17,015 ERROR root:30 unhandled exception getting latest timestamp for AAOI
Traceback (most recent call last):
  File "/Users/dali/workspace/ib_python/runner/services/historical_data_service.py", line 24, in get_latest_timestamp
    response = self.stub.GetLatestTimeStamp(request)
  File "/Users/dali/workspace/ib_python/runner/venv/lib/python3.7/site-packages/grpc/_channel.py", line 604, in __call__
    return _end_unary_response_blocking(state, call, False, None)
  File "/Users/dali/workspace/ib_python/runner/venv/lib/python3.7/site-packages/grpc/_channel.py", line 506, in _end_unary_response_blocking
    raise _Rendezvous(state, None, None, deadline)
grpc._channel._Rendezvous: <_Rendezvous of RPC that terminated with:
	status = StatusCode.UNAVAILABLE
	details = "failed to connect to all addresses"
	debug_error_string = "{"created":"@1581168797.015555000","description":"Failed to pick subchannel","file":"src/core/ext/filters/client_channel/client_channel.cc","file_line":3876,"referenced_errors":[{"created":"@1581168794.485190000","description":"failed to connect to all addresses","file":"src/core/ext/filters/client_channel/lb_policy/pick_first/pick_first.cc","file_line":395,"grpc_status":14}]}"
>
2020-02-08 13:33:17,015 INFO download_runner.impl.historical_runner:32 sending - historical data request : AAOI 2019-12-01 2020-01-01
2020-02-08 13:33:18,070 INFO download_runner.impl.historical_runner:35 sent - historical data request : AAOI 2019-12-01 2020-01-01
2020-02-08 13:33:18,070 DEBUG download_runner.impl.historical_runner:36 request accounted for...
2020-02-08 13:33:18,070 INFO download_runner.impl.historical_runner:37 status : True
2020-02-08 13:33:18,070 INFO download_runner.impl.historical_runner:42 Historical data request sent : AAOI 2019-12-01 2020-01-01
2020-02-08 13:33:18,070 DEBUG download_runner.impl.historical_end_reader:37 poll stock ? => True
2020-02-08 13:33:18,070 ERROR root:30 unhandled exception getting latest timestamp for AAON
Traceback (most recent call last):
  File "/Users/dali/workspace/ib_python/runner/services/historical_data_service.py", line 24, in get_latest_timestamp
    response = self.stub.GetLatestTimeStamp(request)
  File "/Users/dali/workspace/ib_python/runner/venv/lib/python3.7/site-packages/grpc/_channel.py", line 604, in __call__
    return _end_unary_response_blocking(state, call, False, None)
  File "/Users/dali/workspace/ib_python/runner/venv/lib/python3.7/site-packages/grpc/_channel.py", line 506, in _end_unary_response_blocking
    raise _Rendezvous(state, None, None, deadline)
grpc._channel._Rendezvous: <_Rendezvous of RPC that terminated with:
	status = StatusCode.UNAVAILABLE
	details = "failed to connect to all addresses"
	debug_error_string = "{"created":"@1581168798.070904000","description":"Failed to pick subchannel","file":"src/core/ext/filters/client_channel/client_channel.cc","file_line":3876,"referenced_errors":[{"created":"@1581168794.485190000","description":"failed to connect to all addresses","file":"src/core/ext/filters/client_channel/lb_policy/pick_first/pick_first.cc","file_line":395,"grpc_status":14}]}"
>
2020-02-08 13:33:18,071 INFO download_runner.impl.historical_runner:32 sending - historical data request : AAON 2019-12-01 2020-01-01
2020-02-08 13:33:19,091 INFO download_runner.impl.historical_runner:35 sent - historical data request : AAON 2019-12-01 2020-01-01
2020-02-08 13:33:19,091 DEBUG download_runner.impl.historical_runner:36 request accounted for...
2020-02-08 13:33:19,092 INFO download_runner.impl.historical_runner:37 status : True
2020-02-08 13:33:19,092 INFO download_runner.impl.historical_runner:42 Historical data request sent : AAON 2019-12-01 2020-01-01
2020-02-08 13:33:19,092 DEBUG download_runner.impl.historical_end_reader:37 poll stock ? => True
2020-02-08 13:33:19,092 ERROR root:30 unhandled exception getting latest timestamp for AAP
Traceback (most recent call last):
  File "/Users/dali/workspace/ib_python/runner/services/historical_data_service.py", line 24, in get_latest_timestamp
    response = self.stub.GetLatestTimeStamp(request)
  File "/Users/dali/workspace/ib_python/runner/venv/lib/python3.7/site-packages/grpc/_channel.py", line 604, in __call__
    return _end_unary_response_blocking(state, call, False, None)
  File "/Users/dali/workspace/ib_python/runner/venv/lib/python3.7/site-packages/grpc/_channel.py", line 506, in _end_unary_response_blocking
    raise _Rendezvous(state, None, None, deadline)
grpc._channel._Rendezvous: <_Rendezvous of RPC that terminated with:
	status = StatusCode.UNAVAILABLE
	details = "failed to connect to all addresses"
	debug_error_string = "{"created":"@1581168799.092275000","description":"Failed to pick subchannel","file":"src/core/ext/filters/client_channel/client_channel.cc","file_line":3876,"referenced_errors":[{"created":"@1581168794.485190000","description":"failed to connect to all addresses","file":"src/core/ext/filters/client_channel/lb_policy/pick_first/pick_first.cc","file_line":395,"grpc_status":14}]}"
>
2020-02-08 13:33:19,092 INFO download_runner.impl.historical_runner:32 sending - historical data request : AAP 2019-12-01 2020-01-01
2020-02-08 13:33:20,225 INFO download_runner.impl.historical_runner:35 sent - historical data request : AAP 2019-12-01 2020-01-01
2020-02-08 13:33:20,225 DEBUG download_runner.impl.historical_runner:36 request accounted for...
2020-02-08 13:33:20,225 INFO download_runner.impl.historical_runner:37 status : True
2020-02-08 13:33:20,225 INFO download_runner.impl.historical_runner:42 Historical data request sent : AAP 2019-12-01 2020-01-01
2020-02-08 13:33:20,225 DEBUG download_runner.impl.historical_end_reader:37 poll stock ? => True
2020-02-08 13:33:20,225 ERROR root:30 unhandled exception getting latest timestamp for AAPL
Traceback (most recent call last):
  File "/Users/dali/workspace/ib_python/runner/services/historical_data_service.py", line 24, in get_latest_timestamp
    response = self.stub.GetLatestTimeStamp(request)
  File "/Users/dali/workspace/ib_python/runner/venv/lib/python3.7/site-packages/grpc/_channel.py", line 604, in __call__
    return _end_unary_response_blocking(state, call, False, None)
  File "/Users/dali/workspace/ib_python/runner/venv/lib/python3.7/site-packages/grpc/_channel.py", line 506, in _end_unary_response_blocking
    raise _Rendezvous(state, None, None, deadline)
grpc._channel._Rendezvous: <_Rendezvous of RPC that terminated with:
	status = StatusCode.UNAVAILABLE
	details = "failed to connect to all addresses"
	debug_error_string = "{"created":"@1581168800.225599000","description":"Failed to pick subchannel","file":"src/core/ext/filters/client_channel/client_channel.cc","file_line":3876,"referenced_errors":[{"created":"@1581168794.485190000","description":"failed to connect to all addresses","file":"src/core/ext/filters/client_channel/lb_policy/pick_first/pick_first.cc","file_line":395,"grpc_status":14}]}"
>
2020-02-08 13:33:20,225 INFO download_runner.impl.historical_runner:32 sending - historical data request : AAPL 2019-12-01 2020-01-01
2020-02-08 13:33:21,485 INFO download_runner.impl.historical_runner:35 sent - historical data request : AAPL 2019-12-01 2020-01-01
2020-02-08 13:33:21,485 DEBUG download_runner.impl.historical_runner:36 request accounted for...
2020-02-08 13:33:21,485 INFO download_runner.impl.historical_runner:37 status : True
2020-02-08 13:33:21,485 INFO download_runner.impl.historical_runner:42 Historical data request sent : AAPL 2019-12-01 2020-01-01
2020-02-08 13:33:21,485 DEBUG download_runner.impl.historical_end_reader:37 poll stock ? => True
2020-02-08 13:33:21,486 ERROR root:30 unhandled exception getting latest timestamp for AAT
Traceback (most recent call last):
  File "/Users/dali/workspace/ib_python/runner/services/historical_data_service.py", line 24, in get_latest_timestamp
    response = self.stub.GetLatestTimeStamp(request)
  File "/Users/dali/workspace/ib_python/runner/venv/lib/python3.7/site-packages/grpc/_channel.py", line 604, in __call__
    return _end_unary_response_blocking(state, call, False, None)
  File "/Users/dali/workspace/ib_python/runner/venv/lib/python3.7/site-packages/grpc/_channel.py", line 506, in _end_unary_response_blocking
    raise _Rendezvous(state, None, None, deadline)
grpc._channel._Rendezvous: <_Rendezvous of RPC that terminated with:
	status = StatusCode.UNAVAILABLE
	details = "failed to connect to all addresses"
	debug_error_string = "{"created":"@1581168801.486082000","description":"Failed to pick subchannel","file":"src/core/ext/filters/client_channel/client_channel.cc","file_line":3876,"referenced_errors":[{"created":"@1581168801.486080000","description":"failed to connect to all addresses","file":"src/core/ext/filters/client_channel/lb_policy/pick_first/pick_first.cc","file_line":395,"grpc_status":14}]}"
>
2020-02-08 13:33:21,486 INFO download_runner.impl.historical_runner:32 sending - historical data request : AAT 2019-12-01 2020-01-01
2020-02-08 13:33:22,523 INFO download_runner.impl.historical_runner:35 sent - historical data request : AAT 2019-12-01 2020-01-01
2020-02-08 13:33:22,523 DEBUG download_runner.impl.historical_runner:36 request accounted for...
2020-02-08 13:33:22,523 INFO download_runner.impl.historical_runner:37 status : True
2020-02-08 13:33:22,523 INFO download_runner.impl.historical_runner:42 Historical data request sent : AAT 2019-12-01 2020-01-01
2020-02-08 13:33:22,523 DEBUG download_runner.impl.historical_end_reader:37 poll stock ? => True
2020-02-08 13:33:22,523 ERROR root:30 unhandled exception getting latest timestamp for AAU
Traceback (most recent call last):
  File "/Users/dali/workspace/ib_python/runner/services/historical_data_service.py", line 24, in get_latest_timestamp
    response = self.stub.GetLatestTimeStamp(request)
  File "/Users/dali/workspace/ib_python/runner/venv/lib/python3.7/site-packages/grpc/_channel.py", line 604, in __call__
    return _end_unary_response_blocking(state, call, False, None)
  File "/Users/dali/workspace/ib_python/runner/venv/lib/python3.7/site-packages/grpc/_channel.py", line 506, in _end_unary_response_blocking
    raise _Rendezvous(state, None, None, deadline)
grpc._channel._Rendezvous: <_Rendezvous of RPC that terminated with:
	status = StatusCode.UNAVAILABLE
	details = "failed to connect to all addresses"
	debug_error_string = "{"created":"@1581168802.523786000","description":"Failed to pick subchannel","file":"src/core/ext/filters/client_channel/client_channel.cc","file_line":3876,"referenced_errors":[{"created":"@1581168801.486080000","description":"failed to connect to all addresses","file":"src/core/ext/filters/client_channel/lb_policy/pick_first/pick_first.cc","file_line":395,"grpc_status":14}]}"
>
2020-02-08 13:33:22,524 INFO download_runner.impl.historical_runner:32 sending - historical data request : AAU 2019-12-01 2020-01-01
2020-02-08 13:33:24,050 INFO download_runner.impl.historical_runner:35 sent - historical data request : AAU 2019-12-01 2020-01-01
2020-02-08 13:33:24,050 DEBUG download_runner.impl.historical_runner:36 request accounted for...
2020-02-08 13:33:24,050 INFO download_runner.impl.historical_runner:37 status : True
2020-02-08 13:33:24,050 INFO download_runner.impl.historical_runner:42 Historical data request sent : AAU 2019-12-01 2020-01-01
2020-02-08 13:33:24,050 DEBUG download_runner.impl.historical_end_reader:37 poll stock ? => True
2020-02-08 13:33:24,050 ERROR root:30 unhandled exception getting latest timestamp for AAWW
Traceback (most recent call last):
  File "/Users/dali/workspace/ib_python/runner/services/historical_data_service.py", line 24, in get_latest_timestamp
    response = self.stub.GetLatestTimeStamp(request)
  File "/Users/dali/workspace/ib_python/runner/venv/lib/python3.7/site-packages/grpc/_channel.py", line 604, in __call__
    return _end_unary_response_blocking(state, call, False, None)
  File "/Users/dali/workspace/ib_python/runner/venv/lib/python3.7/site-packages/grpc/_channel.py", line 506, in _end_unary_response_blocking
    raise _Rendezvous(state, None, None, deadline)
grpc._channel._Rendezvous: <_Rendezvous of RPC that terminated with:
	status = StatusCode.UNAVAILABLE
	details = "failed to connect to all addresses"
	debug_error_string = "{"created":"@1581168804.050637000","description":"Failed to pick subchannel","file":"src/core/ext/filters/client_channel/client_channel.cc","file_line":3876,"referenced_errors":[{"created":"@1581168801.486080000","description":"failed to connect to all addresses","file":"src/core/ext/filters/client_channel/lb_policy/pick_first/pick_first.cc","file_line":395,"grpc_status":14}]}"
>
2020-02-08 13:33:24,050 INFO download_runner.impl.historical_runner:32 sending - historical data request : AAWW 2019-12-01 2020-01-01
